Workbook

Sheet Sensitivity_Summary
B1: =Class_0!B1 -> features.0.0 | C1: =Class_0!C1 -> features.1.block.0.0 | D1: =Class_0!D1 -> features.1.block.1.0 | E1: =Class_0!E1 -> features.2.block.0.0 | F1: =Class_0!F1 -> features.2.block.1.0 | G1: =Class_0!G1 -> features.2.block.2.0 | H1: =Class_0!H1 -> features.3.block.0.0 | I1: =Class_0!I1 -> features.3.block.1.0 | ... BN1: =Class_0!BN1 -> 0
A2: Deer | B2: =Class_0!B63 -> -0.028542533 | C2: =Class_0!C63 -> -0.19381575 | D2: =Class_0!D63 -> -0.071066833 | E2: =Class_0!E63 -> -0.067782806 | F2: =Class_0!F63 -> -0.010712568 | G2: =Class_0!G63 -> -0.048627278 | H2: =Class_0!H63 -> -0.081474864 | I2: =Class_0!I63 -> -0.10789436 | ... BK2: =Class_0!BK63 -> 1
A3: Horse | B3: =Class_1!B63 -> 0.039765279 | C3: =Class_1!C63 -> 0.12929664 | D3: =Class_1!D63 -> -0.10296702 | E3: =Class_1!E63 -> -0.14549448 | F3: =Class_1!F63 -> -0.089636929 | G3: =Class_1!G63 -> 0.037870565 | H3: =Class_1!H63 -> 0.052973586 | I3: =Class_1!I63 -> 0.012168615 | ... BK3: =Class_1!BK63 -> 1
A4: Zebra | B4: =Class_2!B63 -> -0.08819484 | C4: =Class_2!C63 -> -0.0024580566 | D4: =Class_2!D63 -> 0.0013685613 | E4: =Class_2!E63 -> 0.005025338 | F4: =Class_2!F63 -> -0.019738215 | G4: =Class_2!G63 -> -0.10103492 | H4: =Class_2!H63 -> 0.02853013 | I4: =Class_2!I63 -> -0.081829279 | ... BK4: =Class_2!BK63 -> 1
A6: Overall corelation | B6: =MIN(B2:B4) -> -0.08819484 | C6: =MIN(C2:C4) -> -0.19381575 | D6: =MIN(D2:D4) -> -0.10296702 | E6: =MIN(E2:E4) -> -0.14549448 | F6: =MIN(F2:F4) -> -0.089636929 | G6: =MIN(G2:G4) -> -0.10103492 | H6: =MIN(H2:H4) -> -0.081474864 | I6: =MIN(I2:I4) -> -0.10789436 | ... BJ6: =MIN(BJ2:BJ4) -> 0.26742613
B7: =IF(AND(B2>0,B3>0,B4>0),TRUE,FALSE) -> FALSE | C7: =IF(AND(C2>0,C3>0,C4>0),TRUE,FALSE) -> FALSE | D7: =IF(AND(D2>0,D3>0,D4>0),TRUE,FALSE) -> FALSE | E7: =IF(AND(E2>0,E3>0,E4>0),TRUE,FALSE) -> FALSE | F7: =IF(AND(F2>0,F3>0,F4>0),TRUE,FALSE) -> FALSE | G7: =IF(AND(G2>0,G3>0,G4>0),TRUE,FALSE) -> FALSE | H7: =IF(AND(H2>0,H3>0,H4>0),TRUE,FALSE) -> FALSE | I7: =IF(AND(I2>0,I3>0,I4>0),TRUE,FALSE) -> FALSE | ... BJ7: =IF(AND(BJ2>0,BJ3>0,BJ4>0),TRUE,FALSE) -> TRUE
A8: Max Corelation layer | B8: =MAX(B4:BI6) -> 0.44813417
A9: Affects 2 classes | B9: =IF(OR(AND(B2>0,B3>0), AND(B2>0,B4>0), AND(B3>0,B4>0)), TRUE, FALSE) -> FALSE | C9: =IF(OR(AND(C2>0,C3>0), AND(C2>0,C4>0), AND(C3>0,C4>0)), TRUE, FALSE) -> FALSE | D9: =IF(OR(AND(D2>0,D3>0), AND(D2>0,D4>0), AND(D3>0,D4>0)), TRUE, FALSE) -> FALSE | E9: =IF(OR(AND(E2>0,E3>0), AND(E2>0,E4>0), AND(E3>0,E4>0)), TRUE, FALSE) -> FALSE | F9: =IF(OR(AND(F2>0,F3>0), AND(F2>0,F4>0), AND(F3>0,F4>0)), TRUE, FALSE) -> FALSE | G9: =IF(OR(AND(G2>0,G3>0), AND(G2>0,G4>0), AND(G3>0,G4>0)), TRUE, FALSE) -> FALSE | H9: =IF(OR(AND(H2>0,H3>0), AND(H2>0,H4>0), AND(H3>0,H4>0)), TRUE, FALSE) -> TRUE | I9: =IF(OR(AND(I2>0,I3>0), AND(I2>0,I4>0), AND(I3>0,I4>0)), TRUE, FALSE) -> FALSE | ... BJ9: =IF(OR(AND(BJ2>0,BJ3>0), AND(BJ2>0,BJ4>0), AND(BJ3>0,BJ4>0)), TRUE, FALSE) -> TRUE
B11: =IF(B7=TRUE,B1,"") | C11: =IF(C7=TRUE,C1,"") | D11: =IF(D7=TRUE,D1,"") | E11: =IF(E7=TRUE,E1,"") | F11: =IF(F7=TRUE,F1,"") | G11: =IF(G7=TRUE,G1,"") | H11: =IF(H7=TRUE,H1,"") | I11: =IF(I7=TRUE,I1,"") | ... BJ11: =IF(BJ7=TRUE,BJ1,"") -> features.15.block.3.0
B14: features.5.block.0.0 | D14: '
B15: features.5.block.2.fc1
B16: features.5.block.2.fc2
B17: features.6.block.2.fc1
B18: features.8.block.1.0
B19: features.11.block.3.0
B20: features.12.block.0.0
B21: features.12.block.3.0
B22: features.13.block.2.fc2
B23: features.13.block.3.0
B24: features.15.block.0.0
B25: features.15.block.2.fc2
B26: features.15.block.3.0
D35: 0 | E35: =D35+1 -> 1 | F35: =E35+1 -> 2 | G35: =F35+1 -> 3 | H35: =G35+1 -> 4 | I35: =H35+1 -> 5 | J35: =I35+1 -> 6 | K35: =J35+1 -> 7 | L35: =K35+1 -> 8 | ... BM35: =BL35+1 -> 61
B36: features.0.0 | C36: 0 | D36: =IF(MIN(Class_0!B2,Class_1!B2,Class_2!B2)>0,CHAR(43),CHAR(45)) -> +
B37: features.1.block.0.0 | C37: =C36+1 -> 1 | D37: =IF(MIN(Class_0!B3,Class_1!B3,Class_2!B3)>0,CHAR(43),CHAR(45)) -> + | E37: =IF(MIN(Class_0!C3,Class_1!C3,Class_2!C3)>0,CHAR(43),CHAR(45)) -> + | AT37: =IF(MIN(Class_0!AR3,Class_1!AR3,Class_2!AR3)>0,CHAR(43),CHAR(45)) -> -
B38: features.1.block.1.0 | C38: =C37+1 -> 2 | D38: =IF(MIN(Class_0!B4,Class_1!B4,Class_2!B4)>0,CHAR(43),CHAR(45)) -> - | E38: =IF(MIN(Class_0!C4,Class_1!C4,Class_2!C4)>0,CHAR(43),CHAR(45)) -> - | F38: =IF(MIN(Class_0!D4,Class_1!D4,Class_2!D4)>0,CHAR(43),CHAR(45)) -> +
B39: features.2.block.0.0 | C39: =C38+1 -> 3 | D39: =IF(MIN(Class_0!B5,Class_1!B5,Class_2!B5)>0,CHAR(43),CHAR(45)) -> + | E39: =IF(MIN(Class_0!C5,Class_1!C5,Class_2!C5)>0,CHAR(43),CHAR(45)) -> - | F39: =IF(MIN(Class_0!D5,Class_1!D5,Class_2!D5)>0,CHAR(43),CHAR(45)) -> + | G39: =IF(MIN(Class_0!E5,Class_1!E5,Class_2!E5)>0,CHAR(43),CHAR(45)) -> +
B40: features.2.block.1.0 | C40: =C39+1 -> 4 | D40: =IF(MIN(Class_0!B6,Class_1!B6,Class_2!B6)>0,CHAR(43),CHAR(45)) -> + | E40: =IF(MIN(Class_0!C6,Class_1!C6,Class_2!C6)>0,CHAR(43),CHAR(45)) -> - | F40: =IF(MIN(Class_0!D6,Class_1!D6,Class_2!D6)>0,CHAR(43),CHAR(45)) -> + | G40: =IF(MIN(Class_0!E6,Class_1!E6,Class_2!E6)>0,CHAR(43),CHAR(45)) -> + | H40: =IF(MIN(Class_0!F6,Class_1!F6,Class_2!F6)>0,CHAR(43),CHAR(45)) -> + | Z40: =IF(MIN(Class_0!X6,Class_1!X6,Class_2!X6)>0,CHAR(43),CHAR(45)) -> -
B41: features.2.block.2.0 | C41: =C40+1 -> 5 | D41: =IF(MIN(Class_0!B7,Class_1!B7,Class_2!B7)>0,CHAR(43),CHAR(45)) -> + | E41: =IF(MIN(Class_0!C7,Class_1!C7,Class_2!C7)>0,CHAR(43),CHAR(45)) -> - | F41: =IF(MIN(Class_0!D7,Class_1!D7,Class_2!D7)>0,CHAR(43),CHAR(45)) -> + | G41: =IF(MIN(Class_0!E7,Class_1!E7,Class_2!E7)>0,CHAR(43),CHAR(45)) -> + | H41: =IF(MIN(Class_0!F7,Class_1!F7,Class_2!F7)>0,CHAR(43),CHAR(45)) -> + | I41: =IF(MIN(Class_0!G7,Class_1!G7,Class_2!G7)>0,CHAR(43),CHAR(45)) -> +
B42: features.3.block.0.0 | C42: =C41+1 -> 6 | D42: =IF(MIN(Class_0!B8,Class_1!B8,Class_2!B8)>0,CHAR(43),CHAR(45)) -> - | E42: =IF(MIN(Class_0!C8,Class_1!C8,Class_2!C8)>0,CHAR(43),CHAR(45)) -> - | F42: =IF(MIN(Class_0!D8,Class_1!D8,Class_2!D8)>0,CHAR(43),CHAR(45)) -> - | G42: =IF(MIN(Class_0!E8,Class_1!E8,Class_2!E8)>0,CHAR(43),CHAR(45)) -> - | H42: =IF(MIN(Class_0!F8,Class_1!F8,Class_2!F8)>0,CHAR(43),CHAR(45)) -> - | I42: =IF(MIN(Class_0!G8,Class_1!G8,Class_2!G8)>0,CHAR(43),CHAR(45)) -> - | J42: =IF(MIN(Class_0!H8,Class_1!H8,Class_2!H8)>0,CHAR(43),CHAR(45)) -> +
B43: features.3.block.1.0 | C43: =C42+1 -> 7 | D43: =IF(MIN(Class_0!B9,Class_1!B9,Class_2!B9)>0,CHAR(43),CHAR(45)) -> + | E43: =IF(MIN(Class_0!C9,Class_1!C9,Class_2!C9)>0,CHAR(43),CHAR(45)) -> + | F43: =IF(MIN(Class_0!D9,Class_1!D9,Class_2!D9)>0,CHAR(43),CHAR(45)) -> - | G43: =IF(MIN(Class_0!E9,Class_1!E9,Class_2!E9)>0,CHAR(43),CHAR(45)) -> - | H43: =IF(MIN(Class_0!F9,Class_1!F9,Class_2!F9)>0,CHAR(43),CHAR(45)) -> - | I43: =IF(MIN(Class_0!G9,Class_1!G9,Class_2!G9)>0,CHAR(43),CHAR(45)) -> + | J43: =IF(MIN(Class_0!H9,Class_1!H9,Class_2!H9)>0,CHAR(43),CHAR(45)) -> + | K43: =IF(MIN(Class_0!I9,Class_1!I9,Class_2!I9)>0,CHAR(43),CHAR(45)) -> +
B44: features.3.block.2.0 | C44: =C43+1 -> 8 | D44: =IF(MIN(Class_0!B10,Class_1!B10,Class_2!B10)>0,CHAR(43),CHAR(45)) -> + | E44: =IF(MIN(Class_0!C10,Class_1!C10,Class_2!C10)>0,CHAR(43),CHAR(45)) -> - | F44: =IF(MIN(Class_0!D10,Class_1!D10,Class_2!D10)>0,CHAR(43),CHAR(45)) -> - | G44: =IF(MIN(Class_0!E10,Class_1!E10,Class_2!E10)>0,CHAR(43),CHAR(45)) -> - | H44: =IF(MIN(Class_0!F10,Class_1!F10,Class_2!F10)>0,CHAR(43),CHAR(45)) -> - | I44: =IF(MIN(Class_0!G10,Class_1!G10,Class_2!G10)>0,CHAR(43),CHAR(45)) -> - | J44: =IF(MIN(Class_0!H10,Class_1!H10,Class_2!H10)>0,CHAR(43),CHAR(45)) -> + | K44: =IF(MIN(Class_0!I10,Class_1!I10,Class_2!I10)>0,CHAR(43),CHAR(45)) -> + | L44: =IF(MIN(Class_0!J10,Class_1!J10,Class_2!J10)>0,CHAR(43),CHAR(45)) -> +
B45: features.4.block.0.0 | C45: =C44+1 -> 9 | D45: =IF(MIN(Class_0!B11,Class_1!B11,Class_2!B11)>0,CHAR(43),CHAR(45)) -> + | E45: =IF(MIN(Class_0!C11,Class_1!C11,Class_2!C11)>0,CHAR(43),CHAR(45)) -> - | F45: =IF(MIN(Class_0!D11,Class_1!D11,Class_2!D11)>0,CHAR(43),CHAR(45)) -> + | G45: =IF(MIN(Class_0!E11,Class_1!E11,Class_2!E11)>0,CHAR(43),CHAR(45)) -> + | H45: =IF(MIN(Class_0!F11,Class_1!F11,Class_2!F11)>0,CHAR(43),CHAR(45)) -> + | I45: =IF(MIN(Class_0!G11,Class_1!G11,Class_2!G11)>0,CHAR(43),CHAR(45)) -> + | J45: =IF(MIN(Class_0!H11,Class_1!H11,Class_2!H11)>0,CHAR(43),CHAR(45)) -> - | K45: =IF(MIN(Class_0!I11,Class_1!I11,Class_2!I11)>0,CHAR(43),CHAR(45)) -> - | ... M45: =IF(MIN(Class_0!K11,Class_1!K11,Class_2!K11)>0,CHAR(43),CHAR(45)) -> +
B46: features.4.block.1.0 | C46: =C45+1 -> 10 | D46: =IF(MIN(Class_0!B12,Class_1!B12,Class_2!B12)>0,CHAR(43),CHAR(45)) -> + | E46: =IF(MIN(Class_0!C12,Class_1!C12,Class_2!C12)>0,CHAR(43),CHAR(45)) -> - | F46: =IF(MIN(Class_0!D12,Class_1!D12,Class_2!D12)>0,CHAR(43),CHAR(45)) -> + | G46: =IF(MIN(Class_0!E12,Class_1!E12,Class_2!E12)>0,CHAR(43),CHAR(45)) -> + | H46: =IF(MIN(Class_0!F12,Class_1!F12,Class_2!F12)>0,CHAR(43),CHAR(45)) -> + | I46: =IF(MIN(Class_0!G12,Class_1!G12,Class_2!G12)>0,CHAR(43),CHAR(45)) -> + | J46: =IF(MIN(Class_0!H12,Class_1!H12,Class_2!H12)>0,CHAR(43),CHAR(45)) -> - | K46: =IF(MIN(Class_0!I12,Class_1!I12,Class_2!I12)>0,CHAR(43),CHAR(45)) -> - | ... N46: =IF(MIN(Class_0!L12,Class_1!L12,Class_2!L12)>0,CHAR(43),CHAR(45)) -> +
B47: features.4.block.2.fc1 | C47: =C46+1 -> 11 | D47: =IF(MIN(Class_0!B13,Class_1!B13,Class_2!B13)>0,CHAR(43),CHAR(45)) -> + | E47: =IF(MIN(Class_0!C13,Class_1!C13,Class_2!C13)>0,CHAR(43),CHAR(45)) -> - | F47: =IF(MIN(Class_0!D13,Class_1!D13,Class_2!D13)>0,CHAR(43),CHAR(45)) -> + | G47: =IF(MIN(Class_0!E13,Class_1!E13,Class_2!E13)>0,CHAR(43),CHAR(45)) -> + | H47: =IF(MIN(Class_0!F13,Class_1!F13,Class_2!F13)>0,CHAR(43),CHAR(45)) -> + | I47: =IF(MIN(Class_0!G13,Class_1!G13,Class_2!G13)>0,CHAR(43),CHAR(45)) -> - | J47: =IF(MIN(Class_0!H13,Class_1!H13,Class_2!H13)>0,CHAR(43),CHAR(45)) -> - | K47: =IF(MIN(Class_0!I13,Class_1!I13,Class_2!I13)>0,CHAR(43),CHAR(45)) -> - | ... O47: =IF(MIN(Class_0!M13,Class_1!M13,Class_2!M13)>0,CHAR(43),CHAR(45)) -> +
B48: features.4.block.2.fc2 | C48: =C47+1 -> 12 | D48: =IF(MIN(Class_0!B14,Class_1!B14,Class_2!B14)>0,CHAR(43),CHAR(45)) -> - | E48: =IF(MIN(Class_0!C14,Class_1!C14,Class_2!C14)>0,CHAR(43),CHAR(45)) -> - | F48: =IF(MIN(Class_0!D14,Class_1!D14,Class_2!D14)>0,CHAR(43),CHAR(45)) -> - | G48: =IF(MIN(Class_0!E14,Class_1!E14,Class_2!E14)>0,CHAR(43),CHAR(45)) -> - | H48: =IF(MIN(Class_0!F14,Class_1!F14,Class_2!F14)>0,CHAR(43),CHAR(45)) -> - | I48: =IF(MIN(Class_0!G14,Class_1!G14,Class_2!G14)>0,CHAR(43),CHAR(45)) -> - | J48: =IF(MIN(Class_0!H14,Class_1!H14,Class_2!H14)>0,CHAR(43),CHAR(45)) -> - | K48: =IF(MIN(Class_0!I14,Class_1!I14,Class_2!I14)>0,CHAR(43),CHAR(45)) -> - | ... P48: =IF(MIN(Class_0!N14,Class_1!N14,Class_2!N14)>0,CHAR(43),CHAR(45)) -> +
B49: features.4.block.3.0 | C49: =C48+1 -> 13 | D49: =IF(MIN(Class_0!B15,Class_1!B15,Class_2!B15)>0,CHAR(43),CHAR(45)) -> + | E49: =IF(MIN(Class_0!C15,Class_1!C15,Class_2!C15)>0,CHAR(43),CHAR(45)) -> - | F49: =IF(MIN(Class_0!D15,Class_1!D15,Class_2!D15)>0,CHAR(43),CHAR(45)) -> + | G49: =IF(MIN(Class_0!E15,Class_1!E15,Class_2!E15)>0,CHAR(43),CHAR(45)) -> + | H49: =IF(MIN(Class_0!F15,Class_1!F15,Class_2!F15)>0,CHAR(43),CHAR(45)) -> + | I49: =IF(MIN(Class_0!G15,Class_1!G15,Class_2!G15)>0,CHAR(43),CHAR(45)) -> + | J49: =IF(MIN(Class_0!H15,Class_1!H15,Class_2!H15)>0,CHAR(43),CHAR(45)) -> - | K49: =IF(MIN(Class_0!I15,Class_1!I15,Class_2!I15)>0,CHAR(43),CHAR(45)) -> - | ... Q49: =IF(MIN(Class_0!O15,Class_1!O15,Class_2!O15)>0,CHAR(43),CHAR(45)) -> +
B50: features.5.block.0.0 | C50: =C49+1 -> 14 | D50: =IF(MIN(Class_0!B16,Class_1!B16,Class_2!B16)>0,CHAR(43),CHAR(45)) -> - | E50: =IF(MIN(Class_0!C16,Class_1!C16,Class_2!C16)>0,CHAR(43),CHAR(45)) -> - | F50: =IF(MIN(Class_0!D16,Class_1!D16,Class_2!D16)>0,CHAR(43),CHAR(45)) -> + | G50: =IF(MIN(Class_0!E16,Class_1!E16,Class_2!E16)>0,CHAR(43),CHAR(45)) -> + | H50: =IF(MIN(Class_0!F16,Class_1!F16,Class_2!F16)>0,CHAR(43),CHAR(45)) -> + | I50: =IF(MIN(Class_0!G16,Class_1!G16,Class_2!G16)>0,CHAR(43),CHAR(45)) -> + | J50: =IF(MIN(Class_0!H16,Class_1!H16,Class_2!H16)>0,CHAR(43),CHAR(45)) -> - | K50: =IF(MIN(Class_0!I16,Class_1!I16,Class_2!I16)>0,CHAR(43),CHAR(45)) -> - | ... R50: =IF(MIN(Class_0!P16,Class_1!P16,Class_2!P16)>0,CHAR(43),CHAR(45)) -> +
B51: features.5.block.1.0 | C51: =C50+1 -> 15 | D51: =IF(MIN(Class_0!B17,Class_1!B17,Class_2!B17)>0,CHAR(43),CHAR(45)) -> - | E51: =IF(MIN(Class_0!C17,Class_1!C17,Class_2!C17)>0,CHAR(43),CHAR(45)) -> + | F51: =IF(MIN(Class_0!D17,Class_1!D17,Class_2!D17)>0,CHAR(43),CHAR(45)) -> - | G51: =IF(MIN(Class_0!E17,Class_1!E17,Class_2!E17)>0,CHAR(43),CHAR(45)) -> - | H51: =IF(MIN(Class_0!F17,Class_1!F17,Class_2!F17)>0,CHAR(43),CHAR(45)) -> - | I51: =IF(MIN(Class_0!G17,Class_1!G17,Class_2!G17)>0,CHAR(43),CHAR(45)) -> - | J51: =IF(MIN(Class_0!H17,Class_1!H17,Class_2!H17)>0,CHAR(43),CHAR(45)) -> + | K51: =IF(MIN(Class_0!I17,Class_1!I17,Class_2!I17)>0,CHAR(43),CHAR(45)) -> - | ... S51: =IF(MIN(Class_0!Q17,Class_1!Q17,Class_2!Q17)>0,CHAR(43),CHAR(45)) -> +
B52: features.5.block.2.fc1 | C52: =C51+1 -> 16 | D52: =IF(MIN(Class_0!B18,Class_1!B18,Class_2!B18)>0,CHAR(43),CHAR(45)) -> - | E52: =IF(MIN(Class_0!C18,Class_1!C18,Class_2!C18)>0,CHAR(43),CHAR(45)) -> - | F52: =IF(MIN(Class_0!D18,Class_1!D18,Class_2!D18)>0,CHAR(43),CHAR(45)) -> - | G52: =IF(MIN(Class_0!E18,Class_1!E18,Class_2!E18)>0,CHAR(43),CHAR(45)) -> - | H52: =IF(MIN(Class_0!F18,Class_1!F18,Class_2!F18)>0,CHAR(43),CHAR(45)) -> - | I52: =IF(MIN(Class_0!G18,Class_1!G18,Class_2!G18)>0,CHAR(43),CHAR(45)) -> - | J52: =IF(MIN(Class_0!H18,Class_1!H18,Class_2!H18)>0,CHAR(43),CHAR(45)) -> - | K52: =IF(MIN(Class_0!I18,Class_1!I18,Class_2!I18)>0,CHAR(43),CHAR(45)) -> - | ... T52: =IF(MIN(Class_0!R18,Class_1!R18,Class_2!R18)>0,CHAR(43),CHAR(45)) -> +
...

Sheet Class_0
B1: features.0.0 | C1: features.1.block.0.0 | D1: features.1.block.1.0 | E1: features.2.block.0.0 | F1: features.2.block.1.0 | G1: features.2.block.2.0 | H1: features.3.block.0.0 | I1: features.3.block.1.0 | J1: features.3.block.2.0 | K1: features.4.block.0.0 | L1: features.4.block.1.0 | M1: features.4.block.2.fc1 | N1: features.4.block.2.fc2 | O1: features.4.block.3.0 | P1: features.5.block.0.0 | Q1: features.5.block.1.0 | R1: features.5.block.2.fc1 | S1: features.5.block.2.fc2 | T1: features.5.block.3.0 | U1: features.6.block.0.0 | V1: features.6.block.1.0 | W1: features.6.block.2.fc1 | X1: features.6.block.2.fc2 | Y1: features.6.block.3.0 | Z1: features.7.block.0.0 | AA1: features.7.block.1.0 | AB1: features.7.block.2.0 | AC1: features.8.block.0.0 | AD1: features.8.block.1.0 | AE1: features.8.block.2.0 | AF1: features.9.block.0.0 | AG1: features.9.block.1.0 | AH1: features.9.block.2.0 | AI1: features.10.block.0.0 | AJ1: features.10.block.1.0 | AK1: features.10.block.2.0 | AL1: features.11.block.0.0 | AM1: features.11.block.1.0 | AN1: features.11.block.2.fc1 | AO1: features.11.block.2.fc2 | AP1: features.11.block.3.0 | AQ1: features.12.block.0.0 | AR1: features.12.block.1.0 | AS1: features.12.block.2.fc1 | AT1: features.12.block.2.fc2 | AU1: features.12.block.3.0 | AV1: features.13.block.0.0 | AW1: features.13.block.1.0 | AX1: features.13.block.2.fc1 | AY1: features.13.block.2.fc2 | AZ1: features.13.block.3.0 | BA1: features.14.block.0.0 | BB1: features.14.block.1.0 | BC1: features.14.block.2.fc1 | BD1: features.14.block.2.fc2 | BE1: features.14.block.3.0 | BF1: features.15.block.0.0 | BG1: features.15.block.1.0 | BH1: features.15.block.2.fc1 | BI1: features.15.block.2.fc2 | BJ1: features.15.block.3.0 | BK1: features.16.0
A2: features.0.0 | B2: 1 | C2: 0.059886 | D2: -0.097209466 | E2: 0.069157048 | F2: 0.051716977 | G2: 0.097680239 | H2: 0.11963069 | I2: 0.17047177 | J2: 0.035529087 | K2: 0.03374751 | L2: 0.05296133 | M2: 0.059014857 | N2: -0.052578471 | O2: 0.054693926 | P2: 0.08137009 | Q2: 0.041399635 | R2: -0.0039624719 | S2: -0.028895534 | T2: 0.016899457 | U2: 0.031557604 | V2: 0.0037857141 | W2: -0.0059968197 | X2: 0.051195219 | Y2: 0.073377352 | Z2: 0.098027656 | AA2: 0.069028094 | AB2: 0.074423479 | AC2: 0.075091359 | AD2: 0.035457476 | AE2: 0.028651063 | AF2: -0.040765317 | AG2: -0.014549931 | AH2: 0.022183321 | AI2: -0.048685829 | AJ2: 0.02011572 | AK2: 0.011334199 | AL2: 0.092122971 | AM2: 0.047062648 | AN2: 0.010765676 | AO2: 0.00046422657 | AP2: 0.023734407 | AQ2: 0.024459145 | AR2: 0.055671006 | AS2: 0.016427602 | AT2: 0.024452397 | AU2: 0.065455431 | AV2: 0.027929082 | AW2: 0.041089794 | AX2: -0.006789597 | AY2: 0.028754119 | AZ2: 0.072867283 | BA2: 0.09669756 | BB2: 0.039637106 | BC2: 0.018227796 | BD2: 0.039304263 | BE2: 0.070600694 | BF2: 0.047398915 | BG2: -0.016963717 | BH2: -0.05419176 | BI2: -0.02873559 | BJ2: -0.014934877 | BK2: -0.028542533
A3: features.1.block.0.0 | B3: 0.059886 | C3: 1 | D3: -0.0060203544 | E3: -0.077887783 | F3: -0.090069535 | G3: -0.078285268 | H3: -0.0033726992 | I3: 0.0036871002 | J3: 0.097579762 | K3: -0.062636758 | L3: -0.089080777 | M3: -0.33941566 | N3: 0.4399729 | O3: -0.21102782 | P3: 0.025277954 | Q3: 0.10743896 | R3: 0.05687379 | S3: 0.079988678 | T3: 0.1969453 | U3: 0.199133 | V3: 0.36325666 | W3: -0.24276862 | X3: -0.28765506 | Y3: 0.2106987 | Z3: -0.27073483 | AA3: -0.36227384 | AB3: -0.19990955 | AC3: -0.097167472 | AD3: -0.093337319 | AE3: -0.11781118 | AF3: -0.046368018 | AG3: 0.069028984 | AH3: 0.04764184 | AI3: 0.034380998 | AJ3: 0.1990525 | AK3: 0.051427669 | AL3: -0.31508701 | AM3: -0.3697496 | AN3: -0.18157111 | AO3: -0.26614528 | AP3: -0.17958486 | AQ3: -0.20076321 | AR3: -0.19786938 | AS3: -0.075838828 | AT3: 0.015962365 | AU3: -0.28671082 | AV3: -0.3322839 | AW3: -0.33467168 | AX3: 0.00092831581 | AY3: -0.065961055 | AZ3: -0.24131301 | BA3: -0.23578254 | BB3: -0.25099025 | BC3: -0.15991322 | BD3: -0.019832113 | BE3: -0.10541266 | BF3: -0.11977657 | BG3: -0.1884444 | BH3: -0.086360508 | BI3: -0.064592706 | BJ3: 0.055360621 | BK3: -0.19381575
A4: features.1.block.1.0 | B4: -0.097209466 | C4: -0.0060203544 | D4: 1 | E4: 0.83592081 | F4: 0.71038151 | G4: 0.62718864 | H4: -0.091039261 | I4: -0.088981513 | J4: -0.093729862 | K4: 0.57514901 | L4: 0.47510235 | M4: 0.10080854 | N4: -0.10464598 | O4: 0.48090412 | P4: 0.17632042 | Q4: -0.0035269722 | R4: -0.1980444 | S4: -0.26263593 | T4: -0.011052808 | U4: -0.090625148 | V4: -0.06599667 | W4: 0.034115934 | X4: 0.025539123 | Y4: -0.29519596 | Z4: 0.37025263 | AA4: 0.19608851 | AB4: 0.17124948 | AC4: -0.022319289 | AD4: -0.17244946 | AE4: -0.15154826 | AF4: 0.15970961 | AG4: 0.11195787 | AH4: -0.24563464 | AI4: -0.051139619 | AJ4: 0.040722986 | AK4: 0.12895991 | AL4: 0.2762245 | AM4: 0.15839125 | AN4: -0.11467593 | AO4: -0.13405917 | AP4: 0.081851118 | AQ4: -0.031718938 | AR4: -0.025870106 | AS4: 0.0097194963 | AT4: -0.0043049152 | AU4: 0.063360224 | AV4: 0.29656018 | AW4: 0.11350922 | AX4: 0.16214236 | AY4: 0.13341323 | AZ4: 0.093219726 | BA4: 0.26931429 | BB4: 0.29053926 | BC4: -0.014618261 | BD4: -0.071662978 | BE4: -0.069499525 | BF4: 0.00036870398 | BG4: -0.079238667 | BH4: -0.051623436 | BI4: -0.15187567 | BJ4: -0.085091842 | BK4: -0.071066833
A5: features.2.block.0.0 | B5: 0.069157048 | C5: -0.077887783 | D5: 0.83592081 | E5: 1 | F5: 0.87233726 | G5: 0.72983672 | H5: -0.034332097 | I5: 0.0023170608 | J5: -0.15243345 | K5: 0.62409278 | L5: 0.5123974 | M5: 0.1807937 | N5: -0.19737739 | O5: 0.54196062 | P5: 0.21880674 | Q5: -0.0063423188 | R5: -0.22233463 | S5: -0.25660861 | T5: -0.03055413 | U5: -0.073918091 | V5: -0.11658246 | W5: 0.055330085 | X5: 0.10759623 | Y5: -0.31118602 | Z5: 0.43519583 | AA5: 0.2438254 | AB5: 0.21112889 | AC5: -0.0041667092 | AD5: -0.19545494 | AE5: -0.14410026 | AF5: 0.11042674 | AG5: 0.086199129 | AH5: -0.26361958 | AI5: -0.059887315 | AJ5: 0.023462346 | AK5: 0.13194247 | AL5: 0.36255985 | AM5: 0.23209798 | AN5: -0.099913207 | AO5: -0.11182598 | AP5: 0.10643896 | AQ5: -0.015515649 | AR5: 0.0015173429 | AS5: 0.018043736 | AT5: 0.026205468 | AU5: 0.14086048 | AV5: 0.36354626 | AW5: 0.16147556 | AX5: 0.15490432 | AY5: 0.12882437 | AZ5: 0.15276883 | BA5: 0.33798495 | BB5: 0.34578039 | BC5: 0.034604393 | BD5: -0.067928561 | BE5: -0.051625962 | BF5: 0.03644845 | BG5: -0.077725395 | BH5: -0.066125699 | BI5: -0.13058306 | BJ5: -0.10814027 | BK5: -0.067782806
A6: features.2.block.1.0 | B6: 0.051716977 | C6: -0.090069535 | D6: 0.71038151 | E6: 0.87233726 | F6: 1 | G6: 0.74201031 | H6: -0.018166641 | I6: 0.0026856214 | J6: -0.21280963 | K6: 0.60698603 | L6: 0.44280536 | M6: 0.168367 | N6: -0.18151504 | O6: 0.48361095 | P6: 0.17286489 | Q6: 0.01467137 | R6: -0.1895735 | S6: -0.21299483 | T6: -0.053327384 | U6: -0.02519339 | V6: -0.14669173 | W6: 0.10731494 | X6: 0.20807604 | Y6: -0.3766304 | Z6: 0.40501806 | AA6: 0.18243818 | AB6: 0.1438142 | AC6: 0.0084617081 | AD6: -0.26518067 | AE6: -0.2520605 | AF6: 0.057607024 | AG6: 0.061307058 | AH6: -0.23027709 | AI6: -0.024727684 | AJ6: 0.065159887 | AK6: 0.17900533 | AL6: 0.33069549 | AM6: 0.16326822 | AN6: -0.08805188 | AO6: -0.092010819 | AP6: 0.038599687 | AQ6: -0.026190878 | AR6: -0.021253709 | AS6: -0.0049835047 | AT6: 0.039161848 | AU6: 0.097420741 | AV6: 0.32072719 | AW6: 0.1312061 | AX6: 0.13471238 | AY6: 0.14401099 | AZ6: 0.092900591 | BA6: 0.24427951 | BB6: 0.25874177 | BC6: 0.056117071 | BD6: -0.067432709 | BE6: -0.050759619 | BF6: 0.054796918 | BG6: -0.045313138 | BH6: -0.038780658 | BI6: -0.076982123 | BJ6: -0.12309155 | BK6: -0.010712568
A7: features.2.block.2.0 | B7: 0.097680239 | C7: -0.078285268 | D7: 0.62718864 | E7: 0.72983672 | F7: 0.74201031 | G7: 1 | H7: -0.01599093 | I7: 0.12109511 | J7: -0.026905508 | K7: 0.76021052 | L7: 0.55989304 | M7: 0.04693506 | N7: -0.043979594 | O7: 0.56025872 | P7: 0.28190754 | Q7: 0.10577081 | R7: -0.14203529 | S7: -0.27378813 | T7: 0.011598372 | U7: 0.068944445 | V7: -0.0085423714 | W7: 0.0083896153 | X7: -0.015788177 | Y7: -0.18789482 | Z7: 0.46863397 | AA7: 0.20156226 | AB7: 0.18190027 | AC7: -0.021059556 | AD7: -0.16383178 | AE7: -0.19352142 | AF7: 0.069376999 | AG7: 0.09107256 | AH7: -0.19877615 | AI7: -0.027776675 | AJ7: 0.03781432 | AK7: 0.13988932 | AL7: 0.30028956 | AM7: 0.20409503 | AN7: 0.0036462981 | AO7: -0.083217698 | AP7: 0.058349451 | AQ7: -0.015415878 | AR7: -0.020209073 | AS7: 0.096783233 | AT7: 0.075254731 | AU7: 0.058976863 | AV7: 0.27275013 | AW7: 0.08737153 | AX7: 0.09786279 | AY7: 0.10092323 | AZ7: 0.071566704 | BA7: 0.23453925 | BB7: 0.25297633 | BC7: -0.010838783 | BD7: -0.03592531 | BE7: -0.038793146 | BF7: 0.052782776 | BG7: -0.045628096 | BH7: -0.021696417 | BI7: -0.052127149 | BJ7: -0.17058883 | BK7: -0.048627278
A8: features.3.block.0.0 | B8: 0.11963069 | C8: -0.0033726992 | D8: -0.091039261 | E8: -0.034332097 | F8: -0.018166641 | G8: -0.01599093 | H8: 1 | I8: 0.37579523 | J8: 0.16735544 | K8: -0.057810898 | L8: -0.15218255 | M8: 0.0076521272 | N8: 0.003988338 | O8: -0.14194132 | P8: -0.029314931 | Q8: 0.04312086 | R8: 0.10392142 | S8: 0.17369121 | T8: 0.12272997 | U8: 0.032911536 | V8: 0.021833616 | W8: 0.095016159 | X8: 0.061606645 | Y8: 0.002204861 | Z8: -0.072565181 | AA8: -0.072520228 | AB8: -0.032693696 | AC8: 0.079362421 | AD8: 0.043135995 | AE8: 0.031292201 | AF8: 0.0070101223 | AG8: -0.0047123064 | AH8: 0.0066618992 | AI8: 0.076918333 | AJ8: 0.075489211 | AK8: 0.062466061 | AL8: -0.095065832 | AM8: -0.12494126 | AN8: -0.066466639 | AO8: -0.064015575 | AP8: -0.084701303 | AQ8: -0.016723499 | AR8: 0.019178755 | AS8: -0.078419443 | AT8: -0.059031955 | AU8: -0.0525244 | AV8: -0.17401139 | AW8: -0.1049511 | AX8: -0.03216874 | AY8: -0.034771418 | AZ8: -0.054049911 | BA8: -0.044091529 | BB8: -0.051246506 | BC8: 0.042993282 | BD8: 0.026685981 | BE8: 0.037753824 | BF8: -0.011091024 | BG8: 0.01198718 | BH8: -0.0064540521 | BI8: -0.06550124 | BJ8: 0.029620801 | BK8: -0.081474864
A9: features.3.block.1.0 | B9: 0.17047177 | C9: 0.0036871002 | D9: -0.088981513 | E9: 0.0023170608 | F9: 0.0026856214 | G9: 0.12109511 | H9: 0.37579523 | I9: 1 | J9: 0.28958657 | K9: 0.027310775 | L9: -0.056998049 | M9: 0.050247862 | N9: -0.012943423 | O9: -0.042432864 | P9: 0.047206269 | Q9: 0.022216824 | R9: 0.11051426 | S9: 0.10351407 | T9: 0.089050356 | U9: 0.093596548 | V9: 0.11922065 | W9: -0.013527181 | X9: 0.017200535 | Y9: 0.14308 | Z9: -0.018576902 | AA9: -0.054194007 | AB9: -0.01705019 | AC9: 0.047565514 | AD9: 0.010898383 | AE9: -0.017357307 | AF9: 0.017257094 | AG9: -0.021554577 | AH9: 0.038388154 | AI9: 0.023809916 | AJ9: 0.056362051 | AK9: 0.10367131 | AL9: -0.016465484 | AM9: -0.052402204 | AN9: -0.011015201 | AO9: -0.037014435 | AP9: -0.041231226 | AQ9: 0.059402516 | AR9: 0.055488472 | AS9: 0.011395981 | AT9: 0.082753705 | AU9: 0.028129747 | AV9: -0.10744137 | AW9: -0.07229035 | AX9: -0.035470088 | AY9: -0.046274497 | AZ9: -0.011251532 | BA9: 0.034870164 | BB9: 0.024133321 | BC9: 0.016924118 | BD9: 0.016915735 | BE9: 0.068561184 | BF9: 0.0011790467 | BG9: -0.010199356 | BH9: 0.014552876 | BI9: -0.055243474 | BJ9: -0.011226751 | BK9: -0.10789436
A10: features.3.block.2.0 | B10: 0.035529087 | C10: 0.097579762 | D10: -0.093729862 | E10: -0.15243345 | F10: -0.21280963 | G10: -0.026905508 | H10: 0.16735544 | I10: 0.28958657 | J10: 1 | K10: 0.11870216 | L10: 0.19076254 | M10: -0.22142011 | N10: 0.25592222 | O10: 0.1162174 | P10: 0.020088915 | Q10: 0.072458292 | R10: -0.10270756 | S10: -0.16225005 | T10: 0.22276354 | U10: 0.35580301 | V10: 0.40246188 | W10: -0.2070527 | X10: -0.25336531 | Y10: 0.31827067 | Z10: -0.073975313 | AA10: 0.065591645 | AB10: 0.10652118 | AC10: 0.17210413 | AD10: 0.21852748 | AE10: 0.11853045 | AF10: -0.0044775633 | AG10: 0.12881707 | AH10: 0.17028772 | AI10: 0.1117405 | AJ10: 0.10517405 | AK10: -0.11360917 | AL10: -0.13391856 | AM10: -0.092217975 | AN10: -0.020458225 | AO10: -0.15154635 | AP10: 0.033874602 | AQ10: -0.015373121 | AR10: 0.019098361 | AS10: 0.037774298 | AT10: -0.052083867 | AU10: -0.096759317 | AV10: -0.2192945 | AW10: -0.11187459 | AX10: -0.07637591 | AY10: -0.11285396 | AZ10: -0.056481097 | BA10: -0.12320092 | BB10: -0.18604709 | BC10: -0.19158652 | BD10: 0.078788169 | BE10: -0.13781234 | BF10: -0.066086401 | BG10: -0.054415387 | BH10: -0.039128068 | BI10: -0.066098439 | BJ10: -0.07756395 | BK10: -0.15416566
A11: features.4.block.0.0 | B11: 0.03374751 | C11: -0.062636758 | D11: 0.57514901 | E11: 0.62409278 | F11: 0.60698603 | G11: 0.76021052 | H11: -0.057810898 | I11: 0.027310775 | J11: 0.11870216 | K11: 1 | L11: 0.58783532 | M11: 0.006235661 | N11: -0.012304044 | O11: 0.56560389 | P11: 0.31453836 | Q11: 0.12798169 | R11: -0.17007533 | S11: -0.29309931 | T11: 0.054351557 | U11: 0.12438031 | V11: 0.0068309129 | W11: 0.026091059 | X11: -0.053827116 | Y11: -0.19534857 | Z11: 0.49819702 | AA11: 0.23373157 | AB11: 0.21549886 | AC11: 0.0085515514 | AD11: -0.092360739 | AE11: -0.15275316 | AF11: 0.085275894 | AG11: 0.12646992 | AH11: -0.1674722 | AI11: -0.028899873 | AJ11: 0.017473463 | AK11: 0.080577099 | AL11: 0.28239724 | AM11: 0.22838875 | AN11: -0.00067659633 | AO11: -0.052290659 | AP11: 0.12213089 | AQ11: -0.0072279027 | AR11: -0.032962692 | AS11: 0.090717474 | AT11: 0.088253819 | AU11: 0.090467404 | AV11: 0.26284315 | AW11: 0.14160129 | AX11: 0.093891374 | AY11: 0.070460243 | AZ11: 0.11365567 | BA11: 0.23578527 | BB11: 0.24579474 | BC11: -0.055034933 | BD11: -0.0045618211 | BE11: -0.040844371 | BF11: 0.069204774 | BG11: 0.00046804445 | BH11: 0.058602081 | BI11: -0.021614739 | BJ11: -0.13701682 | BK11: -0.054892162
A12: features.4.block.1.0 | B12: 0.05296133 | C12: -0.089080777 | D12: 0.47510235 | E12: 0.5123974 | F12: 0.44280536 | G12: 0.55989304 | H12: -0.15218255 | I12: -0.056998049 | J12: 0.19076254 | K12: 0.58783532 | L12: 1 | M12: 0.0060060333 | N12: -0.008351243 | O12: 0.88435014 | P12: 0.18327139 | Q12: -0.0033599507 | R12: -0.31770135 | S12: -0.55183763 | T12: -0.097090612 | U12: 0.088721735 | V12: 0.021205081 | W12: -0.072607134 | X12: -0.087806371 | Y12: -0.04536927 | Z12: 0.59444326 | AA12: 0.56574303 | AB12: 0.48309932 | AC12: 0.0866425 | AD12: -0.030302524 | AE12: 0.028014564 | AF12: 0.1110533 | AG12: 0.13246625 | AH12: -0.069317724 | AI12: -0.11727912 | AJ12: -0.026713273 | AK12: -0.04701963 | AL12: 0.42788128 | AM12: 0.43743073 | AN12: -0.052541636 | AO12: -0.19202961 | AP12: 0.33933856 | AQ12: 0.18941893 | AR12: 0.23631033 | AS12: 0.20804798 | AT12: 0.025826401 | AU12: 0.15366802 | AV12: 0.34309391 | AW12: 0.17424761 | AX12: 0.054423866 | AY12: 0.071175025 | AZ12: 0.19982002 | BA12: 0.30490801 | BB12: 0.27659614 | BC12: -0.025606472 | BD12: 0.045186636 | BE12: -0.06210164 | BF12: 0.097860677 | BG12: -0.015519938 | BH12: -0.11723512 | BI12: -0.12206392 | BJ12: -0.11214216 | BK12: -0.1392949
A13: features.4.block.2.fc1 | B13: 0.059014857 | C13: -0.33941566 | D13: 0.10080854 | E13: 0.1807937 | F13: 0.168367 | G13: 0.04693506 | H13: 0.0076521272 | I13: 0.050247862 | J13: -0.22142011 | K13: 0.006235661 | L13: 0.0060060333 | M13: 1 | N13: -0.88386355 | O13: 0.14253976 | P13: -0.010439359 | Q13: -0.10641325 | R13: 0.012982961 | S13: 0.035536312 | T13: -0.15506819 | U13: -0.24509951 | V13: -0.303383 | W13: 0.21164697 | X13: 0.37314924 | Y13: -0.13385275 | Z13: 0.21255424 | AA13: 0.29670605 | AB13: 0.20486503 | AC13: 0.0011533185 | AD13: -0.012007879 | AE13: 0.16099318 | AF13: -0.047606349 | AG13: -0.14816473 | AH13: -0.1008416 | AI13: -0.12487039 | AJ13: -0.24564954 | AK13: -0.07748201 | AL13: 0.44124908 | AM13: 0.39106732 | AN13: 0.083800358 | AO13: 0.17873559 | AP13: 0.24905999 | AQ13: 0.21791749 | AR13: 0.264789 | AS13: 0.13815092 | AT13: 0.064744704 | AU13: 0.33000978 | AV13: 0.38743822 | AW13: 0.31410555 | AX13: 0.0052730125 | AY13: 0.069807035 | AZ13: 0.31885303 | BA13: 0.28986505 | BB13: 0.25934717 | BC13: 0.17656196 | BD13: 0.0078432611 | BE13: 0.090126186 | BF13: 0.10162727 | BG13: 0.11718845 | BH13: 0.067077215 | BI13: 0.024073734 | BJ13: 0.0097008706 | BK13: 0.19182046
... A63: features.16.0 | B63: -0.028542533 | C63: -0.19381575 | D63: -0.071066833 | E63: -0.067782806 | F63: -0.010712568 | G63: -0.048627278 | H63: -0.081474864 | I63: -0.10789436 | J63: -0.15416566 | K63: -0.054892162 | L63: -0.1392949 | M63: 0.19182046 | N63: -0.25056123 | O63: -0.097081554 | P63: 0.060933166 | Q63: -0.0002717029 | R63: 0.061889668 | S63: 0.12361478 | T63: -0.037631068 | U63: -0.035337077 | V63: -0.14732496 | W63: 0.16431881 | X63: 0.044402911 | Y63: -0.10604404 | Z63: -0.053947325 | AA63: -0.052634258 | AB63: -0.12218142 | AC63: -0.17092072 | AD63: 0.0069850805 | AE63: 0.1601553 | AF63: -0.099429027 | AG63: -0.14765099 | AH63: 0.17473386 | AI63: 0.053386775 | AJ63: -0.20091893 | AK63: -0.2304563 | AL63: 0.072695652 | AM63: 0.13836241 | AN63: 0.034435202 | AO63: 0.17488386 | AP63: 0.12627952 | AQ63: 0.034475498 | AR63: -0.040639033 | AS63: 0.056249251 | AT63: 0.067505923 | AU63: 0.14302831 | AV63: 0.3136104 | AW63: 0.35276356 | AX63: 0.17159176 | AY63: 0.1009427 | AZ63: 0.18273003 | BA63: -0.12194583 | BB63: 0.036566151 | BC63: -0.011222843 | BD63: -0.20460006 | BE63: 0.098808808 | BF63: 0.056075815 | BG63: 0.25932224 | BH63: 0.21232562 | BI63: 0.21854451 | BJ63: 0.26742613 | BK63: 1

Sheet Class_1
B1: features.0.0 | C1: features.1.block.0.0 | D1: features.1.block.1.0 | E1: features.2.block.0.0 | F1: features.2.block.1.0 | G1: features.2.block.2.0 | H1: features.3.block.0.0 | I1: features.3.block.1.0 | J1: features.3.block.2.0 | K1: features.4.block.0.0 | L1: features.4.block.1.0 | M1: features.4.block.2.fc1 | N1: features.4.block.2.fc2 | O1: features.4.block.3.0 | P1: features.5.block.0.0 | Q1: features.5.block.1.0 | R1: features.5.block.2.fc1 | S1: features.5.block.2.fc2 | T1: features.5.block.3.0 | U1: features.6.block.0.0 | V1: features.6.block.1.0 | W1: features.6.block.2.fc1 | X1: features.6.block.2.fc2 | Y1: features.6.block.3.0 | Z1: features.7.block.0.0 | AA1: features.7.block.1.0 | AB1: features.7.block.2.0 | AC1: features.8.block.0.0 | AD1: features.8.block.1.0 | AE1: features.8.block.2.0 | AF1: features.9.block.0.0 | AG1: features.9.block.1.0 | AH1: features.9.block.2.0 | AI1: features.10.block.0.0 | AJ1: features.10.block.1.0 | AK1: features.10.block.2.0 | AL1: features.11.block.0.0 | AM1: features.11.block.1.0 | AN1: features.11.block.2.fc1 | AO1: features.11.block.2.fc2 | AP1: features.11.block.3.0 | AQ1: features.12.block.0.0 | AR1: features.12.block.1.0 | AS1: features.12.block.2.fc1 | AT1: features.12.block.2.fc2 | AU1: features.12.block.3.0 | AV1: features.13.block.0.0 | AW1: features.13.block.1.0 | AX1: features.13.block.2.fc1 | AY1: features.13.block.2.fc2 | AZ1: features.13.block.3.0 | BA1: features.14.block.0.0 | BB1: features.14.block.1.0 | BC1: features.14.block.2.fc1 | BD1: features.14.block.2.fc2 | BE1: features.14.block.3.0 | BF1: features.15.block.0.0 | BG1: features.15.block.1.0 | BH1: features.15.block.2.fc1 | BI1: features.15.block.2.fc2 | BJ1: features.15.block.3.0 | BK1: features.16.0
A2: features.0.0 | B2: 1 | C2: 0.037934098 | D2: 0.028350778 | E2: 0.045902121 | F2: 0.011662198 | G2: 0.047356302 | H2: -0.015834925 | I2: 0.0056023997 | J2: 0.030558294 | K2: 0.019235678 | L2: 0.039133288 | M2: 0.039045467 | N2: 0.012265788 | O2: 0.019098068 | P2: 0.098644741 | Q2: 0.069319081 | R2: 0.07132616 | S2: 0.076198734 | T2: 0.048539518 | U2: -0.055187433 | V2: 0.0029968557 | W2: 0.013160785 | X2: -0.022911009 | Y2: 0.034505645 | Z2: -0.0066470241 | AA2: -0.00197058 | AB2: -0.035126279 | AC2: -0.084293221 | AD2: -0.014004971 | AE2: -0.028152453 | AF2: -0.020485974 | AG2: -0.040973698 | AH2: -0.064116546 | AI2: 0.011597092 | AJ2: 0.053863717 | AK2: 0.017729171 | AL2: -0.049933997 | AM2: -0.047373544 | AN2: 0.0094599766 | AO2: 0.047441667 | AP2: -0.024817133 | AQ2: 0.025573263 | AR2: 0.034136514 | AS2: -0.027742755 | AT2: -0.036657599 | AU2: 0.01333953 | AV2: -0.047598218 | AW2: -0.029799413 | AX2: -0.033236611 | AY2: -0.016763311 | AZ2: -0.043202148 | BA2: -0.035074299 | BB2: -0.029145782 | BC2: 0.022611209 | BD2: -0.014030711 | BE2: -0.047186927 | BF2: -0.03639058 | BG2: -0.04452432 | BH2: -0.082742683 | BI2: -0.034636779 | BJ2: 0.014384392 | BK2: 0.039765279
A3: features.1.block.0.0 | B3: 0.037934098 | C3: 1 | D3: -0.12702107 | E3: -0.40741471 | F3: 0.0023440847 | G3: 0.22968033 | H3: 0.2033831 | I3: 0.012126533 | J3: 0.27965585 | K3: -0.18893098 | L3: -0.031133026 | M3: -0.45249152 | N3: -0.62187577 | O3: -0.31591057 | P3: 0.063594052 | Q3: 0.096830047 | R3: 0.0075208931 | S3: 0.16070055 | T3: 0.15347183 | U3: 0.084728251 | V3: 0.3188631 | W3: 0.051018255 | X3: -0.39947772 | Y3: 0.36148388 | Z3: -0.3259959 | AA3: -0.49349145 | AB3: -0.34376901 | AC3: -0.063748724 | AD3: 0.013080817 | AE3: 0.043685985 | AF3: -0.19435394 | AG3: -0.15401066 | AH3: 0.071077718 | AI3: -0.063799501 | AJ3: 0.074012121 | AK3: -0.035799401 | AL3: -0.38859802 | AM3: -0.51410695 | AN3: 0.28324319 | AO3: 0.28409122 | AP3: -0.38817513 | AQ3: -0.29825669 | AR3: -0.23580328 | AS3: -0.13602035 | AT3: 0.047087629 | AU3: -0.20996366 | AV3: -0.42434416 | AW3: -0.24159701 | AX3: -0.016422928 | AY3: 0.010477922 | AZ3: -0.13726992 | BA3: -0.1744934 | BB3: -0.21694097 | BC3: -0.045282283 | BD3: -0.14576798 | BE3: -0.081652827 | BF3: -0.18243038 | BG3: -0.18003658 | BH3: -0.10859182 | BI3: 0.091246379 | BJ3: 0.055371801 | BK3: 0.12929664
A4: features.1.block.1.0 | B4: 0.028350778 | C4: -0.12702107 | D4: 1 | E4: 0.73359268 | F4: 0.4581132 | G4: 0.30033956 | H4: -0.032611986 | I4: -0.1018126 | J4: -0.16557996 | K4: 0.45479028 | L4: 0.32758692 | M4: 0.14907255 | N4: 0.22456409 | O4: 0.4070385 | P4: 0.19678029 | Q4: 0.021090124 | R4: -0.0092092986 | S4: -0.15330598 | T4: -0.055892498 | U4: 0.039115983 | V4: -0.11884405 | W4: -0.1800212 | X4: 0.038648807 | Y4: -0.38465441 | Z4: 0.0592996 | AA4: 0.19205326 | AB4: 0.13487188 | AC4: -0.035876452 | AD4: -0.19357279 | AE4: -0.087002143 | AF4: 0.08126404 | AG4: 0.038237929 | AH4: -0.10715991 | AI4: 0.057841967 | AJ4: 0.054176485 | AK4: 0.052715554 | AL4: 0.36363066 | AM4: 0.2997888 | AN4: -0.10083798 | AO4: -0.049360771 | AP4: 0.13120327 | AQ4: 0.17446327 | AR4: 0.053358252 | AS4: 0.10435111 | AT4: 0.10687829 | AU4: -0.15539633 | AV4: 0.27553512 | AW4: 0.092450854 | AX4: 0.12585907 | AY4: -0.10668581 | AZ4: 0.02348188 | BA4: 0.0087364143 | BB4: 0.082071387 | BC4: -0.088514282 | BD4: 0.091081023 | BE4: 0.068771572 | BF4: 0.11200226 | BG4: 0.07807729 | BH4: 0.046384749 | BI4: -0.076951009 | BJ4: -0.14020007 | BK4: -0.10296702
A5: features.2.block.0.0 | B5: 0.045902121 | C5: -0.40741471 | D5: 0.73359268 | E5: 1 | F5: 0.51843355 | G5: 0.2140626 | H5: -0.1618341 | I5: 0.044646418 | J5: -0.34597608 | K5: 0.52369139 | L5: 0.21788899 | M5: 0.36812178 | N5: 0.55568919 | O5: 0.48416663 | P5: 0.136515 | Q5: -0.082396489 | R5: 0.031237688 | S5: -0.20150806 | T5: -0.14122937 | U5: -0.10979313 | V5: -0.3107529 | W5: -0.057562183 | X5: 0.34131148 | Y5: -0.6208963 | Z5: 0.29348655 | AA5: 0.36481011 | AB5: 0.29314374 | AC5: 0.029390023 | AD5: -0.2722416 | AE5: -0.16832993 | AF5: 0.1434864 | AG5: 0.039687996 | AH5: -0.20131451 | AI5: 0.067949796 | AJ5: -0.028478503 | AK5: 0.10168147 | AL5: 0.53089657 | AM5: 0.51228681 | AN5: -0.18761365 | AO5: -0.1373451 | AP5: 0.3157821 | AQ5: 0.31884973 | AR5: 0.19912251 | AS5: 0.092656984 | AT5: -0.0081519051 | AU5: 0.018581966 | AV5: 0.4696543 | AW5: 0.16355938 | AX5: 0.057567945 | AY5: -0.12650719 | AZ5: 0.11250355 | BA5: 0.12651109 | BB5: 0.21170948 | BC5: -0.035388467 | BD5: 0.17146414 | BE5: 0.1377126 | BF5: 0.15211129 | BG5: 0.13210965 | BH5: 0.052113062 | BI5: -0.14109083 | BJ5: -0.15428316 | BK5: -0.14549448
A6: features.2.block.1.0 | B6: 0.011662198 | C6: 0.0023440847 | D6: 0.4581132 | E6: 0.51843355 | F6: 1 | G6: 0.33111746 | H6: 0.074550767 | I6: -0.033045283 | J6: -0.16495169 | K6: 0.49070296 | L6: 0.079761126 | M6: 0.061337099 | N6: 0.079167755 | O6: 0.15681342 | P6: 0.1037218 | Q6: 0.12748019 | R6: 0.048228512 | S6: 0.02694163 | T6: -0.020170412 | U6: -0.017762392 | V6: -0.12989969 | W6: 0.089382637 | X6: 0.09960517 | Y6: -0.28811621 | Z6: 0.079460433 | AA6: -0.019812755 | AB6: -0.021673284 | AC6: -0.11347574 | AD6: -0.26704314 | AE6: -0.18991947 | AF6: -0.11845451 | AG6: -0.17322581 | AH6: -0.17581894 | AI6: -0.11783159 | AJ6: -0.04656289 | AK6: 0.090300753 | AL6: 0.25221658 | AM6: 0.10513237 | AN6: -0.055930791 | AO6: 0.029780449 | AP6: 0.013357975 | AQ6: 0.04609742 | AR6: 0.0096258179 | AS6: -0.048764089 | AT6: 0.065772595 | AU6: -0.025139562 | AV6: 0.21345224 | AW6: 0.0015740999 | AX6: 0.054076705 | AY6: -0.098538154 | AZ6: 0.016938988 | BA6: -0.0086608795 | BB6: -0.0035541709 | BC6: -0.064367275 | BD6: 0.044032757 | BE6: 0.083540326 | BF6: 0.068035855 | BG6: 0.026977242 | BH6: 0.0041554873 | BI6: -0.081684771 | BJ6: -0.12547903 | BK6: -0.089636929
A7: features.2.block.2.0 | B7: 0.047356302 | C7: 0.22968033 | D7: 0.30033956 | E7: 0.2140626 | F7: 0.33111746 | G7: 1 | H7: 0.22005652 | I7: 0.57554771 | J7: 0.44525634 | K7: 0.50908697 | L7: 0.24752081 | M7: -0.16743435 | N7: -0.20977075 | O7: 0.16902358 | P7: 0.24344937 | Q7: 0.15450563 | R7: -0.004286271 | S7: 0.072593703 | T7: 0.21592157 | U7: -0.024703657 | V7: 0.19588182 | W7: -0.098885323 | X7: -0.25743089 | Y7: -0.010277016 | Z7: 0.037052179 | AA7: -0.22830702 | AB7: -0.026405639 | AC7: 0.12459687 | AD7: 0.036470807 | AE7: 0.043813746 | AF7: -0.050178738 | AG7: -0.081313125 | AH7: -0.20110666 | AI7: 0.066534028 | AJ7: 0.11006238 | AK7: 0.17641033 | AL7: -0.10928489 | AM7: -0.042931657 | AN7: 0.23914274 | AO7: 0.25841067 | AP7: -0.24431831 | AQ7: -0.25505822 | AR7: -0.19424125 | AS7: -0.095246728 | AT7: 0.046592673 | AU7: -0.19878604 | AV7: -0.15127218 | AW7: -0.1286703 | AX7: 0.1268672 | AY7: -0.0053347381 | AZ7: -0.11070282 | BA7: -0.03213458 | BB7: 0.087498476 | BC7: -0.0096762775 | BD7: -0.058317507 | BE7: 0.077878698 | BF7: 0.079282849 | BG7: -0.058194558 | BH7: -0.043004998 | BI7: 0.0010717314 | BJ7: -0.0067673838 | BK7: 0.037870565
A8: features.3.block.0.0 | B8: -0.015834925 | C8: 0.2033831 | D8: -0.032611986 | E8: -0.1618341 | F8: 0.074550767 | G8: 0.22005652 | H8: 1 | I8: 0.20442795 | J8: 0.31594926 | K8: -0.039761232 | L8: -0.061822412 | M8: -0.1373107 | N8: -0.21759621 | O8: -0.13511977 | P8: 0.048568159 | Q8: 0.083311655 | R8: 0.013542522 | S8: 0.16196246 | T8: 0.20074992 | U8: 0.1439623 | V8: 0.24147699 | W8: 0.034676955 | X8: -0.17934221 | Y8: 0.22029951 | Z8: -0.19760566 | AA8: -0.21989945 | AB8: -0.1349335 | AC8: 0.08629689 | AD8: 0.091773483 | AE8: 0.14893575 | AF8: -0.022030876 | AG8: -0.090684895 | AH8: -0.003520955 | AI8: -0.040186634 | AJ8: 0.019313805 | AK8: 0.01754986 | AL8: -0.20663683 | AM8: -0.26042157 | AN8: 0.15151029 | AO8: 0.15429002 | AP8: -0.26244629 | AQ8: -0.17577503 | AR8: -0.16395387 | AS8: -0.036963035 | AT8: 0.12967075 | AU8: -0.094335973 | AV8: -0.23987511 | AW8: -0.080709434 | AX8: 0.084450706 | AY8: -0.014995958 | AZ8: -0.095491077 | BA8: -0.055215183 | BB8: -0.10441311 | BC8: -0.017836818 | BD8: -0.097560214 | BE8: 0.0057873314 | BF8: -0.032151668 | BG8: -0.12297092 | BH8: 0.031088172 | BI8: 0.0028930984 | BJ8: -0.019226901 | BK8: 0.052973586
A9: features.3.block.1.0 | B9: 0.0056023997 | C9: 0.012126533 | D9: -0.1018126 | E9: 0.044646418 | F9: -0.033045283 | G9: 0.57554771 | H9: 0.20442795 | I9: 1 | J9: 0.51248986 | K9: 0.31251953 | L9: 0.11248425 | M9: -0.10537163 | N9: -0.063022201 | O9: 0.15692897 | P9: 0.080361453 | Q9: 0.022664971 | R9: -0.015893569 | S9: 0.067284497 | T9: 0.080396026 | U9: -0.10479797 | V9: 0.076406744 | W9: -0.048295451 | X9: -0.063655722 | Y9: -0.02031672 | Z9: 0.31121175 | AA9: 0.015958491 | AB9: 0.19182872 | AC9: 0.25258702 | AD9: 0.097913563 | AE9: 0.094803458 | AF9: 0.12507666 | AG9: 0.036489697 | AH9: -0.045080587 | AI9: -0.020315045 | AJ9: -0.11256856 | AK9: 0.091698253 | AL9: -0.033397662 | AM9: 0.060287176 | AN9: 0.16254785 | AO9: 0.13182689 | AP9: -0.090004456 | AQ9: -0.14510665 | AR9: -0.027223733 | AS9: -0.13031047 | AT9: -0.036977192 | AU9: 0.12615609 | AV9: -0.034091267 | AW9: 0.035119788 | AX9: 0.09805894 | AY9: -0.0017164559 | AZ9: 0.014619122 | BA9: 0.052263816 | BB9: 0.051115528 | BC9: 0.041040769 | BD9: -0.084982708 | BE9: 0.11873367 | BF9: 0.090342748 | BG9: -0.023856968 | BH9: 0.030708599 | BI9: -0.012281579 | BJ9: 0.0013488025 | BK9: 0.012168615
A10: features.3.block.2.0 | B10: 0.030558294 | C10: 0.27965585 | D10: -0.16557996 | E10: -0.34597608 | F10: -0.16495169 | G10: 0.44525634 | H10: 0.31594926 | I10: 0.51248986 | J10: 1 | K10: 0.1964131 | L10: 0.2023358 | M10: -0.19761769 | N10: -0.39436855 | O10: 0.0096678152 | P10: 0.15473144 | Q10: 0.16211637 | R10: -0.080893893 | S10: 0.056070717 | T10: 0.14978271 | U10: 0.14961158 | V10: 0.37750696 | W10: -0.10752299 | X10: -0.43937711 | Y10: 0.34924968 | Z10: -0.040367996 | AA10: -0.22075476 | AB10: -0.04700482 | AC10: 0.20410629 | AD10: 0.37168493 | AE10: 0.24095443 | AF10: -0.060246146 | AG10: -0.048330692 | AH10: 0.043330548 | AI10: 0.036940363 | AJ10: 0.055295214 | AK10: -0.01302761 | AL10: -0.37133575 | AM10: -0.28272464 | AN10: 0.1718609 | AO10: 0.12880015 | AP10: -0.33068256 | AQ10: -0.28954722 | AR10: -0.22277135 | AS10: -0.14665964 | AT10: 0.021544387 | AU10: -0.059077767 | AV10: -0.38799379 | AW10: -0.13777721 | AX10: 0.025858859 | AY10: -0.023425109 | AZ10: -0.091294519 | BA10: -0.10920314 | BB10: -0.041501198 | BC10: 0.00599156 | BD10: -0.11200471 | BE10: -0.010279423 | BF10: -0.042340776 | BG10: -0.1462155 | BH10: -0.0084455823 | BI10: 0.068715006 | BJ10: 0.047551027 | BK10: 0.11238253
A11: features.4.block.0.0 | B11: 0.019235678 | C11: -0.18893098 | D11: 0.45479028 | E11: 0.52369139 | F11: 0.49070296 | G11: 0.50908697 | H11: -0.039761232 | I11: 0.31251953 | J11: 0.1964131 | K11: 1 | L11: 0.36040306 | M11: 0.14180445 | N11: 0.23401542 | O11: 0.45872519 | P11: 0.17213978 | Q11: -0.015884792 | R11: -0.038495665 | S11: -0.10645443 | T11: -0.08978624 | U11: 0.053004162 | V11: -0.12917034 | W11: -0.10573176 | X11: 0.097419745 | Y11: -0.33832711 | Z11: 0.36312826 | AA11: 0.19901217 | AB11: 0.27333154 | AC11: 0.13150544 | AD11: -0.075530547 | AE11: -0.092596351 | AF11: 0.044663613 | AG11: 0.0058630961 | AH11: -0.15736053 | AI11: 0.042841277 | AJ11: 0.0077273767 | AK11: 0.1009203 | AL11: 0.31279419 | AM11: 0.33529514 | AN11: -0.035256503 | AO11: -0.0159559 | AP11: 0.1125773 | AQ11: 0.058548926 | AR11: 0.042269232 | AS11: -0.015415465 | AT11: 0.0057289058 | AU11: 0.022621115 | AV11: 0.22407043 | AW11: 0.076277499 | AX11: 0.086787698 | AY11: -0.056487053 | AZ11: 0.062352239 | BA11: 0.069595178 | BB11: 0.13844612 | BC11: -0.038381875 | BD11: 0.066642645 | BE11: 0.12509231 | BF11: 0.17215075 | BG11: 0.094247168 | BH11: 0.042087758 | BI11: -0.059784647 | BJ11: -0.065211716 | BK11: -0.07469035
A12: features.4.block.1.0 | B12: 0.039133288 | C12: -0.031133026 | D12: 0.32758692 | E12: 0.21788899 | F12: 0.079761126 | G12: 0.24752081 | H12: -0.061822412 | I12: 0.11248425 | J12: 0.2023358 | K12: 0.36040306 | L12: 1 | M12: 0.079068261 | N12: -0.02176652 | O12: 0.79233205 | P12: 0.18565263 | Q12: -0.021625036 | R12: -0.11944692 | S12: -0.14097262 | T12: -0.29740269 | U12: 0.16668156 | V12: 0.14481845 | W12: -0.3756901 | X12: -0.25307684 | Y12: -0.10595198 | Z12: 0.38125601 | AA12: 0.39235696 | AB12: 0.25649001 | AC12: 0.077585703 | AD12: 0.004345902 | AE12: -0.0071037076 | AF12: 0.13135369 | AG12: 0.090486904 | AH12: 0.14255074 | AI12: 0.062709697 | AJ12: -0.068080503 | AK12: -0.027219889 | AL12: 0.27634205 | AM12: 0.2847147 | AN12: -0.085768326 | AO12: -0.12830451 | AP12: 0.1769296 | AQ12: 0.16150383 | AR12: 0.065575751 | AS12: -0.047365998 | AT12: -0.076898471 | AU12: -0.071954868 | AV12: 0.12183859 | AW12: 0.079276748 | AX12: 0.047438791 | AY12: -0.1200867 | AZ12: 0.077079797 | BA12: -0.012235263 | BB12: -0.0053103657 | BC12: -0.057907989 | BD12: 0.044454642 | BE12: 0.048329745 | BF12: 0.054727226 | BG12: 0.08058634 | BH12: 0.021335119 | BI12: -0.035888783 | BJ12: -0.043326238 | BK12: -0.0054058478
A13: features.4.block.2.fc1 | B13: 0.039045467 | C13: -0.45249152 | D13: 0.14907255 | E13: 0.36812178 | F13: 0.061337099 | G13: -0.16743435 | H13: -0.1373107 | I13: -0.10537163 | J13: -0.19761769 | K13: 0.14180445 | L13: 0.079068261 | M13: 1 | N13: 0.75432476 | O13: 0.29849223 | P13: -0.036462711 | Q13: -0.10858938 | R13: -0.063960045 | S13: -0.24598696 | T13: -0.16526379 | U13: -0.013687903 | V13: -0.14213063 | W13: -0.011403395 | X13: 0.33329008 | Y13: -0.37650006 | Z13: 0.21564877 | AA13: 0.3426771 | AB13: 0.1853024 | AC13: 0.075224916 | AD13: -0.023975589 | AE13: -0.098066034 | AF13: 0.1833839 | AG13: 0.011051474 | AH13: -0.13606714 | AI13: 0.073273246 | AJ13: 0.018435537 | AK13: 0.059037134 | AL13: 0.30982757 | AM13: 0.34184727 | AN13: -0.29437446 | AO13: -0.28647779 | AP13: 0.27822744 | AQ13: 0.27917976 | AR13: 0.17465534 | AS13: 0.14269723 | AT13: -0.082054118 | AU13: 0.11366969 | AV13: 0.28853741 | AW13: 0.060064107 | AX13: -0.13676965 | AY13: -0.16074745 | AZ13: 0.026538563 | BA13: 0.079798382 | BB13: 0.15537491 | BC13: -0.066926929 | BD13: 0.16083916 | BE13: 0.12185654 | BF13: 0.13362851 | BG13: 0.12763626 | BH13: -0.0024621227 | BI13: -0.095648903 | BJ13: -0.049510131 | BK13: -0.067560087
... A63: features.16.0 | B63: 0.039765279 | C63: 0.12929664 | D63: -0.10296702 | E63: -0.14549448 | F63: -0.089636929 | G63: 0.037870565 | H63: 0.052973586 | I63: 0.012168615 | J63: 0.11238253 | K63: -0.07469035 | L63: -0.0054058478 | M63: -0.067560087 | N63: -0.080823026 | O63: -0.077677411 | P63: 0.0041265751 | Q63: 0.070929915 | R63: 0.0078715523 | S63: 0.1663752 | T63: 0.084171952 | U63: 0.0050357371 | V63: 0.090421187 | W63: 0.051048953 | X63: -0.059599301 | Y63: 0.13754072 | Z63: -0.040225405 | AA63: -0.075669136 | AB63: -0.05159623 | AC63: 0.018684326 | AD63: 0.085343047 | AE63: 0.051116763 | AF63: -0.040725128 | AG63: -0.031796758 | AH63: -0.0028510633 | AI63: 0.049126561 | AJ63: 0.085800635 | AK63: 0.05351339 | AL63: -0.11795578 | AM63: -0.080505126 | AN63: 0.053461776 | AO63: 0.012746095 | AP63: 0.021694022 | AQ63: 0.019448329 | AR63: 0.087425549 | AS63: -0.042745536 | AT63: -0.11500026 | AU63: 0.087915313 | AV63: -0.084016773 | AW63: 0.08325772 | AX63: -0.080512309 | AY63: 0.091606729 | AZ63: 0.022525717 | BA63: -0.1035775 | BB63: -0.026199946 | BC63: 0.12772289 | BD63: -0.025343649 | BE63: -0.029755829 | BF63: 0.028751096 | BG63: -0.049206503 | BH63: -0.20151083 | BI63: 0.043772176 | BJ63: 0.39852114 | BK63: 1

Sheet Class_2
B1: features.0.0 | C1: features.1.block.0.0 | D1: features.1.block.1.0 | E1: features.2.block.0.0 | F1: features.2.block.1.0 | G1: features.2.block.2.0 | H1: features.3.block.0.0 | I1: features.3.block.1.0 | J1: features.3.block.2.0 | K1: features.4.block.0.0 | L1: features.4.block.1.0 | M1: features.4.block.2.fc1 | N1: features.4.block.2.fc2 | O1: features.4.block.3.0 | P1: features.5.block.0.0 | Q1: features.5.block.1.0 | R1: features.5.block.2.fc1 | S1: features.5.block.2.fc2 | T1: features.5.block.3.0 | U1: features.6.block.0.0 | V1: features.6.block.1.0 | W1: features.6.block.2.fc1 | X1: features.6.block.2.fc2 | Y1: features.6.block.3.0 | Z1: features.7.block.0.0 | AA1: features.7.block.1.0 | AB1: features.7.block.2.0 | AC1: features.8.block.0.0 | AD1: features.8.block.1.0 | AE1: features.8.block.2.0 | AF1: features.9.block.0.0 | AG1: features.9.block.1.0 | AH1: features.9.block.2.0 | AI1: features.10.block.0.0 | AJ1: features.10.block.1.0 | AK1: features.10.block.2.0 | AL1: features.11.block.0.0 | AM1: features.11.block.1.0 | AN1: features.11.block.2.fc1 | AO1: features.11.block.2.fc2 | AP1: features.11.block.3.0 | AQ1: features.12.block.0.0 | AR1: features.12.block.1.0 | AS1: features.12.block.2.fc1 | AT1: features.12.block.2.fc2 | AU1: features.12.block.3.0 | AV1: features.13.block.0.0 | AW1: features.13.block.1.0 | AX1: features.13.block.2.fc1 | AY1: features.13.block.2.fc2 | AZ1: features.13.block.3.0 | BA1: features.14.block.0.0 | BB1: features.14.block.1.0 | BC1: features.14.block.2.fc1 | BD1: features.14.block.2.fc2 | BE1: features.14.block.3.0 | BF1: features.15.block.0.0 | BG1: features.15.block.1.0 | BH1: features.15.block.2.fc1 | BI1: features.15.block.2.fc2 | BJ1: features.15.block.3.0 | BK1: features.16.0
A2: features.0.0 | B2: 1 | C2: 0.017727528 | D2: 0.024035384 | E2: 0.092424376 | F2: 0.090355858 | G2: 0.12508421 | H2: 0.06828177 | I2: 0.016992276 | J2: 0.046403031 | K2: 0.11453153 | L2: 0.065865227 | M2: 0.010684861 | N2: -0.067314314 | O2: 0.07948289 | P2: -0.011094394 | Q2: -0.025521939 | R2: -0.017884734 | S2: -0.067271776 | T2: -0.057103995 | U2: 0.03153941 | V2: -0.0099012712 | W2: -0.08238965 | X2: -0.073316139 | Y2: 0.041682061 | Z2: 0.088597481 | AA2: 0.038057863 | AB2: 0.043987696 | AC2: -0.028013537 | AD2: -0.045346153 | AE2: 0.0090123253 | AF2: 0.017194145 | AG2: 0.010888763 | AH2: -0.095492146 | AI2: 0.013882453 | AJ2: -0.0011211737 | AK2: -0.016373676 | AL2: 0.037216396 | AM2: 0.025910468 | AN2: 0.044564321 | AO2: 0.037454334 | AP2: 0.029239022 | AQ2: -0.059653109 | AR2: -0.033035519 | AS2: 0.0011356147 | AT2: -0.046934012 | AU2: 0.013240702 | AV2: 0.0365536 | AW2: 0.044288174 | AX2: 0.020741144 | AY2: -0.010423513 | AZ2: -0.042213601 | BA2: -0.031530659 | BB2: -0.050154956 | BC2: -0.056831264 | BD2: -0.01097529 | BE2: -0.0061852685 | BF2: -0.0052476606 | BG2: -0.008552948 | BH2: 0.021067993 | BI2: 0.055580167 | BJ2: -0.090352862 | BK2: -0.08819484
A3: features.1.block.0.0 | B3: 0.017727528 | C3: 1 | D3: 0.14384632 | E3: -0.033729972 | F3: -0.2739243 | G3: -0.35378751 | H3: 0.13026824 | I3: 0.22253301 | J3: -0.25252836 | K3: -0.39216705 | L3: 0.15621929 | M3: -0.37271135 | N3: 0.55971076 | O3: -0.029188528 | P3: -0.032773691 | Q3: 0.081494527 | R3: -0.027602867 | S3: -0.0074350602 | T3: 0.014792109 | U3: -0.18407822 | V3: -0.26251512 | W3: 0.43519269 | X3: 0.31355919 | Y3: -0.34689004 | Z3: -0.25751001 | AA3: -0.41330352 | AB3: -0.30030783 | AC3: 0.091445813 | AD3: 0.10137037 | AE3: 0.063206581 | AF3: -0.038122439 | AG3: -0.17742731 | AH3: 0.032487314 | AI3: 0.17761592 | AJ3: 0.14275284 | AK3: 0.43533409 | AL3: -0.28402946 | AM3: -0.20071066 | AN3: -0.093681844 | AO3: 0.21133958 | AP3: -0.42340282 | AQ3: -0.18502194 | AR3: -0.18995388 | AS3: -0.18097037 | AT3: -0.088007994 | AU3: -0.26534319 | AV3: -0.38474321 | AW3: -0.25929265 | AX3: 0.025127938 | AY3: -0.010159 | AZ3: 0.0061587055 | BA3: -0.048582326 | BB3: -0.04277422 | BC3: 0.022055408 | BD3: 0.04447925 | BE3: 0.03258178 | BF3: 0.041318109 | BG3: 0.058380167 | BH3: -0.00089358356 | BI3: -0.019287252 | BJ3: -0.0023547444 | BK3: -0.0024580566
A4: features.1.block.1.0 | B4: 0.024035384 | C4: 0.14384632 | D4: 1 | E4: 0.80378986 | F4: 0.67247657 | G4: 0.47895465 | H4: -0.028793341 | I4: -0.024380349 | J4: -0.0028973237 | K4: 0.40391684 | L4: 0.36669578 | M4: 0.11110171 | N4: -0.16280971 | O4: 0.35602217 | P4: 0.0057013639 | Q4: -0.26089044 | R4: -0.1067381 | S4: -0.15377615 | T4: -0.23383001 | U4: -0.0029285468 | V4: -0.052593685 | W4: -0.049873965 | X4: -0.030581382 | Y4: 0.19582038 | Z4: 0.44482467 | AA4: 0.1097681 | AB4: 0.13047687 | AC4: -0.12149335 | AD4: -0.23584286 | AE4: -0.17749034 | AF4: -0.080015614 | AG4: -0.032427929 | AH4: -0.20663114 | AI4: 0.0077186379 | AJ4: -0.087422336 | AK4: -0.047473122 | AL4: 0.32834873 | AM4: 0.13078652 | AN4: 0.027078432 | AO4: -0.028027498 | AP4: 0.2035463 | AQ4: -0.00034533303 | AR4: 0.038236747 | AS4: 0.054477574 | AT4: -0.091003653 | AU4: 0.21026992 | AV4: 0.2952206 | AW4: 0.23913216 | AX4: 0.15158633 | AY4: -0.058127947 | AZ4: 0.043773287 | BA4: 0.014118149 | BB4: 0.083832266 | BC4: 0.048248052 | BD4: -0.020616158 | BE4: -0.049464181 | BF4: 0.015109701 | BG4: -0.0010588329 | BH4: 0.017636714 | BI4: 0.046727825 | BJ4: -0.05549062 | BK4: 0.0013685613
A5: features.2.block.0.0 | B5: 0.092424376 | C5: -0.033729972 | D5: 0.80378986 | E5: 1 | F5: 0.86053924 | G5: 0.66791532 | H5: 0.037320617 | I5: -0.019355448 | J5: 0.070761731 | K5: 0.55009173 | L5: 0.3978741 | M5: 0.21039471 | N5: -0.27977983 | O5: 0.43847971 | P5: 0.002179852 | Q5: -0.29336263 | R5: -0.079337255 | S5: -0.15531949 | T5: -0.24894239 | U5: 0.059790834 | V5: -0.037179837 | W5: -0.17942213 | X5: -0.14008511 | Y5: 0.24658463 | Z5: 0.55477523 | AA5: 0.27369332 | AB5: 0.25400943 | AC5: -0.13363557 | AD5: -0.20073829 | AE5: -0.20678973 | AF5: -0.12161943 | AG5: -0.0076284605 | AH5: -0.29588902 | AI5: -0.065796143 | AJ5: -0.22196773 | AK5: -0.19907133 | AL5: 0.4797221 | AM5: 0.2215571 | AN5: 0.022356563 | AO5: -0.095702649 | AP5: 0.32534298 | AQ5: 0.0044115431 | AR5: 0.044455775 | AS5: 0.029017662 | AT5: -0.12239985 | AU5: 0.30527744 | AV5: 0.40593571 | AW5: 0.25766904 | AX5: 0.13585252 | AY5: -0.04235306 | AZ5: 0.0059404007 | BA5: 0.033985565 | BB5: 0.075755079 | BC5: 0.018821755 | BD5: -0.018411246 | BE5: -0.044603245 | BF5: -0.036200712 | BG5: -0.053056995 | BH5: -5.4606362e-05 | BI5: 0.072471797 | BJ5: -0.06450446 | BK5: 0.005025338
A6: features.2.block.1.0 | B6: 0.090355858 | C6: -0.2739243 | D6: 0.67247657 | E6: 0.86053924 | F6: 1 | G6: 0.76222617 | H6: 0.0076681062 | I6: -0.14969529 | J6: 0.16403007 | K6: 0.68551382 | L6: 0.36324551 | M6: 0.32613744 | N6: -0.48082926 | O6: 0.44807574 | P6: 0.042684371 | Q6: -0.29533845 | R6: -0.076042166 | S6: -0.13405059 | T6: -0.22815281 | U6: 0.1503544 | V6: 0.060068169 | W6: -0.33458822 | X6: -0.28777173 | Y6: 0.32450897 | Z6: 0.60580735 | AA6: 0.35158453 | AB6: 0.2915535 | AC6: -0.20075671 | AD6: -0.25831153 | AE6: -0.27498739 | AF6: -0.10225486 | AG6: 0.014390083 | AH6: -0.32612304 | AI6: -0.11652798 | AJ6: -0.22194031 | AK6: -0.29122835 | AL6: 0.54180804 | AM6: 0.22088722 | AN6: 0.08537086 | AO6: -0.12845803 | AP6: 0.41669287 | AQ6: 0.018971125 | AR6: 0.05160813 | AS6: 0.033069997 | AT6: -0.12774077 | AU6: 0.33953831 | AV6: 0.4917024 | AW6: 0.2992517 | AX6: 0.070941488 | AY6: -0.087808251 | AZ6: -0.021893224 | BA6: 0.037482414 | BB6: 0.073765734 | BC6: 0.0021247219 | BD6: -0.026207946 | BE6: -0.057321881 | BF6: -0.058557671 | BG6: -0.081084338 | BH6: -0.010648582 | BI6: 0.05239941 | BJ6: -0.084693328 | BK6: -0.019738215
A7: features.2.block.2.0 | B7: 0.12508421 | C7: -0.35378751 | D7: 0.47895465 | E7: 0.66791532 | F7: 0.76222617 | G7: 1 | H7: 0.10419338 | I7: 0.12546756 | J7: 0.43362113 | K7: 0.78660629 | L7: 0.32494715 | M7: 0.29405463 | N7: -0.52763767 | O7: 0.39836058 | P7: 0.05882064 | Q7: -0.26936653 | R7: -0.15331555 | S7: -0.25621739 | T7: -0.13923466 | U7: 0.17357719 | V7: 0.063294268 | W7: -0.5126443 | X7: -0.43421386 | Y7: 0.32233807 | Z7: 0.59880659 | AA7: 0.47733711 | AB7: 0.43852525 | AC7: -0.1932782 | AD7: -0.20440883 | AE7: -0.10073294 | AF7: 0.017425815 | AG7: 0.17926858 | AH7: -0.23413427 | AI7: -0.092084822 | AJ7: -0.16554986 | AK7: -0.350388 | AL7: 0.52044888 | AM7: 0.31260106 | AN7: 0.10417568 | AO7: -0.19359231 | AP7: 0.49292017 | AQ7: 0.061118071 | AR7: 0.12103688 | AS7: 0.1470918 | AT7: -0.10274142 | AU7: 0.30466392 | AV7: 0.5005158 | AW7: 0.38318181 | AX7: 0.13613609 | AY7: -0.030148904 | AZ7: 0.017077237 | BA7: -0.016851932 | BB7: 0.038828287 | BC7: 0.023714965 | BD7: -0.055288029 | BE7: -0.07665113 | BF7: 0.0013297469 | BG7: 0.02007233 | BH7: 0.055098437 | BI7: 0.085828058 | BJ7: -0.14987232 | BK7: -0.10103492
A8: features.3.block.0.0 | B8: 0.06828177 | C8: 0.13026824 | D8: -0.028793341 | E8: 0.037320617 | F8: 0.0076681062 | G8: 0.10419338 | H8: 1 | I8: 0.22303226 | J8: 0.034874403 | K8: -0.049695607 | L8: -0.067974402 | M8: -0.098220676 | N8: 0.15977222 | O8: -0.080023145 | P8: 0.055389695 | Q8: 0.10191167 | R8: -0.029361531 | S8: 0.0061688572 | T8: 0.12330249 | U8: 0.12202855 | V8: -0.035766779 | W8: 0.10140352 | X8: 0.083264515 | Y8: -0.045707274 | Z8: -0.15359718 | AA8: -0.15397567 | AB8: -0.077812213 | AC8: 0.008785517 | AD8: 0.037278413 | AE8: 0.082552482 | AF8: 0.016570488 | AG8: 0.022680627 | AH8: 0.040987934 | AI8: 0.065055409 | AJ8: 0.062745188 | AK8: 0.14424999 | AL8: -0.099754166 | AM8: -0.028608629 | AN8: -0.050130819 | AO8: -0.011186011 | AP8: -0.093486399 | AQ8: 0.031323949 | AR8: 0.001234927 | AS8: 0.0070761466 | AT8: 0.028032871 | AU8: -0.073037081 | AV8: -0.1329433 | AW8: -0.072951532 | AX8: -0.018070632 | AY8: -0.049536694 | AZ8: 0.043765938 | BA8: -0.0092512121 | BB8: -0.017097707 | BC8: 0.039055086 | BD8: 0.017668406 | BE8: -0.051287922 | BF8: -0.036274817 | BG8: -0.0022409158 | BH8: 0.010057019 | BI8: -0.0074794456 | BJ8: 0.043519667 | BK8: 0.02853013
A9: features.3.block.1.0 | B9: 0.016992276 | C9: 0.22253301 | D9: -0.024380349 | E9: -0.019355448 | F9: -0.14969529 | G9: 0.12546756 | H9: 0.22303226 | I9: 1 | J9: 0.28317687 | K9: -0.05479613 | L9: 0.095309293 | M9: -0.25501722 | N9: 0.3063867 | O9: -0.047709291 | P9: -0.10887564 | Q9: -0.090523447 | R9: -0.18710007 | S9: -0.099642287 | T9: 0.17430003 | U9: -0.056964724 | V9: -0.20704111 | W9: -0.013518002 | X9: -0.026321027 | Y9: -0.18193919 | Z9: -0.081885835 | AA9: 0.033525713 | AB9: 0.1016734 | AC9: 0.098672122 | AD9: 0.19074403 | AE9: 0.17764292 | AF9: 0.096989277 | AG9: 0.16593843 | AH9: 0.14241775 | AI9: 0.084518541 | AJ9: 0.0035131403 | AK9: 0.071645776 | AL9: -0.10315655 | AM9: -0.019048891 | AN9: -0.032640895 | AO9: -0.038569214 | AP9: -0.13732763 | AQ9: -0.084089999 | AR9: 0.0086670977 | AS9: -0.047503003 | AT9: -0.079578882 | AU9: -0.18712445 | AV9: -0.16056186 | AW9: -0.010186291 | AX9: 0.11596045 | AY9: 0.038798367 | AZ9: 0.1012915 | BA9: -0.087543178 | BB9: -0.019873025 | BC9: 0.062887077 | BD9: 0.049678715 | BE9: 0.046502079 | BF9: 0.15706681 | BG9: 0.19532711 | BH9: 0.075040803 | BI9: 0.013616063 | BJ9: -0.074194037 | BK9: -0.081829279
