Workbook

Sheet Sensitivity
B1: =Class_0!B1 -> conv1_0.6 | C1: =Class_0!C1 -> maxpool_0.6 | D1: =Class_0!D1 -> layer1.0.conv1_0.6 | E1: =Class_0!E1 -> layer1.0.conv2_0.6 | F1: =Class_0!F1 -> layer1.0.conv3_0.6 | G1: =Class_0!G1 -> layer1.0.downsample.0_0.6 | H1: =Class_0!H1 -> layer1.1.conv1_0.6 | I1: =Class_0!I1 -> layer1.1.conv2_0.6 | ... BC1: =Class_0!BC1 -> layer4.2.conv3_0.6
A2: Deer | B2: =Class_0!B55 -> -0.03920529 | C2: =Class_0!C55 -> -0.2095956 | D2: =Class_0!D55 -> -0.16733422 | E2: =Class_0!E55 -> -0.098309841 | F2: =Class_0!F55 -> -0.060529187 | G2: =Class_0!G55 -> -0.15163553 | H2: =Class_0!H55 -> -0.012772904 | I2: =Class_0!I55 -> 0.10498255 | ... BD2: =Class_0!BD55 -> 0
A3: Horse | B3: =Class_1!B55 -> -0.0028756202 | C3: =Class_1!C55 -> -0.077112841 | D3: =Class_1!D55 -> -0.1345797 | E3: =Class_1!E55 -> -0.059678947 | F3: =Class_1!F55 -> -0.16027267 | G3: =Class_1!G55 -> -0.043060528 | H3: =Class_1!H55 -> 0.018656805 | I3: =Class_1!I55 -> 0.035208801 | ... BD3: =Class_1!BD55 -> 0
A4: Zebra | B4: =Class_2!B55 -> -0.026175297 | C4: =Class_2!C55 -> 0.0081044982 | D4: =Class_2!D55 -> -0.053679475 | E4: =Class_2!E55 -> 0.014917849 | F4: =Class_2!F55 -> 0.076221649 | G4: =Class_2!G55 -> 0.010992536 | H4: =Class_2!H55 -> 0.026656164 | I4: =Class_2!I55 -> 0.026251538 | ... BD4: =Class_2!BD55 -> 0
A6: Overall corelation | B6: =MIN(B2:B4) -> -0.03920529 | C6: =MIN(C2:C4) -> -0.2095956 | D6: =MIN(D2:D4) -> -0.16733422 | E6: =MIN(E2:E4) -> -0.098309841 | F6: =MIN(F2:F4) -> -0.16027267 | G6: =MIN(G2:G4) -> -0.15163553 | H6: =MIN(H2:H4) -> -0.012772904 | I6: =MIN(I2:I4) -> 0.026251538 | ... BC6: =MIN(BC2:BC4) -> 1
B7: =IF(AND(B2>0,B3>0,B4>0),TRUE,FALSE) -> FALSE | C7: =IF(AND(C2>0,C3>0,C4>0),TRUE,FALSE) -> FALSE | D7: =IF(AND(D2>0,D3>0,D4>0),TRUE,FALSE) -> FALSE | E7: =IF(AND(E2>0,E3>0,E4>0),TRUE,FALSE) -> FALSE | F7: =IF(AND(F2>0,F3>0,F4>0),TRUE,FALSE) -> FALSE | G7: =IF(AND(G2>0,G3>0,G4>0),TRUE,FALSE) -> FALSE | H7: =IF(AND(H2>0,H3>0,H4>0),TRUE,FALSE) -> FALSE | I7: =IF(AND(I2>0,I3>0,I4>0),TRUE,FALSE) -> TRUE | ... BC7: =IF(AND(BC2>0,BC3>0,BC4>0),TRUE,FALSE) -> TRUE
A8: Max Corelation layer | B8: =MAX(B6:BB6) -> 0.27265719
A9: Affects 2 classes | B9: =IF(OR(AND(B2>0,B3>0), AND(B2>0,B4>0), AND(B3>0,B4>0)), TRUE, FALSE) -> FALSE | C9: =IF(OR(AND(C2>0,C3>0), AND(C2>0,C4>0), AND(C3>0,C4>0)), TRUE, FALSE) -> FALSE | D9: =IF(OR(AND(D2>0,D3>0), AND(D2>0,D4>0), AND(D3>0,D4>0)), TRUE, FALSE) -> FALSE | E9: =IF(OR(AND(E2>0,E3>0), AND(E2>0,E4>0), AND(E3>0,E4>0)), TRUE, FALSE) -> FALSE | F9: =IF(OR(AND(F2>0,F3>0), AND(F2>0,F4>0), AND(F3>0,F4>0)), TRUE, FALSE) -> FALSE | G9: =IF(OR(AND(G2>0,G3>0), AND(G2>0,G4>0), AND(G3>0,G4>0)), TRUE, FALSE) -> FALSE | H9: =IF(OR(AND(H2>0,H3>0), AND(H2>0,H4>0), AND(H3>0,H4>0)), TRUE, FALSE) -> TRUE | I9: =IF(OR(AND(I2>0,I3>0), AND(I2>0,I4>0), AND(I3>0,I4>0)), TRUE, FALSE) -> TRUE | ... BB9: =IF(OR(AND(BB2>0,BB3>0), AND(BB2>0,BB4>0), AND(BB3>0,BB4>0)), TRUE, FALSE) -> TRUE
B11: =IF(B7=TRUE,B1,"") | C11: =IF(C7=TRUE,C1,"") | D11: =IF(D7=TRUE,D1,"") | E11: =IF(E7=TRUE,E1,"") | F11: =IF(F7=TRUE,F1,"") | G11: =IF(G7=TRUE,G1,"") | H11: =IF(H7=TRUE,H1,"") | I11: =IF(I7=TRUE,I1,"") -> layer1.1.conv2_0.6 | ... BB11: =IF(BB7=TRUE,BB1,"") -> layer4.2.conv2_0.6
B14: layer1.1.conv2
B15: layer1.1.conv3
B16: layer2.0.conv2
B17: layer2.1.conv3
B18: layer2.2.conv1
B19: layer2.2.conv3
B20: layer2.3.conv1
B21: layer2.3.conv2
B22: layer3.0.conv2
B23: layer3.0.conv3
B24: layer3.0.downsample.0
B25: layer3.1.conv1
... B43: layer4.2.conv2
C54: Layer Name | D54: Layer Index | E54: 1 | F54: =E54+1 -> 2 | G54: =F54+1 -> 3 | H54: =G54+1 -> 4 | I54: =H54+1 -> 5 | J54: =I54+1 -> 6 | K54: =J54+1 -> 7 | L54: =K54+1 -> 8 | M54: =L54+1 -> 9 | ... BF54: =BE54+1 -> 54
C55: conv1 | D55: 1 | E55: =IF(MIN(Class_0!B2,Class_1!B2,Class_2!B2) >0, CHAR(43), CHAR(45)) -> +
C56: maxpool | D56: =D55+1 -> 2 | E56: =IF(MIN(Class_0!B3,Class_1!B3,Class_2!B3) >0, CHAR(43), CHAR(45)) -> + | F56: =IF(MIN(Class_0!C3,Class_1!C3,Class_2!C3) >0, CHAR(43), CHAR(45)) -> +
C57: layer1.0.conv1 | D57: =D56+1 -> 3 | E57: =IF(MIN(Class_0!B4,Class_1!B4,Class_2!B4) >0, CHAR(43), CHAR(45)) -> + | F57: =IF(MIN(Class_0!C4,Class_1!C4,Class_2!C4) >0, CHAR(43), CHAR(45)) -> + | G57: =IF(MIN(Class_0!D4,Class_1!D4,Class_2!D4) >0, CHAR(43), CHAR(45)) -> +
C58: layer1.0.conv2 | D58: =D57+1 -> 4 | E58: =IF(MIN(Class_0!B5,Class_1!B5,Class_2!B5) >0, CHAR(43), CHAR(45)) -> + | F58: =IF(MIN(Class_0!C5,Class_1!C5,Class_2!C5) >0, CHAR(43), CHAR(45)) -> + | G58: =IF(MIN(Class_0!D5,Class_1!D5,Class_2!D5) >0, CHAR(43), CHAR(45)) -> + | H58: =IF(MIN(Class_0!E5,Class_1!E5,Class_2!E5) >0, CHAR(43), CHAR(45)) -> +
C59: layer1.0.conv3 | D59: =D58+1 -> 5 | E59: =IF(MIN(Class_0!B6,Class_1!B6,Class_2!B6) >0, CHAR(43), CHAR(45)) -> + | F59: =IF(MIN(Class_0!C6,Class_1!C6,Class_2!C6) >0, CHAR(43), CHAR(45)) -> + | G59: =IF(MIN(Class_0!D6,Class_1!D6,Class_2!D6) >0, CHAR(43), CHAR(45)) -> + | H59: =IF(MIN(Class_0!E6,Class_1!E6,Class_2!E6) >0, CHAR(43), CHAR(45)) -> + | I59: =IF(MIN(Class_0!F6,Class_1!F6,Class_2!F6) >0, CHAR(43), CHAR(45)) -> +
C60: layer1.0.downsample.0 | D60: =D59+1 -> 6 | E60: =IF(MIN(Class_0!B7,Class_1!B7,Class_2!B7) >0, CHAR(43), CHAR(45)) -> + | F60: =IF(MIN(Class_0!C7,Class_1!C7,Class_2!C7) >0, CHAR(43), CHAR(45)) -> + | G60: =IF(MIN(Class_0!D7,Class_1!D7,Class_2!D7) >0, CHAR(43), CHAR(45)) -> + | H60: =IF(MIN(Class_0!E7,Class_1!E7,Class_2!E7) >0, CHAR(43), CHAR(45)) -> + | I60: =IF(MIN(Class_0!F7,Class_1!F7,Class_2!F7) >0, CHAR(43), CHAR(45)) -> + | J60: =IF(MIN(Class_0!G7,Class_1!G7,Class_2!G7) >0, CHAR(43), CHAR(45)) -> +
C61: layer1.1.conv1 | D61: =D60+1 -> 7 | E61: =IF(MIN(Class_0!B8,Class_1!B8,Class_2!B8) >0, CHAR(43), CHAR(45)) -> - | F61: =IF(MIN(Class_0!C8,Class_1!C8,Class_2!C8) >0, CHAR(43), CHAR(45)) -> + | G61: =IF(MIN(Class_0!D8,Class_1!D8,Class_2!D8) >0, CHAR(43), CHAR(45)) -> + | H61: =IF(MIN(Class_0!E8,Class_1!E8,Class_2!E8) >0, CHAR(43), CHAR(45)) -> + | I61: =IF(MIN(Class_0!F8,Class_1!F8,Class_2!F8) >0, CHAR(43), CHAR(45)) -> + | J61: =IF(MIN(Class_0!G8,Class_1!G8,Class_2!G8) >0, CHAR(43), CHAR(45)) -> + | K61: =IF(MIN(Class_0!H8,Class_1!H8,Class_2!H8) >0, CHAR(43), CHAR(45)) -> +
C62: layer1.1.conv2 | D62: =D61+1 -> 8 | E62: =IF(MIN(Class_0!B9,Class_1!B9,Class_2!B9) >0, CHAR(43), CHAR(45)) -> + | F62: =IF(MIN(Class_0!C9,Class_1!C9,Class_2!C9) >0, CHAR(43), CHAR(45)) -> + | G62: =IF(MIN(Class_0!D9,Class_1!D9,Class_2!D9) >0, CHAR(43), CHAR(45)) -> + | H62: =IF(MIN(Class_0!E9,Class_1!E9,Class_2!E9) >0, CHAR(43), CHAR(45)) -> + | I62: =IF(MIN(Class_0!F9,Class_1!F9,Class_2!F9) >0, CHAR(43), CHAR(45)) -> + | J62: =IF(MIN(Class_0!G9,Class_1!G9,Class_2!G9) >0, CHAR(43), CHAR(45)) -> + | K62: =IF(MIN(Class_0!H9,Class_1!H9,Class_2!H9) >0, CHAR(43), CHAR(45)) -> + | L62: =IF(MIN(Class_0!I9,Class_1!I9,Class_2!I9) >0, CHAR(43), CHAR(45)) -> +
C63: layer1.1.conv3 | D63: =D62+1 -> 9 | E63: =IF(MIN(Class_0!B10,Class_1!B10,Class_2!B10) >0, CHAR(43), CHAR(45)) -> - | F63: =IF(MIN(Class_0!C10,Class_1!C10,Class_2!C10) >0, CHAR(43), CHAR(45)) -> - | G63: =IF(MIN(Class_0!D10,Class_1!D10,Class_2!D10) >0, CHAR(43), CHAR(45)) -> - | H63: =IF(MIN(Class_0!E10,Class_1!E10,Class_2!E10) >0, CHAR(43), CHAR(45)) -> + | I63: =IF(MIN(Class_0!F10,Class_1!F10,Class_2!F10) >0, CHAR(43), CHAR(45)) -> + | J63: =IF(MIN(Class_0!G10,Class_1!G10,Class_2!G10) >0, CHAR(43), CHAR(45)) -> - | K63: =IF(MIN(Class_0!H10,Class_1!H10,Class_2!H10) >0, CHAR(43), CHAR(45)) -> + | L63: =IF(MIN(Class_0!I10,Class_1!I10,Class_2!I10) >0, CHAR(43), CHAR(45)) -> + | M63: =IF(MIN(Class_0!J10,Class_1!J10,Class_2!J10) >0, CHAR(43), CHAR(45)) -> +
C64: layer1.2.conv1 | D64: =D63+1 -> 10 | E64: =IF(MIN(Class_0!B11,Class_1!B11,Class_2!B11) >0, CHAR(43), CHAR(45)) -> - | F64: =IF(MIN(Class_0!C11,Class_1!C11,Class_2!C11) >0, CHAR(43), CHAR(45)) -> + | G64: =IF(MIN(Class_0!D11,Class_1!D11,Class_2!D11) >0, CHAR(43), CHAR(45)) -> + | H64: =IF(MIN(Class_0!E11,Class_1!E11,Class_2!E11) >0, CHAR(43), CHAR(45)) -> + | I64: =IF(MIN(Class_0!F11,Class_1!F11,Class_2!F11) >0, CHAR(43), CHAR(45)) -> + | J64: =IF(MIN(Class_0!G11,Class_1!G11,Class_2!G11) >0, CHAR(43), CHAR(45)) -> + | K64: =IF(MIN(Class_0!H11,Class_1!H11,Class_2!H11) >0, CHAR(43), CHAR(45)) -> + | L64: =IF(MIN(Class_0!I11,Class_1!I11,Class_2!I11) >0, CHAR(43), CHAR(45)) -> + | ... N64: =IF(MIN(Class_0!K11,Class_1!K11,Class_2!K11) >0, CHAR(43), CHAR(45)) -> +
C65: layer1.2.conv2 | D65: =D64+1 -> 11 | E65: =IF(MIN(Class_0!B12,Class_1!B12,Class_2!B12) >0, CHAR(43), CHAR(45)) -> + | F65: =IF(MIN(Class_0!C12,Class_1!C12,Class_2!C12) >0, CHAR(43), CHAR(45)) -> - | G65: =IF(MIN(Class_0!D12,Class_1!D12,Class_2!D12) >0, CHAR(43), CHAR(45)) -> - | H65: =IF(MIN(Class_0!E12,Class_1!E12,Class_2!E12) >0, CHAR(43), CHAR(45)) -> - | I65: =IF(MIN(Class_0!F12,Class_1!F12,Class_2!F12) >0, CHAR(43), CHAR(45)) -> - | J65: =IF(MIN(Class_0!G12,Class_1!G12,Class_2!G12) >0, CHAR(43), CHAR(45)) -> - | K65: =IF(MIN(Class_0!H12,Class_1!H12,Class_2!H12) >0, CHAR(43), CHAR(45)) -> + | L65: =IF(MIN(Class_0!I12,Class_1!I12,Class_2!I12) >0, CHAR(43), CHAR(45)) -> + | ... O65: =IF(MIN(Class_0!L12,Class_1!L12,Class_2!L12) >0, CHAR(43), CHAR(45)) -> +
C66: layer1.2.conv3 | D66: =D65+1 -> 12 | E66: =IF(MIN(Class_0!B13,Class_1!B13,Class_2!B13) >0, CHAR(43), CHAR(45)) -> - | F66: =IF(MIN(Class_0!C13,Class_1!C13,Class_2!C13) >0, CHAR(43), CHAR(45)) -> - | G66: =IF(MIN(Class_0!D13,Class_1!D13,Class_2!D13) >0, CHAR(43), CHAR(45)) -> - | H66: =IF(MIN(Class_0!E13,Class_1!E13,Class_2!E13) >0, CHAR(43), CHAR(45)) -> + | I66: =IF(MIN(Class_0!F13,Class_1!F13,Class_2!F13) >0, CHAR(43), CHAR(45)) -> - | J66: =IF(MIN(Class_0!G13,Class_1!G13,Class_2!G13) >0, CHAR(43), CHAR(45)) -> - | K66: =IF(MIN(Class_0!H13,Class_1!H13,Class_2!H13) >0, CHAR(43), CHAR(45)) -> - | L66: =IF(MIN(Class_0!I13,Class_1!I13,Class_2!I13) >0, CHAR(43), CHAR(45)) -> - | ... P66: =IF(MIN(Class_0!M13,Class_1!M13,Class_2!M13) >0, CHAR(43), CHAR(45)) -> +
C67: layer2.0.conv1 | D67: =D66+1 -> 13 | E67: =IF(MIN(Class_0!B14,Class_1!B14,Class_2!B14) >0, CHAR(43), CHAR(45)) -> + | F67: =IF(MIN(Class_0!C14,Class_1!C14,Class_2!C14) >0, CHAR(43), CHAR(45)) -> + | G67: =IF(MIN(Class_0!D14,Class_1!D14,Class_2!D14) >0, CHAR(43), CHAR(45)) -> + | H67: =IF(MIN(Class_0!E14,Class_1!E14,Class_2!E14) >0, CHAR(43), CHAR(45)) -> + | I67: =IF(MIN(Class_0!F14,Class_1!F14,Class_2!F14) >0, CHAR(43), CHAR(45)) -> + | J67: =IF(MIN(Class_0!G14,Class_1!G14,Class_2!G14) >0, CHAR(43), CHAR(45)) -> + | K67: =IF(MIN(Class_0!H14,Class_1!H14,Class_2!H14) >0, CHAR(43), CHAR(45)) -> - | L67: =IF(MIN(Class_0!I14,Class_1!I14,Class_2!I14) >0, CHAR(43), CHAR(45)) -> + | ... Q67: =IF(MIN(Class_0!N14,Class_1!N14,Class_2!N14) >0, CHAR(43), CHAR(45)) -> +
C68: layer2.0.conv2 | D68: =D67+1 -> 14 | E68: =IF(MIN(Class_0!B15,Class_1!B15,Class_2!B15) >0, CHAR(43), CHAR(45)) -> + | F68: =IF(MIN(Class_0!C15,Class_1!C15,Class_2!C15) >0, CHAR(43), CHAR(45)) -> - | G68: =IF(MIN(Class_0!D15,Class_1!D15,Class_2!D15) >0, CHAR(43), CHAR(45)) -> - | H68: =IF(MIN(Class_0!E15,Class_1!E15,Class_2!E15) >0, CHAR(43), CHAR(45)) -> - | I68: =IF(MIN(Class_0!F15,Class_1!F15,Class_2!F15) >0, CHAR(43), CHAR(45)) -> - | J68: =IF(MIN(Class_0!G15,Class_1!G15,Class_2!G15) >0, CHAR(43), CHAR(45)) -> - | K68: =IF(MIN(Class_0!H15,Class_1!H15,Class_2!H15) >0, CHAR(43), CHAR(45)) -> - | L68: =IF(MIN(Class_0!I15,Class_1!I15,Class_2!I15) >0, CHAR(43), CHAR(45)) -> - | ... R68: =IF(MIN(Class_0!O15,Class_1!O15,Class_2!O15) >0, CHAR(43), CHAR(45)) -> +
C69: layer2.0.conv3 | D69: =D68+1 -> 15 | E69: =IF(MIN(Class_0!B16,Class_1!B16,Class_2!B16) >0, CHAR(43), CHAR(45)) -> - | F69: =IF(MIN(Class_0!C16,Class_1!C16,Class_2!C16) >0, CHAR(43), CHAR(45)) -> - | G69: =IF(MIN(Class_0!D16,Class_1!D16,Class_2!D16) >0, CHAR(43), CHAR(45)) -> - | H69: =IF(MIN(Class_0!E16,Class_1!E16,Class_2!E16) >0, CHAR(43), CHAR(45)) -> - | I69: =IF(MIN(Class_0!F16,Class_1!F16,Class_2!F16) >0, CHAR(43), CHAR(45)) -> - | J69: =IF(MIN(Class_0!G16,Class_1!G16,Class_2!G16) >0, CHAR(43), CHAR(45)) -> - | K69: =IF(MIN(Class_0!H16,Class_1!H16,Class_2!H16) >0, CHAR(43), CHAR(45)) -> - | L69: =IF(MIN(Class_0!I16,Class_1!I16,Class_2!I16) >0, CHAR(43), CHAR(45)) -> - | ... S69: =IF(MIN(Class_0!P16,Class_1!P16,Class_2!P16) >0, CHAR(43), CHAR(45)) -> +
C70: layer2.0.downsample.0 | D70: =D69+1 -> 16 | E70: =IF(MIN(Class_0!B17,Class_1!B17,Class_2!B17) >0, CHAR(43), CHAR(45)) -> + | F70: =IF(MIN(Class_0!C17,Class_1!C17,Class_2!C17) >0, CHAR(43), CHAR(45)) -> + | G70: =IF(MIN(Class_0!D17,Class_1!D17,Class_2!D17) >0, CHAR(43), CHAR(45)) -> + | H70: =IF(MIN(Class_0!E17,Class_1!E17,Class_2!E17) >0, CHAR(43), CHAR(45)) -> + | I70: =IF(MIN(Class_0!F17,Class_1!F17,Class_2!F17) >0, CHAR(43), CHAR(45)) -> + | J70: =IF(MIN(Class_0!G17,Class_1!G17,Class_2!G17) >0, CHAR(43), CHAR(45)) -> + | K70: =IF(MIN(Class_0!H17,Class_1!H17,Class_2!H17) >0, CHAR(43), CHAR(45)) -> - | L70: =IF(MIN(Class_0!I17,Class_1!I17,Class_2!I17) >0, CHAR(43), CHAR(45)) -> - | ... T70: =IF(MIN(Class_0!Q17,Class_1!Q17,Class_2!Q17) >0, CHAR(43), CHAR(45)) -> +
C71: layer2.1.conv1 | D71: =D70+1 -> 17 | E71: =IF(MIN(Class_0!B18,Class_1!B18,Class_2!B18) >0, CHAR(43), CHAR(45)) -> + | F71: =IF(MIN(Class_0!C18,Class_1!C18,Class_2!C18) >0, CHAR(43), CHAR(45)) -> + | G71: =IF(MIN(Class_0!D18,Class_1!D18,Class_2!D18) >0, CHAR(43), CHAR(45)) -> + | H71: =IF(MIN(Class_0!E18,Class_1!E18,Class_2!E18) >0, CHAR(43), CHAR(45)) -> + | I71: =IF(MIN(Class_0!F18,Class_1!F18,Class_2!F18) >0, CHAR(43), CHAR(45)) -> + | J71: =IF(MIN(Class_0!G18,Class_1!G18,Class_2!G18) >0, CHAR(43), CHAR(45)) -> + | K71: =IF(MIN(Class_0!H18,Class_1!H18,Class_2!H18) >0, CHAR(43), CHAR(45)) -> + | L71: =IF(MIN(Class_0!I18,Class_1!I18,Class_2!I18) >0, CHAR(43), CHAR(45)) -> - | ... U71: =IF(MIN(Class_0!R18,Class_1!R18,Class_2!R18) >0, CHAR(43), CHAR(45)) -> +
...

Sheet Class_0
B1: conv1_0.6 | C1: maxpool_0.6 | D1: layer1.0.conv1_0.6 | E1: layer1.0.conv2_0.6 | F1: layer1.0.conv3_0.6 | G1: layer1.0.downsample.0_0.6 | H1: layer1.1.conv1_0.6 | I1: layer1.1.conv2_0.6 | J1: layer1.1.conv3_0.6 | K1: layer1.2.conv1_0.6 | L1: layer1.2.conv2_0.6 | M1: layer1.2.conv3_0.6 | N1: layer2.0.conv1_0.6 | O1: layer2.0.conv2_0.6 | P1: layer2.0.conv3_0.6 | Q1: layer2.0.downsample.0_0.6 | R1: layer2.1.conv1_0.6 | S1: layer2.1.conv2_0.6 | T1: layer2.1.conv3_0.6 | U1: layer2.2.conv1_0.6 | V1: layer2.2.conv2_0.6 | W1: layer2.2.conv3_0.6 | X1: layer2.3.conv1_0.6 | Y1: layer2.3.conv2_0.6 | Z1: layer2.3.conv3_0.6 | AA1: layer3.0.conv1_0.6 | AB1: layer3.0.conv2_0.6 | AC1: layer3.0.conv3_0.6 | AD1: layer3.0.downsample.0_0.6 | AE1: layer3.1.conv1_0.6 | AF1: layer3.1.conv2_0.6 | AG1: layer3.1.conv3_0.6 | AH1: layer3.2.conv1_0.6 | AI1: layer3.2.conv2_0.6 | AJ1: layer3.2.conv3_0.6 | AK1: layer3.3.conv1_0.6 | AL1: layer3.3.conv2_0.6 | AM1: layer3.3.conv3_0.6 | AN1: layer3.4.conv1_0.6 | AO1: layer3.4.conv2_0.6 | AP1: layer3.4.conv3_0.6 | AQ1: layer3.5.conv1_0.6 | AR1: layer3.5.conv2_0.6 | AS1: layer3.5.conv3_0.6 | AT1: layer4.0.conv1_0.6 | AU1: layer4.0.conv2_0.6 | AV1: layer4.0.conv3_0.6 | AW1: layer4.0.downsample.0_0.6 | AX1: layer4.1.conv1_0.6 | AY1: layer4.1.conv2_0.6 | AZ1: layer4.1.conv3_0.6 | BA1: layer4.2.conv1_0.6 | BB1: layer4.2.conv2_0.6 | BC1: layer4.2.conv3_0.6
A2: conv1_0.6 | B2: 1 | C2: 0.14880623 | D2: 0.077711917 | E2: 0.10349909 | F2: 0.056296969 | G2: 0.23077247 | H2: 0.14505239 | I2: 0.090773175 | J2: 0.07552885 | K2: 0.075589023 | L2: 0.049009402 | M2: -0.026164688 | N2: 0.057971324 | O2: 0.017666001 | P2: -0.0045791748 | Q2: 0.065661046 | R2: 0.090445628 | S2: 0.044771656 | T2: 0.0050360063 | U2: -0.0053140245 | V2: 0.038391653 | W2: 0.01684595 | X2: 0.0082270203 | Y2: 0.018816179 | Z2: 0.0087416476 | AA2: -0.0013142896 | AB2: -0.0016306053 | AC2: -0.015659251 | AD2: -0.0011661815 | AE2: 0.016109129 | AF2: 0.010966759 | AG2: -0.025043848 | AH2: 0.0058859446 | AI2: -0.0082420878 | AJ2: -0.053703723 | AK2: -0.043444698 | AL2: -0.072411022 | AM2: -0.054170943 | AN2: -0.023968651 | AO2: -0.017641428 | AP2: -0.0047779625 | AQ2: -0.00042186817 | AR2: 0.037039121 | AS2: 0.015345329 | AT2: 0.026433533 | AU2: 0.041510337 | AV2: 0.02006086 | AW2: -0.016562308 | AX2: 0.03172945 | AY2: 0.018844404 | AZ2: 0.018258885 | BA2: 0.023751064 | BB2: 0.044399665 | BC2: -0.03920529
A3: maxpool_0.6 | B3: 0.14880623 | C3: 1 | D3: 0.72475925 | E3: 0.56427422 | F3: 0.47874987 | G3: 0.77061615 | H3: 0.19106752 | I3: 0.014608439 | J3: -0.0879293 | K3: 0.14165934 | L3: 0.13835958 | M3: 0.082801827 | N3: 0.085980298 | O3: -0.13628194 | P3: 0.031433446 | Q3: 0.5311814 | R3: 0.29551022 | S3: 0.29777457 | T3: 0.21403978 | U3: 0.063230965 | V3: 0.071175746 | W3: -0.042387132 | X3: -0.089644338 | Y3: -0.04091568 | Z3: -0.009983775 | AA3: -0.00095072655 | AB3: -0.14334956 | AC3: -0.093931131 | AD3: 0.071480028 | AE3: -0.05544799 | AF3: -0.022373374 | AG3: -0.11606086 | AH3: -0.09282154 | AI3: -0.10410164 | AJ3: -0.18503987 | AK3: -0.11154499 | AL3: -0.055074227 | AM3: -0.21086692 | AN3: -0.12056458 | AO3: -0.1760169 | AP3: -0.1448972 | AQ3: -0.18233133 | AR3: -0.15032473 | AS3: -0.037483681 | AT3: 0.013423673 | AU3: -0.032738346 | AV3: -0.026666867 | AW3: -0.12059865 | AX3: -0.060704669 | AY3: 0.017365222 | AZ3: 0.055189767 | BA3: 0.042225823 | BB3: -0.050423238 | BC3: -0.2095956
A4: layer1.0.conv1_0.6 | B4: 0.077711917 | C4: 0.72475925 | D4: 1 | E4: 0.60726862 | F4: 0.53986863 | G4: 0.58052639 | H4: 0.22482305 | I4: 0.075834898 | J4: -0.027820086 | K4: 0.15951892 | L4: 0.13347182 | M4: 0.0089325733 | N4: 0.051408167 | O4: -0.13600556 | P4: -0.035311786 | Q4: 0.4386664 | R4: 0.24919059 | S4: 0.25305052 | T4: 0.21360558 | U4: 0.046409997 | V4: 0.089349744 | W4: -0.036992534 | X4: -0.038490768 | Y4: -0.017577612 | Z4: -0.0062844981 | AA4: -0.042117885 | AB4: -0.13582932 | AC4: -0.10588097 | AD4: 0.062770956 | AE4: -0.053631872 | AF4: -0.020235493 | AG4: -0.10212009 | AH4: -0.096065563 | AI4: -0.1120088 | AJ4: -0.19079597 | AK4: -0.10040549 | AL4: -0.035448092 | AM4: -0.18683781 | AN4: -0.11753285 | AO4: -0.16443342 | AP4: -0.12419487 | AQ4: -0.20002415 | AR4: -0.13251783 | AS4: -0.031319404 | AT4: -0.066868287 | AU4: -0.052270902 | AV4: -0.002006146 | AW4: -0.095061255 | AX4: -0.0080374501 | AY4: 0.010227064 | AZ4: 0.04307974 | BA4: 0.070377556 | BB4: -0.02288037 | BC4: -0.16733422
A5: layer1.0.conv2_0.6 | B5: 0.10349909 | C5: 0.56427422 | D5: 0.60726862 | E5: 1 | F5: 0.64507603 | G5: 0.44418226 | H5: 0.17523287 | I5: 0.12708093 | J5: 0.019588006 | K5: 0.1206798 | L5: 0.11354921 | M5: 0.048165044 | N5: 0.12584292 | O5: -0.12865826 | P5: -0.025172379 | Q5: 0.37935987 | R5: 0.24431604 | S5: 0.21245019 | T5: 0.16612549 | U5: 0.016384697 | V5: 0.022110878 | W5: -0.019761987 | X5: -0.011932919 | Y5: 0.0023497567 | Z5: 7.6191978e-05 | AA5: -0.0084414384 | AB5: -0.13098497 | AC5: -0.098412123 | AD5: 0.057897118 | AE5: -0.010583225 | AF5: -0.026467445 | AG5: -0.087866456 | AH5: -0.092097626 | AI5: -0.058047643 | AJ5: -0.10755776 | AK5: -0.098481441 | AL5: -0.063342373 | AM5: -0.16126728 | AN5: -0.055861642 | AO5: -0.095013158 | AP5: -0.056170616 | AQ5: -0.15052583 | AR5: -0.10715937 | AS5: -0.0067913576 | AT5: 0.0060293484 | AU5: -0.0010791464 | AV5: -0.0057429479 | AW5: -0.058191853 | AX5: -0.0010453872 | AY5: 0.0093569146 | AZ5: 0.061657873 | BA5: 0.03840541 | BB5: 0.015081727 | BC5: -0.098309841
A6: layer1.0.conv3_0.6 | B6: 0.056296969 | C6: 0.47874987 | D6: 0.53986863 | E6: 0.64507603 | F6: 1 | G6: 0.3430547 | H6: 0.19892839 | I6: 0.16515111 | J6: 0.1342647 | K6: 0.11520117 | L6: 0.088814526 | M6: 0.1104766 | N6: 0.18012753 | O6: 0.010792058 | P6: 0.054462576 | Q6: 0.35044118 | R6: 0.15682698 | S6: 0.16030616 | T6: 0.18536037 | U6: 0.031540679 | V6: 0.073090443 | W6: -0.0017258305 | X6: 0.057341423 | Y6: 0.11144594 | Z6: 0.051136405 | AA6: 0.058244116 | AB6: -0.001469481 | AC6: 0.041326145 | AD6: 0.1240158 | AE6: 0.11197493 | AF6: 0.096917377 | AG6: -0.0053586465 | AH6: -0.0092872398 | AI6: 0.0033996136 | AJ6: -0.042826897 | AK6: 0.020305985 | AL6: 0.018004996 | AM6: -0.088350667 | AN6: -0.037463365 | AO6: -0.095281135 | AP6: -0.059804267 | AQ6: -0.11952813 | AR6: -0.069213905 | AS6: -0.0063562199 | AT6: -0.025285912 | AU6: -0.037504651 | AV6: -0.019075194 | AW6: -0.017997038 | AX6: 0.028761757 | AY6: 0.017508705 | AZ6: 0.045601827 | BA6: 0.068314324 | BB6: 0.009381472 | BC6: -0.060529187
A7: layer1.0.downsample.0_0.6 | B7: 0.23077247 | C7: 0.77061615 | D7: 0.58052639 | E7: 0.44418226 | F7: 0.3430547 | G7: 1 | H7: 0.20926387 | I7: 0.064991407 | J7: -0.12024002 | K7: 0.13320508 | L7: 0.14159449 | M7: 0.12532622 | N7: 0.11630651 | O7: -0.079868679 | P7: 0.031886207 | Q7: 0.48637806 | R7: 0.29595664 | S7: 0.30994942 | T7: 0.15638381 | U7: 0.080269419 | V7: 0.066112065 | W7: -0.018566035 | X7: -0.10369449 | Y7: -0.042176797 | Z7: 0.02148651 | AA7: 0.015260011 | AB7: -0.09888459 | AC7: -0.030753195 | AD7: 0.034588926 | AE7: -0.017597494 | AF7: -0.019766668 | AG7: -0.08040681 | AH7: -0.075066435 | AI7: -0.074223989 | AJ7: -0.16006983 | AK7: -0.060841181 | AL7: -0.04408085 | AM7: -0.18476939 | AN7: -0.12589195 | AO7: -0.13322792 | AP7: -0.072861956 | AQ7: -0.091410352 | AR7: -0.046688782 | AS7: 0.020539497 | AT7: 0.010278008 | AU7: -0.033896762 | AV7: -0.038362871 | AW7: -0.096165971 | AX7: -0.074472877 | AY7: 0.004056597 | AZ7: -0.017626057 | BA7: -0.0010960441 | BB7: -0.044461654 | BC7: -0.15163553
A8: layer1.1.conv1_0.6 | B8: 0.14505239 | C8: 0.19106752 | D8: 0.22482305 | E8: 0.17523287 | F8: 0.19892839 | G8: 0.20926387 | H8: 1 | I8: 0.34528135 | J8: 0.20384882 | K8: 0.21186576 | L8: 0.13446649 | M8: -0.024142881 | N8: -0.044877072 | O8: -0.045777911 | P8: -0.092604526 | Q8: -0.011190438 | R8: 0.03161497 | S8: 0.030642831 | T8: 0.0035167584 | U8: -0.0034474155 | V8: 0.023818548 | W8: -0.024262337 | X8: -0.0083905217 | Y8: -0.031167507 | Z8: 0.03905081 | AA8: -0.073208416 | AB8: -0.049565185 | AC8: -0.059910541 | AD8: -0.087523454 | AE8: -0.016200769 | AF8: -0.036552875 | AG8: -0.045476704 | AH8: -0.052236399 | AI8: -0.055588307 | AJ8: -0.074232894 | AK8: -0.051053616 | AL8: 0.0068335924 | AM8: -0.01781769 | AN8: -0.05948991 | AO8: -0.020963464 | AP8: -0.022248572 | AQ8: -0.020720028 | AR8: -0.015913487 | AS8: 0.044034656 | AT8: -0.031385933 | AU8: -0.083674857 | AV8: -0.026837492 | AW8: -0.041409221 | AX8: -0.046846482 | AY8: -0.047536281 | AZ8: -0.10416762 | BA8: -0.046750731 | BB8: -0.0019468356 | BC8: -0.012772904
A9: layer1.1.conv2_0.6 | B9: 0.090773175 | C9: 0.014608439 | D9: 0.075834898 | E9: 0.12708093 | F9: 0.16515111 | G9: 0.064991407 | H9: 0.34528135 | I9: 1 | J9: 0.45918789 | K9: 0.11077548 | L9: 0.098368577 | M9: 0.051139589 | N9: 0.092353322 | O9: 0.13470936 | P9: 0.063740249 | Q9: -0.057400173 | R9: -0.034059362 | S9: 0.0059411802 | T9: 0.032132657 | U9: 0.024377826 | V9: 0.063157316 | W9: 0.072704135 | X9: 0.095814852 | Y9: 0.133683 | Z9: 0.11215745 | AA9: 0.032526105 | AB9: 0.088455995 | AC9: 0.083551568 | AD9: 0.064355018 | AE9: 0.048148369 | AF9: 0.0070675591 | AG9: 0.037598512 | AH9: 0.025098568 | AI9: -0.0033301465 | AJ9: 0.030726846 | AK9: 0.057415622 | AL9: -0.0066498962 | AM9: 0.022250506 | AN9: -0.0013875022 | AO9: 0.047321566 | AP9: 0.052144715 | AQ9: 0.031206298 | AR9: 0.016964547 | AS9: 0.021347986 | AT9: 0.024542303 | AU9: 0.021884713 | AV9: 0.02056652 | AW9: 0.045938398 | AX9: 0.024561824 | AY9: -0.013997 | AZ9: -0.032832538 | BA9: 0.004698897 | BB9: 0.047514109 | BC9: 0.10498255
A10: layer1.1.conv3_0.6 | B10: 0.07552885 | C10: -0.0879293 | D10: -0.027820086 | E10: 0.019588006 | F10: 0.1342647 | G10: -0.12024002 | H10: 0.20384882 | I10: 0.45918789 | J10: 1 | K10: 0.049166172 | L10: 0.18284949 | M10: 0.12004714 | N10: 0.15920464 | O10: 0.25534178 | P10: 0.22341016 | Q10: -0.035460023 | R10: -0.0078991288 | S10: -0.063951088 | T10: 0.031078254 | U10: 0.13827211 | V10: 0.16373644 | W10: 0.17269934 | X10: 0.14638242 | Y10: 0.19938268 | Z10: 0.13283457 | AA10: 0.12111633 | AB10: 0.15743928 | AC10: 0.16114446 | AD10: 0.17386551 | AE10: 0.12803344 | AF10: 0.099767459 | AG10: 0.12040194 | AH10: 0.10134409 | AI10: 0.076144519 | AJ10: 0.15074245 | AK10: 0.14333046 | AL10: 0.13344579 | AM10: 0.18663156 | AN10: 0.11868927 | AO10: 0.14878101 | AP10: 0.13974845 | AQ10: 0.1344932 | AR10: 0.090991253 | AS10: 0.067224993 | AT10: 0.078358758 | AU10: 0.095421647 | AV10: 0.068444587 | AW10: 0.13923381 | AX10: 0.13754577 | AY10: 0.084635665 | AZ10: 0.080675877 | BA10: 0.13825512 | BB10: 0.15661388 | BC10: 0.086574544
A11: layer1.2.conv1_0.6 | B11: 0.075589023 | C11: 0.14165934 | D11: 0.15951892 | E11: 0.1206798 | F11: 0.11520117 | G11: 0.13320508 | H11: 0.21186576 | I11: 0.11077548 | J11: 0.049166172 | K11: 1 | L11: 0.33175984 | M11: -0.1625641 | N11: -0.19533694 | O11: -0.28045944 | P11: -0.25643858 | Q11: -0.022478928 | R11: 0.05521413 | S11: 0.03448432 | T11: 0.025829575 | U11: -0.042673418 | V11: -0.067188569 | W11: -0.10364554 | X11: -0.049294201 | Y11: -0.11717996 | Z11: -0.16510178 | AA11: -0.20045267 | AB11: -0.14056994 | AC11: -0.17900978 | AD11: -0.16374664 | AE11: -0.13773122 | AF11: -0.11997965 | AG11: -0.14689745 | AH11: -0.10458294 | AI11: -0.13115556 | AJ11: -0.19993309 | AK11: -0.16103177 | AL11: -0.098974745 | AM11: -0.16686485 | AN11: -0.13848335 | AO11: -0.14713261 | AP11: -0.13704183 | AQ11: -0.11037831 | AR11: -0.051556133 | AS11: 0.023868139 | AT11: -0.0810358 | AU11: -0.074890251 | AV11: -0.022920933 | AW11: -0.13287709 | AX11: -0.097315018 | AY11: -0.090551732 | AZ11: -0.052556571 | BA11: -0.043320199 | BB11: -0.055363922 | BC11: -0.075333782
A12: layer1.2.conv2_0.6 | B12: 0.049009402 | C12: 0.13835958 | D12: 0.13347182 | E12: 0.11354921 | F12: 0.088814526 | G12: 0.14159449 | H12: 0.13446649 | I12: 0.098368577 | J12: 0.18284949 | K12: 0.33175984 | L12: 1 | M12: 0.1549657 | N12: 0.070450871 | O12: -0.058548838 | P12: 0.032348736 | Q12: 0.04408591 | R12: 0.025079118 | S12: -0.0030216496 | T12: -0.019524002 | U12: -0.0020398261 | V12: 0.039807107 | W12: -0.027926 | X12: -0.02592131 | Y12: -0.0053233665 | Z12: -0.043900127 | AA12: 0.026990648 | AB12: -0.044680844 | AC12: -0.023441439 | AD12: -0.023813343 | AE12: -0.059608886 | AF12: 0.011953559 | AG12: 0.0096316366 | AH12: -0.002095473 | AI12: -0.042765439 | AJ12: -0.08831434 | AK12: -0.049800191 | AL12: -0.016034979 | AM12: -0.073475719 | AN12: 0.020003171 | AO12: -0.032010592 | AP12: -0.0077972328 | AQ12: -0.017880335 | AR12: -0.011727971 | AS12: -0.0099334481 | AT12: 0.01085077 | AU12: -0.0075326279 | AV12: -0.012493771 | AW12: -0.049948751 | AX12: -0.058167771 | AY12: -0.035007591 | AZ12: 6.4940021e-06 | BA12: 0.025837197 | BB12: -0.060509222 | BC12: -0.10181265
A13: layer1.2.conv3_0.6 | B13: -0.026164688 | C13: 0.082801827 | D13: 0.0089325733 | E13: 0.048165044 | F13: 0.1104766 | G13: 0.12532622 | H13: -0.024142881 | I13: 0.051139589 | J13: 0.12004714 | K13: -0.1625641 | L13: 0.1549657 | M13: 1 | N13: 0.58616301 | O13: 0.43397782 | P13: 0.48711375 | Q13: 0.17000514 | R13: 0.057745337 | S13: 0.019915948 | T13: 0.065744856 | U13: 0.12414804 | V13: 0.1312557 | W13: 0.097157425 | X13: 0.092057394 | Y13: 0.18591578 | Z13: 0.27517975 | AA13: 0.36983817 | AB13: 0.32250914 | AC13: 0.34112834 | AD13: 0.31584174 | AE13: 0.20869927 | AF13: 0.16484916 | AG13: 0.20927306 | AH13: 0.19438056 | AI13: 0.20882387 | AJ13: 0.19199834 | AK13: 0.24885282 | AL13: 0.16932168 | AM13: 0.19680211 | AN13: 0.20554012 | AO13: 0.17141731 | AP13: 0.11809613 | AQ13: 0.047935017 | AR13: 0.032859912 | AS13: -0.018933753 | AT13: 0.15277216 | AU13: 0.08687483 | AV13: 0.045726073 | AW13: 0.19414007 | AX13: 0.11402382 | AY13: 0.22524245 | AZ13: 0.22037531 | BA13: 0.18132376 | BB13: 0.16741397 | BC13: 0.058940101
... A55: layer4.2.conv3_0.6 | B55: -0.03920529 | C55: -0.2095956 | D55: -0.16733422 | E55: -0.098309841 | F55: -0.060529187 | G55: -0.15163553 | H55: -0.012772904 | I55: 0.10498255 | J55: 0.086574544 | K55: -0.075333782 | L55: -0.10181265 | M55: 0.058940101 | N55: 0.12537859 | O55: 0.15540151 | P55: 0.075032322 | Q55: -0.10357435 | R55: -0.030458215 | S55: -0.028305691 | T55: 0.039943603 | U55: 0.014919964 | V55: -0.017361049 | W55: 0.13489231 | X55: 0.093868002 | Y55: 0.018907885 | Z55: 0.058519158 | AA55: -0.077467091 | AB55: 0.11140939 | AC55: 0.12646169 | AD55: 0.13027681 | AE55: 0.10210029 | AF55: -0.0054600961 | AG55: 0.088007126 | AH55: 0.07850671 | AI55: 0.12629841 | AJ55: 0.19013832 | AK55: 0.091968497 | AL55: 0.04697005 | AM55: 0.13171132 | AN55: 0.028635916 | AO55: 0.15541398 | AP55: 0.17510698 | AQ55: 0.15997554 | AR55: 0.088849111 | AS55: 0.083415717 | AT55: 0.1585964 | AU55: 0.16885817 | AV55: 0.16240058 | AW55: 0.23755605 | AX55: 0.203711 | AY55: 0.22525944 | AZ55: 0.17846822 | BA55: 0.27265719 | BB55: 0.46501712 | BC55: 1

Sheet Class_1
B1: conv1_0.6 | C1: maxpool_0.6 | D1: layer1.0.conv1_0.6 | E1: layer1.0.conv2_0.6 | F1: layer1.0.conv3_0.6 | G1: layer1.0.downsample.0_0.6 | H1: layer1.1.conv1_0.6 | I1: layer1.1.conv2_0.6 | J1: layer1.1.conv3_0.6 | K1: layer1.2.conv1_0.6 | L1: layer1.2.conv2_0.6 | M1: layer1.2.conv3_0.6 | N1: layer2.0.conv1_0.6 | O1: layer2.0.conv2_0.6 | P1: layer2.0.conv3_0.6 | Q1: layer2.0.downsample.0_0.6 | R1: layer2.1.conv1_0.6 | S1: layer2.1.conv2_0.6 | T1: layer2.1.conv3_0.6 | U1: layer2.2.conv1_0.6 | V1: layer2.2.conv2_0.6 | W1: layer2.2.conv3_0.6 | X1: layer2.3.conv1_0.6 | Y1: layer2.3.conv2_0.6 | Z1: layer2.3.conv3_0.6 | AA1: layer3.0.conv1_0.6 | AB1: layer3.0.conv2_0.6 | AC1: layer3.0.conv3_0.6 | AD1: layer3.0.downsample.0_0.6 | AE1: layer3.1.conv1_0.6 | AF1: layer3.1.conv2_0.6 | AG1: layer3.1.conv3_0.6 | AH1: layer3.2.conv1_0.6 | AI1: layer3.2.conv2_0.6 | AJ1: layer3.2.conv3_0.6 | AK1: layer3.3.conv1_0.6 | AL1: layer3.3.conv2_0.6 | AM1: layer3.3.conv3_0.6 | AN1: layer3.4.conv1_0.6 | AO1: layer3.4.conv2_0.6 | AP1: layer3.4.conv3_0.6 | AQ1: layer3.5.conv1_0.6 | AR1: layer3.5.conv2_0.6 | AS1: layer3.5.conv3_0.6 | AT1: layer4.0.conv1_0.6 | AU1: layer4.0.conv2_0.6 | AV1: layer4.0.conv3_0.6 | AW1: layer4.0.downsample.0_0.6 | AX1: layer4.1.conv1_0.6 | AY1: layer4.1.conv2_0.6 | AZ1: layer4.1.conv3_0.6 | BA1: layer4.2.conv1_0.6 | BB1: layer4.2.conv2_0.6 | BC1: layer4.2.conv3_0.6
A2: conv1_0.6 | B2: 1 | C2: 0.073941259 | D2: 0.0093531139 | E2: 0.088187595 | F2: 0.053547716 | G2: 0.14697729 | H2: 0.068902121 | I2: 0.10465273 | J2: 0.081138978 | K2: 0.056971584 | L2: 0.040525574 | M2: -0.021074431 | N2: 0.032716871 | O2: 0.067092207 | P2: 0.026391388 | Q2: 0.059436536 | R2: 0.03445469 | S2: 0.066480977 | T2: 0.068185976 | U2: 0.057430379 | V2: 0.03107329 | W2: -0.010592524 | X2: 0.041122528 | Y2: 0.045667958 | Z2: 0.017579111 | AA2: 0.032564492 | AB2: 0.016048183 | AC2: 0.022914361 | AD2: 0.054864655 | AE2: 0.02168964 | AF2: 0.0064508882 | AG2: 0.044436318 | AH2: 0.0040861922 | AI2: -0.0014405376 | AJ2: 0.032792488 | AK2: 0.040736951 | AL2: 0.015982313 | AM2: 0.023403995 | AN2: 0.0069624168 | AO2: 0.017966204 | AP2: 0.027382034 | AQ2: 0.040739073 | AR2: 0.049879564 | AS2: 0.022684949 | AT2: 0.031558793 | AU2: 0.020145446 | AV2: 0.012740509 | AW2: 0.052375277 | AX2: 0.037226068 | AY2: 0.019651882 | AZ2: 0.026653924 | BA2: 0.058693076 | BB2: 0.0053682309 | BC2: -0.0028756202
A3: maxpool_0.6 | B3: 0.073941259 | C3: 1 | D3: 0.78810515 | E3: 0.40484344 | F3: 0.57019106 | G3: 0.791424 | H3: 0.42769944 | I3: 0.22094304 | J3: 0.053730537 | K3: 0.1171813 | L3: 0.07069645 | M3: -0.078995495 | N3: 0.064012537 | O3: 0.021899396 | P3: -0.11612182 | Q3: 0.39964445 | R3: 0.21950275 | S3: 0.19899957 | T3: 0.031604266 | U3: 0.014673725 | V3: 0.049928375 | W3: -0.04268644 | X3: -0.094460035 | Y3: -0.07915092 | Z3: 0.024426651 | AA3: -0.078946273 | AB3: -0.088986131 | AC3: -0.041087814 | AD3: 0.027571123 | AE3: 0.005712928 | AF3: -0.040183666 | AG3: -0.056334125 | AH3: -0.095213519 | AI3: -0.094436261 | AJ3: -0.075330728 | AK3: -0.065971675 | AL3: -0.080138517 | AM3: -0.10240049 | AN3: -0.076471958 | AO3: -0.15314897 | AP3: -0.14188745 | AQ3: -0.11971725 | AR3: -0.1323548 | AS3: -0.1273651 | AT3: 0.007066982 | AU3: -0.16770423 | AV3: -0.10010884 | AW3: -0.14682043 | AX3: -0.20382832 | AY3: -0.084997132 | AZ3: -0.027330177 | BA3: -0.095049238 | BB3: -0.08591947 | BC3: -0.077112841
A4: layer1.0.conv1_0.6 | B4: 0.0093531139 | C4: 0.78810515 | D4: 1 | E4: 0.47954335 | F4: 0.66284127 | G4: 0.64075729 | H4: 0.42504326 | I4: 0.2072017 | J4: 0.043819814 | K4: 0.10574824 | L4: 0.086071079 | M4: -0.08034074 | N4: 0.034295714 | O4: -0.031381363 | P4: -0.14292074 | Q4: 0.33229443 | R4: 0.17424992 | S4: 0.11853988 | T4: -0.095197411 | U4: -0.043442727 | V4: -0.0060335576 | W4: -0.11369494 | X4: -0.10528589 | Y4: -0.11497045 | Z4: -0.01878616 | AA4: -0.13577545 | AB4: -0.1423274 | AC4: -0.09502627 | AD4: -0.06666493 | AE4: -0.011161952 | AF4: -0.063753646 | AG4: -0.059167406 | AH4: -0.11191506 | AI4: -0.10527556 | AJ4: -0.09577249 | AK4: -0.096832481 | AL4: -0.11675413 | AM4: -0.123187 | AN4: -0.09962408 | AO4: -0.15317396 | AP4: -0.17134621 | AQ4: -0.13780915 | AR4: -0.15232982 | AS4: -0.18326304 | AT4: -0.022160985 | AU4: -0.20464337 | AV4: -0.12497872 | AW4: -0.23849582 | AX4: -0.26974248 | AY4: -0.13970246 | AZ4: -0.044374025 | BA4: -0.15662157 | BB4: -0.15918424 | BC4: -0.1345797
A5: layer1.0.conv2_0.6 | B5: 0.088187595 | C5: 0.40484344 | D5: 0.47954335 | E5: 1 | F5: 0.6551346 | G5: 0.36122764 | H5: 0.29287638 | I5: 0.32464896 | J5: 0.2900328 | K5: 0.10757618 | L5: 0.064498132 | M5: 0.040986485 | N5: 0.15723899 | O5: 0.044690332 | P5: -0.010729752 | Q5: 0.25009722 | R5: 0.071159796 | S5: 0.11772673 | T5: -0.022194801 | U5: 0.039274406 | V5: 0.01037296 | W5: 0.0018970405 | X5: 0.02322278 | Y5: 0.029646359 | Z5: -0.0023908879 | AA5: 0.040722661 | AB5: -0.0023898912 | AC5: -0.017420932 | AD5: 0.012928247 | AE5: 0.028570511 | AF5: -0.026576669 | AG5: -0.0062364201 | AH5: -0.024121688 | AI5: 0.00044951814 | AJ5: -0.050178717 | AK5: -0.081180545 | AL5: -0.053007129 | AM5: -0.08273287 | AN5: -0.053548771 | AO5: -0.05861794 | AP5: -0.053278093 | AQ5: -0.011330079 | AR5: -0.043008236 | AS5: -0.070990346 | AT5: -0.016274032 | AU5: -0.097821823 | AV5: -0.077116515 | AW5: -0.11275025 | AX5: -0.1411235 | AY5: -0.077674822 | AZ5: -0.031129468 | BA5: -0.13123161 | BB5: -0.069281304 | BC5: -0.059678947
A6: layer1.0.conv3_0.6 | B6: 0.053547716 | C6: 0.57019106 | D6: 0.66284127 | E6: 0.6551346 | F6: 1 | G6: 0.46309982 | H6: 0.29757922 | I6: 0.29945843 | J6: 0.19741976 | K6: 0.13931553 | L6: 0.12053437 | M6: -0.03094056 | N6: 0.1555456 | O6: -0.0034219843 | P6: -0.039924149 | Q6: 0.35344501 | R6: 0.15603841 | S6: 0.039560425 | T6: -0.13922164 | U6: -0.017316402 | V6: -0.024157638 | W6: -0.090669685 | X6: -0.066633253 | Y6: -0.083594501 | Z6: -0.032482296 | AA6: -0.0072517305 | AB6: -0.024083552 | AC6: -0.034547675 | AD6: -0.0078591927 | AE6: -0.0034126048 | AF6: -0.067566653 | AG6: -0.070807101 | AH6: -0.067917155 | AI6: -0.048430236 | AJ6: -0.051842055 | AK6: -0.13255261 | AL6: -0.11592506 | AM6: -0.091596089 | AN6: -0.1005209 | AO6: -0.13169891 | AP6: -0.12255596 | AQ6: -0.06614769 | AR6: -0.080987024 | AS6: -0.14097092 | AT6: -0.015036551 | AU6: -0.16171276 | AV6: -0.1686422 | AW6: -0.19892204 | AX6: -0.23522165 | AY6: -0.22775142 | AZ6: -0.10519991 | BA6: -0.19312932 | BB6: -0.082988038 | BC6: -0.16027267
A7: layer1.0.downsample.0_0.6 | B7: 0.14697729 | C7: 0.791424 | D7: 0.64075729 | E7: 0.36122764 | F7: 0.46309982 | G7: 1 | H7: 0.41954713 | I7: 0.23627131 | J7: 0.11945648 | K7: 0.1148185 | L7: 0.055882325 | M7: -0.076349977 | N7: 0.055367702 | O7: 0.058585572 | P7: -0.1058926 | Q7: 0.35687146 | R7: 0.16990721 | S7: 0.19368779 | T7: 0.058402036 | U7: 0.071890704 | V7: 0.10297647 | W7: -0.0046651014 | X7: -0.032229495 | Y7: 0.0023692452 | Z7: 0.062522442 | AA7: -0.046946958 | AB7: -0.070021245 | AC7: -0.040372196 | AD7: 0.042312433 | AE7: 0.0095002292 | AF7: -0.018223589 | AG7: -0.033178658 | AH7: -0.087991973 | AI7: -0.069830053 | AJ7: -0.077560454 | AK7: -0.033867746 | AL7: -0.054008194 | AM7: -0.10510559 | AN7: -0.088190328 | AO7: -0.13955575 | AP7: -0.10337159 | AQ7: -0.090039303 | AR7: -0.089256564 | AS7: -0.11659068 | AT7: 0.020679985 | AU7: -0.11714707 | AV7: -0.049319044 | AW7: -0.12588523 | AX7: -0.16376421 | AY7: -0.039637333 | AZ7: 0.027650662 | BA7: -0.078955973 | BB7: -0.078023123 | BC7: -0.043060528
A8: layer1.1.conv1_0.6 | B8: 0.068902121 | C8: 0.42769944 | D8: 0.42504326 | E8: 0.29287638 | F8: 0.29757922 | G8: 0.41954713 | H8: 1 | I8: 0.44750599 | J8: 0.29696737 | K8: 0.20049148 | L8: 0.12873291 | M8: -0.088960114 | N8: -0.0087087853 | O8: 0.0039345002 | P8: -0.095628302 | Q8: 0.070221111 | R8: 0.0064939748 | S8: 0.073284523 | T8: 0.0052715806 | U8: 0.044794402 | V8: 0.08684452 | W8: 0.077148857 | X8: 0.041114757 | Y8: 0.041352714 | Z8: 0.075521056 | AA8: -0.040960415 | AB8: -0.021470536 | AC8: -0.039368585 | AD8: -0.03752103 | AE8: 0.0019856379 | AF8: -0.038513153 | AG8: 0.013530984 | AH8: -0.012786959 | AI8: -0.039629893 | AJ8: -0.066568786 | AK8: -0.043732587 | AL8: -0.019982205 | AM8: -0.11388378 | AN8: -0.013002807 | AO8: -0.044792784 | AP8: -0.045942045 | AQ8: -0.055187661 | AR8: -0.090572704 | AS8: -0.066714962 | AT8: 0.0085627896 | AU8: -0.071662245 | AV8: -0.018479597 | AW8: -0.0653315 | AX8: -0.10850677 | AY8: -0.0058355106 | AZ8: -0.022272325 | BA8: -0.01502126 | BB8: -0.00025867026 | BC8: 0.018656805
A9: layer1.1.conv2_0.6 | B9: 0.10465273 | C9: 0.22094304 | D9: 0.2072017 | E9: 0.32464896 | F9: 0.29945843 | G9: 0.23627131 | H9: 0.44750599 | I9: 1 | J9: 0.40064588 | K9: 0.13526684 | L9: 0.11900151 | M9: -0.043421466 | N9: 0.075068562 | O9: 0.094915654 | P9: 0.083746151 | Q9: 0.06710984 | R9: -0.0039631876 | S9: -0.029833315 | T9: -0.031234937 | U9: 0.070450432 | V9: 0.050076272 | W9: 0.058521599 | X9: 0.0038326504 | Y9: -0.0053563736 | Z9: 0.032912016 | AA9: 0.067936769 | AB9: 0.064756029 | AC9: 0.046232789 | AD9: -0.0041337469 | AE9: -0.018084331 | AF9: -0.060197319 | AG9: 0.0067927211 | AH9: 0.036754885 | AI9: 0.037859575 | AJ9: 0.025246741 | AK9: 0.058743382 | AL9: 0.0099180303 | AM9: 0.012087757 | AN9: 0.008534345 | AO9: 0.038104443 | AP9: 0.071203313 | AQ9: 0.089407137 | AR9: 0.026982265 | AS9: 0.045528225 | AT9: 0.0002372683 | AU9: -0.063443728 | AV9: -0.027211254 | AW9: 0.0087954295 | AX9: -0.014589186 | AY9: 0.0022763488 | AZ9: -0.0021423112 | BA9: -0.044197592 | BB9: -0.042112217 | BC9: 0.035208801
A10: layer1.1.conv3_0.6 | B10: 0.081138978 | C10: 0.053730537 | D10: 0.043819814 | E10: 0.2900328 | F10: 0.19741976 | G10: 0.11945648 | H10: 0.29696737 | I10: 0.40064588 | J10: 1 | K10: 0.12766379 | L10: 0.16622373 | M10: 0.019567725 | N10: 0.11401508 | O10: 0.17722732 | P10: 0.13637773 | Q10: 0.070976544 | R10: -0.028148228 | S10: 0.0098418367 | T10: 0.021212195 | U10: 0.1023292 | V10: 0.11430925 | W10: 0.13731664 | X10: 0.14004022 | Y10: 0.12356769 | Z10: 0.044865188 | AA10: 0.057715626 | AB10: 0.083378013 | AC10: 0.032404888 | AD10: 0.06569137 | AE10: 0.052089432 | AF10: 0.02862727 | AG10: 0.10185209 | AH10: 0.051628487 | AI10: 0.022923798 | AJ10: 0.020706357 | AK10: 0.011756628 | AL10: 0.0094317767 | AM10: 0.013885146 | AN10: 0.036006968 | AO10: 0.014868642 | AP10: 0.078165714 | AQ10: 0.050688798 | AR10: 0.05229293 | AS10: 0.07094488 | AT10: -0.012253543 | AU10: 0.0013633675 | AV10: -0.011501513 | AW10: 0.079217303 | AX10: 0.070342139 | AY10: 0.039014266 | AZ10: 0.041806213 | BA10: 0.010442478 | BB10: 0.02412786 | BC10: 0.037408356
A11: layer1.2.conv1_0.6 | B11: 0.056971584 | C11: 0.1171813 | D11: 0.10574824 | E11: 0.10757618 | F11: 0.13931553 | G11: 0.1148185 | H11: 0.20049148 | I11: 0.13526684 | J11: 0.12766379 | K11: 1 | L11: 0.39125178 | M11: -0.12502736 | N11: -0.10263842 | O11: -0.17942975 | P11: -0.32924577 | Q11: -0.025470554 | R11: 0.022424925 | S11: 0.032437511 | T11: 0.016988261 | U11: -0.12031131 | V11: -0.039937334 | W11: -0.075559927 | X11: -0.10135347 | Y11: -0.026438002 | Z11: -0.10944541 | AA11: -0.15443183 | AB11: -0.12126149 | AC11: -0.12246766 | AD11: -0.1417155 | AE11: -0.092500889 | AF11: -0.078677385 | AG11: -0.055915396 | AH11: -0.090364718 | AI11: -0.087935919 | AJ11: -0.082865309 | AK11: -0.10184315 | AL11: -0.060477814 | AM11: -0.12532729 | AN11: -0.082431245 | AO11: -0.084747475 | AP11: -0.11625027 | AQ11: -0.059611768 | AR11: -0.10092203 | AS11: -0.11111819 | AT11: -0.045242635 | AU11: -0.029521685 | AV11: -0.038361086 | AW11: -0.07083801 | AX11: -0.094535132 | AY11: -0.038572591 | AZ11: -0.016074489 | BA11: -0.038038373 | BB11: 0.050519055 | BC11: -0.038074882
A12: layer1.2.conv2_0.6 | B12: 0.040525574 | C12: 0.07069645 | D12: 0.086071079 | E12: 0.064498132 | F12: 0.12053437 | G12: 0.055882325 | H12: 0.12873291 | I12: 0.11900151 | J12: 0.16622373 | K12: 0.39125178 | L12: 1 | M12: 0.013739452 | N12: 0.04609292 | O12: -0.126737 | P12: -0.16225972 | Q12: 0.046024207 | R12: 0.015128159 | S12: 0.028925577 | T12: 0.034310119 | U12: -0.052520721 | V12: -0.00022118082 | W12: -0.024236704 | X12: -0.019046292 | Y12: -0.015054701 | Z12: -0.071448628 | AA12: -0.10495085 | AB12: -0.041997593 | AC12: -0.036139734 | AD12: -0.14267374 | AE12: -0.085844886 | AF12: -0.055869439 | AG12: -0.051100041 | AH12: -0.097229104 | AI12: -0.082094614 | AJ12: -0.069517439 | AK12: -0.13489723 | AL12: -0.14385504 | AM12: -0.12579585 | AN12: -0.1618831 | AO12: -0.18047548 | AP12: -0.14708166 | AQ12: -0.12445324 | AR12: -0.12793735 | AS12: -0.15705074 | AT12: -0.074697408 | AU12: -0.022605756 | AV12: -0.017961754 | AW12: -0.094096432 | AX12: -0.092088929 | AY12: -0.097959671 | AZ12: -0.10166128 | BA12: -0.10713342 | BB12: -0.067381282 | BC12: -0.058606915
A13: layer1.2.conv3_0.6 | B13: -0.021074431 | C13: -0.078995495 | D13: -0.08034074 | E13: 0.040986485 | F13: -0.03094056 | G13: -0.076349977 | H13: -0.088960114 | I13: -0.043421466 | J13: 0.019567725 | K13: -0.12502736 | L13: 0.013739452 | M13: 1 | N13: 0.37672134 | O13: 0.30029463 | P13: 0.28262868 | Q13: -0.020685081 | R13: 0.018870265 | S13: -0.037857771 | T13: 0.066691266 | U13: 0.0022098108 | V13: -0.0061714561 | W13: 0.0073600884 | X13: 0.012284212 | Y13: -0.037565584 | Z13: 0.025619636 | AA13: 0.14617668 | AB13: 0.15185649 | AC13: 0.083760908 | AD13: 0.15263071 | AE13: -0.032231941 | AF13: -0.02333296 | AG13: 0.045906558 | AH13: -0.054090612 | AI13: -0.032695169 | AJ13: -0.002540346 | AK13: -0.0025905426 | AL13: 0.015754913 | AM13: 0.040990978 | AN13: 0.013151118 | AO13: 0.016258133 | AP13: 0.027086176 | AQ13: -0.028462963 | AR13: -0.027437056 | AS13: -0.059714461 | AT13: -0.019666858 | AU13: -0.061462129 | AV13: -0.058271169 | AW13: -0.1059456 | AX13: -0.04470457 | AY13: -0.046272913 | AZ13: -0.031918181 | BA13: -0.11226754 | BB13: -0.11019543 | BC13: -0.087285288
... A55: layer4.2.conv3_0.6 | B55: -0.0028756202 | C55: -0.077112841 | D55: -0.1345797 | E55: -0.059678947 | F55: -0.16027267 | G55: -0.043060528 | H55: 0.018656805 | I55: 0.035208801 | J55: 0.037408356 | K55: -0.038074882 | L55: -0.058606915 | M55: -0.087285288 | N55: -0.044865162 | O55: 0.0032097521 | P55: -0.053760669 | Q55: 0.058536857 | R55: -0.070813725 | S55: 0.035657155 | T55: 0.084387877 | U55: 0.11396332 | V55: 0.2142118 | W55: 0.21123721 | X55: 0.1366337 | Y55: 0.13772878 | Z55: -0.057978308 | AA55: 0.0028986451 | AB55: 0.05926545 | AC55: 0.031094673 | AD55: 0.1072523 | AE55: 0.18632074 | AF55: 0.19220596 | AG55: 0.15982311 | AH55: 0.14109788 | AI55: 0.1513237 | AJ55: 0.12333613 | AK55: 0.14753593 | AL55: 0.17130798 | AM55: 0.18455623 | AN55: 0.12951624 | AO55: 0.18807318 | AP55: 0.2180808 | AQ55: 0.19450433 | AR55: 0.26942604 | AS55: 0.38385666 | AT55: 0.13430656 | AU55: 0.23814246 | AV55: 0.28073406 | AW55: 0.29774672 | AX55: 0.26924927 | AY55: 0.50187264 | AZ55: 0.30854306 | BA55: 0.3413903 | BB55: 0.080008045 | BC55: 1

Sheet Class_2
B1: conv1_0.6 | C1: maxpool_0.6 | D1: layer1.0.conv1_0.6 | E1: layer1.0.conv2_0.6 | F1: layer1.0.conv3_0.6 | G1: layer1.0.downsample.0_0.6 | H1: layer1.1.conv1_0.6 | I1: layer1.1.conv2_0.6 | J1: layer1.1.conv3_0.6 | K1: layer1.2.conv1_0.6 | L1: layer1.2.conv2_0.6 | M1: layer1.2.conv3_0.6 | N1: layer2.0.conv1_0.6 | O1: layer2.0.conv2_0.6 | P1: layer2.0.conv3_0.6 | Q1: layer2.0.downsample.0_0.6 | R1: layer2.1.conv1_0.6 | S1: layer2.1.conv2_0.6 | T1: layer2.1.conv3_0.6 | U1: layer2.2.conv1_0.6 | V1: layer2.2.conv2_0.6 | W1: layer2.2.conv3_0.6 | X1: layer2.3.conv1_0.6 | Y1: layer2.3.conv2_0.6 | Z1: layer2.3.conv3_0.6 | AA1: layer3.0.conv1_0.6 | AB1: layer3.0.conv2_0.6 | AC1: layer3.0.conv3_0.6 | AD1: layer3.0.downsample.0_0.6 | AE1: layer3.1.conv1_0.6 | AF1: layer3.1.conv2_0.6 | AG1: layer3.1.conv3_0.6 | AH1: layer3.2.conv1_0.6 | AI1: layer3.2.conv2_0.6 | AJ1: layer3.2.conv3_0.6 | AK1: layer3.3.conv1_0.6 | AL1: layer3.3.conv2_0.6 | AM1: layer3.3.conv3_0.6 | AN1: layer3.4.conv1_0.6 | AO1: layer3.4.conv2_0.6 | AP1: layer3.4.conv3_0.6 | AQ1: layer3.5.conv1_0.6 | AR1: layer3.5.conv2_0.6 | AS1: layer3.5.conv3_0.6 | AT1: layer4.0.conv1_0.6 | AU1: layer4.0.conv2_0.6 | AV1: layer4.0.conv3_0.6 | AW1: layer4.0.downsample.0_0.6 | AX1: layer4.1.conv1_0.6 | AY1: layer4.1.conv2_0.6 | AZ1: layer4.1.conv3_0.6 | BA1: layer4.2.conv1_0.6 | BB1: layer4.2.conv2_0.6 | BC1: layer4.2.conv3_0.6
A2: conv1_0.6 | B2: 1 | C2: 0.046166572 | D2: 0.0022916028 | E2: 0.0039664366 | F2: 0.013899225 | G2: 0.043638703 | H2: -0.0030559556 | I2: 0.0027437805 | J2: -0.0016542421 | K2: -0.007809605 | L2: 0.026616512 | M2: 0.011703351 | N2: 0.051458392 | O2: 0.038770112 | P2: 0.032850389 | Q2: 0.074617061 | R2: 0.098168828 | S2: 0.15482246 | T2: 0.023195765 | U2: 0.035427703 | V2: 0.038958987 | W2: 0.042716347 | X2: 0.025867724 | Y2: 0.035279473 | Z2: 0.030550522 | AA2: 0.026865019 | AB2: 0.034275303 | AC2: 0.037807735 | AD2: 0.011147745 | AE2: -0.017050845 | AF2: 0.0047317943 | AG2: 0.015125409 | AH2: 0.016651212 | AI2: -0.0083001189 | AJ2: -0.014791428 | AK2: -0.030298141 | AL2: -0.04364871 | AM2: -0.013846749 | AN2: -0.014770581 | AO2: -0.0049817981 | AP2: 0.014760053 | AQ2: 0.0036893924 | AR2: 0.052403754 | AS2: 0.00062299916 | AT2: 0.021496907 | AU2: 0.010249901 | AV2: -7.6478566e-05 | AW2: 0.009712109 | AX2: 0.00072988377 | AY2: 0.02631468 | AZ2: 0.0037679322 | BA2: -0.016593261 | BB2: -0.048845242 | BC2: -0.026175297
A3: maxpool_0.6 | B3: 0.046166572 | C3: 1 | D3: 0.75113307 | E3: 0.66882699 | F3: 0.71037063 | G3: 0.75155658 | H3: 0.33160024 | I3: 0.21093467 | J3: 0.21991532 | K3: 0.046122686 | L3: -0.16705209 | M3: 0.015152068 | N3: 0.28696609 | O3: -0.025012181 | P3: -0.0038771054 | Q3: 0.42305904 | R3: 0.023618871 | S3: 0.038584745 | T3: -0.081094511 | U3: -0.022271674 | V3: -0.030725406 | W3: -0.13856663 | X3: -0.068383264 | Y3: 0.03645721 | Z3: 0.040702748 | AA3: 0.043561916 | AB3: -0.066514478 | AC3: -0.05533073 | AD3: 0.017771096 | AE3: 0.011690613 | AF3: 0.036528002 | AG3: -0.029602998 | AH3: -0.038233981 | AI3: -0.051145433 | AJ3: -0.051813308 | AK3: -0.051663959 | AL3: -0.011485396 | AM3: -0.0089494764 | AN3: -0.054427815 | AO3: -0.042984848 | AP3: -0.059933004 | AQ3: -0.03206246 | AR3: 0.00080503388 | AS3: -0.0045979798 | AT3: 0.016273446 | AU3: 0.060009902 | AV3: -0.022195736 | AW3: 0.036942807 | AX3: -0.0081411746 | AY3: -0.056119717 | AZ3: -0.065337923 | BA3: -0.11177631 | BB3: 0.0040222487 | BC3: 0.0081044982
A4: layer1.0.conv1_0.6 | B4: 0.0022916028 | C4: 0.75113307 | D4: 1 | E4: 0.72234019 | F4: 0.68321241 | G4: 0.51959181 | H4: 0.34261707 | I4: 0.24196335 | J4: 0.23165144 | K4: 0.13619384 | L4: -0.10737199 | M4: 0.0090080735 | N4: 0.17298587 | O4: -0.0048113701 | P4: -0.062016718 | Q4: 0.36029141 | R4: 0.045955952 | S4: 0.068390637 | T4: 0.023474853 | U4: -0.025097846 | V4: -0.03180119 | W4: -0.12427355 | X4: -0.0057116506 | Y4: 0.065872405 | Z4: 0.075242623 | AA4: -0.0032108815 | AB4: -0.089173216 | AC4: -0.067182077 | AD4: 0.028881856 | AE4: 0.062435722 | AF4: 0.064323889 | AG4: -0.032723182 | AH4: -0.072662015 | AI4: -0.069769143 | AJ4: -0.081884607 | AK4: -0.11472119 | AL4: -0.042710801 | AM4: -0.046823191 | AN4: -0.084784052 | AO4: -0.054350851 | AP4: -0.074065055 | AQ4: 0.0092559743 | AR4: 0.02785889 | AS4: -0.016726036 | AT4: 0.042727878 | AU4: 0.080292411 | AV4: 0.049874135 | AW4: -0.022864032 | AX4: 0.0085655259 | AY4: -0.030453413 | AZ4: -0.078197256 | BA4: -0.086466311 | BB4: -0.011389406 | BC4: -0.053679475
A5: layer1.0.conv2_0.6 | B5: 0.0039664366 | C5: 0.66882699 | D5: 0.72234019 | E5: 1 | F5: 0.8004243 | G5: 0.57440374 | H5: 0.23254198 | I5: 0.18510844 | J5: 0.11050074 | K5: 0.074139163 | L5: -0.14683436 | M5: 0.029947756 | N5: 0.23103886 | O5: -0.027440095 | P5: -0.079301427 | Q5: 0.35549749 | R5: 0.05030475 | S5: -0.036560966 | T5: -0.20834117 | U5: -0.069972264 | V5: -0.1017352 | W5: -0.21908833 | X5: -0.072560239 | Y5: 0.0063208007 | Z5: -0.0039911901 | AA5: -0.015548615 | AB5: -0.12717406 | AC5: -0.12277913 | AD5: -0.080344462 | AE5: -0.02142093 | AF5: -0.0053520368 | AG5: -0.07603998 | AH5: -0.096343157 | AI5: -0.081495093 | AJ5: -0.10563305 | AK5: -0.086519981 | AL5: -0.042599318 | AM5: -0.035675907 | AN5: -0.090400113 | AO5: -0.048063116 | AP5: -0.10317722 | AQ5: 0.0024848554 | AR5: -0.011226058 | AS5: -0.020366682 | AT5: -0.023050797 | AU5: 0.063199491 | AV5: 0.013709046 | AW5: 0.0078890305 | AX5: 0.026930463 | AY5: -0.019578995 | AZ5: -0.072831076 | BA5: -0.15121233 | BB5: -0.00043971189 | BC5: 0.014917849
A6: layer1.0.conv3_0.6 | B6: 0.013899225 | C6: 0.71037063 | D6: 0.68321241 | E6: 0.8004243 | F6: 1 | G6: 0.64201193 | H6: 0.22793443 | I6: 0.216745 | J6: 0.16744955 | K6: 0.079485297 | L6: -0.12618196 | M6: 0.003377489 | N6: 0.27623295 | O6: -0.032312687 | P6: -0.079414051 | Q6: 0.42315731 | R6: 0.02413356 | S6: -0.038655815 | T6: -0.17889023 | U6: -0.058649244 | V6: -0.09128249 | W6: -0.21220733 | X6: -0.075533897 | Y6: 0.020088197 | Z6: 0.0020278304 | AA6: 0.018333314 | AB6: -0.12614697 | AC6: -0.068531949 | AD6: -0.0045115637 | AE6: 0.0080770008 | AF6: 0.038262043 | AG6: -0.06036089 | AH6: -0.087180965 | AI6: -0.078422109 | AJ6: -0.12108711 | AK6: -0.061722928 | AL6: -0.010046869 | AM6: -0.0034808357 | AN6: -0.096882869 | AO6: -0.045134519 | AP6: -0.083196146 | AQ6: -0.043121994 | AR6: -0.041021736 | AS6: -0.024280481 | AT6: 0.057457036 | AU6: 0.10267853 | AV6: 0.051049405 | AW6: 0.062337242 | AX6: 0.02702446 | AY6: -0.038858236 | AZ6: -0.011924327 | BA6: -0.10586157 | BB6: 0.028487067 | BC6: 0.076221649
A7: layer1.0.downsample.0_0.6 | B7: 0.043638703 | C7: 0.75155658 | D7: 0.51959181 | E7: 0.57440374 | F7: 0.64201193 | G7: 1 | H7: 0.24127269 | I7: 0.14370594 | J7: 0.11862957 | K7: 0.016860245 | L7: -0.17130539 | M7: -0.010620548 | N7: 0.33872059 | O7: -0.0054284659 | P7: 0.0059192517 | Q7: 0.3774151 | R7: 0.013131795 | S7: -0.042285254 | T7: -0.21761344 | U7: -0.041895341 | V7: -0.031613469 | W7: -0.1719491 | X7: -0.13450584 | Y7: -0.037251734 | Z7: -0.026733798 | AA7: 0.027261925 | AB7: -0.076975 | AC7: -0.063546012 | AD7: -0.042474979 | AE7: -0.041008827 | AF7: -0.010717046 | AG7: -0.069280018 | AH7: -0.068063324 | AI7: -0.083966505 | AJ7: -0.071347514 | AK7: -0.039561423 | AL7: -0.024571005 | AM7: 0.010396958 | AN7: -0.06137749 | AO7: -0.043803469 | AP7: -0.070475233 | AQ7: -0.037375039 | AR7: -0.038796735 | AS7: -0.033107967 | AT7: -0.032067726 | AU7: 0.032712945 | AV7: -0.09709208 | AW7: 0.049073143 | AX7: -0.033039597 | AY7: -0.083001895 | AZ7: -0.081024791 | BA7: -0.13751608 | BB7: -0.0087748373 | BC7: 0.010992536
A8: layer1.1.conv1_0.6 | B8: -0.0030559556 | C8: 0.33160024 | D8: 0.34261707 | E8: 0.23254198 | F8: 0.22793443 | G8: 0.24127269 | H8: 1 | I8: 0.41363678 | J8: 0.32227593 | K8: 0.23673414 | L8: 0.083643748 | M8: 0.025338971 | N8: 0.086567753 | O8: -0.093977807 | P8: -0.010289455 | Q8: 0.081730187 | R8: 0.019098079 | S8: 0.027889816 | T8: 0.053992583 | U8: 0.028070798 | V8: 0.067324702 | W8: 0.026079618 | X8: 0.032482177 | Y8: 0.059119841 | Z8: 0.025099055 | AA8: 0.011522457 | AB8: -0.0023895998 | AC8: 0.0047201362 | AD8: 0.014311227 | AE8: -0.034128111 | AF8: -0.0370119 | AG8: -0.0073404309 | AH8: -0.020970445 | AI8: -0.0039253966 | AJ8: -0.00031471626 | AK8: -0.008600752 | AL8: 0.011601284 | AM8: -0.028745331 | AN8: 0.0075142874 | AO8: -0.01477116 | AP8: -0.010189739 | AQ8: -0.046352815 | AR8: 0.0023287352 | AS8: -0.0039492591 | AT8: 0.014335897 | AU8: 0.011492923 | AV8: 0.013105748 | AW8: 0.01640073 | AX8: -0.055532829 | AY8: -0.07667577 | AZ8: -0.029083176 | BA8: -0.012969051 | BB8: -0.011424698 | BC8: 0.026656164
A9: layer1.1.conv2_0.6 | B9: 0.0027437805 | C9: 0.21093467 | D9: 0.24196335 | E9: 0.18510844 | F9: 0.216745 | G9: 0.14370594 | H9: 0.41363678 | I9: 1 | J9: 0.41691269 | K9: 0.21185208 | L9: 0.14799058 | M9: 0.025576 | N9: 0.083450816 | O9: -0.025165989 | P9: -0.01476266 | Q9: 0.18835165 | R9: -0.024289845 | S9: 0.035813344 | T9: 0.093638264 | U9: 0.039732921 | V9: 0.082640887 | W9: -0.0027814875 | X9: 0.056869977 | Y9: 0.10676335 | Z9: 0.04220776 | AA9: -0.010898129 | AB9: -0.014858748 | AC9: 0.028860802 | AD9: 0.084997044 | AE9: 0.086470931 | AF9: 0.093828848 | AG9: 0.031857015 | AH9: -0.012257978 | AI9: 0.019570586 | AJ9: -0.0047673753 | AK9: 0.032684622 | AL9: 0.026537512 | AM9: -0.030558344 | AN9: -0.0054050098 | AO9: -0.01812839 | AP9: 0.026526146 | AQ9: -0.019242689 | AR9: 0.0071054978 | AS9: 0.016014053 | AT9: 0.043519789 | AU9: 0.041681473 | AV9: 0.052330079 | AW9: 0.021419393 | AX9: -0.035475396 | AY9: -0.029191071 | AZ9: 0.017861401 | BA9: 0.027684257 | BB9: 0.038576554 | BC9: 0.026251538
A10: layer1.1.conv3_0.6 | B10: -0.0016542421 | C10: 0.21991532 | D10: 0.23165144 | E10: 0.11050074 | F10: 0.16744955 | G10: 0.11862957 | H10: 0.32227593 | I10: 0.41691269 | J10: 1 | K10: 0.22412889 | L10: 0.10424127 | M10: -0.008050237 | N10: -0.011941105 | O10: -0.11344044 | P10: 0.029201203 | Q10: 0.23999629 | R10: 0.04695082 | S10: 0.1169212 | T10: 0.28058808 | U10: 0.021559344 | V10: 0.13735147 | W10: 0.13280684 | X10: 0.088898162 | Y10: 0.12287916 | Z10: 0.12174902 | AA10: 0.097734759 | AB10: 0.085273565 | AC10: 0.16581485 | AD10: 0.25341171 | AE10: 0.14979128 | AF10: 0.16100685 | AG10: 0.19620972 | AH10: 0.092525524 | AI10: 0.082448474 | AJ10: 0.03555179 | AK10: 0.087968414 | AL10: 0.10323578 | AM10: 0.018915107 | AN10: -0.023310018 | AO10: 0.019460064 | AP10: 0.14723115 | AQ10: -0.075072387 | AR10: 0.020985756 | AS10: 0.098773314 | AT10: 0.19448404 | AU10: 0.04632868 | AV10: 0.093686764 | AW10: 0.086273164 | AX10: -0.045228502 | AY10: -0.070897538 | AZ10: 0.075843482 | BA10: 0.18091362 | BB10: 0.11761152 | BC10: 0.076387099
A11: layer1.2.conv1_0.6 | B11: -0.007809605 | C11: 0.046122686 | D11: 0.13619384 | E11: 0.074139163 | F11: 0.079485297 | G11: 0.016860245 | H11: 0.23673414 | I11: 0.21185208 | J11: 0.22412889 | K11: 1 | L11: 0.33478001 | M11: 0.043285479 | N11: -0.089580612 | O11: -0.049822562 | P11: -0.08033213 | Q11: 0.044217102 | R11: 0.027458269 | S11: 0.01750231 | T11: 0.077527628 | U11: 0.032096599 | V11: 0.028664145 | W11: 0.015971183 | X11: 0.0058703263 | Y11: 0.0324583 | Z11: 0.0166632 | AA11: -0.02779915 | AB11: 0.0064051047 | AC11: 0.0059194784 | AD11: 0.031390581 | AE11: 0.00659435 | AF11: 0.031924871 | AG11: 0.042471878 | AH11: -0.04586089 | AI11: -0.015040731 | AJ11: -0.046041298 | AK11: -0.046526691 | AL11: -0.046134808 | AM11: -0.033944686 | AN11: -0.027294887 | AO11: -0.057384069 | AP11: 0.021060197 | AQ11: -0.017690112 | AR11: 0.02409407 | AS11: 0.053461678 | AT11: 0.041245328 | AU11: 0.02468311 | AV11: 0.060490145 | AW11: -0.0020506532 | AX11: -0.020748284 | AY11: -0.060899942 | AZ11: 0.015902667 | BA11: 0.063863502 | BB11: 0.015940442 | BC11: 0.030441313
A12: layer1.2.conv2_0.6 | B12: 0.026616512 | C12: -0.16705209 | D12: -0.10737199 | E12: -0.14683436 | F12: -0.12618196 | G12: -0.17130539 | H12: 0.083643748 | I12: 0.14799058 | J12: 0.10424127 | K12: 0.33478001 | L12: 1 | M12: 0.065067707 | N12: -0.19039543 | O12: -0.12880502 | P12: -0.15337476 | Q12: -0.08054358 | R12: 0.05528717 | S12: 0.064683407 | T12: 0.10825182 | U12: 0.039078734 | V12: 0.069513411 | W12: -0.0047447839 | X12: -0.0026111243 | Y12: -0.0050117969 | Z12: -0.10962626 | AA12: -0.16336049 | AB12: -0.0558622 | AC12: -0.050021914 | AD12: -0.011893907 | AE12: -0.012016119 | AF12: -0.0021276556 | AG12: 0.051904022 | AH12: 0.0018596882 | AI12: 0.0093555395 | AJ12: -0.001518077 | AK12: 0.00010813065 | AL12: -0.004940523 | AM12: -0.021467051 | AN12: -0.021171559 | AO12: -0.016067238 | AP12: 0.040741242 | AQ12: 0.041811556 | AR12: 0.04288742 | AS12: 0.07888624 | AT12: 0.003839419 | AU12: -0.011689326 | AV12: 0.024201088 | AW12: 0.0032898272 | AX12: -4.941198e-05 | AY12: -0.031437561 | AZ12: 0.0074113774 | BA12: 0.042669334 | BB12: 0.016604682 | BC12: -0.010747007
A13: layer1.2.conv3_0.6 | B13: 0.011703351 | C13: 0.015152068 | D13: 0.0090080735 | E13: 0.029947756 | F13: 0.003377489 | G13: -0.010620548 | H13: 0.025338971 | I13: 0.025576 | J13: -0.008050237 | K13: 0.043285479 | L13: 0.065067707 | M13: 1 | N13: 0.23081208 | O13: 0.33495783 | P13: 0.25282161 | Q13: 0.095295322 | R13: 0.081635034 | S13: 0.16540873 | T13: 0.079317564 | U13: 0.14427747 | V13: 0.1505495 | W13: 0.20791761 | X13: 0.13400773 | Y13: 0.13301539 | Z13: 0.1783807 | AA13: 0.20973932 | AB13: 0.18834552 | AC13: 0.18875289 | AD13: 0.12558439 | AE13: 0.10819738 | AF13: 0.072484578 | AG13: 0.052311557 | AH13: 0.14959189 | AI13: 0.13558845 | AJ13: 0.11856083 | AK13: 0.14927482 | AL13: 0.12516958 | AM13: 0.11712738 | AN13: 0.11442446 | AO13: 0.089245471 | AP13: 0.10736717 | AQ13: 0.12862433 | AR13: 0.048117372 | AS13: 0.071389999 | AT13: 0.02766067 | AU13: 0.051891574 | AV13: 0.054016912 | AW13: 0.0653059 | AX13: 0.070011927 | AY13: 0.073020602 | AZ13: 0.064700513 | BA13: -0.012332208 | BB13: 0.030427864 | BC13: 0.16208968
... A55: layer4.2.conv3_0.6 | B55: -0.026175297 | C55: 0.0081044982 | D55: -0.053679475 | E55: 0.014917849 | F55: 0.076221649 | G55: 0.010992536 | H55: 0.026656164 | I55: 0.026251538 | J55: 0.076387099 | K55: 0.030441313 | L55: -0.010747007 | M55: 0.16208968 | N55: 0.027916638 | O55: 0.031995537 | P55: 0.096836575 | Q55: 0.15586328 | R55: 0.092841805 | S55: 0.11067798 | T55: 0.11542461 | U55: 0.010792005 | V55: 0.12968649 | W55: 0.148277 | X55: 0.035321534 | Y55: 0.066243625 | Z55: 0.10065656 | AA55: 0.19556774 | AB55: 0.21128936 | AC55: 0.24633869 | AD55: 0.25234821 | AE55: 0.12259205 | AF55: 0.15455386 | AG55: 0.19044322 | AH55: 0.037974864 | AI55: -0.0083604781 | AJ55: -0.018975632 | AK55: 0.12349817 | AL55: 0.14327807 | AM55: 0.13854611 | AN55: 0.026091948 | AO55: 0.17375341 | AP55: 0.14795591 | AQ55: -0.06312503 | AR55: -0.036011753 | AS55: 0.12665058 | AT55: 0.24256604 | AU55: 0.1080953 | AV55: 0.17395322 | AW55: 0.37118191 | AX55: 0.081312281 | AY55: 0.093746717 | AZ55: 0.48096221 | BA55: 0.28402805 | BB55: 0.43219472 | BC55: 1

Sheet SensitivityFiles
A1: Most important layre
C2: /mnt/sdd/basics/resnet50/loss_resnet50_layer4.1.conv3_0.6.pth | K2: Layers4.1
C3: /mnt/sdd/basics/resnet50/loss_resnet50_layer4.1.conv3_0.7.pth | K3: Layerw4.2
C4: /mnt/sdd/basics/resnet50/loss_resnet50_layer4.1.conv3_0.8.pth
C5: /mnt/sdd/basics/resnet50/loss_resnet50_layer4.1.conv3_0.9.pth
C6: /mnt/sdd/basics/resnet50/loss_resnet50_layer4.1.conv3_1.0.pth
C10: /mnt/sdd/basics/resnet50/loss_resnet50_layer4.2.conv1_0.0.pth
C11: /mnt/sdd/basics/resnet50/loss_resnet50_layer4.2.conv1_0.1.pth
C12: /mnt/sdd/basics/resnet50/loss_resnet50_layer4.2.conv1_0.2.pth
C13: /mnt/sdd/basics/resnet50/loss_resnet50_layer4.2.conv1_0.3.pth
C14: /mnt/sdd/basics/resnet50/loss_resnet50_layer4.2.conv1_0.4.pth
C15: /mnt/sdd/basics/resnet50/loss_resnet50_layer4.2.conv1_0.5.pth
C16: /mnt/sdd/basics/resnet50/loss_resnet50_layer4.2.conv1_0.6.pth
C17: /mnt/sdd/basics/resnet50/loss_resnet50_layer4.2.conv1_0.7.pth
C18: /mnt/sdd/basics/resnet50/loss_resnet50_layer4.2.conv1_0.8.pth
... C37: /mnt/sdd/basics/resnet50/loss_resnet50_layer4.2.conv3_0.5.pth
