Workbook

Sheet SensitiveLayers
B1: =Class_0!B1 -> features.0 | C1: =Class_0!C1 -> features.2 | D1: =Class_0!D1 -> features.4 | E1: =Class_0!E1 -> features.5 | F1: =Class_0!F1 -> features.7 | G1: =Class_0!G1 -> features.9 | H1: =Class_0!H1 -> features.10 | I1: =Class_0!I1 -> features.12 | ... S1: =Class_0!S1 -> features.30
A2: Deer | B2: =Class_0!B19 -> 0.1014402 | C2: =Class_0!C19 -> 0.22237559 | D2: =Class_0!D19 -> 0.18828391 | E2: =Class_0!E19 -> 0.24728718 | F2: =Class_0!F19 -> 0.25566087 | G2: =Class_0!G19 -> 0.19770361 | H2: =Class_0!H19 -> 0.20609307 | I2: =Class_0!I19 -> 0.14246384 | ... S2: =Class_0!S19 -> 1
A3: Horse | B3: =Class_1!B19 -> -0.10599016 | C3: =Class_1!C19 -> 0.028475338 | D3: =Class_1!D19 -> -0.0045493052 | E3: =Class_1!E19 -> 0.067674097 | F3: =Class_1!F19 -> 0.15472172 | G3: =Class_1!G19 -> 0.10602578 | H3: =Class_1!H19 -> 0.062109113 | I3: =Class_1!I19 -> 0.0078706588 | ... S3: =Class_1!S19 -> 1
A4: Zebra | B4: =Class_2!B19 -> -0.049743897 | C4: =Class_2!C19 -> 0.086804963 | D4: =Class_2!D19 -> 0.089896006 | E4: =Class_2!E19 -> 0.17560806 | F4: =Class_2!F19 -> 0.15383962 | G4: =Class_2!G19 -> 0.22124612 | H4: =Class_2!H19 -> 0.26666054 | I4: =Class_2!I19 -> 0.24672609 | ... S4: =Class_2!S19 -> 1
A6: Overall corelation | B6: =MIN(B2:B4) -> -0.10599016 | C6: =MIN(C2:C4) -> 0.028475338 | D6: =MIN(D2:D4) -> -0.0045493052 | E6: =MIN(E2:E4) -> 0.067674097 | F6: =MIN(F2:F4) -> 0.15383962 | G6: =MIN(G2:G4) -> 0.10602578 | H6: =MIN(H2:H4) -> 0.062109113 | I6: =MIN(I2:I4) -> 0.0078706588 | ... R6: =MIN(R2:R4) -> 0.71523781
B7: =IF(AND(B2>0,B3>0,B4>0),TRUE,FALSE) -> FALSE | C7: =IF(AND(C2>0,C3>0,C4>0),TRUE,FALSE) -> TRUE | D7: =IF(AND(D2>0,D3>0,D4>0),TRUE,FALSE) -> FALSE | E7: =IF(AND(E2>0,E3>0,E4>0),TRUE,FALSE) -> TRUE | F7: =IF(AND(F2>0,F3>0,F4>0),TRUE,FALSE) -> TRUE | G7: =IF(AND(G2>0,G3>0,G4>0),TRUE,FALSE) -> TRUE | H7: =IF(AND(H2>0,H3>0,H4>0),TRUE,FALSE) -> TRUE | I7: =IF(AND(I2>0,I3>0,I4>0),TRUE,FALSE) -> TRUE | ... R7: =IF(AND(R2>0,R3>0,R4>0),TRUE,FALSE) -> TRUE
A8: Max Corelation layer | B8: =MAX(B6:R6) -> 0.71523781
A9: Affects 2 classes | B9: =IF(OR(AND(B2>0,B3>0), AND(B2>0,B4>0), AND(B3>0,B4>0)), TRUE, FALSE) -> FALSE | C9: =IF(OR(AND(C2>0,C3>0), AND(C2>0,C4>0), AND(C3>0,C4>0)), TRUE, FALSE) -> TRUE | D9: =IF(OR(AND(D2>0,D3>0), AND(D2>0,D4>0), AND(D3>0,D4>0)), TRUE, FALSE) -> TRUE | E9: =IF(OR(AND(E2>0,E3>0), AND(E2>0,E4>0), AND(E3>0,E4>0)), TRUE, FALSE) -> TRUE | F9: =IF(OR(AND(F2>0,F3>0), AND(F2>0,F4>0), AND(F3>0,F4>0)), TRUE, FALSE) -> TRUE | G9: =IF(OR(AND(G2>0,G3>0), AND(G2>0,G4>0), AND(G3>0,G4>0)), TRUE, FALSE) -> TRUE | H9: =IF(OR(AND(H2>0,H3>0), AND(H2>0,H4>0), AND(H3>0,H4>0)), TRUE, FALSE) -> TRUE | I9: =IF(OR(AND(I2>0,I3>0), AND(I2>0,I4>0), AND(I3>0,I4>0)), TRUE, FALSE) -> TRUE | ... S9: =IF(OR(AND(S2>0,S3>0), AND(S2>0,S4>0), AND(S3>0,S4>0)), TRUE, FALSE) -> TRUE

Sheet Comparison of sensitivity
D1: 0 | E1: 2 | F1: 4 | G1: 5 | H1: 7 | I1: 9 | J1: 10 | K1: 12 | L1: 14 | M1: 16 | N1: 17 | O1: 19 | P1: 21 | Q1: 23 | R1: 24 | S1: 26 | T1: 28 | U1: 30
B2: features.0 | D2: =MIN(Class_0!B2,Class_1!B2,Class_2!B2) -> 1
B3: features.2 | D3: =MIN(Class_0!B3,Class_1!B3,Class_2!B3) -> -0.086712228 | E3: =MIN(Class_0!C3,Class_1!C3,Class_2!C3) -> 1
B4: features.4 | D4: =MIN(Class_0!B4,Class_1!B4,Class_2!B4) -> -0.10641144 | E4: =MIN(Class_0!C4,Class_1!C4,Class_2!C4) -> 0.63105558 | F4: =MIN(Class_0!D4,Class_1!D4,Class_2!D4) -> 1
B5: features.5 | D5: =MIN(Class_0!B5,Class_1!B5,Class_2!B5) -> -0.0036869224 | E5: =MIN(Class_0!C5,Class_1!C5,Class_2!C5) -> 0.34298447 | F5: =MIN(Class_0!D5,Class_1!D5,Class_2!D5) -> 0.41143349 | G5: =MIN(Class_0!E5,Class_1!E5,Class_2!E5) -> 1
B6: features.7 | D6: =MIN(Class_0!B6,Class_1!B6,Class_2!B6) -> 0.0095669622 | E6: =MIN(Class_0!C6,Class_1!C6,Class_2!C6) -> 0.20243189 | F6: =MIN(Class_0!D6,Class_1!D6,Class_2!D6) -> 0.22119186 | G6: =MIN(Class_0!E6,Class_1!E6,Class_2!E6) -> 0.28642749 | H6: =MIN(Class_0!F6,Class_1!F6,Class_2!F6) -> 1
B7: features.9 | D7: =MIN(Class_0!B7,Class_1!B7,Class_2!B7) -> -0.025290658 | E7: =MIN(Class_0!C7,Class_1!C7,Class_2!C7) -> 0.21504496 | F7: =MIN(Class_0!D7,Class_1!D7,Class_2!D7) -> 0.19099452 | G7: =MIN(Class_0!E7,Class_1!E7,Class_2!E7) -> 0.1408517 | H7: =MIN(Class_0!F7,Class_1!F7,Class_2!F7) -> 0.58859066 | I7: =MIN(Class_0!G7,Class_1!G7,Class_2!G7) -> 1
B8: features.10 | D8: =MIN(Class_0!B8,Class_1!B8,Class_2!B8) -> -0.12391104 | E8: =MIN(Class_0!C8,Class_1!C8,Class_2!C8) -> 0.090080296 | F8: =MIN(Class_0!D8,Class_1!D8,Class_2!D8) -> 0.051141492 | G8: =MIN(Class_0!E8,Class_1!E8,Class_2!E8) -> 0.088900394 | H8: =MIN(Class_0!F8,Class_1!F8,Class_2!F8) -> 0.3554457 | I8: =MIN(Class_0!G8,Class_1!G8,Class_2!G8) -> 0.50834173 | J8: =MIN(Class_0!H8,Class_1!H8,Class_2!H8) -> 1
B9: features.12 | D9: =MIN(Class_0!B9,Class_1!B9,Class_2!B9) -> -0.104856 | E9: =MIN(Class_0!C9,Class_1!C9,Class_2!C9) -> 0.010080239 | F9: =MIN(Class_0!D9,Class_1!D9,Class_2!D9) -> -0.012723926 | G9: =MIN(Class_0!E9,Class_1!E9,Class_2!E9) -> 0.048741285 | H9: =MIN(Class_0!F9,Class_1!F9,Class_2!F9) -> 0.22546388 | I9: =MIN(Class_0!G9,Class_1!G9,Class_2!G9) -> 0.31078321 | J9: =MIN(Class_0!H9,Class_1!H9,Class_2!H9) -> 0.56384028 | K9: =MIN(Class_0!I9,Class_1!I9,Class_2!I9) -> 1
B10: features.14 | D10: =MIN(Class_0!B10,Class_1!B10,Class_2!B10) -> -0.11984025 | E10: =MIN(Class_0!C10,Class_1!C10,Class_2!C10) -> 0.11101663 | F10: =MIN(Class_0!D10,Class_1!D10,Class_2!D10) -> 0.1086848 | G10: =MIN(Class_0!E10,Class_1!E10,Class_2!E10) -> 0.089662736 | H10: =MIN(Class_0!F10,Class_1!F10,Class_2!F10) -> 0.21747645 | I10: =MIN(Class_0!G10,Class_1!G10,Class_2!G10) -> 0.30099536 | J10: =MIN(Class_0!H10,Class_1!H10,Class_2!H10) -> 0.47841463 | K10: =MIN(Class_0!I10,Class_1!I10,Class_2!I10) -> 0.44464204 | L10: =MIN(Class_0!J10,Class_1!J10,Class_2!J10) -> 1
B11: features.16 | D11: =MIN(Class_0!B11,Class_1!B11,Class_2!B11) -> -0.11003064 | E11: =MIN(Class_0!C11,Class_1!C11,Class_2!C11) -> 0.13393667 | F11: =MIN(Class_0!D11,Class_1!D11,Class_2!D11) -> 0.10247539 | G11: =MIN(Class_0!E11,Class_1!E11,Class_2!E11) -> 0.042182547 | H11: =MIN(Class_0!F11,Class_1!F11,Class_2!F11) -> 0.2168714 | I11: =MIN(Class_0!G11,Class_1!G11,Class_2!G11) -> 0.33640543 | J11: =MIN(Class_0!H11,Class_1!H11,Class_2!H11) -> 0.53984218 | K11: =MIN(Class_0!I11,Class_1!I11,Class_2!I11) -> 0.55256603 | ... M11: =MIN(Class_0!K11,Class_1!K11,Class_2!K11) -> 1
B12: features.17 | D12: =MIN(Class_0!B12,Class_1!B12,Class_2!B12) -> -0.084560584 | E12: =MIN(Class_0!C12,Class_1!C12,Class_2!C12) -> 0.17080081 | F12: =MIN(Class_0!D12,Class_1!D12,Class_2!D12) -> 0.16095832 | G12: =MIN(Class_0!E12,Class_1!E12,Class_2!E12) -> 0.1891138 | H12: =MIN(Class_0!F12,Class_1!F12,Class_2!F12) -> 0.19387386 | I12: =MIN(Class_0!G12,Class_1!G12,Class_2!G12) -> 0.23158876 | J12: =MIN(Class_0!H12,Class_1!H12,Class_2!H12) -> 0.26951276 | K12: =MIN(Class_0!I12,Class_1!I12,Class_2!I12) -> 0.28780461 | ... N12: =MIN(Class_0!L12,Class_1!L12,Class_2!L12) -> 1
B13: features.19 | D13: =MIN(Class_0!B13,Class_1!B13,Class_2!B13) -> -0.06681008 | E13: =MIN(Class_0!C13,Class_1!C13,Class_2!C13) -> 0.19888006 | F13: =MIN(Class_0!D13,Class_1!D13,Class_2!D13) -> 0.11659015 | G13: =MIN(Class_0!E13,Class_1!E13,Class_2!E13) -> 0.061207575 | H13: =MIN(Class_0!F13,Class_1!F13,Class_2!F13) -> 0.27599567 | I13: =MIN(Class_0!G13,Class_1!G13,Class_2!G13) -> 0.31966749 | J13: =MIN(Class_0!H13,Class_1!H13,Class_2!H13) -> 0.22518905 | K13: =MIN(Class_0!I13,Class_1!I13,Class_2!I13) -> 0.18867983 | ... O13: =MIN(Class_0!M13,Class_1!M13,Class_2!M13) -> 1
B14: features.21 | D14: =MIN(Class_0!B14,Class_1!B14,Class_2!B14) -> -0.088222242 | E14: =MIN(Class_0!C14,Class_1!C14,Class_2!C14) -> 0.094754369 | F14: =MIN(Class_0!D14,Class_1!D14,Class_2!D14) -> 0.062970976 | G14: =MIN(Class_0!E14,Class_1!E14,Class_2!E14) -> 0.13043239 | H14: =MIN(Class_0!F14,Class_1!F14,Class_2!F14) -> 0.15095424 | I14: =MIN(Class_0!G14,Class_1!G14,Class_2!G14) -> 0.14065166 | J14: =MIN(Class_0!H14,Class_1!H14,Class_2!H14) -> 0.065290104 | K14: =MIN(Class_0!I14,Class_1!I14,Class_2!I14) -> 0.14223495 | ... P14: =MIN(Class_0!N14,Class_1!N14,Class_2!N14) -> 1
B15: features.23 | D15: =MIN(Class_0!B15,Class_1!B15,Class_2!B15) -> -0.053886539 | E15: =MIN(Class_0!C15,Class_1!C15,Class_2!C15) -> -0.11609945 | F15: =MIN(Class_0!D15,Class_1!D15,Class_2!D15) -> -0.093344758 | G15: =MIN(Class_0!E15,Class_1!E15,Class_2!E15) -> -0.012713545 | H15: =MIN(Class_0!F15,Class_1!F15,Class_2!F15) -> 0.0096909992 | I15: =MIN(Class_0!G15,Class_1!G15,Class_2!G15) -> 0.086678523 | J15: =MIN(Class_0!H15,Class_1!H15,Class_2!H15) -> 0.10422983 | K15: =MIN(Class_0!I15,Class_1!I15,Class_2!I15) -> 0.14777133 | ... Q15: =MIN(Class_0!O15,Class_1!O15,Class_2!O15) -> 1
B16: features.24 | D16: =MIN(Class_0!B16,Class_1!B16,Class_2!B16) -> -0.045800944 | E16: =MIN(Class_0!C16,Class_1!C16,Class_2!C16) -> 0.095761712 | F16: =MIN(Class_0!D16,Class_1!D16,Class_2!D16) -> 0.051419769 | G16: =MIN(Class_0!E16,Class_1!E16,Class_2!E16) -> 0.11683317 | H16: =MIN(Class_0!F16,Class_1!F16,Class_2!F16) -> 0.18474873 | I16: =MIN(Class_0!G16,Class_1!G16,Class_2!G16) -> 0.21751284 | J16: =MIN(Class_0!H16,Class_1!H16,Class_2!H16) -> 0.23227549 | K16: =MIN(Class_0!I16,Class_1!I16,Class_2!I16) -> 0.17150836 | ... R16: =MIN(Class_0!P16,Class_1!P16,Class_2!P16) -> 1
B17: features.26 | D17: =MIN(Class_0!B17,Class_1!B17,Class_2!B17) -> -0.086935845 | E17: =MIN(Class_0!C17,Class_1!C17,Class_2!C17) -> -0.006862807 | F17: =MIN(Class_0!D17,Class_1!D17,Class_2!D17) -> -0.024970658 | G17: =MIN(Class_0!E17,Class_1!E17,Class_2!E17) -> 0.0019969163 | H17: =MIN(Class_0!F17,Class_1!F17,Class_2!F17) -> 0.1343272 | I17: =MIN(Class_0!G17,Class_1!G17,Class_2!G17) -> 0.11440302 | J17: =MIN(Class_0!H17,Class_1!H17,Class_2!H17) -> -0.051804388 | K17: =MIN(Class_0!I17,Class_1!I17,Class_2!I17) -> -0.044809466 | ... S17: =MIN(Class_0!Q17,Class_1!Q17,Class_2!Q17) -> 1
B18: features.28 | D18: =MIN(Class_0!B18,Class_1!B18,Class_2!B18) -> -0.072656046 | E18: =MIN(Class_0!C18,Class_1!C18,Class_2!C18) -> 0.0017300142 | F18: =MIN(Class_0!D18,Class_1!D18,Class_2!D18) -> -0.011305207 | G18: =MIN(Class_0!E18,Class_1!E18,Class_2!E18) -> 0.040029888 | H18: =MIN(Class_0!F18,Class_1!F18,Class_2!F18) -> 0.086407793 | I18: =MIN(Class_0!G18,Class_1!G18,Class_2!G18) -> 0.11002061 | J18: =MIN(Class_0!H18,Class_1!H18,Class_2!H18) -> 0.18467371 | K18: =MIN(Class_0!I18,Class_1!I18,Class_2!I18) -> 0.12735782 | ... T18: =MIN(Class_0!R18,Class_1!R18,Class_2!R18) -> 1
B19: features.30 | D19: =MIN(Class_0!B19,Class_1!B19,Class_2!B19) -> -0.10599016 | E19: =MIN(Class_0!C19,Class_1!C19,Class_2!C19) -> 0.028475338 | F19: =MIN(Class_0!D19,Class_1!D19,Class_2!D19) -> -0.0045493052 | G19: =MIN(Class_0!E19,Class_1!E19,Class_2!E19) -> 0.067674097 | H19: =MIN(Class_0!F19,Class_1!F19,Class_2!F19) -> 0.15383962 | I19: =MIN(Class_0!G19,Class_1!G19,Class_2!G19) -> 0.10602578 | J19: =MIN(Class_0!H19,Class_1!H19,Class_2!H19) -> 0.062109113 | K19: =MIN(Class_0!I19,Class_1!I19,Class_2!I19) -> 0.0078706588 | ... U19: =MIN(Class_0!S19,Class_1!S19,Class_2!S19) -> 1
B26: VGG16
D27: 0 | E27: 2 | F27: 4 | G27: 5 | H27: 7 | I27: 9 | J27: 10 | K27: 12 | L27: 14 | M27: 16 | N27: 17 | O27: 19 | P27: 21 | Q27: 23 | R27: 24 | S27: 26 | T27: 28 | U27: 30
B28: features.0 | D28: =IF(D2>0,CHAR(43),CHAR(45)) -> +
B29: features.2 | D29: =IF(D3>0,CHAR(43),CHAR(45)) -> - | E29: =IF(E3>0,CHAR(43),CHAR(45)) -> +
B30: features.4 | D30: =IF(D4>0,CHAR(43),CHAR(45)) -> - | E30: =IF(E4>0,CHAR(43),CHAR(45)) -> + | F30: =IF(F4>0,CHAR(43),CHAR(45)) -> +
B31: features.5 | D31: =IF(D5>0,CHAR(43),CHAR(45)) -> - | E31: =IF(E5>0,CHAR(43),CHAR(45)) -> + | F31: =IF(F5>0,CHAR(43),CHAR(45)) -> + | G31: =IF(G5>0,CHAR(43),CHAR(45)) -> +
B32: features.7 | D32: =IF(D6>0,CHAR(43),CHAR(45)) -> + | E32: =IF(E6>0,CHAR(43),CHAR(45)) -> + | F32: =IF(F6>0,CHAR(43),CHAR(45)) -> + | G32: =IF(G6>0,CHAR(43),CHAR(45)) -> + | H32: =IF(H6>0,CHAR(43),CHAR(45)) -> +
B33: features.9 | D33: =IF(D7>0,CHAR(43),CHAR(45)) -> - | E33: =IF(E7>0,CHAR(43),CHAR(45)) -> + | F33: =IF(F7>0,CHAR(43),CHAR(45)) -> + | G33: =IF(G7>0,CHAR(43),CHAR(45)) -> + | H33: =IF(H7>0,CHAR(43),CHAR(45)) -> + | I33: =IF(I7>0,CHAR(43),CHAR(45)) -> +
B34: features.10 | D34: =IF(D8>0,CHAR(43),CHAR(45)) -> - | E34: =IF(E8>0,CHAR(43),CHAR(45)) -> + | F34: =IF(F8>0,CHAR(43),CHAR(45)) -> + | G34: =IF(G8>0,CHAR(43),CHAR(45)) -> + | H34: =IF(H8>0,CHAR(43),CHAR(45)) -> + | I34: =IF(I8>0,CHAR(43),CHAR(45)) -> + | J34: =IF(J8>0,CHAR(43),CHAR(45)) -> +
B35: features.12 | D35: =IF(D9>0,CHAR(43),CHAR(45)) -> - | E35: =IF(E9>0,CHAR(43),CHAR(45)) -> + | F35: =IF(F9>0,CHAR(43),CHAR(45)) -> - | G35: =IF(G9>0,CHAR(43),CHAR(45)) -> + | H35: =IF(H9>0,CHAR(43),CHAR(45)) -> + | I35: =IF(I9>0,CHAR(43),CHAR(45)) -> + | J35: =IF(J9>0,CHAR(43),CHAR(45)) -> + | K35: =IF(K9>0,CHAR(43),CHAR(45)) -> +
B36: features.14 | D36: =IF(D10>0,CHAR(43),CHAR(45)) -> - | E36: =IF(E10>0,CHAR(43),CHAR(45)) -> + | F36: =IF(F10>0,CHAR(43),CHAR(45)) -> + | G36: =IF(G10>0,CHAR(43),CHAR(45)) -> + | H36: =IF(H10>0,CHAR(43),CHAR(45)) -> + | I36: =IF(I10>0,CHAR(43),CHAR(45)) -> + | J36: =IF(J10>0,CHAR(43),CHAR(45)) -> + | K36: =IF(K10>0,CHAR(43),CHAR(45)) -> + | L36: =IF(L10>0,CHAR(43),CHAR(45)) -> +
B37: features.16 | D37: =IF(D11>0,CHAR(43),CHAR(45)) -> - | E37: =IF(E11>0,CHAR(43),CHAR(45)) -> + | F37: =IF(F11>0,CHAR(43),CHAR(45)) -> + | G37: =IF(G11>0,CHAR(43),CHAR(45)) -> + | H37: =IF(H11>0,CHAR(43),CHAR(45)) -> + | I37: =IF(I11>0,CHAR(43),CHAR(45)) -> + | J37: =IF(J11>0,CHAR(43),CHAR(45)) -> + | K37: =IF(K11>0,CHAR(43),CHAR(45)) -> + | ... M37: =IF(M11>0,CHAR(43),CHAR(45)) -> +
B38: features.17 | D38: =IF(D12>0,CHAR(43),CHAR(45)) -> - | E38: =IF(E12>0,CHAR(43),CHAR(45)) -> + | F38: =IF(F12>0,CHAR(43),CHAR(45)) -> + | G38: =IF(G12>0,CHAR(43),CHAR(45)) -> + | H38: =IF(H12>0,CHAR(43),CHAR(45)) -> + | I38: =IF(I12>0,CHAR(43),CHAR(45)) -> + | J38: =IF(J12>0,CHAR(43),CHAR(45)) -> + | K38: =IF(K12>0,CHAR(43),CHAR(45)) -> + | ... N38: =IF(N12>0,CHAR(43),CHAR(45)) -> +
B39: features.19 | D39: =IF(D13>0,CHAR(43),CHAR(45)) -> - | E39: =IF(E13>0,CHAR(43),CHAR(45)) -> + | F39: =IF(F13>0,CHAR(43),CHAR(45)) -> + | G39: =IF(G13>0,CHAR(43),CHAR(45)) -> + | H39: =IF(H13>0,CHAR(43),CHAR(45)) -> + | I39: =IF(I13>0,CHAR(43),CHAR(45)) -> + | J39: =IF(J13>0,CHAR(43),CHAR(45)) -> + | K39: =IF(K13>0,CHAR(43),CHAR(45)) -> + | ... O39: =IF(O13>0,CHAR(43),CHAR(45)) -> +
B40: features.21 | D40: =IF(D14>0,CHAR(43),CHAR(45)) -> - | E40: =IF(E14>0,CHAR(43),CHAR(45)) -> + | F40: =IF(F14>0,CHAR(43),CHAR(45)) -> + | G40: =IF(G14>0,CHAR(43),CHAR(45)) -> + | H40: =IF(H14>0,CHAR(43),CHAR(45)) -> + | I40: =IF(I14>0,CHAR(43),CHAR(45)) -> + | J40: =IF(J14>0,CHAR(43),CHAR(45)) -> + | K40: =IF(K14>0,CHAR(43),CHAR(45)) -> + | ... P40: =IF(P14>0,CHAR(43),CHAR(45)) -> +
B41: features.23 | D41: =IF(D15>0,CHAR(43),CHAR(45)) -> - | E41: =IF(E15>0,CHAR(43),CHAR(45)) -> - | F41: =IF(F15>0,CHAR(43),CHAR(45)) -> - | G41: =IF(G15>0,CHAR(43),CHAR(45)) -> - | H41: =IF(H15>0,CHAR(43),CHAR(45)) -> + | I41: =IF(I15>0,CHAR(43),CHAR(45)) -> + | J41: =IF(J15>0,CHAR(43),CHAR(45)) -> + | K41: =IF(K15>0,CHAR(43),CHAR(45)) -> + | ... Q41: =IF(Q15>0,CHAR(43),CHAR(45)) -> +
B42: features.24 | D42: =IF(D16>0,CHAR(43),CHAR(45)) -> - | E42: =IF(E16>0,CHAR(43),CHAR(45)) -> + | F42: =IF(F16>0,CHAR(43),CHAR(45)) -> + | G42: =IF(G16>0,CHAR(43),CHAR(45)) -> + | H42: =IF(H16>0,CHAR(43),CHAR(45)) -> + | I42: =IF(I16>0,CHAR(43),CHAR(45)) -> + | J42: =IF(J16>0,CHAR(43),CHAR(45)) -> + | K42: =IF(K16>0,CHAR(43),CHAR(45)) -> + | ... R42: =IF(R16>0,CHAR(43),CHAR(45)) -> +
B43: features.26 | D43: =IF(D17>0,CHAR(43),CHAR(45)) -> - | E43: =IF(E17>0,CHAR(43),CHAR(45)) -> - | F43: =IF(F17>0,CHAR(43),CHAR(45)) -> - | G43: =IF(G17>0,CHAR(43),CHAR(45)) -> + | H43: =IF(H17>0,CHAR(43),CHAR(45)) -> + | I43: =IF(I17>0,CHAR(43),CHAR(45)) -> + | J43: =IF(J17>0,CHAR(43),CHAR(45)) -> - | K43: =IF(K17>0,CHAR(43),CHAR(45)) -> - | ... S43: =IF(S17>0,CHAR(43),CHAR(45)) -> +
B44: features.28 | D44: =IF(D18>0,CHAR(43),CHAR(45)) -> - | E44: =IF(E18>0,CHAR(43),CHAR(45)) -> + | F44: =IF(F18>0,CHAR(43),CHAR(45)) -> - | G44: =IF(G18>0,CHAR(43),CHAR(45)) -> + | H44: =IF(H18>0,CHAR(43),CHAR(45)) -> + | I44: =IF(I18>0,CHAR(43),CHAR(45)) -> + | J44: =IF(J18>0,CHAR(43),CHAR(45)) -> + | K44: =IF(K18>0,CHAR(43),CHAR(45)) -> + | ... T44: =IF(T18>0,CHAR(43),CHAR(45)) -> +
B45: features.30 | D45: =IF(D19>0,CHAR(43),CHAR(45)) -> - | E45: =IF(E19>0,CHAR(43),CHAR(45)) -> + | F45: =IF(F19>0,CHAR(43),CHAR(45)) -> - | G45: =IF(G19>0,CHAR(43),CHAR(45)) -> + | H45: =IF(H19>0,CHAR(43),CHAR(45)) -> + | I45: =IF(I19>0,CHAR(43),CHAR(45)) -> + | J45: =IF(J19>0,CHAR(43),CHAR(45)) -> + | K45: =IF(K19>0,CHAR(43),CHAR(45)) -> + | ... U45: =IF(U19>0,CHAR(43),CHAR(45)) -> +
B49: INCEPTIONV3
...

Sheet VGG16_Heatmap
D3: Layer Index | E3: 0 | F3: 2 | G3: 4 | H3: 5 | I3: 7 | J3: 9 | K3: 10 | L3: 12 | M3: 14 | N3: 16 | O3: 17 | P3: 19 | Q3: 21 | R3: 23 | S3: 24 | T3: 26 | U3: 28 | V3: 30
C4: features.0 | D4: 0 | E4: +
C5: features.2 | D5: =D4+1 -> 1 | E5: - | F5: +
C6: features.4 | D6: =D5+1 -> 2 | E6: - | F6: + | G6: +
C7: features.5 | D7: =D6+1 -> 3 | E7: - | F7: + | G7: + | H7: +
C8: features.7 | D8: =D7+1 -> 4 | E8: + | F8: + | G8: + | H8: + | I8: +
C9: features.9 | D9: =D8+1 -> 5 | E9: - | F9: + | G9: + | H9: + | I9: + | J9: +
C10: features.10 | D10: =D9+1 -> 6 | E10: - | F10: + | G10: + | H10: + | I10: + | J10: + | K10: +
C11: features.12 | D11: =D10+1 -> 7 | E11: - | F11: + | G11: - | H11: + | I11: + | J11: + | K11: + | L11: +
C12: features.14 | D12: =D11+1 -> 8 | E12: - | F12: + | G12: + | H12: + | I12: + | J12: + | K12: + | L12: + | M12: +
C13: features.16 | D13: =D12+1 -> 9 | E13: - | F13: + | G13: + | H13: + | I13: + | J13: + | K13: + | L13: + | M13: + | N13: +
C14: features.17 | D14: =D13+1 -> 10 | E14: - | F14: + | G14: + | H14: + | I14: + | J14: + | K14: + | L14: + | M14: + | N14: + | O14: +
C15: features.19 | D15: =D14+1 -> 11 | E15: - | F15: + | G15: + | H15: + | I15: + | J15: + | K15: + | L15: + | M15: + | N15: + | O15: + | P15: +
C16: features.21 | D16: =D15+1 -> 12 | E16: - | F16: + | G16: + | H16: + | I16: + | J16: + | K16: + | L16: + | M16: + | N16: + | O16: + | P16: + | Q16: +
C17: features.23 | D17: =D16+1 -> 13 | E17: - | F17: - | G17: - | H17: - | I17: + | J17: + | K17: + | L17: + | M17: + | N17: + | O17: + | P17: + | Q17: + | R17: +
C18: features.24 | D18: =D17+1 -> 14 | E18: - | F18: + | G18: + | H18: + | I18: + | J18: + | K18: + | L18: + | M18: + | N18: + | O18: + | P18: + | Q18: + | R18: + | S18: +
C19: features.26 | D19: =D18+1 -> 15 | E19: - | F19: - | G19: - | H19: + | I19: + | J19: + | K19: - | L19: - | M19: - | N19: - | O19: + | P19: + | Q19: + | R19: + | S19: + | T19: +
C20: features.28 | D20: =D19+1 -> 16 | E20: - | F20: + | G20: - | H20: + | I20: + | J20: + | K20: + | L20: + | M20: + | N20: + | O20: + | P20: + | Q20: + | R20: + | S20: + | T20: + | U20: +
C21: features.30 | D21: =D20+1 -> 17 | E21: - | F21: + | G21: - | H21: + | I21: + | J21: + | K21: + | L21: + | M21: - | N21: - | O21: + | P21: + | Q21: + | R21: + | S21: + | T21: + | U21: + | V21: +

Sheet Inception_V3_Heatmap
C3: Layer name | D3: Layer Index | E3: 0 | F3: 1 | G3: 2 | H3: 3 | I3: 4 | J3: 5 | K3: 6 | L3: 7 | M3: 8 | N3: 9 | O3: 10 | P3: 11 | Q3: 12 | R3: 13 | S3: 14 | T3: 15 | U3: 16 | V3: 17 | W3: 18 | X3: 19
C4: Mixed_6b.branch7x7dbl_4.conv | D4: 0 | E4: +
C5: Mixed_6c.branch1x1.conv | D5: 1 | E5: + | F5: +
C6: Mixed_6c.branch7x7_2.conv | D6: 2 | E6: + | F6: - | G6: +
C7: Mixed_6c.branch7x7_3.conv | D7: 3 | E7: + | F7: - | G7: + | H7: +
C8: Mixed_6c.branch7x7dbl_1.conv | D8: 4 | E8: + | F8: - | G8: + | H8: + | I8: +
C9: Mixed_6c.branch7x7dbl_2.conv | D9: 5 | E9: + | F9: + | G9: + | H9: + | I9: + | J9: +
C10: Mixed_6c.branch_pool.conv | D10: 6 | E10: + | F10: - | G10: - | H10: - | I10: + | J10: - | K10: +
C11: Mixed_6d.branch7x7dbl_1.conv | D11: 7 | E11: + | F11: + | G11: + | H11: + | I11: + | J11: + | K11: + | L11: +
C12: Mixed_6d.branch7x7dbl_2.conv | D12: 8 | E12: + | F12: + | G12: + | H12: + | I12: + | J12: + | K12: + | L12: + | M12: +
C13: Mixed_6d.branch7x7dbl_4.conv | D13: 9 | E13: + | F13: + | G13: + | H13: + | I13: + | J13: + | K13: + | L13: + | M13: + | N13: +
C14: Mixed_6e.branch1x1.conv | D14: 10 | E14: + | F14: + | G14: + | H14: - | I14: + | J14: + | K14: - | L14: - | M14: - | N14: + | O14: +
C15: Mixed_6e.branch7x7_1.conv | D15: 11 | E15: + | F15: + | G15: - | H15: - | I15: + | J15: - | K15: + | L15: + | M15: + | N15: + | O15: + | P15: +
C16: Mixed_6e.branch7x7_2.conv | D16: 12 | E16: - | F16: + | G16: - | H16: - | I16: - | J16: - | K16: - | L16: + | M16: + | N16: + | O16: + | P16: + | Q16: +
C17: Mixed_6e.branch7x7dbl_2.conv | D17: 13 | E17: + | F17: + | G17: - | H17: + | I17: + | J17: - | K17: - | L17: - | M17: - | N17: + | O17: + | P17: + | Q17: + | R17: +
C18: Mixed_6e.branch7x7dbl_5.conv | D18: 14 | E18: - | F18: + | G18: - | H18: - | I18: - | J18: + | K18: - | L18: - | M18: - | N18: - | O18: - | P18: + | Q18: + | R18: + | S18: +
C19: Mixed_7a.branch3x3_2.conv | D19: 15 | E19: - | F19: + | G19: - | H19: - | I19: - | J19: - | K19: - | L19: - | M19: - | N19: - | O19: + | P19: + | Q19: + | R19: - | S19: - | T19: +
C20: Mixed_7a.branch7x7x3_1.conv | D20: 16 | E20: - | F20: + | G20: - | H20: - | I20: + | J20: + | K20: + | L20: + | M20: + | N20: + | O20: - | P20: + | Q20: + | R20: + | S20: + | T20: + | U20: +
C21: Mixed_7b.branch3x3_1.conv | D21: 17 | E21: - | F21: - | G21: - | H21: - | I21: - | J21: - | K21: - | L21: - | M21: - | N21: - | O21: + | P21: - | Q21: - | R21: + | S21: - | T21: - | U21: - | V21: +
C22: Mixed_7b.branch3x3dbl_1.conv | D22: 18 | E22: + | F22: + | G22: - | H22: - | I22: - | J22: - | K22: + | L22: - | M22: - | N22: - | O22: + | P22: - | Q22: + | R22: + | S22: + | T22: - | U22: - | V22: - | W22: +
C23: Mixed_7b.branch3x3dbl_2.conv | D23: 19 | E23: - | F23: + | G23: - | H23: - | I23: - | J23: - | K23: - | L23: - | M23: - | N23: - | O23: + | P23: + | Q23: + | R23: + | S23: + | T23: - | U23: - | V23: + | W23: + | X23: +

Sheet MNet_Small
B2: Layer Number | C2: 0 | D2: 1 | E2: 2 | F2: 3 | G2: 4 | H2: 5 | I2: 6 | J2: 7 | K2: 8 | L2: 9 | M2: 10 | N2: 11 | O2: 12 | P2: 13 | Q2: 14 | R2: 15 | S2: 16 | T2: 17 | U2: 18 | V2: 19 | W2: 20 | X2: 21 | Y2: 22 | Z2: 23 | AA2: 24 | AB2: 25 | AC2: 26 | AD2: 27 | AE2: 28 | AF2: 29 | AG2: 30 | AH2: 31 | AI2: 32 | AJ2: 33 | AK2: 34 | AL2: 35 | AM2: 36 | AN2: 37 | AO2: 38 | AP2: 39 | AQ2: 40 | AR2: 41 | AS2: 42 | AT2: 43 | AU2: 44 | AV2: 45 | AW2: 46 | AX2: 47 | AY2: 48 | AZ2: 49 | BA2: 50 | BB2: 51
A3: features.0.0 | B3: 0 | C3: +
A4: features.1.block.0.0 | B4: 1 | C4: + | D4: +
A5: features.1.block.1.fc1 | B5: 2 | C5: - | D5: - | E5: -
A6: features.1.block.1.fc2 | B6: 3 | C6: - | D6: - | E6: - | F6: +
A7: features.1.block.2.0 | B7: 4 | C7: + | D7: + | E7: - | F7: - | G7: +
A8: features.2.block.0.0 | B8: 5 | C8: + | D8: + | E8: - | F8: - | G8: + | H8: +
A9: features.2.block.1.0 | B9: 6 | C9: - | D9: + | E9: - | F9: - | G9: - | H9: - | I9: +
A10: features.2.block.2.0 | B10: 7 | C10: - | D10: + | E10: - | F10: - | G10: - | H10: - | I10: + | J10: +
A11: features.3.block.0.0 | B11: 8 | C11: - | D11: - | E11: - | F11: - | G11: - | H11: - | I11: + | J11: + | K11: +
A12: features.3.block.1.0 | B12: 9 | C12: - | D12: - | E12: - | F12: - | G12: - | H12: - | I12: + | J12: + | K12: + | L12: +
A13: features.3.block.2.0 | B13: 10 | C13: - | D13: - | E13: - | F13: - | G13: - | H13: - | I13: - | J13: - | K13: + | L13: + | M13: +
A14: features.4.block.0.0 | B14: 11 | C14: - | D14: + | E14: - | F14: - | G14: - | H14: - | I14: + | J14: + | K14: - | L14: - | M14: - | N14: +
A15: features.4.block.1.0 | B15: 12 | C15: + | D15: + | E15: - | F15: - | G15: - | H15: - | I15: + | J15: + | K15: - | L15: - | M15: + | N15: + | O15: +
A16: features.4.block.2.fc1 | B16: 13 | C16: - | D16: - | E16: - | F16: - | G16: - | H16: - | I16: - | J16: - | K16: - | L16: - | M16: - | N16: - | O16: + | P16: +
A17: features.4.block.2.fc2 | B17: 14 | C17: - | D17: - | E17: - | F17: - | G17: - | H17: + | I17: - | J17: - | K17: + | L17: - | M17: - | N17: - | O17: - | P17: + | Q17: +
A18: features.4.block.3.0 | B18: 15 | C18: + | D18: + | E18: - | F18: - | G18: - | H18: - | I18: + | J18: + | K18: - | L18: - | M18: + | N18: + | O18: + | P18: - | Q18: - | R18: +
A19: features.5.block.0.0 | B19: 16 | C19: - | D19: + | E19: - | F19: - | G19: - | H19: - | I19: + | J19: + | K19: + | L19: - | M19: + | N19: + | O19: + | P19: - | Q19: + | R19: + | S19: +
A20: features.5.block.1.0 | B20: 17 | C20: + | D20: - | E20: - | F20: - | G20: - | H20: - | I20: + | J20: + | K20: - | L20: - | M20: + | N20: - | O20: + | P20: - | Q20: + | R20: + | S20: + | T20: +
A21: features.5.block.2.fc1 | B21: 18 | C21: - | D21: - | E21: - | F21: - | G21: - | H21: - | I21: - | J21: - | K21: + | L21: - | M21: - | N21: - | O21: - | P21: - | Q21: - | R21: - | S21: - | T21: - | U21: +
A22: features.5.block.2.fc2 | B22: 19 | C22: - | D22: - | E22: - | F22: - | G22: - | H22: - | I22: + | J22: - | K22: - | L22: - | M22: - | N22: - | O22: - | P22: - | Q22: - | R22: - | S22: - | T22: - | U22: + | V22: +
A23: features.5.block.3.0 | B23: 20 | C23: - | D23: - | E23: - | F23: + | G23: - | H23: - | I23: + | J23: - | K23: - | L23: + | M23: + | N23: - | O23: - | P23: - | Q23: + | R23: + | S23: + | T23: + | U23: - | V23: - | W23: +
A24: features.6.block.0.0 | B24: 21 | C24: - | D24: + | E24: - | F24: - | G24: + | H24: + | I24: + | J24: + | K24: - | L24: + | M24: + | N24: + | O24: + | P24: - | Q24: - | R24: + | S24: - | T24: - | U24: - | V24: - | W24: + | X24: +
A25: features.6.block.1.0 | B25: 22 | C25: - | D25: - | E25: - | F25: + | G25: - | H25: + | I25: + | J25: + | K25: - | L25: - | M25: - | N25: + | O25: + | P25: - | Q25: + | R25: + | S25: - | T25: + | U25: - | V25: - | W25: + | X25: + | Y25: +
A26: features.6.block.2.fc1 | B26: 23 | C26: - | D26: - | E26: - | F26: - | G26: - | H26: - | I26: - | J26: - | K26: - | L26: - | M26: - | N26: + | O26: - | P26: - | Q26: - | R26: - | S26: - | T26: - | U26: - | V26: - | W26: - | X26: + | Y26: + | Z26: +
A27: features.6.block.2.fc2 | B27: 24 | C27: - | D27: + | E27: - | F27: - | G27: - | H27: - | I27: - | J27: - | K27: - | L27: - | M27: - | N27: - | O27: - | P27: - | Q27: - | R27: - | S27: - | T27: - | U27: - | V27: - | W27: - | X27: + | Y27: - | Z27: + | AA27: +
A28: features.6.block.3.0 | B28: 25 | C28: - | D28: - | E28: - | F28: - | G28: - | H28: - | I28: - | J28: - | K28: - | L28: - | M28: - | N28: - | O28: - | P28: - | Q28: - | R28: - | S28: - | T28: - | U28: - | V28: + | W28: + | X28: - | Y28: - | Z28: - | AA28: - | AB28: +
A29: features.7.block.0.0 | B29: 26 | C29: - | D29: - | E29: - | F29: - | G29: + | H29: + | I29: + | J29: + | K29: - | L29: - | M29: + | N29: + | O29: + | P29: - | Q29: - | R29: + | S29: + | T29: - | U29: - | V29: - | W29: + | X29: - | Y29: + | Z29: - | AA29: - | AB29: + | AC29: +
A30: features.7.block.1.0 | B30: 27 | C30: + | D30: - | E30: - | F30: - | G30: - | H30: - | I30: + | J30: + | K30: - | L30: + | M30: + | N30: - | O30: + | P30: - | Q30: - | R30: + | S30: - | T30: + | U30: - | V30: - | W30: + | X30: - | Y30: - | Z30: - | AA30: - | AB30: + | AC30: + | AD30: +
A31: features.7.block.2.fc1 | B31: 28 | C31: - | D31: - | E31: - | F31: - | G31: - | H31: - | I31: - | J31: - | K31: - | L31: - | M31: - | N31: - | O31: - | P31: - | Q31: - | R31: - | S31: - | T31: + | U31: - | V31: - | W31: + | X31: - | Y31: - | Z31: - | AA31: - | AB31: - | AC31: - | AD31: + | AE31: +
A32: features.7.block.2.fc2 | B32: 29 | C32: - | D32: - | E32: - | F32: - | G32: - | H32: - | I32: - | J32: - | K32: - | L32: - | M32: - | N32: - | O32: - | P32: - | Q32: - | R32: + | S32: - | T32: - | U32: - | V32: - | W32: - | X32: - | Y32: - | Z32: - | AA32: - | AB32: - | AC32: - | AD32: - | AE32: - | AF32: +
A33: features.7.block.3.0 | B33: 30 | C33: - | D33: - | E33: - | F33: - | G33: - | H33: - | I33: + | J33: - | K33: - | L33: + | M33: + | N33: + | O33: + | P33: - | Q33: - | R33: + | S33: - | T33: + | U33: - | V33: - | W33: + | X33: - | Y33: + | Z33: - | AA33: - | AB33: + | AC33: + | AD33: + | AE33: - | AF33: + | AG33: +
A34: features.8.block.0.0 | B34: 31 | C34: - | D34: - | E34: - | F34: - | G34: - | H34: - | I34: - | J34: + | K34: + | L34: + | M34: + | N34: - | O34: - | P34: - | Q34: - | R34: + | S34: - | T34: + | U34: - | V34: - | W34: - | X34: - | Y34: + | Z34: - | AA34: - | AB34: - | AC34: + | AD34: + | AE34: - | AF34: - | AG34: + | AH34: +
A35: features.8.block.1.0 | B35: 32 | C35: - | D35: - | E35: - | F35: - | G35: - | H35: - | I35: + | J35: + | K35: - | L35: + | M35: + | N35: - | O35: + | P35: - | Q35: - | R35: + | S35: - | T35: + | U35: - | V35: - | W35: + | X35: - | Y35: - | Z35: - | AA35: - | AB35: - | AC35: + | AD35: + | AE35: - | AF35: + | AG35: + | AH35: + | AI35: +
A36: features.8.block.2.fc1 | B36: 33 | C36: - | D36: - | E36: - | F36: - | G36: - | H36: - | I36: - | J36: - | K36: - | L36: + | M36: + | N36: - | O36: - | P36: - | Q36: - | R36: - | S36: - | T36: - | U36: - | V36: - | W36: - | X36: - | Y36: - | Z36: + | AA36: - | AB36: + | AC36: + | AD36: + | AE36: - | AF36: - | AG36: + | AH36: + | AI36: + | AJ36: +
A37: features.8.block.2.fc2 | B37: 34 | C37: - | D37: - | E37: - | F37: - | G37: - | H37: - | I37: - | J37: + | K37: - | L37: + | M37: - | N37: - | O37: + | P37: - | Q37: - | R37: + | S37: + | T37: - | U37: - | V37: - | W37: + | X37: - | Y37: + | Z37: - | AA37: - | AB37: - | AC37: - | AD37: - | AE37: - | AF37: - | AG37: - | AH37: + | AI37: + | AJ37: + | AK37: +
A38: features.8.block.3.0 | B38: 35 | C38: - | D38: - | E38: - | F38: - | G38: - | H38: - | I38: - | J38: - | K38: - | L38: + | M38: + | N38: - | O38: - | P38: + | Q38: - | R38: - | S38: + | T38: - | U38: - | V38: - | W38: + | X38: - | Y38: - | Z38: - | AA38: - | AB38: - | AC38: - | AD38: + | AE38: + | AF38: - | AG38: + | AH38: + | AI38: + | AJ38: - | AK38: - | AL38: +
A39: features.9.block.0.0 | B39: 36 | C39: - | D39: + | E39: - | F39: - | G39: + | H39: + | I39: + | J39: - | K39: - | L39: - | M39: + | N39: + | O39: + | P39: - | Q39: - | R39: + | S39: - | T39: - | U39: - | V39: - | W39: + | X39: - | Y39: + | Z39: + | AA39: - | AB39: + | AC39: + | AD39: + | AE39: + | AF39: - | AG39: + | AH39: - | AI39: - | AJ39: - | AK39: - | AL39: - | AM39: +
A40: features.9.block.1.0 | B40: 37 | C40: - | D40: - | E40: - | F40: - | G40: - | H40: - | I40: - | J40: - | K40: - | L40: - | M40: + | N40: - | O40: - | P40: - | Q40: - | R40: + | S40: - | T40: - | U40: - | V40: - | W40: + | X40: - | Y40: - | Z40: - | AA40: - | AB40: + | AC40: + | AD40: + | AE40: + | AF40: - | AG40: + | AH40: + | AI40: + | AJ40: - | AK40: - | AL40: + | AM40: + | AN40: +
A41: features.9.block.2.fc1 | B41: 38 | C41: - | D41: - | E41: - | F41: - | G41: - | H41: - | I41: - | J41: - | K41: - | L41: - | M41: - | N41: - | O41: - | P41: - | Q41: - | R41: - | S41: - | T41: - | U41: - | V41: - | W41: - | X41: - | Y41: - | Z41: - | AA41: - | AB41: - | AC41: + | AD41: + | AE41: - | AF41: - | AG41: - | AH41: - | AI41: - | AJ41: - | AK41: - | AL41: - | AM41: + | AN41: + | AO41: +
...

Sheet MNet_Large
C2: 0 | D2: 1 | E2: 2 | F2: 3 | G2: 4 | H2: 5 | I2: 6 | J2: 7 | K2: 8 | L2: 9 | M2: 10 | N2: 11 | O2: 12 | P2: 13 | Q2: 14 | R2: 15 | S2: 16 | T2: 17 | U2: 18 | V2: 19 | W2: 20 | X2: 21 | Y2: 22 | Z2: 23 | AA2: 24 | AB2: 25 | AC2: 26 | AD2: 27 | AE2: 28 | AF2: 29 | AG2: 30 | AH2: 31 | AI2: 32 | AJ2: 33 | AK2: 34 | AL2: 35 | AM2: 36 | AN2: 37 | AO2: 38 | AP2: 39 | AQ2: 40 | AR2: 41 | AS2: 42 | AT2: 43 | AU2: 44 | AV2: 45 | AW2: 46 | AX2: 47 | AY2: 48 | AZ2: 49 | BA2: 50 | BB2: 51 | BC2: 52 | BD2: 53 | BE2: 54 | BF2: 55 | BG2: 56 | BH2: 57 | BI2: 58 | BJ2: 59 | BK2: 60 | BL2: 61
A3: features.0.0 | B3: 0 | C3: +
A4: features.1.block.0.0 | B4: 1 | C4: + | D4: + | AS4: -
A5: features.1.block.1.0 | B5: 2 | C5: - | D5: - | E5: +
A6: features.2.block.0.0 | B6: 3 | C6: + | D6: - | E6: + | F6: +
A7: features.2.block.1.0 | B7: 4 | C7: + | D7: - | E7: + | F7: + | G7: +
A8: features.2.block.2.0 | B8: 5 | C8: + | D8: - | E8: + | F8: + | G8: + | H8: +
A9: features.3.block.0.0 | B9: 6 | C9: - | D9: - | E9: - | F9: - | G9: - | H9: - | I9: +
A10: features.3.block.1.0 | B10: 7 | C10: + | D10: + | E10: - | F10: - | G10: - | H10: + | I10: + | J10: +
A11: features.3.block.2.0 | B11: 8 | C11: + | D11: - | E11: - | F11: - | G11: - | H11: - | I11: + | J11: + | K11: +
A12: features.4.block.0.0 | B12: 9 | C12: + | D12: - | E12: + | F12: + | G12: + | H12: + | I12: - | J12: - | K12: + | L12: +
A13: features.4.block.1.0 | B13: 10 | C13: + | D13: - | E13: + | F13: + | G13: + | H13: + | I13: - | J13: - | K13: + | L13: + | M13: +
A14: features.4.block.2.fc1 | B14: 11 | C14: + | D14: - | E14: + | F14: + | G14: + | H14: - | I14: - | J14: - | K14: - | L14: + | M14: - | N14: +
A15: features.4.block.2.fc2 | B15: 12 | C15: - | D15: - | E15: - | F15: - | G15: - | H15: - | I15: - | J15: - | K15: - | L15: - | M15: - | N15: - | O15: +
A16: features.4.block.3.0 | B16: 13 | C16: + | D16: - | E16: + | F16: + | G16: + | H16: + | I16: - | J16: - | K16: + | L16: + | M16: + | N16: + | O16: - | P16: +
A17: features.5.block.0.0 | B17: 14 | C17: - | D17: - | E17: + | F17: + | G17: + | H17: + | I17: - | J17: - | K17: + | L17: + | M17: + | N17: - | O17: - | P17: + | Q17: +
A18: features.5.block.1.0 | B18: 15 | C18: - | D18: + | E18: - | F18: - | G18: - | H18: - | I18: + | J18: - | K18: - | L18: - | M18: - | N18: - | O18: - | P18: - | Q18: + | R18: +
A19: features.5.block.2.fc1 | B19: 16 | C19: - | D19: - | E19: - | F19: - | G19: - | H19: - | I19: - | J19: - | K19: - | L19: - | M19: - | N19: - | O19: - | P19: - | Q19: - | R19: + | S19: +
A20: features.5.block.2.fc2 | B20: 17 | C20: - | D20: - | E20: - | F20: - | G20: - | H20: - | I20: + | J20: - | K20: - | L20: - | M20: - | N20: - | O20: - | P20: - | Q20: - | R20: - | S20: + | T20: +
A21: features.5.block.3.0 | B21: 18 | C21: - | D21: + | E21: - | F21: - | G21: - | H21: - | I21: + | J21: + | K21: + | L21: - | M21: - | N21: - | O21: - | P21: - | Q21: + | R21: + | S21: + | T21: + | U21: +
A22: features.6.block.0.0 | B22: 19 | C22: - | D22: - | E22: - | F22: - | G22: - | H22: - | I22: + | J22: - | K22: + | L22: + | M22: + | N22: - | O22: - | P22: + | Q22: + | R22: - | S22: - | T22: - | U22: + | V22: + | AS22: -
A23: features.6.block.1.0 | B23: 20 | C23: - | D23: - | E23: - | F23: - | G23: - | H23: - | I23: - | J23: - | K23: + | L23: - | M23: - | N23: - | O23: - | P23: - | Q23: - | R23: - | S23: + | T23: - | U23: + | V23: + | W23: +
A24: features.6.block.2.fc1 | B24: 21 | C24: - | D24: - | E24: - | F24: - | G24: - | H24: - | I24: + | J24: - | K24: - | L24: - | M24: - | N24: - | O24: - | P24: - | Q24: - | R24: - | S24: + | T24: + | U24: - | V24: - | W24: - | X24: +
A25: features.6.block.2.fc2 | B25: 22 | C25: - | D25: - | E25: - | F25: - | G25: - | H25: - | I25: - | J25: - | K25: - | L25: - | M25: - | N25: - | O25: - | P25: - | Q25: - | R25: - | S25: - | T25: - | U25: - | V25: - | W25: - | X25: + | Y25: +
A26: features.6.block.3.0 | B26: 23 | C26: + | D26: - | E26: - | F26: - | G26: - | H26: - | I26: - | J26: - | K26: + | L26: - | M26: - | N26: - | O26: - | P26: - | Q26: - | R26: - | S26: - | T26: - | U26: - | V26: + | W26: + | X26: - | Y26: - | Z26: +
A27: features.7.block.0.0 | B27: 24 | C27: - | D27: - | E27: + | F27: + | G27: + | H27: + | I27: - | J27: - | K27: - | L27: + | M27: + | N27: + | O27: - | P27: + | Q27: - | R27: - | S27: - | T27: - | U27: - | V27: - | W27: - | X27: - | Y27: - | Z27: - | AA27: +
A28: features.7.block.1.0 | B28: 25 | C28: - | D28: - | E28: + | F28: + | G28: - | H28: - | I28: - | J28: - | K28: - | L28: + | M28: + | N28: + | O28: - | P28: + | Q28: - | R28: - | S28: - | T28: - | U28: - | V28: - | W28: - | X28: - | Y28: - | Z28: - | AA28: + | AB28: +
A29: features.7.block.2.0 | B29: 26 | C29: - | D29: - | E29: + | F29: + | G29: - | H29: - | I29: - | J29: - | K29: - | L29: + | M29: + | N29: + | O29: - | P29: + | Q29: - | R29: - | S29: - | T29: - | U29: - | V29: - | W29: - | X29: - | Y29: - | Z29: - | AA29: + | AB29: + | AC29: +
A30: features.8.block.0.0 | B30: 27 | C30: - | D30: - | E30: - | F30: - | G30: - | H30: - | I30: + | J30: + | K30: - | L30: - | M30: - | N30: - | O30: - | P30: + | Q30: - | R30: - | S30: - | T30: - | U30: - | V30: - | W30: - | X30: - | Y30: - | Z30: - | AA30: + | AB30: + | AC30: + | AD30: +
A31: features.8.block.1.0 | B31: 28 | C31: - | D31: - | E31: - | F31: - | G31: - | H31: - | I31: + | J31: + | K31: + | L31: - | M31: - | N31: - | O31: - | P31: - | Q31: - | R31: + | S31: - | T31: - | U31: + | V31: + | W31: - | X31: - | Y31: - | Z31: - | AA31: - | AB31: - | AC31: - | AD31: + | AE31: +
A32: features.8.block.2.0 | B32: 29 | C32: - | D32: - | E32: - | F32: - | G32: - | H32: - | I32: + | J32: - | K32: - | L32: - | M32: - | N32: - | O32: - | P32: - | Q32: - | R32: - | S32: - | T32: - | U32: - | V32: - | W32: - | X32: - | Y32: - | Z32: - | AA32: - | AB32: - | AC32: + | AD32: + | AE32: + | AF32: +
A33: features.9.block.0.0 | B33: 30 | C33: - | D33: - | E33: - | F33: - | G33: - | H33: - | I33: - | J33: + | K33: - | L33: + | M33: - | N33: - | O33: - | P33: - | Q33: + | R33: - | S33: - | T33: - | U33: - | V33: - | W33: - | X33: - | Y33: - | Z33: - | AA33: - | AB33: - | AC33: + | AD33: + | AE33: - | AF33: + | AG33: +
A34: features.9.block.1.0 | B34: 31 | C34: - | D34: - | E34: - | F34: - | G34: - | H34: - | I34: - | J34: - | K34: - | L34: + | M34: - | N34: - | O34: - | P34: - | Q34: + | R34: - | S34: - | T34: - | U34: - | V34: + | W34: - | X34: - | Y34: - | Z34: - | AA34: + | AB34: + | AC34: + | AD34: - | AE34: - | AF34: + | AG34: + | AH34: +
A35: features.9.block.2.0 | B35: 32 | C35: - | D35: + | E35: - | F35: - | G35: - | H35: - | I35: - | J35: - | K35: + | L35: - | M35: - | N35: - | O35: - | P35: - | Q35: - | R35: - | S35: - | T35: + | U35: - | V35: - | W35: - | X35: - | Y35: - | Z35: - | AA35: - | AB35: - | AC35: + | AD35: - | AE35: - | AF35: + | AG35: + | AH35: + | AI35: +
A36: features.10.block.0.0 | B36: 33 | C36: - | D36: - | E36: - | F36: - | G36: - | H36: - | I36: - | J36: - | K36: - | L36: - | M36: - | N36: - | O36: + | P36: - | Q36: - | R36: - | S36: - | T36: - | U36: + | V36: + | W36: + | X36: - | Y36: + | Z36: - | AA36: - | AB36: - | AC36: - | AD36: + | AE36: + | AF36: + | AG36: + | AH36: + | AI36: + | AJ36: +
A37: features.10.block.1.0 | B37: 34 | C37: - | D37: + | E37: - | F37: - | G37: - | H37: - | I37: + | J37: - | K37: - | L37: - | M37: - | N37: - | O37: - | P37: - | Q37: - | R37: - | S37: - | T37: - | U37: + | V37: + | W37: + | X37: - | Y37: - | Z37: - | AA37: - | AB37: - | AC37: - | AD37: + | AE37: + | AF37: - | AG37: + | AH37: + | AI37: - | AJ37: + | AK37: +
A38: features.10.block.2.0 | B38: 35 | C38: - | D38: - | E38: - | F38: - | G38: - | H38: - | I38: + | J38: + | K38: - | L38: - | M38: - | N38: - | O38: + | P38: - | Q38: - | R38: + | S38: - | T38: - | U38: - | V38: - | W38: - | X38: + | Y38: + | Z38: - | AA38: - | AB38: - | AC38: - | AD38: + | AE38: - | AF38: - | AG38: + | AH38: - | AI38: - | AJ38: + | AK38: + | AL38: +
A39: features.11.block.0.0 | B39: 36 | C39: - | D39: - | E39: + | F39: + | G39: + | H39: - | I39: - | J39: - | K39: - | L39: + | M39: + | N39: + | O39: - | P39: + | Q39: - | R39: - | S39: - | T39: - | U39: - | V39: - | W39: - | X39: - | Y39: - | Z39: - | AA39: + | AB39: + | AC39: + | AD39: - | AE39: - | AF39: - | AG39: - | AH39: - | AI39: - | AJ39: - | AK39: - | AL39: - | AM39: +
A40: features.11.block.1.0 | B40: 37 | C40: - | D40: - | E40: + | F40: + | G40: + | H40: - | I40: - | J40: - | K40: - | L40: + | M40: + | N40: + | O40: - | P40: + | Q40: - | R40: - | S40: - | T40: - | U40: - | V40: - | W40: - | X40: - | Y40: - | Z40: - | AA40: + | AB40: + | AC40: + | AD40: - | AE40: - | AF40: + | AG40: - | AH40: - | AI40: + | AJ40: - | AK40: - | AL40: - | AM40: + | AN40: +
A41: features.11.block.2.fc1 | B41: 38 | C41: + | D41: - | E41: - | F41: - | G41: - | H41: + | I41: - | J41: - | K41: - | L41: - | M41: - | N41: - | O41: - | P41: - | Q41: - | R41: - | S41: + | T41: - | U41: - | V41: - | W41: - | X41: - | Y41: - | Z41: - | AA41: - | AB41: - | AC41: - | AD41: - | AE41: - | AF41: - | AG41: - | AH41: - | AI41: - | AJ41: - | AK41: - | AL41: - | AM41: - | AN41: - | AO41: +
...

Sheet Resnet50
A2: Layer Name | B2: Layer Index | C2: 1 | D2: 2 | E2: 3 | F2: 4 | G2: 5 | H2: 6 | I2: 7 | J2: 8 | K2: 9 | L2: 10 | M2: 11 | N2: 12 | O2: 13 | P2: 14 | Q2: 15 | R2: 16 | S2: 17 | T2: 18 | U2: 19 | V2: 20 | W2: 21 | X2: 22 | Y2: 23 | Z2: 24 | AA2: 25 | AB2: 26 | AC2: 27 | AD2: 28 | AE2: 29 | AF2: 30 | AG2: 31 | AH2: 32 | AI2: 33 | AJ2: 34 | AK2: 35 | AL2: 36 | AM2: 37 | AN2: 38 | AO2: 39 | AP2: 40 | AQ2: 41 | AR2: 42 | AS2: 43 | AT2: 44 | AU2: 45 | AV2: 46 | AW2: 47 | AX2: 48 | AY2: 49 | AZ2: 50 | BA2: 51 | BB2: 52 | BC2: 53 | BD2: 54
A3: conv1 | B3: 1 | C3: +
A4: maxpool | B4: 2 | C4: + | D4: +
A5: layer1.0.conv1 | B5: 3 | C5: + | D5: + | E5: +
A6: layer1.0.conv2 | B6: 4 | C6: + | D6: + | E6: + | F6: +
A7: layer1.0.conv3 | B7: 5 | C7: + | D7: + | E7: + | F7: + | G7: +
A8: layer1.0.downsample.0 | B8: 6 | C8: + | D8: + | E8: + | F8: + | G8: + | H8: +
A9: layer1.1.conv1 | B9: 7 | C9: - | D9: + | E9: + | F9: + | G9: + | H9: + | I9: +
A10: layer1.1.conv2 | B10: 8 | C10: + | D10: + | E10: + | F10: + | G10: + | H10: + | I10: + | J10: +
A11: layer1.1.conv3 | B11: 9 | C11: - | D11: - | E11: - | F11: + | G11: + | H11: - | I11: + | J11: + | K11: +
A12: layer1.2.conv1 | B12: 10 | C12: - | D12: + | E12: + | F12: + | G12: + | H12: + | I12: + | J12: + | K12: + | L12: +
A13: layer1.2.conv2 | B13: 11 | C13: + | D13: - | E13: - | F13: - | G13: - | H13: - | I13: + | J13: + | K13: + | L13: + | M13: +
A14: layer1.2.conv3 | B14: 12 | C14: - | D14: - | E14: - | F14: + | G14: - | H14: - | I14: - | J14: - | K14: - | L14: - | M14: + | N14: +
A15: layer2.0.conv1 | B15: 13 | C15: + | D15: + | E15: + | F15: + | G15: + | H15: + | I15: - | J15: + | K15: - | L15: - | M15: - | N15: + | O15: +
A16: layer2.0.conv2 | B16: 14 | C16: + | D16: - | E16: - | F16: - | G16: - | H16: - | I16: - | J16: - | K16: - | L16: - | M16: - | N16: + | O16: + | P16: +
A17: layer2.0.conv3 | B17: 15 | C17: - | D17: - | E17: - | F17: - | G17: - | H17: - | I17: - | J17: - | K17: + | L17: - | M17: - | N17: + | O17: + | P17: + | Q17: +
A18: layer2.0.downsample.0 | B18: 16 | C18: + | D18: + | E18: + | F18: + | G18: + | H18: + | I18: - | J18: - | K18: - | L18: - | M18: - | N18: - | O18: + | P18: + | Q18: - | R18: +
A19: layer2.1.conv1 | B19: 17 | C19: + | D19: + | E19: + | F19: + | G19: + | H19: + | I19: + | J19: - | K19: - | L19: + | M19: + | N19: + | O19: - | P19: - | Q19: - | R19: + | S19: +
A20: layer2.1.conv2 | B20: 18 | C20: + | D20: + | E20: + | F20: - | G20: - | H20: - | I20: + | J20: - | K20: - | L20: + | M20: - | N20: - | O20: - | P20: - | Q20: - | R20: + | S20: + | T20: +
A21: layer2.1.conv3 | B21: 19 | C21: + | D21: - | E21: - | F21: - | G21: - | H21: - | I21: + | J21: - | K21: + | L21: + | M21: - | N21: + | O21: - | P21: + | Q21: + | R21: + | S21: + | T21: + | U21: +
A22: layer2.2.conv1 | B22: 20 | C22: - | D22: - | E22: - | F22: - | G22: - | H22: - | I22: - | J22: + | K22: + | L22: - | M22: - | N22: + | O22: + | P22: + | Q22: + | R22: + | S22: + | T22: + | U22: + | V22: +
A23: layer2.2.conv2 | B23: 21 | C23: + | D23: - | E23: - | F23: - | G23: - | H23: - | I23: + | J23: + | K23: + | L23: - | M23: - | N23: - | O23: - | P23: + | Q23: + | R23: + | S23: + | T23: + | U23: + | V23: + | W23: +
A24: layer2.2.conv3 | B24: 22 | C24: - | D24: - | E24: - | F24: - | G24: - | H24: - | I24: - | J24: - | K24: + | L24: - | M24: - | N24: + | O24: - | P24: + | Q24: + | R24: - | S24: - | T24: + | U24: + | V24: + | W24: + | X24: +
A25: layer2.3.conv1 | B25: 23 | C25: + | D25: - | E25: - | F25: - | G25: - | H25: - | I25: - | J25: + | K25: + | L25: - | M25: - | N25: + | O25: + | P25: + | Q25: + | R25: - | S25: - | T25: - | U25: + | V25: + | W25: + | X25: + | Y25: +
A26: layer2.3.conv2 | B26: 24 | C26: + | D26: - | E26: - | F26: + | G26: - | H26: - | I26: - | J26: - | K26: + | L26: - | M26: - | N26: - | O26: + | P26: + | Q26: + | R26: - | S26: - | T26: + | U26: + | V26: + | W26: + | X26: + | Y26: + | Z26: +
A27: layer2.3.conv3 | B27: 25 | C27: + | D27: - | E27: - | F27: - | G27: - | H27: - | I27: + | J27: + | K27: + | L27: - | M27: - | N27: + | O27: - | P27: + | Q27: + | R27: - | S27: - | T27: - | U27: + | V27: - | W27: + | X27: + | Y27: + | Z27: + | AA27: +
A28: layer3.0.conv1 | B28: 26 | C28: - | D28: - | E28: - | F28: - | G28: - | H28: - | I28: - | J28: - | K28: + | L28: - | M28: - | N28: + | O28: + | P28: + | Q28: + | R28: + | S28: - | T28: + | U28: + | V28: - | W28: - | X28: + | Y28: + | Z28: + | AA28: + | AB28: +
A29: layer3.0.conv2 | B29: 27 | C29: - | D29: - | E29: - | F29: - | G29: - | H29: - | I29: - | J29: - | K29: + | L29: - | M29: - | N29: + | O29: + | P29: + | Q29: + | R29: + | S29: - | T29: - | U29: - | V29: - | W29: - | X29: + | Y29: + | Z29: + | AA29: + | AB29: + | AC29: +
A30: layer3.0.conv3 | B30: 28 | C30: - | D30: - | E30: - | F30: - | G30: - | H30: - | I30: - | J30: + | K30: + | L30: - | M30: - | N30: + | O30: + | P30: + | Q30: + | R30: + | S30: - | T30: - | U30: + | V30: - | W30: - | X30: + | Y30: + | Z30: + | AA30: + | AB30: + | AC30: + | AD30: +
A31: layer3.0.downsample.0 | B31: 29 | C31: - | D31: + | E31: - | F31: - | G31: - | H31: - | I31: - | J31: - | K31: + | L31: - | M31: - | N31: + | O31: + | P31: + | Q31: + | R31: + | S31: - | T31: + | U31: + | V31: + | W31: + | X31: + | Y31: + | Z31: + | AA31: + | AB31: + | AC31: + | AD31: + | AE31: +
A32: layer3.1.conv1 | B32: 30 | C32: - | D32: - | E32: - | F32: - | G32: - | H32: - | I32: - | J32: - | K32: + | L32: - | M32: - | N32: - | O32: - | P32: + | Q32: + | R32: + | S32: - | T32: + | U32: + | V32: + | W32: + | X32: + | Y32: + | Z32: + | AA32: + | AB32: + | AC32: + | AD32: + | AE32: + | AF32: +
A33: layer3.1.conv2 | B33: 31 | C33: + | D33: - | E33: - | F33: - | G33: - | H33: - | I33: - | J33: - | K33: + | L33: - | M33: - | N33: - | O33: - | P33: + | Q33: + | R33: + | S33: - | T33: + | U33: + | V33: + | W33: + | X33: + | Y33: + | Z33: + | AA33: + | AB33: + | AC33: + | AD33: + | AE33: + | AF33: + | AG33: +
A34: layer3.1.conv3 | B34: 32 | C34: - | D34: - | E34: - | F34: - | G34: - | H34: - | I34: - | J34: + | K34: + | L34: - | M34: - | N34: + | O34: - | P34: + | Q34: + | R34: - | S34: - | T34: + | U34: + | V34: + | W34: + | X34: + | Y34: + | Z34: + | AA34: + | AB34: + | AC34: + | AD34: + | AE34: + | AF34: + | AG34: + | AH34: +
A35: layer3.2.conv1 | B35: 33 | C35: + | D35: - | E35: - | F35: - | G35: - | H35: - | I35: - | J35: - | K35: + | L35: - | M35: - | N35: - | O35: - | P35: + | Q35: + | R35: - | S35: - | T35: - | U35: + | V35: + | W35: + | X35: + | Y35: + | Z35: + | AA35: + | AB35: + | AC35: + | AD35: + | AE35: + | AF35: + | AG35: + | AH35: + | AI35: +
A36: layer3.2.conv2 | B36: 34 | C36: - | D36: - | E36: - | F36: - | G36: - | H36: - | I36: - | J36: - | K36: + | L36: - | M36: - | N36: - | O36: - | P36: + | Q36: + | R36: - | S36: - | T36: - | U36: + | V36: + | W36: + | X36: + | Y36: + | Z36: + | AA36: + | AB36: + | AC36: + | AD36: + | AE36: + | AF36: + | AG36: + | AH36: + | AI36: + | AJ36: +
A37: layer3.2.conv3 | B37: 35 | C37: - | D37: - | E37: - | F37: - | G37: - | H37: - | I37: - | J37: - | K37: + | L37: - | M37: - | N37: - | O37: + | P37: + | Q37: + | R37: - | S37: - | T37: - | U37: + | V37: + | W37: + | X37: + | Y37: + | Z37: + | AA37: + | AB37: + | AC37: + | AD37: + | AE37: + | AF37: + | AG37: + | AH37: + | AI37: + | AJ37: + | AK37: +
A38: layer3.3.conv1 | B38: 36 | C38: - | D38: - | E38: - | F38: - | G38: - | H38: - | I38: - | J38: + | K38: + | L38: - | M38: - | N38: - | O38: + | P38: + | Q38: + | R38: + | S38: - | T38: - | U38: - | V38: + | W38: + | X38: + | Y38: + | Z38: + | AA38: + | AB38: + | AC38: + | AD38: + | AE38: + | AF38: + | AG38: + | AH38: + | AI38: + | AJ38: + | AK38: + | AL38: +
A39: layer3.3.conv2 | B39: 37 | C39: - | D39: - | E39: - | F39: - | G39: - | H39: - | I39: - | J39: - | K39: + | L39: - | M39: - | N39: + | O39: + | P39: + | Q39: + | R39: - | S39: - | T39: - | U39: + | V39: + | W39: + | X39: + | Y39: + | Z39: + | AA39: + | AB39: + | AC39: + | AD39: + | AE39: + | AF39: + | AG39: + | AH39: + | AI39: + | AJ39: + | AK39: + | AL39: + | AM39: +
A40: layer3.3.conv3 | B40: 38 | C40: - | D40: - | E40: - | F40: - | G40: - | H40: - | I40: - | J40: - | K40: + | L40: - | M40: - | N40: + | O40: + | P40: + | Q40: + | R40: - | S40: - | T40: - | U40: - | V40: + | W40: + | X40: + | Y40: + | Z40: + | AA40: + | AB40: + | AC40: + | AD40: + | AE40: + | AF40: + | AG40: + | AH40: + | AI40: + | AJ40: + | AK40: + | AL40: + | AM40: + | AN40: +
A41: layer3.4.conv1 | B41: 39 | C41: - | D41: - | E41: - | F41: - | G41: - | H41: - | I41: - | J41: - | K41: - | L41: - | M41: - | N41: + | O41: + | P41: + | Q41: + | R41: - | S41: - | T41: - | U41: + | V41: + | W41: + | X41: + | Y41: + | Z41: + | AA41: + | AB41: + | AC41: + | AD41: + | AE41: + | AF41: + | AG41: + | AH41: + | AI41: + | AJ41: + | AK41: + | AL41: + | AM41: + | AN41: + | AO41: +
...

Sheet Class_0
B1: features.0 | C1: features.2 | D1: features.4 | E1: features.5 | F1: features.7 | G1: features.9 | H1: features.10 | I1: features.12 | J1: features.14 | K1: features.16 | L1: features.17 | M1: features.19 | N1: features.21 | O1: features.23 | P1: features.24 | Q1: features.26 | R1: features.28 | S1: features.30
A2: features.0 | B2: 1 | C2: 0.41519292 | D2: 0.32484426 | E2: 0.42973768 | F2: 0.29760182 | G2: 0.29762972 | H2: 0.24057084 | I2: 0.20942007 | J2: 0.17225033 | K2: 0.18706651 | L2: 0.17056448 | M2: 0.14175543 | N2: 0.094389765 | O2: 0.11764595 | P2: 0.10896145 | Q2: 0.073013929 | R2: 0.1058914 | S2: 0.1014402
A3: features.2 | B3: 0.41519292 | C3: 1 | D3: 0.68986715 | E3: 0.44876515 | F3: 0.42604352 | G3: 0.38817958 | H3: 0.31019921 | I3: 0.33198694 | J3: 0.16113381 | K3: 0.19908715 | L3: 0.23127714 | M3: 0.26107213 | N3: 0.21384307 | O3: 0.24655173 | P3: 0.2013502 | Q3: 0.11956871 | R3: 0.24760021 | S3: 0.22237559
A4: features.4 | B4: 0.32484426 | C4: 0.68986715 | D4: 1 | E4: 0.41143349 | F4: 0.38812197 | G4: 0.35701845 | H4: 0.2958598 | I4: 0.30935845 | J4: 0.11588966 | K4: 0.1483506 | L4: 0.18773366 | M4: 0.23358234 | N4: 0.19724022 | O4: 0.24267769 | P4: 0.17013953 | Q4: 0.058690013 | R4: 0.21440138 | S4: 0.18828391
A5: features.5 | B5: 0.42973768 | C5: 0.44876515 | D5: 0.41143349 | E5: 1 | F5: 0.45723544 | G5: 0.41296699 | H5: 0.4136801 | I5: 0.34505052 | J5: 0.35425199 | K5: 0.34337406 | L5: 0.30917489 | M5: 0.26198213 | N5: 0.26149178 | O5: 0.26930803 | P5: 0.22893678 | Q5: 0.17484908 | R5: 0.25535566 | S5: 0.24728718
A6: features.7 | B6: 0.29760182 | C6: 0.42604352 | D6: 0.38812197 | E6: 0.45723544 | F6: 1 | G6: 0.82405723 | H6: 0.70286331 | I6: 0.4952514 | J6: 0.46856187 | K6: 0.47383012 | L6: 0.37004999 | M6: 0.30657297 | N6: 0.29744039 | O6: 0.28391588 | P6: 0.28841853 | Q6: 0.15889853 | R6: 0.24648894 | S6: 0.25566087
A7: features.9 | B7: 0.29762972 | C7: 0.38817958 | D7: 0.35701845 | E7: 0.41296699 | F7: 0.82405723 | G7: 1 | H7: 0.68353319 | I7: 0.51718739 | J7: 0.46097495 | K7: 0.48520859 | L7: 0.33870107 | M7: 0.31966749 | N7: 0.26357717 | O7: 0.24899701 | P7: 0.27317423 | Q7: 0.12073087 | R7: 0.19159445 | S7: 0.19770361
A8: features.10 | B8: 0.24057084 | C8: 0.31019921 | D8: 0.2958598 | E8: 0.4136801 | F8: 0.70286331 | G8: 0.68353319 | H8: 1 | I8: 0.56384028 | J8: 0.55208225 | K8: 0.53984218 | L8: 0.50044008 | M8: 0.35022026 | N8: 0.37258289 | O8: 0.34531342 | P8: 0.31037492 | Q8: 0.14859279 | R8: 0.19314984 | S8: 0.20609307
A9: features.12 | B9: 0.20942007 | C9: 0.33198694 | D9: 0.30935845 | E9: 0.34505052 | F9: 0.4952514 | G9: 0.51718739 | H9: 0.56384028 | I9: 1 | J9: 0.58925794 | K9: 0.60568597 | L9: 0.47357702 | M9: 0.39881644 | N9: 0.32203165 | O9: 0.28764419 | P9: 0.32108226 | Q9: 0.11677793 | R9: 0.13378894 | S9: 0.14246384
A10: features.14 | B10: 0.17225033 | C10: 0.16113381 | D10: 0.11588966 | E10: 0.35425199 | F10: 0.46856187 | G10: 0.46097495 | H10: 0.55208225 | I10: 0.58925794 | J10: 1 | K10: 0.82485263 | L10: 0.61037003 | M10: 0.44133217 | N10: 0.44155948 | O10: 0.38972464 | P10: 0.4181047 | Q10: 0.17722502 | R10: 0.14256363 | S10: 0.13796825
A11: features.16 | B11: 0.18706651 | C11: 0.19908715 | D11: 0.1483506 | E11: 0.34337406 | F11: 0.47383012 | G11: 0.48520859 | H11: 0.53984218 | I11: 0.60568597 | J11: 0.82485263 | K11: 1 | L11: 0.62457397 | M11: 0.4687723 | N11: 0.43082371 | O11: 0.35845902 | P11: 0.42017749 | Q11: 0.16068647 | R11: 0.18564339 | S11: 0.1728567
A12: features.17 | B12: 0.17056448 | C12: 0.23127714 | D12: 0.18773366 | E12: 0.30917489 | F12: 0.37004999 | G12: 0.33870107 | H12: 0.50044008 | I12: 0.47357702 | J12: 0.61037003 | K12: 0.62457397 | L12: 1 | M12: 0.53586574 | N12: 0.54483701 | O12: 0.52155822 | P12: 0.48451733 | Q12: 0.21584828 | R12: 0.32947242 | S12: 0.27802012
A13: features.19 | B13: 0.14175543 | C13: 0.26107213 | D13: 0.23358234 | E13: 0.26198213 | F13: 0.30657297 | G13: 0.31966749 | H13: 0.35022026 | I13: 0.39881644 | J13: 0.44133217 | K13: 0.4687723 | L13: 0.53586574 | M13: 1 | N13: 0.49341888 | O13: 0.48140947 | P13: 0.49334299 | Q13: 0.22391498 | R13: 0.3365535 | S13: 0.3222746
... A19: features.30 | B19: 0.1014402 | C19: 0.22237559 | D19: 0.18828391 | E19: 0.24728718 | F19: 0.25566087 | G19: 0.19770361 | H19: 0.20609307 | I19: 0.14246384 | J19: 0.13796825 | K19: 0.1728567 | L19: 0.27802012 | M19: 0.3222746 | N19: 0.31485861 | O19: 0.40686374 | P19: 0.41542917 | Q19: 0.53441426 | R19: 0.88699356 | S19: 1

Sheet Class_1
B1: features.0 | C1: features.2 | D1: features.4 | E1: features.5 | F1: features.7 | G1: features.9 | H1: features.10 | I1: features.12 | J1: features.14 | K1: features.16 | L1: features.17 | M1: features.19 | N1: features.21 | O1: features.23 | P1: features.24 | Q1: features.26 | R1: features.28 | S1: features.30
A2: features.0 | B2: 1 | C2: 0.29373459 | D2: 0.25745242 | E2: 0.20159647 | F2: 0.25285243 | G2: 0.27985144 | H2: 0.30590597 | I2: 0.22318016 | J2: 0.24571081 | K2: 0.21959723 | L2: 0.082559582 | M2: 0.077791023 | N2: -0.018453496 | O2: -0.039726358 | P2: -0.0326759 | Q2: -0.086935845 | R2: -0.058742324 | S2: -0.10599016
A3: features.2 | B3: 0.29373459 | C3: 1 | D3: 0.63105558 | E3: 0.34298447 | F3: 0.27210659 | G3: 0.23397945 | H3: 0.16262636 | I3: 0.13374909 | J3: 0.11101663 | K3: 0.15066582 | L3: 0.18296686 | M3: 0.19888006 | N3: 0.094754369 | O3: -0.11609945 | P3: 0.095761712 | Q3: -0.006862807 | R3: 0.0017300142 | S3: 0.028475338
A4: features.4 | B4: 0.25745242 | C4: 0.63105558 | D4: 1 | E4: 0.43087384 | F4: 0.24917199 | G4: 0.2430441 | H4: 0.17099466 | I4: 0.1258177 | J4: 0.1086848 | K4: 0.10247539 | L4: 0.17106742 | M4: 0.11659015 | N4: 0.062970976 | O4: -0.093344758 | P4: 0.051419769 | Q4: -0.024970658 | R4: -0.011305207 | S4: -0.0045493052
A5: features.5 | B5: 0.20159647 | C5: 0.34298447 | D5: 0.43087384 | E5: 1 | F5: 0.28642749 | G5: 0.1408517 | H5: 0.10673706 | I5: 0.12203667 | J5: 0.089662736 | K5: 0.042182547 | L5: 0.1891138 | M5: 0.061207575 | N5: 0.13043239 | O5: -0.012713545 | P5: 0.11683317 | Q5: 0.0019969163 | R5: 0.040029888 | S5: 0.067674097
A6: features.7 | B6: 0.25285243 | C6: 0.27210659 | D6: 0.24917199 | E6: 0.28642749 | F6: 1 | G6: 0.58859066 | H6: 0.3874128 | I6: 0.34666383 | J6: 0.38968955 | K6: 0.28517473 | L6: 0.19387386 | M6: 0.37373927 | N6: 0.26268717 | O6: 0.0096909992 | P6: 0.18474873 | Q6: 0.1343272 | R6: 0.086407793 | S6: 0.15472172
A7: features.9 | B7: 0.27985144 | C7: 0.23397945 | D7: 0.2430441 | E7: 0.1408517 | F7: 0.58859066 | G7: 1 | H7: 0.63127772 | I7: 0.51773008 | J7: 0.44051216 | K7: 0.53191659 | L7: 0.23158876 | M7: 0.34150485 | N7: 0.14065166 | O7: 0.086678523 | P7: 0.21751284 | Q7: 0.11440302 | R7: 0.11002061 | S7: 0.10602578
A8: features.10 | B8: 0.30590597 | C8: 0.16262636 | D8: 0.17099466 | E8: 0.10673706 | F8: 0.3874128 | G8: 0.63127772 | H8: 1 | I8: 0.5793998 | J8: 0.47841463 | K8: 0.6590434 | L8: 0.26951276 | M8: 0.22518905 | N8: 0.065290104 | O8: 0.10422983 | P8: 0.23227549 | Q8: 0.060297568 | R8: 0.18467371 | S8: 0.062109113
A9: features.12 | B9: 0.22318016 | C9: 0.13374909 | D9: 0.1258177 | E9: 0.12203667 | F9: 0.34666383 | G9: 0.51773008 | H9: 0.5793998 | I9: 1 | J9: 0.44464204 | K9: 0.55256603 | L9: 0.28780461 | M9: 0.18867983 | N9: 0.14223495 | O9: 0.14777133 | P9: 0.17150836 | Q9: 0.037645593 | R9: 0.12735782 | S9: 0.0078706588
A10: features.14 | B10: 0.24571081 | C10: 0.11101663 | D10: 0.1086848 | E10: 0.089662736 | F10: 0.38968955 | G10: 0.44051216 | H10: 0.47841463 | I10: 0.44464204 | J10: 1 | K10: 0.61989767 | L10: 0.13870925 | M10: 0.27672544 | N10: 0.033882261 | O10: 0.056188925 | P10: 0.035238308 | Q10: -0.11086646 | R10: 0.068126141 | S10: -0.090862481
A11: features.16 | B11: 0.21959723 | C11: 0.15066582 | D11: 0.10247539 | E11: 0.042182547 | F11: 0.28517473 | G11: 0.53191659 | H11: 0.6590434 | I11: 0.55256603 | J11: 0.61989767 | K11: 1 | L11: 0.24442314 | M11: 0.28101582 | N11: 0.06098467 | O11: 0.13483839 | P11: 0.16786805 | Q11: -0.034800095 | R11: 0.13036692 | S11: -0.01893941
A12: features.17 | B12: 0.082559582 | C12: 0.18296686 | D12: 0.17106742 | E12: 0.1891138 | F12: 0.19387386 | G12: 0.23158876 | H12: 0.26951276 | I12: 0.28780461 | J12: 0.13870925 | K12: 0.24442314 | L12: 1 | M12: 0.19941992 | N12: 0.35893377 | O12: 0.18397208 | P12: 0.29038041 | Q12: 0.16006425 | R12: 0.16953049 | S12: 0.17193231
A13: features.19 | B13: 0.077791023 | C13: 0.19888006 | D13: 0.11659015 | E13: 0.061207575 | F13: 0.37373927 | G13: 0.34150485 | H13: 0.22518905 | I13: 0.18867983 | J13: 0.27672544 | K13: 0.28101582 | L13: 0.19941992 | M13: 1 | N13: 0.30216334 | O13: 0.0044331746 | P13: 0.30258297 | Q13: 0.31861495 | R13: 0.2479513 | S13: 0.27098567
... A19: features.30 | B19: -0.10599016 | C19: 0.028475338 | D19: -0.0045493052 | E19: 0.067674097 | F19: 0.15472172 | G19: 0.10602578 | H19: 0.062109113 | I19: 0.0078706588 | J19: -0.090862481 | K19: -0.01893941 | L19: 0.17193231 | M19: 0.27098567 | N19: 0.4059548 | O19: 0.17106036 | P19: 0.50626283 | Q19: 0.54760068 | R19: 0.71523781 | S19: 1

Sheet Class_2
B1: features.0 | C1: features.2 | D1: features.4 | E1: features.5 | F1: features.7 | G1: features.9 | H1: features.10 | I1: features.12 | J1: features.14 | K1: features.16 | L1: features.17 | M1: features.19 | N1: features.21 | O1: features.23 | P1: features.24 | Q1: features.26 | R1: features.28 | S1: features.30
A2: features.0 | B2: 1 | C2: -0.086712228 | D2: -0.10641144 | E2: -0.0036869224 | F2: 0.0095669622 | G2: -0.025290658 | H2: -0.12391104 | I2: -0.104856 | J2: -0.11984025 | K2: -0.11003064 | L2: -0.084560584 | M2: -0.06681008 | N2: -0.088222242 | O2: -0.053886539 | P2: -0.045800944 | Q2: 0.082260656 | R2: -0.072656046 | S2: -0.049743897
A3: features.2 | B3: -0.086712228 | C3: 1 | D3: 0.77389024 | E3: 0.50447819 | F3: 0.20243189 | G3: 0.21504496 | H3: 0.090080296 | I3: 0.010080239 | J3: 0.1282105 | K3: 0.13393667 | L3: 0.17080081 | M3: 0.21401216 | N3: 0.17906015 | O3: 0.21445625 | P3: 0.23744525 | Q3: 0.1108272 | R3: 0.17064201 | S3: 0.086804963
A4: features.4 | B4: -0.10641144 | C4: 0.77389024 | D4: 1 | E4: 0.55858942 | F4: 0.22119186 | G4: 0.19099452 | H4: 0.051141492 | I4: -0.012723926 | J4: 0.12531898 | K4: 0.10678947 | L4: 0.16095832 | M4: 0.23327166 | N4: 0.17548135 | O4: 0.2115671 | P4: 0.25785362 | Q4: 0.13522905 | R4: 0.19332074 | S4: 0.089896006
A5: features.5 | B5: -0.0036869224 | C5: 0.50447819 | D5: 0.55858942 | E5: 1 | F5: 0.32620124 | G5: 0.26973116 | H5: 0.088900394 | I5: 0.048741285 | J5: 0.20098084 | K5: 0.16146872 | L5: 0.21727118 | M5: 0.38254955 | N5: 0.29285178 | O5: 0.34600243 | P5: 0.34157444 | Q5: 0.22224372 | R5: 0.32170236 | S5: 0.17560806
A6: features.7 | B6: 0.0095669622 | C6: 0.20243189 | D6: 0.22119186 | E6: 0.32620124 | F6: 1 | G6: 0.76338944 | H6: 0.3554457 | I6: 0.22546388 | J6: 0.21747645 | K6: 0.2168714 | L6: 0.21998574 | M6: 0.27599567 | N6: 0.15095424 | O6: 0.21556104 | P6: 0.21886297 | Q6: 0.20334276 | R6: 0.17507018 | S6: 0.15383962
