Workbook

Sheet Sheet1
A1: Class | B1: =Class_0!B1 -> Mixed_6e.branch1x1.conv | C1: =Class_0!C1 -> sensitivityscore_After_Mixed_6e.branch1x1.conv_0.5 | D1: =Class_0!D1 -> sensitivityscore_After_Mixed_6e.branch1x1.conv_0.6 | E1: =Class_0!E1 -> sensitivityscore_After_Mixed_6e.branch1x1.conv_0.7 | F1: =Class_0!F1 -> Mixed_6e.branch1x1 | G1: =Class_0!G1 -> Mixed_6e.branch7x7_1.conv | H1: =Class_0!H1 -> sensitivityscore_After_Mixed_6e.branch7x7_1.conv_0.5 | I1: =Class_0!I1 -> sensitivityscore_After_Mixed_6e.branch7x7_1.conv_0.6 | ... BV1: =Class_0!BV1 -> 0
A2: 0 | B2: =Class_0!B43 -> 0.087718433 | C2: =Class_0!C43 -> -0.042802473 | D2: =Class_0!D43 -> 0.0046925785 | E2: =Class_0!E43 -> -0.080351237 | F2: =Class_0!F43 -> 0.25953947 | G2: =Class_0!G43 -> -0.044314856 | H2: =Class_0!H43 -> 0.29303209 | I2: =Class_0!I43 -> 0.35042077 | ... AQ2: =Class_0!AQ43 -> 1
A3: 1 | B3: =Class_1!B43 -> -0.17657219 | C3: =Class_1!C43 -> 0.0010179868 | D3: =Class_1!D43 -> -0.029376092 | E3: =Class_1!E43 -> -0.10767259 | F3: =Class_1!F43 -> -0.20144412 | G3: =Class_1!G43 -> -0.021773693 | H3: =Class_1!H43 -> 0.41097772 | I3: =Class_1!I43 -> 0.077567889 | ... AQ3: =Class_1!AQ43 -> 1
A4: 2 | B4: =Class_2!B43 -> -0.42856716 | C4: =Class_2!C43 -> -0.098487106 | D4: =Class_2!D43 -> -0.12979432 | E4: =Class_2!E43 -> -0.010912593 | F4: =Class_2!F43 -> -0.4681809 | G4: =Class_2!G43 -> -0.15979542 | H4: =Class_2!H43 -> -0.10388173 | I4: =Class_2!I43 -> -0.1061427 | ... AQ4: =Class_2!AQ43 -> 1
A5: 3 | B5: =Class_3!B43 -> 0.050717414 | C5: =Class_3!C43 -> -0.12306337 | D5: =Class_3!D43 -> -0.20626317 | E5: =Class_3!E43 -> -0.093591427 | F5: =Class_3!F43 -> 0.18160791 | G5: =Class_3!G43 -> 0.11974803 | H5: =Class_3!H43 -> -0.16046449 | I5: =Class_3!I43 -> -0.058487543 | ... AQ5: =Class_3!AQ43 -> 1
A6: 4 | B6: =Class_4!B43 -> -0.20834262 | C6: =Class_4!C43 -> -0.074840774 | D6: =Class_4!D43 -> -0.059380956 | E6: =Class_4!E43 -> -0.089618746 | F6: =Class_4!F43 -> -0.023044971 | G6: =Class_4!G43 -> -0.13183005 | H6: =Class_4!H43 -> -0.48152449 | I6: =Class_4!I43 -> -0.31416635 | ... AQ6: =Class_4!AQ43 -> 1
A7: 5 | B7: =Class_5!B43 -> 0.43861552 | C7: =Class_5!C43 -> 0.17804268 | D7: =Class_5!D43 -> -0.061058942 | E7: =Class_5!E43 -> -0.092267512 | F7: =Class_5!F43 -> 0.16274645 | G7: =Class_5!G43 -> 0.096270953 | H7: =Class_5!H43 -> -0.099067442 | I7: =Class_5!I43 -> -0.14207175 | ... AQ7: =Class_5!AQ43 -> 1
A8: 6 | B8: =Class_6!B43 -> 0.015892716 | C8: =Class_6!C43 -> 0.23267605 | D8: =Class_6!D43 -> 0.04428948 | E8: =Class_6!E43 -> 0.081528868 | F8: =Class_6!F43 -> -0.080042555 | G8: =Class_6!G43 -> -0.19629669 | H8: =Class_6!H43 -> 0.029866283 | I8: =Class_6!I43 -> -0.0073953154 | ... AQ8: =Class_6!AQ43 -> 1
A9: 7 | B9: =Class_7!B43 -> 0.46847892 | C9: =Class_7!C43 -> 0.24267336 | D9: =Class_7!D43 -> 0.11038373 | E9: =Class_7!E43 -> -0.02577648 | F9: =Class_7!F43 -> 0.030361241 | G9: =Class_7!G43 -> -0.04386372 | H9: =Class_7!H43 -> 0.26371727 | I9: =Class_7!I43 -> -0.18328669 | ... AQ9: =Class_7!AQ43 -> 1
A10: 8 | B10: =Class_8!B43 -> -0.051629765 | C10: =Class_8!C43 -> -0.083165977 | D10: =Class_8!D43 -> -0.16789829 | E10: =Class_8!E43 -> -0.064988998 | F10: =Class_8!F43 -> 0.037363478 | G10: =Class_8!G43 -> 0.011288055 | H10: =Class_8!H43 -> 0.10277883 | I10: =Class_8!I43 -> 0.1367877 | ... AQ10: =Class_8!AQ43 -> 1
A11: 9 | B11: =Class_9!B43 -> 0.16846475 | C11: =Class_9!C43 -> -0.12255907 | D11: =Class_9!D43 -> 0.059876754 | E11: =Class_9!E43 -> -0.06571216 | F11: =Class_9!F43 -> 0.090351506 | G11: =Class_9!G43 -> 0.16900918 | H11: =Class_9!H43 -> 0.14987395 | I11: =Class_9!I43 -> -0.14538294 | ... AQ11: =Class_9!AQ43 -> 1

Sheet Class_0
B1: Mixed_6e.branch1x1.conv | C1: sensitivityscore_After_Mixed_6e.branch1x1.conv_0.5 | D1: sensitivityscore_After_Mixed_6e.branch1x1.conv_0.6 | E1: sensitivityscore_After_Mixed_6e.branch1x1.conv_0.7 | F1: Mixed_6e.branch1x1 | G1: Mixed_6e.branch7x7_1.conv | H1: sensitivityscore_After_Mixed_6e.branch7x7_1.conv_0.5 | I1: sensitivityscore_After_Mixed_6e.branch7x7_1.conv_0.6 | J1: sensitivityscore_After_Mixed_6e.branch7x7_1.conv_0.7 | K1: Mixed_6e.branch7x7_2.conv | L1: sensitivityscore_After_Mixed_6e.branch7x7_2.conv_0.5 | M1: sensitivityscore_After_Mixed_6e.branch7x7_2.conv_0.6 | N1: sensitivityscore_After_Mixed_6e.branch7x7_2.conv_0.7 | O1: Mixed_6e.branch7x7_3.conv | P1: sensitivityscore_After_Mixed_6e.branch7x7_3.conv_0.5 | Q1: sensitivityscore_After_Mixed_6e.branch7x7_3.conv_0.6 | R1: sensitivityscore_After_Mixed_6e.branch7x7_3.conv_0.7 | S1: Mixed_6e.branch7x7dbl_1.conv | T1: sensitivityscore_After_Mixed_6e.branch7x7dbl_1.conv_0.5 | U1: sensitivityscore_After_Mixed_6e.branch7x7dbl_1.conv_0.6 | V1: sensitivityscore_After_Mixed_6e.branch7x7dbl_1.conv_0.7 | W1: Mixed_7b.branch1x1.conv | X1: sensitivityscore_After_Mixed_7b.branch1x1.conv_0.5 | Y1: sensitivityscore_After_Mixed_7b.branch1x1.conv_0.6 | Z1: sensitivityscore_After_Mixed_7b.branch1x1.conv_0.7 | AA1: Mixed_7b.branch3x3_1.conv | AB1: sensitivityscore_After_Mixed_7b.branch3x3_1.conv_0.5 | AC1: sensitivityscore_After_Mixed_7b.branch3x3_1.conv_0.6 | AD1: sensitivityscore_After_Mixed_7b.branch3x3_1.conv_0.7 | AE1: Mixed_7b.branch3x3_2a.conv | AF1: sensitivityscore_After_Mixed_7b.branch3x3_2a.conv_0.5 | AG1: sensitivityscore_After_Mixed_7b.branch3x3_2a.conv_0.6 | AH1: sensitivityscore_After_Mixed_7b.branch3x3_2a.conv_0.7 | AI1: Mixed_7b.branch3x3_2b.conv | AJ1: sensitivityscore_After_Mixed_7b.branch3x3_2b.conv_0.5 | AK1: sensitivityscore_After_Mixed_7b.branch3x3_2b.conv_0.6 | AL1: sensitivityscore_After_Mixed_7b.branch3x3_2b.conv_0.7 | AM1: Mixed_7b.branch3x3dbl_3a | AN1: Mixed_7b.branch_pool.conv | AO1: sensitivityscore_After_Mixed_7b.branch_pool.conv_0.5 | AP1: sensitivityscore_After_Mixed_7b.branch_pool.conv_0.6 | AQ1: sensitivityscore_After_Mixed_7b.branch_pool.conv_0.7
A2: Mixed_6e.branch1x1.conv | B2: 1 | C2: 0.21841233 | D2: 0.28959344 | E2: 0.17972005 | F2: 0.65803499 | G2: 0.26345245 | H2: -0.17783096 | I2: -0.0098955209 | J2: 0.021441438 | K2: 0.0099158232 | L2: 0.066721763 | M2: 0.31108616 | N2: -0.2296752 | O2: 0.07835724 | P2: -0.027497251 | Q2: 0.17365518 | R2: 0.18890533 | S2: 0.33968332 | T2: -0.19737739 | U2: -0.044845325 | V2: -0.095988933 | W2: 0.085131019 | X2: 0.14861512 | Y2: 0.10245205 | Z2: -0.076933846 | AA2: 0.30945063 | AB2: 0.2937752 | AC2: 0.25259759 | AD2: 0.19459749 | AE2: -0.070395842 | AF2: -0.048097276 | AG2: -0.033416571 | AH2: 0.035059195 | AI2: -0.1373933 | AJ2: 0.042117308 | AK2: 0.030017118 | AL2: 0.14593179 | AM2: 0.21154691 | AN2: 0.160097 | AO2: 0.069457237 | AP2: -0.059993454 | AQ2: 0.087718433
A3: sensitivityscore_After_Mixed_6e.branch1x1.conv_0.5 | B3: 0.21841233 | C3: 1 | D3: 0.63076663 | E3: 0.50016035 | F3: 0.17676134 | G3: -0.063795939 | H3: -0.052691006 | I3: 0.23213439 | J3: 0.2052924 | K3: 0.092319644 | L3: 0.13968798 | M3: 0.31998031 | N3: 0.025145388 | O3: -0.064536702 | P3: 0.14513108 | Q3: 0.049388693 | R3: 0.2394424 | S3: 0.26878327 | T3: -0.06656276 | U3: -0.17095095 | V3: -0.19007616 | W3: 0.10851275 | X3: 0.056137508 | Y3: 0.033464674 | Z3: -0.0087067333 | AA3: 0.24296763 | AB3: 0.21156326 | AC3: 0.28020423 | AD3: -0.055217919 | AE3: 0.26215018 | AF3: -0.082451818 | AG3: -0.040830938 | AH3: -0.0031661515 | AI3: -0.086161169 | AJ3: 0.072376569 | AK3: 0.24046292 | AL3: 0.21915167 | AM3: -0.018091498 | AN3: 0.20536149 | AO3: 0.083397523 | AP3: -0.064735415 | AQ3: -0.042802473
A4: sensitivityscore_After_Mixed_6e.branch1x1.conv_0.6 | B4: 0.28959344 | C4: 0.63076663 | D4: 1 | E4: 0.67026017 | F4: 0.22714165 | G4: -0.073802439 | H4: -0.053890624 | I4: 0.13274566 | J4: -0.052726979 | K4: -0.010190929 | L4: -0.039011957 | M4: 0.23867896 | N4: 0.063779605 | O4: -0.03879137 | P4: 0.16758318 | Q4: 0.14609711 | R4: 0.075345853 | S4: 0.068807401 | T4: -0.10317819 | U4: -0.099702532 | V4: -0.19176232 | W4: 0.015375776 | X4: 0.21288254 | Y4: 0.14845761 | Z4: 0.17591618 | AA4: 0.28178131 | AB4: 0.098783542 | AC4: 0.25739976 | AD4: 0.0039212105 | AE4: 0.09902747 | AF4: 0.056200644 | AG4: 0.15589639 | AH4: 0.062875535 | AI4: 0.023872644 | AJ4: 0.082520285 | AK4: 0.16299489 | AL4: 0.060550091 | AM4: 0.098584951 | AN4: 0.18886774 | AO4: 0.15455229 | AP4: 0.14666114 | AQ4: 0.0046925785
A5: sensitivityscore_After_Mixed_6e.branch1x1.conv_0.7 | B5: 0.17972005 | C5: 0.50016035 | D5: 0.67026017 | E5: 1 | F5: 0.16295473 | G5: -0.10926131 | H5: -0.15641183 | I5: -0.0048178556 | J5: 0.039879448 | K5: 0.064425804 | L5: -0.055472169 | M5: 0.23507584 | N5: -0.074074039 | O5: -0.040446785 | P5: 0.1542382 | Q5: 0.01484802 | R5: 0.031414523 | S5: -0.055308311 | T5: -0.06763399 | U5: -0.094562502 | V5: -0.22433353 | W5: 0.058533696 | X5: -0.10310591 | Y5: -0.12677225 | Z5: 0.029207427 | AA5: 0.35057453 | AB5: -0.072731812 | AC5: 0.1640535 | AD5: 0.089588198 | AE5: 0.21154704 | AF5: 0.098750478 | AG5: 0.20421064 | AH5: 0.26674183 | AI5: 0.080302538 | AJ5: 0.11194638 | AK5: 0.27811451 | AL5: 0.094700539 | AM5: -0.057606578 | AN5: 0.16589456 | AO5: 0.16062342 | AP5: 0.086621004 | AQ5: -0.080351237
A6: Mixed_6e.branch1x1 | B6: 0.65803499 | C6: 0.17676134 | D6: 0.22714165 | E6: 0.16295473 | F6: 1 | G6: 0.15365607 | H6: 0.093636805 | I6: -0.062003908 | J6: 0.063116165 | K6: 0.1743098 | L6: 0.017603944 | M6: 0.13492688 | N6: -0.3041098 | O6: 0.25808454 | P6: -0.078430044 | Q6: 0.16918888 | R6: -0.044515001 | S6: 0.30410917 | T6: -0.011822497 | U6: -0.088308006 | V6: -0.10399249 | W6: 0.056476963 | X6: -0.077899372 | Y6: -0.029541196 | Z6: -0.22778157 | AA6: 0.09979073 | AB6: 0.1634736 | AC6: 0.22623104 | AD6: 0.21034575 | AE6: 0.033425649 | AF6: 0.060226457 | AG6: 0.046104123 | AH6: 0.098573057 | AI6: -0.00034761465 | AJ6: 0.10444688 | AK6: 0.200254 | AL6: 0.17489238 | AM6: 0.061240053 | AN6: -0.12155891 | AO6: 0.32889328 | AP6: 0.29064085 | AQ6: 0.25953947
A7: Mixed_6e.branch7x7_1.conv | B7: 0.26345245 | C7: -0.063795939 | D7: -0.073802439 | E7: -0.10926131 | F7: 0.15365607 | G7: 1 | H7: -0.24302409 | I7: -0.5170457 | J7: -0.15830034 | K7: 0.54898633 | L7: 0.26884006 | M7: 0.1910615 | N7: 0.058142256 | O7: 0.52873919 | P7: 0.077536386 | Q7: 0.064474143 | R7: -0.027701409 | S7: 0.23965109 | T7: 0.047497664 | U7: 0.28199643 | V7: 0.31519885 | W7: -0.10056858 | X7: -0.11467404 | Y7: -0.048385723 | Z7: 0.028073619 | AA7: -0.005671697 | AB7: 0.021750337 | AC7: 0.027640983 | AD7: 0.13163369 | AE7: -0.053597987 | AF7: -0.25294172 | AG7: -0.23388624 | AH7: -0.19122882 | AI7: 0.093508326 | AJ7: 0.057174767 | AK7: 0.080754399 | AL7: 0.073199366 | AM7: 0.10084523 | AN7: 0.083831882 | AO7: 0.16035176 | AP7: -0.10818041 | AQ7: -0.044314856
A8: sensitivityscore_After_Mixed_6e.branch7x7_1.conv_0.5 | B8: -0.17783096 | C8: -0.052691006 | D8: -0.053890624 | E8: -0.15641183 | F8: 0.093636805 | G8: -0.24302409 | H8: 1 | I8: 0.47477825 | J8: 0.28025761 | K8: 0.078018252 | L8: -0.11653452 | M8: -0.14501984 | N8: -0.0033749554 | O8: 0.05781443 | P8: 0.092008432 | Q8: 0.15917499 | R8: 0.010106307 | S8: -0.070111116 | T8: 0.03476969 | U8: -0.055777051 | V8: -0.046308963 | W8: -0.09737761 | X8: 0.1641778 | Y8: 0.10089872 | Z8: 0.043724992 | AA8: -0.21940317 | AB8: 0.09638762 | AC8: -0.080552714 | AD8: -0.24650138 | AE8: 0.032829999 | AF8: 0.32522577 | AG8: 0.32774778 | AH8: 0.13893235 | AI8: -0.14743267 | AJ8: 0.22283723 | AK8: 0.15632378 | AL8: 0.11571689 | AM8: 0.095835155 | AN8: -0.24550406 | AO8: 0.024075122 | AP8: 0.265183 | AQ8: 0.29303209
A9: sensitivityscore_After_Mixed_6e.branch7x7_1.conv_0.6 | B9: -0.0098955209 | C9: 0.23213439 | D9: 0.13274566 | E9: -0.0048178556 | F9: -0.062003908 | G9: -0.5170457 | H9: 0.47477825 | I9: 1 | J9: 0.57117936 | K9: -0.25231844 | L9: -0.10487764 | M9: 0.038325033 | N9: -0.02081494 | O9: -0.11537739 | P9: 0.23264385 | Q9: 0.12999496 | R9: 0.27794794 | S9: 0.086760662 | T9: -0.16570105 | U9: -0.22167921 | V9: -0.14352228 | W9: -0.046370646 | X9: 0.33199077 | Y9: 0.13138901 | Z9: 0.11312831 | AA9: -0.0032124538 | AB9: 0.26660439 | AC9: 0.11188284 | AD9: -0.20115527 | AE9: -0.01982868 | AF9: 0.2472021 | AG9: 0.15237933 | AH9: 0.19711517 | AI9: -0.14506759 | AJ9: 0.12799999 | AK9: 0.20637392 | AL9: 0.32145586 | AM9: -0.042185985 | AN9: -0.10509651 | AO9: 0.11390974 | AP9: 0.31243369 | AQ9: 0.35042077
A10: sensitivityscore_After_Mixed_6e.branch7x7_1.conv_0.7 | B10: 0.021441438 | C10: 0.2052924 | D10: -0.052726979 | E10: 0.039879448 | F10: 0.063116165 | G10: -0.15830034 | H10: 0.28025761 | I10: 0.57117936 | J10: 1 | K10: 0.1216409 | L10: 0.050589409 | M10: 0.14790444 | N10: 0.11014611 | O10: 0.05366744 | P10: 0.17520882 | Q10: 0.10253171 | R10: 0.10437553 | S10: 0.23213048 | T10: -0.055906826 | U10: 0.055926783 | V10: 0.21079674 | W10: 0.048925308 | X10: 0.0096437049 | Y10: 0.020486913 | Z10: -0.027520896 | AA10: -0.086536353 | AB10: 0.19235732 | AC10: 0.019356055 | AD10: -0.0050739995 | AE10: 0.088955889 | AF10: 0.026970782 | AG10: 0.094985858 | AH10: 0.21110315 | AI10: -0.036497073 | AJ10: 0.010514547 | AK10: 0.1975663 | AL10: 0.27952407 | AM10: -0.087266271 | AN10: -0.12337316 | AO10: 0.17665512 | AP10: 0.12421418 | AQ10: 0.31934609
A11: Mixed_6e.branch7x7_2.conv | B11: 0.0099158232 | C11: 0.092319644 | D11: -0.010190929 | E11: 0.064425804 | F11: 0.1743098 | G11: 0.54898633 | H11: 0.078018252 | I11: -0.25231844 | J11: 0.1216409 | K11: 1 | L11: 0.20820319 | M11: 0.042295715 | N11: -0.014518352 | O11: 0.74047251 | P11: 0.042041318 | Q11: 0.047375875 | R11: -0.26349684 | S11: 0.10901868 | T11: 0.074439351 | U11: 0.20607041 | V11: 0.24133413 | W11: 0.053912323 | X11: -0.4164928 | Y11: -0.45070125 | Z11: -0.38297587 | AA11: -0.33541501 | AB11: -0.19628603 | AC11: -0.086958174 | AD11: 0.033749459 | AE11: 0.078712579 | AF11: 0.065429787 | AG11: 0.0068927173 | AH11: 0.034837242 | AI11: -0.1606771 | AJ11: 0.12651732 | AK11: 0.152493 | AL11: -0.038967817 | AM11: 0.13373247 | AN11: -0.055241822 | AO11: 0.13543822 | AP11: 0.10061646 | AQ11: 0.073517659
A12: sensitivityscore_After_Mixed_6e.branch7x7_2.conv_0.5 | B12: 0.066721763 | C12: 0.13968798 | D12: -0.039011957 | E12: -0.055472169 | F12: 0.017603944 | G12: 0.26884006 | H12: -0.11653452 | I12: -0.10487764 | J12: 0.050589409 | K12: 0.20820319 | L12: 1 | M12: 0.57379057 | N12: 0.33106519 | O12: 0.22715844 | P12: 0.20179184 | Q12: 0.081268892 | R12: 0.14033405 | S12: 0.093890133 | T12: 0.196994 | U12: 0.12006319 | V12: 0.023697867 | W12: 0.076357816 | X12: -0.18852628 | Y12: 0.064049802 | Z12: -0.11203668 | AA12: -0.037817291 | AB12: 0.041169697 | AC12: -0.15957063 | AD12: -0.048623393 | AE12: 0.018526181 | AF12: -0.10012445 | AG12: -0.2518768 | AH12: -0.033211811 | AI12: -0.017236144 | AJ12: 0.051967367 | AK12: -0.16182989 | AL12: -0.19650966 | AM12: 0.034278511 | AN12: -0.028720088 | AO12: 0.018618175 | AP12: -0.16185256 | AQ12: -0.14300901
A13: sensitivityscore_After_Mixed_6e.branch7x7_2.conv_0.6 | B13: 0.31108616 | C13: 0.31998031 | D13: 0.23867896 | E13: 0.23507584 | F13: 0.13492688 | G13: 0.1910615 | H13: -0.14501984 | I13: 0.038325033 | J13: 0.14790444 | K13: 0.042295715 | L13: 0.57379057 | M13: 1 | N13: 0.23873924 | O13: 0.12066005 | P13: 0.42421718 | Q13: 0.36223008 | R13: 0.2020245 | S13: 0.27816257 | T13: -0.057558626 | U13: -0.06344447 | V13: -0.082750583 | W13: 0.16898325 | X13: -0.087721669 | Y13: 0.078947316 | Z13: -0.053203196 | AA13: 0.079094358 | AB13: 0.38696494 | AC13: 0.12696785 | AD13: 0.011056255 | AE13: 0.1787394 | AF13: -0.15802484 | AG13: -0.081531718 | AH13: -0.045927966 | AI13: 0.036987803 | AJ13: 0.083369127 | AK13: 0.1064802 | AL13: 0.037699057 | AM13: -0.081272722 | AN13: 0.070011073 | AO13: 0.025239357 | AP13: -0.12106768 | AQ13: -0.14558326
... A43: sensitivityscore_After_Mixed_7b.branch_pool.conv_0.7 | B43: 0.087718433 | C43: -0.042802473 | D43: 0.0046925785 | E43: -0.080351237 | F43: 0.25953947 | G43: -0.044314856 | H43: 0.29303209 | I43: 0.35042077 | J43: 0.31934609 | K43: 0.073517659 | L43: -0.14300901 | M43: -0.14558326 | N43: -0.07786144 | O43: 0.21983248 | P43: 0.16915798 | Q43: 0.33486323 | R43: 0.0042658563 | S43: -0.057037414 | T43: -0.068535255 | U43: 0.006658497 | V43: 0.10881701 | W43: -0.040663572 | X43: 0.14282318 | Y43: 0.041838295 | Z43: -0.25634745 | AA43: -0.19011361 | AB43: 0.27555968 | AC43: 0.43013708 | AD43: 0.22582141 | AE43: -0.15716091 | AF43: 0.20415634 | AG43: 0.0075133282 | AH43: -0.0052082803 | AI43: 0.19868286 | AJ43: 0.21591458 | AK43: 0.30121742 | AL43: 0.29295759 | AM43: -0.012761631 | AN43: -0.38936769 | AO43: 0.55398082 | AP43: 0.65649075 | AQ43: 1

Sheet Class_1
B1: Mixed_6e.branch1x1.conv | C1: sensitivityscore_After_Mixed_6e.branch1x1.conv_0.5 | D1: sensitivityscore_After_Mixed_6e.branch1x1.conv_0.6 | E1: sensitivityscore_After_Mixed_6e.branch1x1.conv_0.7 | F1: Mixed_6e.branch1x1 | G1: Mixed_6e.branch7x7_1.conv | H1: sensitivityscore_After_Mixed_6e.branch7x7_1.conv_0.5 | I1: sensitivityscore_After_Mixed_6e.branch7x7_1.conv_0.6 | J1: sensitivityscore_After_Mixed_6e.branch7x7_1.conv_0.7 | K1: Mixed_6e.branch7x7_2.conv | L1: sensitivityscore_After_Mixed_6e.branch7x7_2.conv_0.5 | M1: sensitivityscore_After_Mixed_6e.branch7x7_2.conv_0.6 | N1: sensitivityscore_After_Mixed_6e.branch7x7_2.conv_0.7 | O1: Mixed_6e.branch7x7_3.conv | P1: sensitivityscore_After_Mixed_6e.branch7x7_3.conv_0.5 | Q1: sensitivityscore_After_Mixed_6e.branch7x7_3.conv_0.6 | R1: sensitivityscore_After_Mixed_6e.branch7x7_3.conv_0.7 | S1: Mixed_6e.branch7x7dbl_1.conv | T1: sensitivityscore_After_Mixed_6e.branch7x7dbl_1.conv_0.5 | U1: sensitivityscore_After_Mixed_6e.branch7x7dbl_1.conv_0.6 | V1: sensitivityscore_After_Mixed_6e.branch7x7dbl_1.conv_0.7 | W1: Mixed_7b.branch1x1.conv | X1: sensitivityscore_After_Mixed_7b.branch1x1.conv_0.5 | Y1: sensitivityscore_After_Mixed_7b.branch1x1.conv_0.6 | Z1: sensitivityscore_After_Mixed_7b.branch1x1.conv_0.7 | AA1: Mixed_7b.branch3x3_1.conv | AB1: sensitivityscore_After_Mixed_7b.branch3x3_1.conv_0.5 | AC1: sensitivityscore_After_Mixed_7b.branch3x3_1.conv_0.6 | AD1: sensitivityscore_After_Mixed_7b.branch3x3_1.conv_0.7 | AE1: Mixed_7b.branch3x3_2a.conv | AF1: sensitivityscore_After_Mixed_7b.branch3x3_2a.conv_0.5 | AG1: sensitivityscore_After_Mixed_7b.branch3x3_2a.conv_0.6 | AH1: sensitivityscore_After_Mixed_7b.branch3x3_2a.conv_0.7 | AI1: Mixed_7b.branch3x3_2b.conv | AJ1: sensitivityscore_After_Mixed_7b.branch3x3_2b.conv_0.5 | AK1: sensitivityscore_After_Mixed_7b.branch3x3_2b.conv_0.6 | AL1: sensitivityscore_After_Mixed_7b.branch3x3_2b.conv_0.7 | AM1: Mixed_7b.branch3x3dbl_3a | AN1: Mixed_7b.branch_pool.conv | AO1: sensitivityscore_After_Mixed_7b.branch_pool.conv_0.5 | AP1: sensitivityscore_After_Mixed_7b.branch_pool.conv_0.6 | AQ1: sensitivityscore_After_Mixed_7b.branch_pool.conv_0.7
A2: Mixed_6e.branch1x1.conv | B2: 1 | C2: -0.073709359 | D2: -0.10248636 | E2: -0.083277367 | F2: 0.59514506 | G2: 0.045961501 | H2: 0.22352718 | I2: -0.004970126 | J2: -0.010423182 | K2: 0.0099848076 | L2: 0.1447692 | M2: 0.13721981 | N2: -0.33286997 | O2: -0.071130221 | P2: -0.12935588 | Q2: -0.00064073336 | R2: 0.22031262 | S2: 0.1362065 | T2: 0.042852437 | U2: 0.0068663469 | V2: 0.070276331 | W2: 0.47767338 | X2: -0.24467039 | Y2: -0.16469921 | Z2: -0.020728998 | AA2: 0.23669908 | AB2: -0.083998998 | AC2: -0.12879618 | AD2: -0.25928373 | AE2: 0.22783677 | AF2: 0.22725099 | AG2: 0.18309791 | AH2: 0.14755651 | AI2: 0.30805669 | AJ2: -0.15613678 | AK2: -0.067072162 | AL2: 0.0039372698 | AM2: -0.1519195 | AN2: 0.28313381 | AO2: -0.25876186 | AP2: -0.24696306 | AQ2: -0.17657219
A3: sensitivityscore_After_Mixed_6e.branch1x1.conv_0.5 | B3: -0.073709359 | C3: 1 | D3: 0.6784882 | E3: 0.65007185 | F3: 0.0097106142 | G3: -0.2212527 | H3: 0.15580485 | I3: 0.00047676241 | J3: -0.075648613 | K3: -0.27130102 | L3: -0.16286582 | M3: 0.040531815 | N3: -0.13468345 | O3: -0.28011064 | P3: -0.027128211 | Q3: -0.023421724 | R3: -0.150807 | S3: -0.0090908076 | T3: -0.043561396 | U3: -0.13699712 | V3: -0.23560894 | W3: 0.10842094 | X3: 0.16020646 | Y3: 0.099933198 | Z3: 0.089646826 | AA3: 0.11693749 | AB3: -0.12512657 | AC3: -0.065053623 | AD3: 0.050408733 | AE3: -0.094738963 | AF3: -0.004225076 | AG3: -0.11832893 | AH3: 0.05282151 | AI3: 0.011255877 | AJ3: -0.045994467 | AK3: 0.055198733 | AL3: -0.071520922 | AM3: 0.34317243 | AN3: -0.0058912299 | AO3: -0.018034753 | AP3: -0.12310175 | AQ3: 0.0010179868
A4: sensitivityscore_After_Mixed_6e.branch1x1.conv_0.6 | B4: -0.10248636 | C4: 0.6784882 | D4: 1 | E4: 0.71509024 | F4: 0.090340408 | G4: -0.23830398 | H4: 0.20149252 | I4: 0.12346465 | J4: 0.073591876 | K4: -0.18474737 | L4: -0.289731 | M4: -0.13452252 | N4: -0.035867178 | O4: -0.19313257 | P4: -0.23712712 | Q4: -0.14034417 | R4: -0.38453568 | S4: -0.16050107 | T4: -0.094556139 | U4: -0.10253034 | V4: -0.090507249 | W4: -0.013206093 | X4: 0.1788554 | Y4: 0.064052691 | Z4: -0.14972537 | AA4: 0.065918019 | AB4: -0.14123968 | AC4: 0.029084627 | AD4: -0.0041027788 | AE4: 0.0080629856 | AF4: -0.1681146 | AG4: -0.11950695 | AH4: 0.13465774 | AI4: -0.022855815 | AJ4: 0.046244156 | AK4: 0.094381466 | AL4: -0.01979265 | AM4: 0.26177479 | AN4: 0.058884727 | AO4: 0.05934465 | AP4: -0.036600038 | AQ4: -0.029376092
A5: sensitivityscore_After_Mixed_6e.branch1x1.conv_0.7 | B5: -0.083277367 | C5: 0.65007185 | D5: 0.71509024 | E5: 1 | F5: 0.074292046 | G5: -0.32243979 | H5: 0.12957559 | I5: 0.081305636 | J5: 0.04597585 | K5: -0.39191835 | L5: -0.18347139 | M5: -0.17325736 | N5: -0.045216271 | O5: -0.43676022 | P5: -0.23607205 | Q5: -0.10524628 | R5: -0.1060937 | S5: -0.039113372 | T5: -0.10894368 | U5: 0.0335837 | V5: -0.2044215 | W5: -0.080234006 | X5: 0.20136275 | Y5: 0.13394071 | Z5: 0.052943045 | AA5: 0.0068247082 | AB5: -0.15878278 | AC5: 0.081569032 | AD5: 0.12051953 | AE5: -0.074675226 | AF5: -0.061662284 | AG5: -0.032484348 | AH5: 0.14833731 | AI5: -0.10465235 | AJ5: 0.0076688302 | AK5: 0.069147767 | AL5: -0.11067828 | AM5: 0.25721933 | AN5: 0.14168707 | AO5: -0.083929326 | AP5: -0.12575904 | AQ5: -0.10767259
A6: Mixed_6e.branch1x1 | B6: 0.59514506 | C6: 0.0097106142 | D6: 0.090340408 | E6: 0.074292046 | F6: 1 | G6: -0.13673914 | H6: 0.21308784 | I6: 0.20483786 | J6: -0.057441234 | K6: -0.1296456 | L6: 0.19047332 | M6: 0.17912449 | N6: -0.24040057 | O6: -0.16838577 | P6: -0.23740383 | Q6: -0.084467792 | R6: 0.021254759 | S6: 0.1851698 | T6: 0.12414443 | U6: 0.030079877 | V6: -0.085139657 | W6: 0.22787318 | X6: -0.21243539 | Y6: -0.044995156 | Z6: 0.022216743 | AA6: 0.085570484 | AB6: 0.043713592 | AC6: -0.0060986468 | AD6: -0.12517594 | AE6: 0.050214252 | AF6: 0.13069339 | AG6: -0.0043673596 | AH6: 0.16064453 | AI6: -0.069167639 | AJ6: -0.059153734 | AK6: -0.0044688154 | AL6: -0.021727451 | AM6: -0.16538483 | AN6: 0.22903077 | AO6: -0.32625872 | AP6: -0.31876922 | AQ6: -0.20144412
A7: Mixed_6e.branch7x7_1.conv | B7: 0.045961501 | C7: -0.2212527 | D7: -0.23830398 | E7: -0.32243979 | F7: -0.13673914 | G7: 1 | H7: -0.025941008 | I7: 0.10886842 | J7: 0.2940948 | K7: 0.73407803 | L7: 0.17230671 | M7: 0.099005163 | N7: -0.027067536 | O7: 0.65689584 | P7: -0.2426908 | Q7: 0.063246115 | R7: 0.19662506 | S7: 0.34076686 | T7: -0.15650946 | U7: 0.15345814 | V7: 0.21916736 | W7: -0.083006758 | X7: -0.20877045 | Y7: -0.21248954 | Z7: -0.24454444 | AA7: -0.012959909 | AB7: 0.24902857 | AC7: -0.19997148 | AD7: -0.13490619 | AE7: 0.27219402 | AF7: 0.044586505 | AG7: 0.062152502 | AH7: -0.091883543 | AI7: 0.0054126426 | AJ7: 0.045220478 | AK7: -0.17052318 | AL7: -0.12027992 | AM7: -0.28285105 | AN7: -0.024702805 | AO7: -0.087557809 | AP7: 0.051760164 | AQ7: -0.021773693
A8: sensitivityscore_After_Mixed_6e.branch7x7_1.conv_0.5 | B8: 0.22352718 | C8: 0.15580485 | D8: 0.20149252 | E8: 0.12957559 | F8: 0.21308784 | G8: -0.025941008 | H8: 1 | I8: 0.5568079 | J8: 0.33371985 | K8: 0.19473921 | L8: 0.18969605 | M8: 0.3755192 | N8: 0.16866624 | O8: 0.19023142 | P8: 0.10042368 | Q8: 0.4001442 | R8: 0.24532793 | S8: 0.35472979 | T8: 0.24570122 | U8: 0.29694187 | V8: 0.1285376 | W8: 0.040629607 | X8: -0.33140385 | Y8: -0.45698889 | Z8: -0.43732893 | AA8: 0.094157254 | AB8: 0.20843063 | AC8: -0.2052123 | AD8: -0.18568941 | AE8: 0.42570996 | AF8: 0.51026327 | AG8: 0.31318941 | AH8: 0.29144155 | AI8: -0.041113591 | AJ8: 0.061917186 | AK8: 0.17078552 | AL8: 0.091951485 | AM8: -0.17537206 | AN8: -0.1350295 | AO8: 0.17291552 | AP8: 0.26776954 | AQ8: 0.41097772
A9: sensitivityscore_After_Mixed_6e.branch7x7_1.conv_0.6 | B9: -0.004970126 | C9: 0.00047676241 | D9: 0.12346465 | E9: 0.081305636 | F9: 0.20483786 | G9: 0.10886842 | H9: 0.5568079 | I9: 1 | J9: 0.65836122 | K9: 0.16926351 | L9: 0.37322229 | M9: 0.3475588 | N9: 0.32734286 | O9: 0.21687689 | P9: -0.0099468152 | Q9: 0.31386389 | R9: 0.26544153 | S9: 0.26830937 | T9: 0.20223695 | U9: 0.31692086 | V9: -0.010463917 | W9: -0.25127228 | X9: -0.29002805 | Y9: -0.33840695 | Z9: -0.28127229 | AA9: 0.060299745 | AB9: 0.36954984 | AC9: 0.11476077 | AD9: 0.1411381 | AE9: 0.26841338 | AF9: 0.39261156 | AG9: 0.29719748 | AH9: 0.40669798 | AI9: -0.22859147 | AJ9: 0.25822191 | AK9: 0.26898325 | AL9: 0.19978969 | AM9: -0.3789025 | AN9: 0.027946682 | AO9: -0.02601598 | AP9: -0.012018071 | AQ9: 0.077567889
A10: sensitivityscore_After_Mixed_6e.branch7x7_1.conv_0.7 | B10: -0.010423182 | C10: -0.075648613 | D10: 0.073591876 | E10: 0.04597585 | F10: -0.057441234 | G10: 0.2940948 | H10: 0.33371985 | I10: 0.65836122 | J10: 1 | K10: 0.28628751 | L10: 0.081984683 | M10: 0.16335167 | N10: 0.31700608 | O10: 0.25437693 | P10: -0.23555626 | Q10: 0.16644404 | R10: 0.26549851 | S10: 0.20331266 | T10: 0.16506729 | U10: 0.32728124 | V10: -0.049473472 | W10: -0.30042761 | X10: -0.15624994 | Y10: -0.17622602 | Z10: -0.17859538 | AA10: 0.0677122 | AB10: 0.31946447 | AC10: -0.034501582 | AD10: 0.10248746 | AE10: 0.28839781 | AF10: 0.23151492 | AG10: 0.19753116 | AH10: 0.30833865 | AI10: -0.12100322 | AJ10: -0.020462197 | AK10: 0.0018429217 | AL10: -0.010502189 | AM10: -0.39082677 | AN10: 0.030655896 | AO10: 0.020075959 | AP10: 0.16224555 | AQ10: 0.1829676
A11: Mixed_6e.branch7x7_2.conv | B11: 0.0099848076 | C11: -0.27130102 | D11: -0.18474737 | E11: -0.39191835 | F11: -0.1296456 | G11: 0.73407803 | H11: 0.19473921 | I11: 0.16926351 | J11: 0.28628751 | K11: 1 | L11: 0.17174204 | M11: 0.13945678 | N11: 0.095306946 | O11: 0.86194878 | P11: -0.17973226 | Q11: 0.25808363 | R11: 0.24337369 | S11: 0.37392073 | T11: -0.019599218 | U11: 0.25994604 | V11: 0.3774947 | W11: 0.055883034 | X11: -0.33747573 | Y11: -0.35522517 | Z11: -0.41160505 | AA11: -0.14053499 | AB11: 0.20723298 | AC11: -0.23162406 | AD11: -0.12222356 | AE11: 0.36427951 | AF11: 0.16541968 | AG11: 0.082281039 | AH11: -0.15706274 | AI11: -0.075385659 | AJ11: 0.095133126 | AK11: -0.05288881 | AL11: 0.056276046 | AM11: -0.34385114 | AN11: -0.01932878 | AO11: 0.14887515 | AP11: 0.30835909 | AQ11: 0.33355253
A12: sensitivityscore_After_Mixed_6e.branch7x7_2.conv_0.5 | B12: 0.1447692 | C12: -0.16286582 | D12: -0.289731 | E12: -0.18347139 | F12: 0.19047332 | G12: 0.17230671 | H12: 0.18969605 | I12: 0.37322229 | J12: 0.081984683 | K12: 0.17174204 | L12: 1 | M12: 0.72008481 | N12: 0.17028713 | O12: 0.3212506 | P12: 0.25141313 | Q12: 0.39912685 | R12: 0.48664654 | S12: 0.24208372 | T12: 0.13349844 | U12: 0.22553114 | V12: 0.1637835 | W12: 0.096033059 | X12: -0.54495309 | Y12: -0.4843574 | Z12: -0.26400362 | AA12: 0.03897152 | AB12: 0.14146358 | AC12: 0.11814932 | AD12: 0.048153253 | AE12: 0.10077465 | AF12: 0.35278512 | AG12: 0.22367171 | AH12: 0.20055069 | AI12: -0.024779196 | AJ12: 0.26047429 | AK12: 0.30331387 | AL12: 0.22864279 | AM12: -0.28718229 | AN12: -0.10088353 | AO12: -0.27565225 | AP12: -0.33635791 | AQ12: -0.11796549
A13: sensitivityscore_After_Mixed_6e.branch7x7_2.conv_0.6 | B13: 0.13721981 | C13: 0.040531815 | D13: -0.13452252 | E13: -0.17325736 | F13: 0.17912449 | G13: 0.099005163 | H13: 0.3755192 | I13: 0.3475588 | J13: 0.16335167 | K13: 0.13945678 | L13: 0.72008481 | M13: 1 | N13: 0.29232449 | O13: 0.21359797 | P13: 0.31675977 | Q13: 0.27958285 | R13: 0.3612829 | S13: 0.27529831 | T13: 0.25638613 | U13: 0.23315227 | V13: 0.08438141 | W13: 0.075187951 | X13: -0.53896109 | Y13: -0.50191033 | Z13: -0.3387367 | AA13: 0.049960128 | AB13: 0.27594039 | AC13: 0.086615214 | AD13: 0.07848183 | AE13: 0.15979969 | AF13: 0.37797727 | AG13: 0.21542045 | AH13: 0.33295262 | AI13: -0.05966588 | AJ13: 0.19526158 | AK13: 0.153995 | AL13: 0.15397903 | AM13: -0.28693279 | AN13: -0.21773527 | AO13: -0.22455954 | AP13: -0.3115769 | AQ13: -0.020576338
... A43: sensitivityscore_After_Mixed_7b.branch_pool.conv_0.7 | B43: -0.17657219 | C43: 0.0010179868 | D43: -0.029376092 | E43: -0.10767259 | F43: -0.20144412 | G43: -0.021773693 | H43: 0.41097772 | I43: 0.077567889 | J43: 0.1829676 | K43: 0.33355253 | L43: -0.11796549 | M43: -0.020576338 | N43: 0.12393169 | O43: 0.36796535 | P43: -0.04066048 | Q43: 0.14530311 | R43: 0.10865922 | S43: 0.14867531 | T43: 0.15845911 | U43: 0.14221649 | V43: 0.19972041 | W43: -0.063431869 | X43: -0.060673006 | Y43: -0.1739042 | Z43: -0.28196993 | AA43: 0.16053996 | AB43: -0.02556923 | AC43: -0.33225227 | AD43: -0.26763286 | AE43: 0.43216063 | AF43: 0.24187039 | AG43: 0.096009596 | AH43: -0.026675636 | AI43: 0.087841313 | AJ43: 0.032632993 | AK43: 0.033495522 | AL43: 0.10207839 | AM43: 0.022427681 | AN43: 0.040338288 | AO43: 0.79541355 | AP43: 0.80880208 | AQ43: 1

Sheet Class_2
B1: Mixed_6e.branch1x1.conv | C1: sensitivityscore_After_Mixed_6e.branch1x1.conv_0.5 | D1: sensitivityscore_After_Mixed_6e.branch1x1.conv_0.6 | E1: sensitivityscore_After_Mixed_6e.branch1x1.conv_0.7 | F1: Mixed_6e.branch1x1 | G1: Mixed_6e.branch7x7_1.conv | H1: sensitivityscore_After_Mixed_6e.branch7x7_1.conv_0.5 | I1: sensitivityscore_After_Mixed_6e.branch7x7_1.conv_0.6 | J1: sensitivityscore_After_Mixed_6e.branch7x7_1.conv_0.7 | K1: Mixed_6e.branch7x7_2.conv | L1: sensitivityscore_After_Mixed_6e.branch7x7_2.conv_0.5 | M1: sensitivityscore_After_Mixed_6e.branch7x7_2.conv_0.6 | N1: sensitivityscore_After_Mixed_6e.branch7x7_2.conv_0.7 | O1: Mixed_6e.branch7x7_3.conv | P1: sensitivityscore_After_Mixed_6e.branch7x7_3.conv_0.5 | Q1: sensitivityscore_After_Mixed_6e.branch7x7_3.conv_0.6 | R1: sensitivityscore_After_Mixed_6e.branch7x7_3.conv_0.7 | S1: Mixed_6e.branch7x7dbl_1.conv | T1: sensitivityscore_After_Mixed_6e.branch7x7dbl_1.conv_0.5 | U1: sensitivityscore_After_Mixed_6e.branch7x7dbl_1.conv_0.6 | V1: sensitivityscore_After_Mixed_6e.branch7x7dbl_1.conv_0.7 | W1: Mixed_7b.branch1x1.conv | X1: sensitivityscore_After_Mixed_7b.branch1x1.conv_0.5 | Y1: sensitivityscore_After_Mixed_7b.branch1x1.conv_0.6 | Z1: sensitivityscore_After_Mixed_7b.branch1x1.conv_0.7 | AA1: Mixed_7b.branch3x3_1.conv | AB1: sensitivityscore_After_Mixed_7b.branch3x3_1.conv_0.5 | AC1: sensitivityscore_After_Mixed_7b.branch3x3_1.conv_0.6 | AD1: sensitivityscore_After_Mixed_7b.branch3x3_1.conv_0.7 | AE1: Mixed_7b.branch3x3_2a.conv | AF1: sensitivityscore_After_Mixed_7b.branch3x3_2a.conv_0.5 | AG1: sensitivityscore_After_Mixed_7b.branch3x3_2a.conv_0.6 | AH1: sensitivityscore_After_Mixed_7b.branch3x3_2a.conv_0.7 | AI1: Mixed_7b.branch3x3_2b.conv | AJ1: sensitivityscore_After_Mixed_7b.branch3x3_2b.conv_0.5 | AK1: sensitivityscore_After_Mixed_7b.branch3x3_2b.conv_0.6 | AL1: sensitivityscore_After_Mixed_7b.branch3x3_2b.conv_0.7 | AM1: Mixed_7b.branch3x3dbl_3a | AN1: Mixed_7b.branch_pool.conv | AO1: sensitivityscore_After_Mixed_7b.branch_pool.conv_0.5 | AP1: sensitivityscore_After_Mixed_7b.branch_pool.conv_0.6 | AQ1: sensitivityscore_After_Mixed_7b.branch_pool.conv_0.7
A2: Mixed_6e.branch1x1.conv | B2: 1 | C2: 0.16151561 | D2: 0.1355541 | E2: -0.14397005 | F2: 0.50996606 | G2: 0.12129679 | H2: 0.035468233 | I2: -0.11174963 | J2: 0.099354526 | K2: 0.11120931 | L2: -0.081436924 | M2: -0.080078868 | N2: 0.24831749 | O2: 0.0019921793 | P2: -0.2414753 | Q2: -0.14888767 | R2: 0.043285319 | S2: 0.16740816 | T2: -0.10643597 | U2: 0.0043348108 | V2: -0.070516618 | W2: -0.14926492 | X2: 0.1195231 | Y2: 0.11795855 | Z2: 0.1223384 | AA2: -0.040414101 | AB2: 0.21183298 | AC2: 0.14955674 | AD2: 0.14051515 | AE2: -0.060532968 | AF2: -0.080729239 | AG2: 0.17903067 | AH2: 0.098458079 | AI2: -0.099982003 | AJ2: -0.043003278 | AK2: 0.097913785 | AL2: 0.13567642 | AM2: 0.043481407 | AN2: 0.21228165 | AO2: -0.46264771 | AP2: -0.39398173 | AQ2: -0.42856716
A3: sensitivityscore_After_Mixed_6e.branch1x1.conv_0.5 | B3: 0.16151561 | C3: 1 | D3: 0.57872557 | E3: 0.48339689 | F3: -0.1139252 | G3: -0.059634252 | H3: -0.014053574 | I3: -0.01770576 | J3: 0.041917822 | K3: -0.018664238 | L3: -0.17538311 | M3: 0.20976897 | N3: -0.15826904 | O3: 0.0089928171 | P3: -0.17679733 | Q3: 0.037482029 | R3: 0.016792236 | S3: 0.057527511 | T3: -0.17317219 | U3: -0.21525911 | V3: 0.018562149 | W3: -0.1390572 | X3: -0.0061136969 | Y3: 0.075383332 | Z3: 0.051972047 | AA3: -0.046966755 | AB3: 0.08929136 | AC3: 0.066277202 | AD3: -0.10516593 | AE3: -0.074289465 | AF3: -0.11854866 | AG3: 0.10681009 | AH3: 0.081614498 | AI3: -0.09033701 | AJ3: 0.098945586 | AK3: 0.080050783 | AL3: -0.066205212 | AM3: -0.072965293 | AN3: -0.010537183 | AO3: -0.14035424 | AP3: -0.11836771 | AQ3: -0.098487106
A4: sensitivityscore_After_Mixed_6e.branch1x1.conv_0.6 | B4: 0.1355541 | C4: 0.57872557 | D4: 1 | E4: 0.61212171 | F4: -0.055362455 | G4: 0.1141794 | H4: -0.24590631 | I4: -0.21785756 | J4: -0.10294056 | K4: 0.005118763 | L4: -0.25326067 | M4: 0.10712545 | N4: -0.063240997 | O4: 0.1136688 | P4: -0.28109279 | Q4: -0.13339386 | R4: 0.084378774 | S4: 0.18100983 | T4: -0.1134028 | U4: -0.10839106 | V4: -0.0081210617 | W4: -0.14997195 | X4: -0.014561866 | Y4: -0.029416368 | Z4: -0.097059543 | AA4: 0.020876904 | AB4: -0.007087444 | AC4: 0.02497406 | AD4: -0.086014394 | AE4: -0.064820015 | AF4: -0.1584071 | AG4: 0.28857342 | AH4: 0.16531582 | AI4: 0.028757117 | AJ4: -0.00087581809 | AK4: 0.15262699 | AL4: 0.041806199 | AM4: -0.069483772 | AN4: 0.10549171 | AO4: -0.10054398 | AP4: -0.24313535 | AQ4: -0.12979432
A5: sensitivityscore_After_Mixed_6e.branch1x1.conv_0.7 | B5: -0.14397005 | C5: 0.48339689 | D5: 0.61212171 | E5: 1 | F5: -0.17588438 | G5: -0.021303409 | H5: -0.40636601 | I5: -0.15461586 | J5: -0.15717526 | K5: -0.032338848 | L5: 0.015763149 | M5: 0.08134046 | N5: -0.16102153 | O5: -0.052066913 | P5: 0.031859193 | Q5: 0.078359632 | R5: 0.20288908 | S5: 0.23533853 | T5: -0.22858743 | U5: -0.00077096958 | V5: 0.045102645 | W5: -0.041337466 | X5: -0.038039757 | Y5: -0.069366703 | Z5: -0.066418419 | AA5: 0.020865568 | AB5: 0.050472701 | AC5: 0.03646444 | AD5: -0.097008762 | AE5: -0.1260368 | AF5: -0.030613489 | AG5: 0.095746843 | AH5: 0.01038363 | AI5: 0.15826161 | AJ5: 0.099844673 | AK5: 0.28155911 | AL5: 0.17710098 | AM5: -0.095029244 | AN5: -0.12619214 | AO5: 0.071105594 | AP5: -0.11562726 | AQ5: -0.010912593
A6: Mixed_6e.branch1x1 | B6: 0.50996606 | C6: -0.1139252 | D6: -0.055362455 | E6: -0.17588438 | F6: 1 | G6: 0.055900339 | H6: 0.14119406 | I6: 0.029123413 | J6: 0.19977279 | K6: 0.14024414 | L6: -0.058722549 | M6: 0.051626868 | N6: 0.12824256 | O6: 0.0060209789 | P6: 0.037229887 | Q6: -0.12915748 | R6: 0.019454742 | S6: 0.30202741 | T6: -0.12365986 | U6: -0.0081199624 | V6: -0.059490713 | W6: -0.12906768 | X6: 0.095771669 | Y6: 0.1547849 | Z6: 0.22098077 | AA6: -0.20514821 | AB6: 0.20204461 | AC6: 0.2441007 | AD6: 0.30937945 | AE6: -0.042489836 | AF6: 0.024059843 | AG6: 0.058702452 | AH6: 0.022893205 | AI6: -0.030960266 | AJ6: -0.045154748 | AK6: 0.056137892 | AL6: -0.052332031 | AM6: -0.015983702 | AN6: 0.12877383 | AO6: -0.4861254 | AP6: -0.41568452 | AQ6: -0.4681809
A7: Mixed_6e.branch7x7_1.conv | B7: 0.12129679 | C7: -0.059634252 | D7: 0.1141794 | E7: -0.021303409 | F7: 0.055900339 | G7: 1 | H7: -0.14056114 | I7: -0.095665288 | J7: -0.076031944 | K7: 0.52756986 | L7: -0.12232985 | M7: -0.054729895 | N7: 0.073457991 | O7: 0.45665026 | P7: -0.11376554 | Q7: -0.22158458 | R7: -0.17515417 | S7: 0.088063988 | T7: 0.064041849 | U7: -0.19299411 | V7: -0.22702667 | W7: 0.01023012 | X7: -0.23759281 | Y7: -0.3153533 | Z7: -0.3043521 | AA7: 0.060165383 | AB7: -0.077015224 | AC7: 0.030248481 | AD7: -0.057679552 | AE7: -0.16676918 | AF7: -0.19620769 | AG7: -0.046489555 | AH7: -0.0011162015 | AI7: 0.0046599839 | AJ7: -0.11692636 | AK7: 0.029763128 | AL7: 0.045991587 | AM7: -0.058379902 | AN7: 0.22364233 | AO7: -0.21220605 | AP7: -0.29907207 | AQ7: -0.15979542
A8: sensitivityscore_After_Mixed_6e.branch7x7_1.conv_0.5 | B8: 0.035468233 | C8: -0.014053574 | D8: -0.24590631 | E8: -0.40636601 | F8: 0.14119406 | G8: -0.14056114 | H8: 1 | I8: 0.32341287 | J8: 0.32252049 | K8: 0.071663399 | L8: -0.15100512 | M8: 0.10119799 | N8: 0.044188602 | O8: 0.094237856 | P8: 0.042942663 | Q8: -0.17171053 | R8: -0.30039795 | S8: 0.063084984 | T8: 0.037558663 | U8: -0.035740804 | V8: 0.049963096 | W8: -0.03606706 | X8: -0.027952068 | Y8: 0.14248149 | Z8: 0.15369787 | AA8: -0.063823283 | AB8: 0.1406918 | AC8: 0.074879293 | AD8: 0.30637652 | AE8: 0.092712941 | AF8: 0.10157338 | AG8: -0.091115879 | AH8: 0.21011328 | AI8: -0.36108078 | AJ8: 0.15142683 | AK8: -0.12169497 | AL8: -0.033300111 | AM8: -0.087649016 | AN8: 0.030636173 | AO8: -0.017582135 | AP8: 0.20607589 | AQ8: -0.10388173
A9: sensitivityscore_After_Mixed_6e.branch7x7_1.conv_0.6 | B9: -0.11174963 | C9: -0.01770576 | D9: -0.21785756 | E9: -0.15461586 | F9: 0.029123413 | G9: -0.095665288 | H9: 0.32341287 | I9: 1 | J9: 0.37192313 | K9: 0.011396408 | L9: -0.14781478 | M9: 0.20327021 | N9: 0.20045504 | O9: 0.047397826 | P9: -0.075232266 | Q9: -0.11867012 | R9: 0.052058671 | S9: -0.05608321 | T9: -0.43656382 | U9: -0.37380852 | V9: -0.3891987 | W9: 0.12630292 | X9: 0.036552354 | Y9: -0.023426128 | Z9: -0.016960871 | AA9: -0.099794575 | AB9: -0.058028395 | AC9: -0.056800262 | AD9: -0.037228463 | AE9: 0.022112597 | AF9: 0.08742617 | AG9: 0.034788572 | AH9: -0.10465843 | AI9: -0.038193883 | AJ9: 0.026193349 | AK9: -0.12996453 | AL9: -0.1033363 | AM9: -0.23379142 | AN9: 0.10518732 | AO9: -0.070278178 | AP9: 0.022495586 | AQ9: -0.1061427
A10: sensitivityscore_After_Mixed_6e.branch7x7_1.conv_0.7 | B10: 0.099354526 | C10: 0.041917822 | D10: -0.10294056 | E10: -0.15717526 | F10: 0.19977279 | G10: -0.076031944 | H10: 0.32252049 | I10: 0.37192313 | J10: 1 | K10: -0.10755681 | L10: 0.052109706 | M10: 0.16281701 | N10: 0.034495325 | O10: -0.17795081 | P10: -0.057668518 | Q10: -0.18095728 | R10: 0.040188158 | S10: -0.17873583 | T10: -0.068492797 | U10: -0.052941162 | V10: -0.22907005 | W10: 0.030283581 | X10: 0.034979109 | Y10: -0.052687569 | Z10: 0.041387263 | AA10: -0.084172844 | AB10: -0.18797572 | AC10: -0.024508454 | AD10: -0.0037473485 | AE10: -0.024793577 | AF10: 0.20841795 | AG10: -0.19829325 | AH10: -0.1336755 | AI10: -0.17529713 | AJ10: 0.38935069 | AK10: 0.15987683 | AL10: 0.25923844 | AM10: -0.17294883 | AN10: 0.15232215 | AO10: -0.066263752 | AP10: -0.014756789 | AQ10: -0.11389483
A11: Mixed_6e.branch7x7_2.conv | B11: 0.11120931 | C11: -0.018664238 | D11: 0.005118763 | E11: -0.032338848 | F11: 0.14024414 | G11: 0.52756986 | H11: 0.071663399 | I11: 0.011396408 | J11: -0.10755681 | K11: 1 | L11: 0.12749458 | M11: -0.05856022 | N11: 0.12491355 | O11: 0.66820636 | P11: -0.10462377 | Q11: -0.27384414 | R11: -0.11660564 | S11: 0.21410404 | T11: -0.081190005 | U11: -0.23030832 | V11: -0.1583106 | W11: -0.031706454 | X11: -0.31179304 | Y11: -0.25884916 | Z11: -0.14706858 | AA11: 0.04602528 | AB11: 0.17919262 | AC11: 0.15672234 | AD11: 0.11799857 | AE11: 0.049624998 | AF11: -0.17987241 | AG11: -0.045133968 | AH11: -0.13306182 | AI11: -0.18451312 | AJ11: -0.2125667 | AK11: -0.080995279 | AL11: 0.046789143 | AM11: 0.0024701142 | AN11: 0.16809906 | AO11: -0.21589976 | AP11: -0.072726906 | AQ11: -0.057240473
A12: sensitivityscore_After_Mixed_6e.branch7x7_2.conv_0.5 | B12: -0.081436924 | C12: -0.17538311 | D12: -0.25326067 | E12: 0.015763149 | F12: -0.058722549 | G12: -0.12232985 | H12: -0.15100512 | I12: -0.14781478 | J12: 0.052109706 | K12: 0.12749458 | L12: 1 | M12: 0.38468792 | N12: 0.058735572 | O12: -0.2643946 | P12: 0.25096477 | Q12: 0.3911395 | R12: 0.044569627 | S12: -0.036294039 | T12: 0.024885674 | U12: 0.070470771 | V12: 0.067413064 | W12: 0.0072692467 | X12: -0.27599347 | Y12: -0.13161312 | Z12: -0.17315936 | AA12: -0.023191854 | AB12: -0.04203167 | AC12: 0.010713426 | AD12: 0.07028862 | AE12: -0.025474657 | AF12: -0.26989458 | AG12: -0.14768571 | AH12: -0.26915304 | AI12: -0.045657061 | AJ12: -0.12177684 | AK12: 0.031941741 | AL12: 0.05954343 | AM12: 0.16204414 | AN12: -0.24085613 | AO12: 0.053249016 | AP12: 0.1048263 | AQ12: 0.084935596
A13: sensitivityscore_After_Mixed_6e.branch7x7_2.conv_0.6 | B13: -0.080078868 | C13: 0.20976897 | D13: 0.10712545 | E13: 0.08134046 | F13: 0.051626868 | G13: -0.054729895 | H13: 0.10119799 | I13: 0.20327021 | J13: 0.16281701 | K13: -0.05856022 | L13: 0.38468792 | M13: 1 | N13: 0.22857508 | O13: -0.13958613 | P13: 0.16683701 | Q13: 0.23798055 | R13: -0.016126109 | S13: -0.054949999 | T13: -0.17080349 | U13: -0.17670681 | V13: -0.12238764 | W13: -0.052088518 | X13: 0.030222278 | Y13: 0.20249506 | Z13: -0.050134471 | AA13: 0.095580476 | AB13: -0.045717032 | AC13: 0.11770258 | AD13: 0.19484515 | AE13: 0.095777739 | AF13: -0.24546215 | AG13: -0.056002898 | AH13: -0.17062367 | AI13: -0.0059017462 | AJ13: -0.13871829 | AK13: 0.13793008 | AL13: 0.071559377 | AM13: -0.038591968 | AN13: -0.24323144 | AO13: -0.18689038 | AP13: -0.11784424 | AQ13: 0.0077981011
... A43: sensitivityscore_After_Mixed_7b.branch_pool.conv_0.7 | B43: -0.42856716 | C43: -0.098487106 | D43: -0.12979432 | E43: -0.010912593 | F43: -0.4681809 | G43: -0.15979542 | H43: -0.10388173 | I43: -0.1061427 | J43: -0.11389483 | K43: -0.057240473 | L43: 0.084935596 | M43: 0.0077981011 | N43: -0.00083501219 | O43: 0.23209872 | P43: 0.29961133 | Q43: 0.4596241 | R43: 0.17543194 | S43: -0.15916083 | T43: 0.070366466 | U43: 0.12779528 | V43: 0.066824423 | W43: 0.29331524 | X43: -0.18547248 | Y43: -0.1018533 | Z43: -0.16591178 | AA43: 0.14478155 | AB43: -0.1031736 | AC43: -0.35075477 | AD43: -0.33112383 | AE43: 0.074960338 | AF43: -0.059317147 | AG43: -0.21141482 | AH43: -0.098410371 | AI43: 0.11418456 | AJ43: -0.032863489 | AK43: -0.14655697 | AL43: 0.038292753 | AM43: -0.042316679 | AN43: -0.31372902 | AO43: 0.72705653 | AP43: 0.76821962 | AQ43: 1

Sheet Class_3
B1: Mixed_6e.branch1x1.conv | C1: sensitivityscore_After_Mixed_6e.branch1x1.conv_0.5 | D1: sensitivityscore_After_Mixed_6e.branch1x1.conv_0.6 | E1: sensitivityscore_After_Mixed_6e.branch1x1.conv_0.7 | F1: Mixed_6e.branch1x1 | G1: Mixed_6e.branch7x7_1.conv | H1: sensitivityscore_After_Mixed_6e.branch7x7_1.conv_0.5 | I1: sensitivityscore_After_Mixed_6e.branch7x7_1.conv_0.6 | J1: sensitivityscore_After_Mixed_6e.branch7x7_1.conv_0.7 | K1: Mixed_6e.branch7x7_2.conv | L1: sensitivityscore_After_Mixed_6e.branch7x7_2.conv_0.5 | M1: sensitivityscore_After_Mixed_6e.branch7x7_2.conv_0.6 | N1: sensitivityscore_After_Mixed_6e.branch7x7_2.conv_0.7 | O1: Mixed_6e.branch7x7_3.conv | P1: sensitivityscore_After_Mixed_6e.branch7x7_3.conv_0.5 | Q1: sensitivityscore_After_Mixed_6e.branch7x7_3.conv_0.6 | R1: sensitivityscore_After_Mixed_6e.branch7x7_3.conv_0.7 | S1: Mixed_6e.branch7x7dbl_1.conv | T1: sensitivityscore_After_Mixed_6e.branch7x7dbl_1.conv_0.5 | U1: sensitivityscore_After_Mixed_6e.branch7x7dbl_1.conv_0.6 | V1: sensitivityscore_After_Mixed_6e.branch7x7dbl_1.conv_0.7 | W1: Mixed_7b.branch1x1.conv | X1: sensitivityscore_After_Mixed_7b.branch1x1.conv_0.5 | Y1: sensitivityscore_After_Mixed_7b.branch1x1.conv_0.6 | Z1: sensitivityscore_After_Mixed_7b.branch1x1.conv_0.7 | AA1: Mixed_7b.branch3x3_1.conv | AB1: sensitivityscore_After_Mixed_7b.branch3x3_1.conv_0.5 | AC1: sensitivityscore_After_Mixed_7b.branch3x3_1.conv_0.6 | AD1: sensitivityscore_After_Mixed_7b.branch3x3_1.conv_0.7 | AE1: Mixed_7b.branch3x3_2a.conv | AF1: sensitivityscore_After_Mixed_7b.branch3x3_2a.conv_0.5 | AG1: sensitivityscore_After_Mixed_7b.branch3x3_2a.conv_0.6 | AH1: sensitivityscore_After_Mixed_7b.branch3x3_2a.conv_0.7 | AI1: Mixed_7b.branch3x3_2b.conv | AJ1: sensitivityscore_After_Mixed_7b.branch3x3_2b.conv_0.5 | AK1: sensitivityscore_After_Mixed_7b.branch3x3_2b.conv_0.6 | AL1: sensitivityscore_After_Mixed_7b.branch3x3_2b.conv_0.7 | AM1: Mixed_7b.branch3x3dbl_3a | AN1: Mixed_7b.branch_pool.conv | AO1: sensitivityscore_After_Mixed_7b.branch_pool.conv_0.5 | AP1: sensitivityscore_After_Mixed_7b.branch_pool.conv_0.6 | AQ1: sensitivityscore_After_Mixed_7b.branch_pool.conv_0.7
A2: Mixed_6e.branch1x1.conv | B2: 1 | C2: 0.21877273 | D2: 0.29042638 | E2: 0.23680868 | F2: 0.60707343 | G2: 0.013851895 | H2: -0.19054052 | I2: -0.11338743 | J2: -0.045464176 | K2: -0.086863302 | L2: 0.0070917252 | M2: 0.054496582 | N2: -0.11980194 | O2: -0.042966636 | P2: 0.049742419 | Q2: 0.063099171 | R2: 0.13070417 | S2: 0.012581274 | T2: 0.11334495 | U2: 0.188436 | V2: 0.037985372 | W2: 0.19880585 | X2: 0.058137303 | Y2: 0.14201193 | Z2: 0.064911378 | AA2: 0.30806354 | AB2: -0.046360585 | AC2: 0.059548045 | AD2: 0.079231754 | AE2: 0.35193734 | AF2: -0.00016559563 | AG2: 0.11002553 | AH2: -0.013696834 | AI2: 0.025522701 | AJ2: 0.06935704 | AK2: -0.080967235 | AL2: 0.073370359 | AM2: 0.16603023 | AN2: 0.002442365 | AO2: 0.12522515 | AP2: 0.11007729 | AQ2: 0.050717414
A3: sensitivityscore_After_Mixed_6e.branch1x1.conv_0.5 | B3: 0.21877273 | C3: 1 | D3: 0.6841941 | E3: 0.63227323 | F3: 0.14740623 | G3: -0.19964195 | H3: 0.18409895 | I3: 0.10276938 | J3: 0.033672769 | K3: -0.14402082 | L3: -0.20732375 | M3: -0.20720674 | N3: 0.11043176 | O3: -0.092814864 | P3: -0.1075195 | Q3: -0.24739029 | R3: -0.29595632 | S3: -0.10025674 | T3: -0.082156281 | U3: 0.035513502 | V3: 0.064720192 | W3: 0.061393675 | X3: 0.0185729 | Y3: -0.059291598 | Z3: 0.012303468 | AA3: -0.071755965 | AB3: 0.1079179 | AC3: 0.03515699 | AD3: 0.34223024 | AE3: 0.23475393 | AF3: -0.036919037 | AG3: 0.085364546 | AH3: 0.081744571 | AI3: -0.16484577 | AJ3: -0.061212495 | AK3: -0.0011067157 | AL3: 0.11585424 | AM3: 0.19823065 | AN3: -0.0043415679 | AO3: -0.090656735 | AP3: -0.0034633532 | AQ3: -0.12306337
A4: sensitivityscore_After_Mixed_6e.branch1x1.conv_0.6 | B4: 0.29042638 | C4: 0.6841941 | D4: 1 | E4: 0.75130288 | F4: 0.24909835 | G4: -0.094834297 | H4: 0.064793252 | I4: 0.057294071 | J4: 0.039954031 | K4: -0.19541007 | L4: -0.17662354 | M4: -0.15812349 | N4: 0.012324214 | O4: -0.014431413 | P4: -0.14719737 | Q4: -0.22895652 | R4: -0.27788908 | S4: -0.040061447 | T4: 0.099850939 | U4: 0.077419407 | V4: 0.093900177 | W4: 0.066673437 | X4: 0.13977799 | Y4: -0.078537401 | Z4: 0.049235957 | AA4: -0.085258822 | AB4: 0.057708153 | AC4: -0.080549004 | AD4: 0.25727867 | AE4: 0.25875706 | AF4: -0.096231258 | AG4: -0.0071202825 | AH4: -0.090114879 | AI4: -0.10163727 | AJ4: -0.04667221 | AK4: -0.0091986327 | AL4: 0.17619587 | AM4: 0.148999 | AN4: -0.082517454 | AO4: -0.12878391 | AP4: -0.038335208 | AQ4: -0.20626317
A5: sensitivityscore_After_Mixed_6e.branch1x1.conv_0.7 | B5: 0.23680868 | C5: 0.63227323 | D5: 0.75130288 | E5: 1 | F5: 0.059470837 | G5: -0.099972815 | H5: 0.0010836974 | I5: -0.036770792 | J5: 0.015852062 | K5: -0.14968126 | L5: -0.13362101 | M5: -0.029721326 | N5: 0.048034324 | O5: -0.12459737 | P5: -0.20615999 | Q5: -0.29249016 | R5: -0.044578826 | S5: -0.088704078 | T5: 0.04813419 | U5: -0.034664317 | V5: -0.023247633 | W5: 0.20390107 | X5: 0.15729957 | Y5: -0.067616577 | Z5: 0.052524512 | AA5: 0.011127561 | AB5: 0.081997358 | AC5: -0.062333824 | AD5: 0.10844308 | AE5: 0.1920248 | AF5: 0.012164981 | AG5: 0.12279627 | AH5: -0.0076647018 | AI5: -0.048643359 | AJ5: -0.33555986 | AK5: -0.29801351 | AL5: -0.058196547 | AM5: 0.13907737 | AN5: -0.011664066 | AO5: -0.075421367 | AP5: 0.019335712 | AQ5: -0.093591427
A6: Mixed_6e.branch1x1 | B6: 0.60707343 | C6: 0.14740623 | D6: 0.24909835 | E6: 0.059470837 | F6: 1 | G6: 0.10096833 | H6: -0.063994529 | I6: -0.070638855 | J6: -0.019739703 | K6: -0.094962268 | L6: 0.05974233 | M6: 0.065924927 | N6: -0.074160077 | O6: 0.15723242 | P6: 0.036760499 | Q6: 0.065204318 | R6: 0.099117569 | S6: 0.10582936 | T6: 0.0038767097 | U6: -0.052386694 | V6: 0.021407581 | W6: 0.11253473 | X6: 0.087772262 | Y6: 0.26355501 | Z6: 0.07373092 | AA6: 0.097889426 | AB6: 0.00068863672 | AC6: 0.11861129 | AD6: 0.3662909 | AE6: 0.26776608 | AF6: -0.054495266 | AG6: -0.0084491058 | AH6: 0.018891701 | AI6: -0.0822929 | AJ6: 0.26172399 | AK6: 0.32550339 | AL6: 0.15480661 | AM6: 0.052814694 | AN6: 0.21402457 | AO6: 0.16960878 | AP6: 0.17156715 | AQ6: 0.18160791
A7: Mixed_6e.branch7x7_1.conv | B7: 0.013851895 | C7: -0.19964195 | D7: -0.094834297 | E7: -0.099972815 | F7: 0.10096833 | G7: 1 | H7: 0.07124906 | I7: -0.029751342 | J7: 0.099688083 | K7: 0.31839401 | L7: 0.034926546 | M7: -0.040232458 | N7: 0.027804839 | O7: 0.36639509 | P7: -0.064113714 | Q7: 0.028049681 | R7: 0.13621904 | S7: 0.37465477 | T7: 0.15540081 | U7: -0.077853388 | V7: -0.061784197 | W7: -0.059790379 | X7: 0.029185852 | Y7: 0.47561931 | Z7: 0.23908743 | AA7: -0.006038679 | AB7: -0.26563208 | AC7: -0.19311559 | AD7: -0.021828478 | AE7: -0.10524612 | AF7: -0.14142042 | AG7: -0.04940796 | AH7: -0.092723906 | AI7: 0.18079076 | AJ7: -0.014498959 | AK7: -0.0011488027 | AL7: -0.066373497 | AM7: -0.13755781 | AN7: 0.028493582 | AO7: 0.1646799 | AP7: 0.12470496 | AQ7: 0.11974803
A8: sensitivityscore_After_Mixed_6e.branch7x7_1.conv_0.5 | B8: -0.19054052 | C8: 0.18409895 | D8: 0.064793252 | E8: 0.0010836974 | F8: -0.063994529 | G8: 0.07124906 | H8: 1 | I8: 0.46773973 | J8: 0.24616694 | K8: 0.27117282 | L8: 0.050939269 | M8: -0.15143869 | N8: 0.23541423 | O8: 0.32450707 | P8: 0.037718567 | Q8: 0.0005667683 | R8: -0.15145637 | S8: 0.13567956 | T8: -0.07121876 | U8: 0.065539031 | V8: 0.014721904 | W8: 0.099778029 | X8: -0.19710699 | Y8: -0.07755525 | Z8: -0.28052447 | AA8: -0.023835596 | AB8: -0.1269751 | AC8: 0.13869047 | AD8: 0.27261098 | AE8: 0.020767128 | AF8: -0.050026346 | AG8: 0.073313212 | AH8: -0.048946434 | AI8: 0.04871493 | AJ8: 0.28164468 | AK8: 0.3365942 | AL8: 0.25206216 | AM8: 0.15274811 | AN8: 0.13591924 | AO8: -0.025596107 | AP8: -0.11569261 | AQ8: -0.16046449
A9: sensitivityscore_After_Mixed_6e.branch7x7_1.conv_0.6 | B9: -0.11338743 | C9: 0.10276938 | D9: 0.057294071 | E9: -0.036770792 | F9: -0.070638855 | G9: -0.029751342 | H9: 0.46773973 | I9: 1 | J9: 0.56348349 | K9: 0.15293062 | L9: 0.038269011 | M9: -0.11310305 | N9: 0.023959937 | O9: 0.22133043 | P9: 0.11794711 | Q9: 0.13192127 | R9: 0.01322723 | S9: 0.010874798 | T9: 0.24949258 | U9: 0.1369985 | V9: 0.042381871 | W9: -0.16842505 | X9: -0.0023083564 | Y9: -0.14928477 | Z9: -0.20423589 | AA9: 0.084055175 | AB9: -0.10350508 | AC9: 0.045471051 | AD9: 0.11952269 | AE9: -0.17138362 | AF9: 0.1089567 | AG9: 0.042364461 | AH9: -0.22705153 | AI9: 0.14266738 | AJ9: 0.14036543 | AK9: 0.13632019 | AL9: 0.066080837 | AM9: 0.082224174 | AN9: -0.029556685 | AO9: 0.041053015 | AP9: -0.021584342 | AQ9: -0.058487543
A10: sensitivityscore_After_Mixed_6e.branch7x7_1.conv_0.7 | B10: -0.045464176 | C10: 0.033672769 | D10: 0.039954031 | E10: 0.015852062 | F10: -0.019739703 | G10: 0.099688083 | H10: 0.24616694 | I10: 0.56348349 | J10: 1 | K10: 0.18153368 | L10: -0.0050366883 | M10: -0.28356276 | N10: -0.18260359 | O10: 0.070721606 | P10: 0.34607492 | Q10: 0.27388194 | R10: 0.23944689 | S10: -0.04858076 | T10: -0.00060810948 | U10: -0.045555283 | V10: -0.19537151 | W10: -0.19944454 | X10: 0.25845578 | Y10: 0.037768047 | Z10: 0.10104359 | AA10: 0.087956816 | AB10: -0.12448108 | AC10: -0.097658489 | AD10: -0.019900532 | AE10: -0.19713981 | AF10: 0.16302525 | AG10: 0.30151508 | AH10: 0.06053599 | AI10: 0.096755732 | AJ10: 0.021996913 | AK10: -0.081791248 | AL10: -0.29693786 | AM10: -0.025305567 | AN10: -0.25045513 | AO10: 0.042207721 | AP10: 0.12858361 | AQ10: -0.014666431
A11: Mixed_6e.branch7x7_2.conv | B11: -0.086863302 | C11: -0.14402082 | D11: -0.19541007 | E11: -0.14968126 | F11: -0.094962268 | G11: 0.31839401 | H11: 0.27117282 | I11: 0.15293062 | J11: 0.18153368 | K11: 1 | L11: 0.26553876 | M11: 0.1165495 | N11: 0.10627032 | O11: 0.70821551 | P11: 0.037903579 | Q11: 0.080059198 | R11: 0.1546102 | S11: 0.17149816 | T11: 0.028770888 | U11: 0.074460133 | V11: -0.15369877 | W11: 0.0504173 | X11: -0.010382879 | Y11: 0.1185067 | Z11: -0.076982851 | AA11: 0.093036755 | AB11: -0.20114834 | AC11: 0.046121437 | AD11: -0.0094508869 | AE11: -0.1262309 | AF11: -0.18070877 | AG11: -0.13190712 | AH11: -0.14974103 | AI11: 0.11308649 | AJ11: 0.22448143 | AK11: 0.093360918 | AL11: 0.13680628 | AM11: -0.095027963 | AN11: 0.15911128 | AO11: -0.015729126 | AP11: 0.12573787 | AQ11: -0.073845326
A12: sensitivityscore_After_Mixed_6e.branch7x7_2.conv_0.5 | B12: 0.0070917252 | C12: -0.20732375 | D12: -0.17662354 | E12: -0.13362101 | F12: 0.05974233 | G12: 0.034926546 | H12: 0.050939269 | I12: 0.038269011 | J12: -0.0050366883 | K12: 0.26553876 | L12: 1 | M12: 0.53503416 | N12: 0.27318276 | O12: 0.39535042 | P12: 0.17650489 | Q12: 0.35504628 | R12: 0.35056178 | S12: 0.11043167 | T12: -0.14631104 | U12: -0.19348135 | V12: -0.45660646 | W12: 0.23731158 | X12: 0.2333655 | Y12: 0.30115845 | Z12: 0.16155032 | AA12: 0.13800603 | AB12: 0.057338745 | AC12: 0.28320196 | AD12: 0.10799061 | AE12: -0.083305213 | AF12: 0.025413851 | AG12: 0.064720462 | AH12: -0.059378613 | AI12: 0.11194264 | AJ12: 0.1395535 | AK12: -0.0022861771 | AL12: -0.083515878 | AM12: -0.13808215 | AN12: 0.023161874 | AO12: 0.26844799 | AP12: 0.27714846 | AQ12: 0.21731412
A13: sensitivityscore_After_Mixed_6e.branch7x7_2.conv_0.6 | B13: 0.054496582 | C13: -0.20720674 | D13: -0.15812349 | E13: -0.029721326 | F13: 0.065924927 | G13: -0.040232458 | H13: -0.15143869 | I13: -0.11310305 | J13: -0.28356276 | K13: 0.1165495 | L13: 0.53503416 | M13: 1 | N13: 0.4160779 | O13: 0.25414131 | P13: -0.10163829 | Q13: 0.047795175 | R13: 0.065386841 | S13: 0.17221334 | T13: -0.036545371 | U13: 0.0033424276 | V13: -0.10989886 | W13: 0.27678395 | X13: 0.16658266 | Y13: 0.17832509 | Z13: 0.10507215 | AA13: 0.14079293 | AB13: 0.16139544 | AC13: 0.22834863 | AD13: 0.089271522 | AE13: 0.031851762 | AF13: -0.063599147 | AG13: -0.04009951 | AH13: -0.074841697 | AI13: 0.1761104 | AJ13: 0.13450695 | AK13: 0.059103266 | AL13: 0.093977763 | AM13: 0.04455522 | AN13: -0.0083388093 | AO13: 0.13406528 | AP13: 0.19191896 | AQ13: 0.16857354
... A43: sensitivityscore_After_Mixed_7b.branch_pool.conv_0.7 | B43: 0.050717414 | C43: -0.12306337 | D43: -0.20626317 | E43: -0.093591427 | F43: 0.18160791 | G43: 0.11974803 | H43: -0.16046449 | I43: -0.058487543 | J43: -0.014666431 | K43: -0.073845326 | L43: 0.21731412 | M43: 0.16857354 | N43: -0.1146351 | O43: 0.09988748 | P43: 0.16129395 | Q43: 0.19623448 | R43: 0.24007717 | S43: -0.058164537 | T43: 0.20881929 | U43: -0.27829717 | V43: -0.11671757 | W43: 0.067199517 | X43: 0.19889388 | Y43: 0.36663597 | Z43: 0.27221146 | AA43: 0.18475799 | AB43: -0.034064025 | AC43: 0.038723499 | AD43: -0.17579753 | AE43: -0.070800327 | AF43: 0.30381212 | AG43: 0.14411001 | AH43: 0.082943005 | AI43: 0.044801759 | AJ43: -0.10723372 | AK43: -0.19112984 | AL43: -0.33643686 | AM43: -0.022839447 | AN43: 0.24390711 | AO43: 0.8514756 | AP43: 0.78589981 | AQ43: 1

Sheet Class_4
B1: Mixed_6e.branch1x1.conv | C1: sensitivityscore_After_Mixed_6e.branch1x1.conv_0.5 | D1: sensitivityscore_After_Mixed_6e.branch1x1.conv_0.6 | E1: sensitivityscore_After_Mixed_6e.branch1x1.conv_0.7 | F1: Mixed_6e.branch1x1 | G1: Mixed_6e.branch7x7_1.conv | H1: sensitivityscore_After_Mixed_6e.branch7x7_1.conv_0.5 | I1: sensitivityscore_After_Mixed_6e.branch7x7_1.conv_0.6 | J1: sensitivityscore_After_Mixed_6e.branch7x7_1.conv_0.7 | K1: Mixed_6e.branch7x7_2.conv | L1: sensitivityscore_After_Mixed_6e.branch7x7_2.conv_0.5 | M1: sensitivityscore_After_Mixed_6e.branch7x7_2.conv_0.6 | N1: sensitivityscore_After_Mixed_6e.branch7x7_2.conv_0.7 | O1: Mixed_6e.branch7x7_3.conv | P1: sensitivityscore_After_Mixed_6e.branch7x7_3.conv_0.5 | Q1: sensitivityscore_After_Mixed_6e.branch7x7_3.conv_0.6 | R1: sensitivityscore_After_Mixed_6e.branch7x7_3.conv_0.7 | S1: Mixed_6e.branch7x7dbl_1.conv | T1: sensitivityscore_After_Mixed_6e.branch7x7dbl_1.conv_0.5 | U1: sensitivityscore_After_Mixed_6e.branch7x7dbl_1.conv_0.6 | V1: sensitivityscore_After_Mixed_6e.branch7x7dbl_1.conv_0.7 | W1: Mixed_7b.branch1x1.conv | X1: sensitivityscore_After_Mixed_7b.branch1x1.conv_0.5 | Y1: sensitivityscore_After_Mixed_7b.branch1x1.conv_0.6 | Z1: sensitivityscore_After_Mixed_7b.branch1x1.conv_0.7 | AA1: Mixed_7b.branch3x3_1.conv | AB1: sensitivityscore_After_Mixed_7b.branch3x3_1.conv_0.5 | AC1: sensitivityscore_After_Mixed_7b.branch3x3_1.conv_0.6 | AD1: sensitivityscore_After_Mixed_7b.branch3x3_1.conv_0.7 | AE1: Mixed_7b.branch3x3_2a.conv | AF1: sensitivityscore_After_Mixed_7b.branch3x3_2a.conv_0.5 | AG1: sensitivityscore_After_Mixed_7b.branch3x3_2a.conv_0.6 | AH1: sensitivityscore_After_Mixed_7b.branch3x3_2a.conv_0.7 | AI1: Mixed_7b.branch3x3_2b.conv | AJ1: sensitivityscore_After_Mixed_7b.branch3x3_2b.conv_0.5 | AK1: sensitivityscore_After_Mixed_7b.branch3x3_2b.conv_0.6 | AL1: sensitivityscore_After_Mixed_7b.branch3x3_2b.conv_0.7 | AM1: Mixed_7b.branch3x3dbl_3a | AN1: Mixed_7b.branch_pool.conv | AO1: sensitivityscore_After_Mixed_7b.branch_pool.conv_0.5 | AP1: sensitivityscore_After_Mixed_7b.branch_pool.conv_0.6 | AQ1: sensitivityscore_After_Mixed_7b.branch_pool.conv_0.7
A2: Mixed_6e.branch1x1.conv | B2: 1 | C2: -0.019355832 | D2: -0.15878871 | E2: -0.0067225879 | F2: 0.32901811 | G2: -0.069032619 | H2: 0.39509278 | I2: 0.066807757 | J2: 0.21033771 | K2: 0.086504398 | L2: 0.065027081 | M2: -0.13018446 | N2: -0.18167641 | O2: -0.036843752 | P2: 0.0023685455 | Q2: 0.16096515 | R2: -0.21091846 | S2: -0.089625118 | T2: -0.057326535 | U2: -0.0011433025 | V2: -0.14403993 | W2: 0.26730603 | X2: -0.17945363 | Y2: -0.16365428 | Z2: 0.074361984 | AA2: 0.14105465 | AB2: 0.30486869 | AC2: 0.16339551 | AD2: 0.2138547 | AE2: -0.12767974 | AF2: -0.27501757 | AG2: -0.35116408 | AH2: -0.24812775 | AI2: 0.28084092 | AJ2: -0.23135388 | AK2: -0.31039316 | AL2: -0.26984635 | AM2: -0.013742843 | AN2: 0.34316524 | AO2: 0.067663758 | AP2: 0.010717126 | AQ2: -0.20834262
A3: sensitivityscore_After_Mixed_6e.branch1x1.conv_0.5 | B3: -0.019355832 | C3: 1 | D3: 0.45041529 | E3: 0.4633579 | F3: 0.021184469 | G3: 0.11921964 | H3: 0.081949554 | I3: 0.41002436 | J3: 0.34715494 | K3: 0.18129351 | L3: -0.359369 | M3: -0.071739051 | N3: -0.055207688 | O3: 0.12230254 | P3: 0.12541039 | Q3: -0.12213365 | R3: 0.13172794 | S3: 0.11232589 | T3: 0.23071399 | U3: 0.15195768 | V3: -0.12323287 | W3: -0.095574894 | X3: 0.17730097 | Y3: 0.24829805 | Z3: -0.053976406 | AA3: 0.11455229 | AB3: -0.11602476 | AC3: -0.1991748 | AD3: -0.026241602 | AE3: -0.22713901 | AF3: -0.14062718 | AG3: -0.13519103 | AH3: -0.02855109 | AI3: 0.13916559 | AJ3: 0.14240411 | AK3: 0.11653003 | AL3: 0.19879603 | AM3: -0.054972864 | AN3: 0.11102656 | AO3: -0.1656787 | AP3: -0.050267628 | AQ3: -0.074840774
A4: sensitivityscore_After_Mixed_6e.branch1x1.conv_0.6 | B4: -0.15878871 | C4: 0.45041529 | D4: 1 | E4: 0.75277887 | F4: -0.22250789 | G4: -0.076098321 | H4: 0.26747352 | I4: 0.45248319 | J4: 0.31143114 | K4: 0.15121592 | L4: -0.15998544 | M4: -0.12620626 | N4: -0.0065460347 | O4: 0.098902979 | P4: -0.079779379 | Q4: 0.071935408 | R4: 0.41167035 | S4: 0.30941795 | T4: 0.25307803 | U4: 0.18208037 | V4: -0.086719137 | W4: -0.13089733 | X4: -0.10981785 | Y4: 0.020491285 | Z4: -0.25720264 | AA4: 0.30632305 | AB4: -0.43115812 | AC4: -0.19830243 | AD4: 0.019663403 | AE4: 0.0092321141 | AF4: 0.15907784 | AG4: 0.17833343 | AH4: 0.24371175 | AI4: 0.10824233 | AJ4: 0.30881396 | AK4: 0.14376052 | AL4: 0.16878269 | AM4: 0.11526667 | AN4: 0.065810335 | AO4: -0.22805265 | AP4: -0.21582241 | AQ4: -0.059380956
