Workbook

Sheet Sheet1
A1: Class | B1: =Class_0!B1 -> features.5.block.0.0 | C1: =Class_0!C1 -> sensitivityscore_After_features.5.block.0.0_0.5 | D1: =Class_0!D1 -> sensitivityscore_After_features.5.block.0.0_0.6 | E1: =Class_0!E1 -> sensitivityscore_After_features.5.block.0.0_0.7 | F1: =Class_0!F1 -> features.5.block.1.0 | G1: =Class_0!G1 -> sensitivityscore_After_features.5.block.1.0_0.5 | H1: =Class_0!H1 -> sensitivityscore_After_features.5.block.1.0_0.6 | I1: =Class_0!I1 -> sensitivityscore_After_features.5.block.1.0_0.7 | ... BN1: =Class_0!BN1 -> 0
A2: 0 | B2: =Class_0!B49 -> 0.0011500097 | C2: =Class_0!C49 -> 0.10376321 | D2: =Class_0!D49 -> 0.14208394 | E2: =Class_0!E49 -> 0.0090042531 | F2: =Class_0!F49 -> 0.11136113 | G2: =Class_0!G49 -> -0.095261806 | H2: =Class_0!H49 -> 0.055502664 | I2: =Class_0!I49 -> -0.14512435 | ... AW2: =Class_0!AW49 -> 1
A3: 1 | B3: =Class_1!B49 -> 0.073092053 | C3: =Class_1!C49 -> 0.0073313764 | D3: =Class_1!D49 -> 0.21647044 | E3: =Class_1!E49 -> 0.13495408 | F3: =Class_1!F49 -> 0.17283101 | G3: =Class_1!G49 -> -0.20585343 | H3: =Class_1!H49 -> -0.26228604 | I3: =Class_1!I49 -> -0.041960112 | ... AW3: =Class_1!AW49 -> 1
A4: 2 | B4: =Class_2!B49 -> -0.18352871 | C4: =Class_2!C49 -> 0.095875212 | D4: =Class_2!D49 -> 0.41248567 | E4: =Class_2!E49 -> 0.3600069 | F4: =Class_2!F49 -> -0.12432641 | G4: =Class_2!G49 -> 0.12461054 | H4: =Class_2!H49 -> -0.037362327 | I4: =Class_2!I49 -> -0.034621253 | ... AW4: =Class_2!AW49 -> 1
A5: 3 | B5: =Class_3!B49 -> 0.029479851 | C5: =Class_3!C49 -> 0.24529023 | D5: =Class_3!D49 -> 0.089861901 | E5: =Class_3!E49 -> 0.066138201 | F5: =Class_3!F49 -> 0.028299661 | G5: =Class_3!G49 -> 0.070023588 | H5: =Class_3!H49 -> 0.00096168237 | I5: =Class_3!I49 -> -0.083279404 | ... AW5: =Class_3!AW49 -> 1
A6: 4 | B6: =Class_4!B49 -> -0.15600168 | C6: =Class_4!C49 -> 0.0093692212 | D6: =Class_4!D49 -> -0.032362267 | E6: =Class_4!E49 -> 0.14177586 | F6: =Class_4!F49 -> -0.29479915 | G6: =Class_4!G49 -> -0.17614344 | H6: =Class_4!H49 -> -0.071061236 | I6: =Class_4!I49 -> -0.10197857 | ... AW6: =Class_4!AW49 -> 1
A7: 5 | B7: =Class_5!B49 -> 0.12603887 | C7: =Class_5!C49 -> 0.13137907 | D7: =Class_5!D49 -> 0.28696989 | E7: =Class_5!E49 -> -0.0078441564 | F7: =Class_5!F49 -> 0.14011214 | G7: =Class_5!G49 -> -0.17568595 | H7: =Class_5!H49 -> 0.26484809 | I7: =Class_5!I49 -> -0.14242635 | ... AW7: =Class_5!AW49 -> 1
A8: 6 | B8: =Class_6!B49 -> -0.23446258 | C8: =Class_6!C49 -> 0.098167815 | D8: =Class_6!D49 -> -0.014831716 | E8: =Class_6!E49 -> 0.030865903 | F8: =Class_6!F49 -> 0.022460961 | G8: =Class_6!G49 -> -0.048476684 | H8: =Class_6!H49 -> -0.13279115 | I8: =Class_6!I49 -> 0.00035303932 | ... AW8: =Class_6!AW49 -> 1
A9: 7 | B9: =Class_7!B49 -> 0.075119564 | C9: =Class_7!C49 -> 0.040690745 | D9: =Class_7!D49 -> 0.067441586 | E9: =Class_7!E49 -> 0.22631806 | F9: =Class_7!F49 -> 0.10960237 | G9: =Class_7!G49 -> 0.041359449 | H9: =Class_7!H49 -> 0.10053038 | I9: =Class_7!I49 -> -0.012738792 | ... AW9: =Class_7!AW49 -> 1
A10: 8 | B10: =Class_8!B49 -> 0.17379615 | C10: =Class_8!C49 -> 0.0076330658 | D10: =Class_8!D49 -> -0.060189083 | E10: =Class_8!E49 -> -0.19498933 | F10: =Class_8!F49 -> -0.079352389 | G10: =Class_8!G49 -> 0.0035878043 | H10: =Class_8!H49 -> -0.036223874 | I10: =Class_8!I49 -> 0.12191489 | ... AW10: =Class_8!AW49 -> 1
A11: 9 | B11: =Class_9!B49 -> -0.0037904267 | C11: =Class_9!C49 -> 0.12855339 | D11: =Class_9!D49 -> 0.088727094 | E11: =Class_9!E49 -> -0.073569738 | F11: =Class_9!F49 -> -0.071284294 | G11: =Class_9!G49 -> -0.11667369 | H11: =Class_9!H49 -> -0.025812281 | I11: =Class_9!I49 -> 0.049859423 | ... AW11: =Class_9!AW49 -> 1

Sheet Class_0
B1: features.5.block.0.0 | C1: sensitivityscore_After_features.5.block.0.0_0.5 | D1: sensitivityscore_After_features.5.block.0.0_0.6 | E1: sensitivityscore_After_features.5.block.0.0_0.7 | F1: features.5.block.1.0 | G1: sensitivityscore_After_features.5.block.1.0_0.5 | H1: sensitivityscore_After_features.5.block.1.0_0.6 | I1: sensitivityscore_After_features.5.block.1.0_0.7 | J1: features.5.block.2.fc2 | K1: sensitivityscore_After_features.5.block.2.fc2_0.5 | L1: sensitivityscore_After_features.5.block.2.fc2_0.6 | M1: sensitivityscore_After_features.5.block.2.fc2_0.7 | N1: features.5.block.3.0 | O1: sensitivityscore_After_features.5.block.3.0_0.5 | P1: sensitivityscore_After_features.5.block.3.0_0.6 | Q1: sensitivityscore_After_features.5.block.3.0_0.7 | R1: features.6.block.0.0 | S1: sensitivityscore_After_features.6.block.0.0_0.5 | T1: sensitivityscore_After_features.6.block.0.0_0.6 | U1: sensitivityscore_After_features.6.block.0.0_0.7 | V1: features.6.block.1.0 | W1: sensitivityscore_After_features.6.block.1.0_0.5 | X1: sensitivityscore_After_features.6.block.1.0_0.6 | Y1: sensitivityscore_After_features.6.block.1.0_0.7 | Z1: features.6.block.2.fc2 | AA1: sensitivityscore_After_features.6.block.2.fc2_0.5 | AB1: sensitivityscore_After_features.6.block.2.fc2_0.6 | AC1: sensitivityscore_After_features.6.block.2.fc2_0.7 | AD1: features.6.block.3.0 | AE1: sensitivityscore_After_features.6.block.3.0_0.5 | AF1: sensitivityscore_After_features.6.block.3.0_0.6 | AG1: sensitivityscore_After_features.6.block.3.0_0.7 | AH1: features.7.block.0.0 | AI1: sensitivityscore_After_features.7.block.0.0_0.5 | AJ1: sensitivityscore_After_features.7.block.0.0_0.6 | AK1: sensitivityscore_After_features.7.block.0.0_0.7 | AL1: features.7.block.1.0 | AM1: sensitivityscore_After_features.7.block.1.0_0.5 | AN1: sensitivityscore_After_features.7.block.1.0_0.6 | AO1: sensitivityscore_After_features.7.block.1.0_0.7 | AP1: features.7.block.2.fc2 | AQ1: sensitivityscore_After_features.7.block.2.fc2_0.5 | AR1: sensitivityscore_After_features.7.block.2.fc2_0.6 | AS1: sensitivityscore_After_features.7.block.2.fc2_0.7 | AT1: features.7.block.3.0 | AU1: sensitivityscore_After_features.7.block.3.0_0.5 | AV1: sensitivityscore_After_features.7.block.3.0_0.6 | AW1: sensitivityscore_After_features.7.block.3.0_0.7
A2: features.5.block.0.0 | B2: 1 | C2: 0.040155332 | D2: 0.16856954 | E2: 0.39606985 | F2: 0.64921845 | G2: 0.06984133 | H2: 0.00095883116 | I2: -0.085167376 | J2: 0.43933786 | K2: -0.022068488 | L2: -0.03393404 | M2: -0.07837436 | N2: 0.22143946 | O2: 0.11221528 | P2: -0.16244688 | Q2: 0.018408432 | R2: -0.21671077 | S2: -0.015027118 | T2: -0.10495831 | U2: 0.00091929301 | V2: 0.035399195 | W2: -0.08133563 | X2: 0.052983821 | Y2: -0.33081098 | Z2: 0.17085059 | AA2: -0.10564098 | AB2: 0.019125423 | AC2: -0.027621944 | AD2: -0.11058355 | AE2: -0.065790204 | AF2: 0.12728976 | AG2: 0.063845617 | AH2: 0.19185965 | AI2: -0.014427901 | AJ2: 0.0069779512 | AK2: -0.076832084 | AL2: -0.044615612 | AM2: -0.16504371 | AN2: 0.071396581 | AO2: -0.07223617 | AP2: 0.35347938 | AQ2: 0.16441002 | AR2: 0.12057472 | AS2: -0.061509233 | AT2: 0.095541893 | AU2: -0.30072974 | AV2: 0.26775719 | AW2: 0.0011500097
A3: sensitivityscore_After_features.5.block.0.0_0.5 | B3: 0.040155332 | C3: 1 | D3: 0.41724415 | E3: 0.22344695 | F3: 0.17238469 | G3: 0.033132536 | H3: 0.043439232 | I3: 0.031665221 | J3: 0.18326102 | K3: 0.1639752 | L3: 0.069507948 | M3: 0.04825379 | N3: -0.26208875 | O3: 0.0018861662 | P3: 0.21792967 | Q3: -0.16216549 | R3: 0.0086395029 | S3: 0.064712421 | T3: -0.022200974 | U3: 0.15196014 | V3: 0.027057719 | W3: 0.074971303 | X3: -0.1146553 | Y3: 0.043413769 | Z3: 0.035884378 | AA3: 0.31798344 | AB3: 0.22056783 | AC3: 0.12902958 | AD3: -0.12908987 | AE3: -0.0069835982 | AF3: 0.20624311 | AG3: 0.26867025 | AH3: -0.24240097 | AI3: 0.043097158 | AJ3: 0.13367029 | AK3: 0.20730124 | AL3: 0.050956618 | AM3: -0.014247059 | AN3: -0.082898844 | AO3: -0.12069809 | AP3: -0.16359645 | AQ3: 0.066354256 | AR3: 0.034434005 | AS3: -0.0090553681 | AT3: 0.023387526 | AU3: -0.17725595 | AV3: 0.039766075 | AW3: 0.10376321
A4: sensitivityscore_After_features.5.block.0.0_0.6 | B4: 0.16856954 | C4: 0.41724415 | D4: 1 | E4: 0.38490913 | F4: 0.22781574 | G4: 0.12296775 | H4: 0.013643021 | I4: 0.02285503 | J4: 0.22393644 | K4: -0.11667518 | L4: -0.15408014 | M4: -0.14033234 | N4: -0.072786447 | O4: -0.19072948 | P4: -0.069057088 | Q4: -0.17837376 | R4: -0.0096628852 | S4: 0.11807147 | T4: 0.014385242 | U4: 0.28679354 | V4: 0.05860213 | W4: -0.0029279052 | X4: -0.18848883 | Y4: 0.0044673715 | Z4: 0.047337182 | AA4: 0.011597814 | AB4: 0.083975756 | AC4: -0.18697816 | AD4: -0.18646378 | AE4: -0.036890686 | AF4: 0.14218892 | AG4: 0.12715392 | AH4: -0.13159827 | AI4: -0.076456139 | AJ4: -0.081249896 | AK4: -0.10689707 | AL4: 0.036239417 | AM4: -0.31630899 | AN4: -0.19059333 | AO4: -0.21334992 | AP4: -0.027778233 | AQ4: 0.086282329 | AR4: 0.15905394 | AS4: 0.12336315 | AT4: 0.077578521 | AU4: -0.0014087865 | AV4: 0.10753894 | AW4: 0.14208394
A5: sensitivityscore_After_features.5.block.0.0_0.7 | B5: 0.39606985 | C5: 0.22344695 | D5: 0.38490913 | E5: 1 | F5: 0.29999632 | G5: 0.084549177 | H5: -0.083474825 | I5: -0.042778885 | J5: 0.16835838 | K5: -0.007862932 | L5: 0.015494962 | M5: -0.03525722 | N5: -0.083761358 | O5: -0.069200225 | P5: 0.010937168 | Q5: 0.058021251 | R5: -0.013617016 | S5: 0.1069183 | T5: -0.078295323 | U5: -0.099283916 | V5: 0.048954402 | W5: 0.0090041804 | X5: -0.15624697 | Y5: -0.28567136 | Z5: 0.059140028 | AA5: -0.011232948 | AB5: 0.033575098 | AC5: -0.068577929 | AD5: 0.059737248 | AE5: -0.063448854 | AF5: 0.16254294 | AG5: -0.039101184 | AH5: 0.22402326 | AI5: -0.17822709 | AJ5: -0.14383892 | AK5: -0.0023312806 | AL5: 0.061766045 | AM5: -0.083001432 | AN5: 0.006365463 | AO5: -0.16881708 | AP5: 0.14194075 | AQ5: 0.073101604 | AR5: 0.06377106 | AS5: 0.013396808 | AT5: 0.28608764 | AU5: -0.16974672 | AV5: 0.29815438 | AW5: 0.0090042531
A6: features.5.block.1.0 | B6: 0.64921845 | C6: 0.17238469 | D6: 0.22781574 | E6: 0.29999632 | F6: 1 | G6: -0.009789403 | H6: -0.012950037 | I6: 0.045206001 | J6: 0.36355695 | K6: 0.015150183 | L6: 0.14220803 | M6: 0.18711882 | N6: 0.16566583 | O6: 0.21531398 | P6: -0.27677969 | Q6: 0.041928776 | R6: -0.1154689 | S6: 0.18952037 | T6: 0.057660447 | U6: -0.04510339 | V6: 0.097265449 | W6: -0.18907173 | X6: -0.15247605 | Y6: -0.45190778 | Z6: 0.43726905 | AA6: -0.065774262 | AB6: -0.0026272092 | AC6: -0.093015919 | AD6: -0.016219583 | AE6: -0.016025486 | AF6: -0.060613441 | AG6: -0.00059219011 | AH6: 0.20237759 | AI6: -0.12106338 | AJ6: 0.023309845 | AK6: -0.023624226 | AL6: -0.0082434481 | AM6: -0.16355325 | AN6: -0.021791577 | AO6: -0.055063716 | AP6: 0.28739729 | AQ6: 0.23676447 | AR6: 0.18928374 | AS6: -0.045299047 | AT6: 0.15858607 | AU6: -0.079278613 | AV6: 0.12997327 | AW6: 0.11136113
A7: sensitivityscore_After_features.5.block.1.0_0.5 | B7: 0.06984133 | C7: 0.033132536 | D7: 0.12296775 | E7: 0.084549177 | F7: -0.009789403 | G7: 1 | H7: 0.44278001 | I7: 0.60126214 | J7: 0.13659084 | K7: -0.25639922 | L7: -0.10537208 | M7: -0.072537894 | N7: 0.19424687 | O7: 0.077847449 | P7: 0.077577672 | Q7: -0.045171946 | R7: 0.040646391 | S7: 0.051858539 | T7: 0.04276425 | U7: 0.024536618 | V7: 0.14566757 | W7: -0.087268806 | X7: -0.010127957 | Y7: -0.038701413 | Z7: -0.21366747 | AA7: -0.086007301 | AB7: -0.16705478 | AC7: 0.053147119 | AD7: 0.14228298 | AE7: -0.12089463 | AF7: -0.21486935 | AG7: -0.23983303 | AH7: -0.19561066 | AI7: 0.22607006 | AJ7: 0.10897089 | AK7: 0.062102317 | AL7: -0.26930043 | AM7: 0.14352373 | AN7: 0.020768676 | AO7: 0.28843523 | AP7: 0.11600064 | AQ7: 0.24397579 | AR7: 0.13401303 | AS7: 0.17563873 | AT7: -0.20735106 | AU7: 0.13794389 | AV7: -0.0035223088 | AW7: -0.095261806
A8: sensitivityscore_After_features.5.block.1.0_0.6 | B8: 0.00095883116 | C8: 0.043439232 | D8: 0.013643021 | E8: -0.083474825 | F8: -0.012950037 | G8: 0.44278001 | H8: 1 | I8: 0.48792392 | J8: 0.20608348 | K8: -0.15060825 | L8: -0.20485723 | M8: -0.10392822 | N8: 0.11355046 | O8: 0.012201836 | P8: 0.14556341 | Q8: -0.14241968 | R8: -0.16662987 | S8: -0.01936002 | T8: -0.075722438 | U8: -0.13298465 | V8: -0.087945785 | W8: 0.3105709 | X8: 0.22823396 | Y8: 0.15473609 | Z8: -0.22039557 | AA8: -0.07888682 | AB8: -0.29153586 | AC8: -0.19841575 | AD8: 0.15999793 | AE8: 0.17399672 | AF8: 0.030075079 | AG8: 0.12884705 | AH8: 0.11330911 | AI8: -0.050880879 | AJ8: 0.032624426 | AK8: -0.040845612 | AL8: 0.045859834 | AM8: 0.15934777 | AN8: -0.068857125 | AO8: 0.15707942 | AP8: 0.070579461 | AQ8: 0.01080186 | AR8: -0.012463065 | AS8: -0.068362587 | AT8: -0.15313852 | AU8: -0.064100436 | AV8: 0.05343113 | AW8: 0.055502664
A9: sensitivityscore_After_features.5.block.1.0_0.7 | B9: -0.085167376 | C9: 0.031665221 | D9: 0.02285503 | E9: -0.042778885 | F9: 0.045206001 | G9: 0.60126214 | H9: 0.48792392 | I9: 1 | J9: 0.19867034 | K9: -0.41688324 | L9: -0.10167872 | M9: -0.041156037 | N9: 0.099132578 | O9: 0.11502266 | P9: -0.0059504698 | Q9: -0.21355857 | R9: -0.01515769 | S9: -0.11219899 | T9: 0.045932949 | U9: -0.044974057 | V9: 0.11812267 | W9: -0.080788276 | X9: -0.08929934 | Y9: 0.10345536 | Z9: -0.11525455 | AA9: -0.16738918 | AB9: -0.33677059 | AC9: -0.16851528 | AD9: 0.01642632 | AE9: 0.023126805 | AF9: -0.14296423 | AG9: -0.038946822 | AH9: -0.12169077 | AI9: 0.058987748 | AJ9: 0.034268013 | AK9: -0.014055899 | AL9: -0.023924429 | AM9: 0.18287665 | AN9: 0.119673 | AO9: 0.27312281 | AP9: 0.050262204 | AQ9: 0.13073484 | AR9: 0.13885169 | AS9: 0.080959322 | AT9: -0.17860972 | AU9: 0.34549454 | AV9: -0.17290954 | AW9: -0.14512435
A10: features.5.block.2.fc2 | B10: 0.43933786 | C10: 0.18326102 | D10: 0.22393644 | E10: 0.16835838 | F10: 0.36355695 | G10: 0.13659084 | H10: 0.20608348 | I10: 0.19867034 | J10: 1 | K10: -0.164824 | L10: -0.050323081 | M10: 0.036660083 | N10: 0.13832162 | O10: 0.20502078 | P10: 0.1151464 | Q10: 0.0025812384 | R10: -0.31191317 | S10: -0.023345902 | T10: -0.032943648 | U10: 0.10633526 | V10: -0.25707959 | W10: 0.18386921 | X10: 0.047712041 | Y10: -0.038203994 | Z10: -0.086750776 | AA10: -0.19948012 | AB10: 0.031338143 | AC10: -0.059866102 | AD10: -0.10673225 | AE10: -0.18414356 | AF10: 0.013536429 | AG10: -0.062720413 | AH10: 0.094515557 | AI10: -0.13294737 | AJ10: -0.0028567489 | AK10: -0.30917706 | AL10: 0.0010661795 | AM10: -0.19967932 | AN10: -0.22302226 | AO10: 0.084972198 | AP10: -0.033918458 | AQ10: 0.0025697728 | AR10: 0.03396693 | AS10: -0.041253873 | AT10: 0.014566488 | AU10: -0.1381092 | AV10: 0.04480176 | AW10: 0.023442462
A11: sensitivityscore_After_features.5.block.2.fc2_0.5 | B11: -0.022068488 | C11: 0.1639752 | D11: -0.11667518 | E11: -0.007862932 | F11: 0.015150183 | G11: -0.25639922 | H11: -0.15060825 | I11: -0.41688324 | J11: -0.164824 | K11: 1 | L11: 0.55195569 | M11: 0.33657505 | N11: -0.25938195 | O11: -0.042830757 | P11: 0.027195677 | Q11: 0.24287045 | R11: 0.11326962 | S11: 0.091394304 | T11: 0.040421004 | U11: -0.030960585 | V11: 0.090899809 | W11: 0.040936085 | X11: 0.14650895 | Y11: -0.034100873 | Z11: 0.17263665 | AA11: 0.050769228 | AB11: 0.011221577 | AC11: 0.10345068 | AD11: -0.011418581 | AE11: 0.12440691 | AF11: 0.057047812 | AG11: 0.10305848 | AH11: 0.0037873826 | AI11: 0.024896231 | AJ11: -0.0290549 | AK11: 0.14018236 | AL11: -0.046002629 | AM11: 0.093733387 | AN11: 0.13867916 | AO11: -0.0094046791 | AP11: 0.1507174 | AQ11: 0.044631413 | AR11: -0.048087979 | AS11: -0.040214459 | AT11: 0.057671908 | AU11: -0.16573328 | AV11: -0.10479124 | AW11: 0.34324388
A12: sensitivityscore_After_features.5.block.2.fc2_0.6 | B12: -0.03393404 | C12: 0.069507948 | D12: -0.15408014 | E12: 0.015494962 | F12: 0.14220803 | G12: -0.10537208 | H12: -0.20485723 | I12: -0.10167872 | J12: -0.050323081 | K12: 0.55195569 | L12: 1 | M12: 0.79416055 | N12: -0.15475716 | O12: -0.16460599 | P12: -0.013655515 | Q12: 0.20505964 | R12: 0.0067664412 | S12: -0.14423387 | T12: 0.11505191 | U12: 0.048795748 | V12: 0.10315468 | W12: -0.096366462 | X12: -0.062324005 | Y12: -0.25920491 | Z12: 0.16951625 | AA12: -0.1285125 | AB12: -0.07353963 | AC12: 0.047567508 | AD12: -0.065246019 | AE12: 0.068581173 | AF12: -0.24015518 | AG12: -0.1123107 | AH12: -0.057199615 | AI12: -0.0069667073 | AJ12: 0.28649218 | AK12: 0.22239374 | AL12: -0.080720928 | AM12: 0.075382495 | AN12: 0.25429144 | AO12: 0.056678117 | AP12: 0.16431679 | AQ12: 0.12270163 | AR12: 0.12369057 | AS12: 0.11864094 | AT12: -0.10861339 | AU12: -0.026578797 | AV12: -0.17546734 | AW12: 0.22768832
A13: sensitivityscore_After_features.5.block.2.fc2_0.7 | B13: -0.07837436 | C13: 0.04825379 | D13: -0.14033234 | E13: -0.03525722 | F13: 0.18711882 | G13: -0.072537894 | H13: -0.10392822 | I13: -0.041156037 | J13: 0.036660083 | K13: 0.33657505 | L13: 0.79416055 | M13: 1 | N13: 0.030508884 | O13: -0.075411963 | P13: -0.15992913 | Q13: 0.24286315 | R13: 0.020341544 | S13: -0.1093411 | T13: 0.15622704 | U13: 0.072047763 | V13: 0.1514201 | W13: -0.10153904 | X13: -0.14240238 | Y13: -0.25478171 | Z13: 0.10880678 | AA13: -0.17179904 | AB13: -0.094552232 | AC13: 0.029447822 | AD13: 0.088677019 | AE13: 0.027860464 | AF13: -0.3016683 | AG13: -0.064559858 | AH13: 0.030438485 | AI13: -0.043736817 | AJ13: 0.14876628 | AK13: 0.075973461 | AL13: -0.022165829 | AM13: 0.19042143 | AN13: 0.18312532 | AO13: 0.11642591 | AP13: 0.1959298 | AQ13: 0.36206892 | AR13: 0.31291071 | AS13: 0.17370432 | AT13: -0.073163179 | AU13: 0.024701126 | AV13: -0.31940039 | AW13: 0.29712977
... A49: sensitivityscore_After_features.7.block.3.0_0.7 | B49: 0.0011500097 | C49: 0.10376321 | D49: 0.14208394 | E49: 0.0090042531 | F49: 0.11136113 | G49: -0.095261806 | H49: 0.055502664 | I49: -0.14512435 | J49: 0.023442462 | K49: 0.34324388 | L49: 0.22768832 | M49: 0.29712977 | N49: -0.25674604 | O49: -0.075780134 | P49: -0.21262756 | Q49: 0.15865883 | R49: -0.024170029 | S49: -0.050236749 | T49: -0.048057957 | U49: 0.17512297 | V49: 0.017142589 | W49: 0.062791928 | X49: 0.12783163 | Y49: 0.01293515 | Z49: 0.10866563 | AA49: -0.041078269 | AB49: -0.070751605 | AC49: -0.027111 | AD49: -0.2865805 | AE49: 0.23283373 | AF49: 0.051329695 | AG49: 0.12195933 | AH49: -0.33825333 | AI49: -0.034899383 | AJ49: 0.030602599 | AK49: 0.14555287 | AL49: -0.23736738 | AM49: 0.055142588 | AN49: 0.10063789 | AO49: 0.17208856 | AP49: 0.14215757 | AQ49: 0.16777615 | AR49: 0.078020804 | AS49: -0.057843117 | AT49: -0.17792942 | AU49: -0.075595623 | AV49: -0.003539918 | AW49: 1

Sheet Class_1
B1: features.5.block.0.0 | C1: sensitivityscore_After_features.5.block.0.0_0.5 | D1: sensitivityscore_After_features.5.block.0.0_0.6 | E1: sensitivityscore_After_features.5.block.0.0_0.7 | F1: features.5.block.1.0 | G1: sensitivityscore_After_features.5.block.1.0_0.5 | H1: sensitivityscore_After_features.5.block.1.0_0.6 | I1: sensitivityscore_After_features.5.block.1.0_0.7 | J1: features.5.block.2.fc2 | K1: sensitivityscore_After_features.5.block.2.fc2_0.5 | L1: sensitivityscore_After_features.5.block.2.fc2_0.6 | M1: sensitivityscore_After_features.5.block.2.fc2_0.7 | N1: features.5.block.3.0 | O1: sensitivityscore_After_features.5.block.3.0_0.5 | P1: sensitivityscore_After_features.5.block.3.0_0.6 | Q1: sensitivityscore_After_features.5.block.3.0_0.7 | R1: features.6.block.0.0 | S1: sensitivityscore_After_features.6.block.0.0_0.5 | T1: sensitivityscore_After_features.6.block.0.0_0.6 | U1: sensitivityscore_After_features.6.block.0.0_0.7 | V1: features.6.block.1.0 | W1: sensitivityscore_After_features.6.block.1.0_0.5 | X1: sensitivityscore_After_features.6.block.1.0_0.6 | Y1: sensitivityscore_After_features.6.block.1.0_0.7 | Z1: features.6.block.2.fc2 | AA1: sensitivityscore_After_features.6.block.2.fc2_0.5 | AB1: sensitivityscore_After_features.6.block.2.fc2_0.6 | AC1: sensitivityscore_After_features.6.block.2.fc2_0.7 | AD1: features.6.block.3.0 | AE1: sensitivityscore_After_features.6.block.3.0_0.5 | AF1: sensitivityscore_After_features.6.block.3.0_0.6 | AG1: sensitivityscore_After_features.6.block.3.0_0.7 | AH1: features.7.block.0.0 | AI1: sensitivityscore_After_features.7.block.0.0_0.5 | AJ1: sensitivityscore_After_features.7.block.0.0_0.6 | AK1: sensitivityscore_After_features.7.block.0.0_0.7 | AL1: features.7.block.1.0 | AM1: sensitivityscore_After_features.7.block.1.0_0.5 | AN1: sensitivityscore_After_features.7.block.1.0_0.6 | AO1: sensitivityscore_After_features.7.block.1.0_0.7 | AP1: features.7.block.2.fc2 | AQ1: sensitivityscore_After_features.7.block.2.fc2_0.5 | AR1: sensitivityscore_After_features.7.block.2.fc2_0.6 | AS1: sensitivityscore_After_features.7.block.2.fc2_0.7 | AT1: features.7.block.3.0 | AU1: sensitivityscore_After_features.7.block.3.0_0.5 | AV1: sensitivityscore_After_features.7.block.3.0_0.6 | AW1: sensitivityscore_After_features.7.block.3.0_0.7
A2: features.5.block.0.0 | B2: 1 | C2: -0.039505294 | D2: 0.05696322 | E2: -0.061434414 | F2: 0.72143629 | G2: 0.11397801 | H2: -0.042570182 | I2: 0.13019178 | J2: 0.45661645 | K2: -0.0041591383 | L2: 0.03249871 | M2: 0.032220378 | N2: 0.48188113 | O2: 0.11680005 | P2: -0.068766622 | Q2: 0.25811288 | R2: 0.087477507 | S2: 0.048634747 | T2: 0.0044179838 | U2: -0.12941461 | V2: 0.21401246 | W2: -0.11748227 | X2: -0.12150339 | Y2: -0.012300776 | Z2: 0.042485623 | AA2: 0.095121614 | AB2: 0.094409266 | AC2: 0.011976611 | AD2: 0.16867227 | AE2: -0.12396105 | AF2: -0.031502388 | AG2: 0.30903878 | AH2: 0.088190731 | AI2: 0.12760086 | AJ2: 0.21217715 | AK2: 0.097323383 | AL2: 0.1662703 | AM2: 0.24788039 | AN2: 0.32860178 | AO2: 0.1324416 | AP2: -0.064800097 | AQ2: -0.22635763 | AR2: -0.10149409 | AS2: -0.051793622 | AT2: -0.10556908 | AU2: 0.072231196 | AV2: 0.097305241 | AW2: 0.073092053
A3: sensitivityscore_After_features.5.block.0.0_0.5 | B3: -0.039505294 | C3: 1 | D3: 0.65936108 | E3: 0.56235433 | F3: 0.031099009 | G3: 0.084081835 | H3: 0.31179558 | I3: 0.23574899 | J3: -0.049516952 | K3: 0.11523823 | L3: -0.032260178 | M3: 0.068899795 | N3: -0.10068266 | O3: 8.0126986e-05 | P3: -0.071161292 | Q3: -0.0033538976 | R3: 0.015717814 | S3: -0.038155198 | T3: 0.05055765 | U3: 0.015883559 | V3: -0.030577965 | W3: 0.06539041 | X3: 0.096393038 | Y3: 0.11019391 | Z3: -0.14573696 | AA3: -0.15468096 | AB3: 0.016199373 | AC3: 0.088789817 | AD3: -0.12250535 | AE3: 0.0032972161 | AF3: -0.046432357 | AG3: -0.11461145 | AH3: 0.13166643 | AI3: -0.079381649 | AJ3: 0.044868736 | AK3: -0.019753981 | AL3: 0.24351633 | AM3: -0.12354292 | AN3: -0.27919413 | AO3: -0.049312721 | AP3: -0.03164842 | AQ3: 0.060309051 | AR3: 0.24743595 | AS3: 0.11154195 | AT3: 0.26758596 | AU3: -0.17190688 | AV3: -0.023490735 | AW3: 0.0073313764
A4: sensitivityscore_After_features.5.block.0.0_0.6 | B4: 0.05696322 | C4: 0.65936108 | D4: 1 | E4: 0.48464598 | F4: 0.17444957 | G4: 0.21790455 | H4: 0.24381847 | I4: 0.10251229 | J4: 0.019869615 | K4: 0.16326706 | L4: -0.04469552 | M4: -0.1787369 | N4: 0.15684366 | O4: 0.11392478 | P4: -0.026772049 | Q4: 0.078029101 | R4: 0.26369618 | S4: -0.10653142 | T4: 0.036723109 | U4: -0.030221629 | V4: -0.00050962505 | W4: 0.055925032 | X4: 0.27409998 | Y4: 0.24751862 | Z4: -0.066963528 | AA4: -0.067596754 | AB4: 0.16454929 | AC4: 0.24595836 | AD4: 0.14553033 | AE4: 0.1219375 | AF4: -0.020250842 | AG4: -0.16795545 | AH4: 0.20628688 | AI4: 0.034211209 | AJ4: 0.14268834 | AK4: 0.084356564 | AL4: 0.076805834 | AM4: -0.097486977 | AN4: -0.36673808 | AO4: -0.23446201 | AP4: -0.06578709 | AQ4: -0.067127271 | AR4: 0.12102057 | AS4: 0.14700967 | AT4: 0.25045921 | AU4: -0.031140345 | AV4: 0.01315884 | AW4: 0.21647044
A5: sensitivityscore_After_features.5.block.0.0_0.7 | B5: -0.061434414 | C5: 0.56235433 | D5: 0.48464598 | E5: 1 | F5: 0.097370443 | G5: 0.10779414 | H5: 0.22084737 | I5: 0.14733527 | J5: 0.012189588 | K5: 0.20245505 | L5: -0.032133057 | M5: -0.093934514 | N5: -0.090478237 | O5: -0.014258353 | P5: -0.023487062 | Q5: -0.14816349 | R5: -0.057783196 | S5: -0.11663044 | T5: 0.24543931 | U5: 0.21538943 | V5: 0.058987416 | W5: 0.15567346 | X5: 0.1265576 | Y5: 0.20106133 | Z5: -0.11776561 | AA5: -0.099390778 | AB5: -0.11564369 | AC5: 0.22019769 | AD5: 0.09467845 | AE5: 0.014229884 | AF5: 0.0037032667 | AG5: -0.015752796 | AH5: 0.25090349 | AI5: 0.15281782 | AJ5: 0.26751789 | AK5: 0.12244109 | AL5: 0.14971355 | AM5: -0.066633117 | AN5: -0.1380964 | AO5: 0.028332906 | AP5: -0.012569788 | AQ5: -0.12718504 | AR5: 0.14900285 | AS5: 0.15414425 | AT5: 0.24733585 | AU5: 0.0069371572 | AV5: 0.073855316 | AW5: 0.13495408
A6: features.5.block.1.0 | B6: 0.72143629 | C6: 0.031099009 | D6: 0.17444957 | E6: 0.097370443 | F6: 1 | G6: 0.14171942 | H6: -0.083340443 | I6: -0.038473635 | J6: 0.49603805 | K6: -0.037184904 | L6: -0.13521505 | M6: -0.08881381 | N6: 0.54956432 | O6: 0.071221459 | P6: -0.01132241 | Q6: 0.17469949 | R6: 0.1231125 | S6: -0.081882513 | T6: 0.084039469 | U6: 0.024211141 | V6: 0.043778917 | W6: -0.13902093 | X6: -0.11815862 | Y6: -0.1383695 | Z6: -0.064474082 | AA6: -0.12286029 | AB6: -0.022815803 | AC6: 0.073171697 | AD6: 0.19549731 | AE6: 0.02611424 | AF6: 0.16191249 | AG6: 0.32773586 | AH6: 0.03882346 | AI6: 0.0023530051 | AJ6: 0.14606265 | AK6: 0.057175913 | AL6: 0.11071687 | AM6: 0.18161401 | AN6: 0.14793969 | AO6: 0.17805737 | AP6: -0.26930073 | AQ6: -0.20460408 | AR6: -0.043732132 | AS6: 0.057910609 | AT6: 0.043896735 | AU6: -0.01900696 | AV6: 0.066747097 | AW6: 0.17283101
A7: sensitivityscore_After_features.5.block.1.0_0.5 | B7: 0.11397801 | C7: 0.084081835 | D7: 0.21790455 | E7: 0.10779414 | F7: 0.14171942 | G7: 1 | H7: 0.3709925 | I7: 0.25290008 | J7: 0.062298778 | K7: -0.046615484 | L7: -0.015642878 | M7: -0.07326719 | N7: 0.24995682 | O7: -0.10345264 | P7: 0.13315557 | Q7: 0.13731832 | R7: -0.10041781 | S7: -0.068613756 | T7: 0.15382821 | U7: -0.071004051 | V7: -0.16227412 | W7: 0.041415679 | X7: 0.037536902 | Y7: -0.077103366 | Z7: 0.12645895 | AA7: 0.09732495 | AB7: -0.0095218603 | AC7: 0.088714685 | AD7: 0.019454245 | AE7: 0.031144685 | AF7: 0.15579027 | AG7: 0.11014974 | AH7: -0.12827483 | AI7: 0.064527442 | AJ7: 0.098117593 | AK7: 0.097517994 | AL7: -0.12839354 | AM7: 0.14829184 | AN7: -0.085049544 | AO7: 0.053919176 | AP7: -0.019395784 | AQ7: -0.1202232 | AR7: 0.12978624 | AS7: 0.13766078 | AT7: 0.077616157 | AU7: 0.28766633 | AV7: 0.029670915 | AW7: -0.20585343
A8: sensitivityscore_After_features.5.block.1.0_0.6 | B8: -0.042570182 | C8: 0.31179558 | D8: 0.24381847 | E8: 0.22084737 | F8: -0.083340443 | G8: 0.3709925 | H8: 1 | I8: 0.42487984 | J8: 0.0264279 | K8: 0.09482575 | L8: -0.094162291 | M8: -0.076241472 | N8: 0.033427514 | O8: 0.076650661 | P8: -0.061662074 | Q8: -0.0058156474 | R8: -0.018529241 | S8: -0.19086321 | T8: -0.19593184 | U8: -0.054600491 | V8: -0.01896841 | W8: 0.20038222 | X8: 0.11661806 | Y8: 0.096742423 | Z8: 0.094516565 | AA8: -0.075877498 | AB8: -0.096288478 | AC8: 0.040470094 | AD8: -0.19527287 | AE8: -0.065195414 | AF8: 0.017075138 | AG8: -0.030113463 | AH8: 0.10373207 | AI8: -0.16958778 | AJ8: -0.13527778 | AK8: -0.062884634 | AL8: 0.043088386 | AM8: 0.22670607 | AN8: 0.12571923 | AO8: 0.15305146 | AP8: -0.054155404 | AQ8: 0.012312638 | AR8: 0.11909474 | AS8: 0.043707429 | AT8: 0.35623388 | AU8: -0.015843729 | AV8: -0.20568412 | AW8: -0.26228604
A9: sensitivityscore_After_features.5.block.1.0_0.7 | B9: 0.13019178 | C9: 0.23574899 | D9: 0.10251229 | E9: 0.14733527 | F9: -0.038473635 | G9: 0.25290008 | H9: 0.42487984 | I9: 1 | J9: 0.036428318 | K9: 0.26067735 | L9: 0.084686165 | M9: 0.015375964 | N9: 0.024278594 | O9: 0.2417254 | P9: 0.21580352 | Q9: 0.35827636 | R9: -0.12775841 | S9: -0.052744001 | T9: -0.014965487 | U9: -0.086485249 | V9: 0.28001759 | W9: 0.2220505 | X9: -0.078897347 | Y9: 0.14266856 | Z9: 0.10667108 | AA9: 0.13887517 | AB9: -0.051361146 | AC9: 0.038196069 | AD9: -0.12147063 | AE9: -0.029661981 | AF9: -0.036687834 | AG9: 0.1126654 | AH9: 0.13605325 | AI9: -0.13928746 | AJ9: 0.001737858 | AK9: -0.11403707 | AL9: 0.12230211 | AM9: 0.30088786 | AN9: 0.19153387 | AO9: 0.20274577 | AP9: 0.14979882 | AQ9: 0.018172622 | AR9: 0.17901427 | AS9: 0.12127367 | AT9: 0.0028641065 | AU9: 0.065545952 | AV9: 0.18293981 | AW9: -0.041960112
A10: features.5.block.2.fc2 | B10: 0.45661645 | C10: -0.049516952 | D10: 0.019869615 | E10: 0.012189588 | F10: 0.49603805 | G10: 0.062298778 | H10: 0.0264279 | I10: 0.036428318 | J10: 1 | K10: -0.04955584 | L10: -0.11571729 | M10: 0.010912338 | N10: 0.4033471 | O10: 0.10131891 | P10: -0.11290964 | Q10: 0.19742798 | R10: -0.037026258 | S10: 0.34287018 | T10: 0.14767989 | U10: 0.31836789 | V10: 0.060029635 | W10: -0.15120816 | X10: -0.37290183 | Y10: -0.23378716 | Z10: 0.069489428 | AA10: -0.35200899 | AB10: -0.27463837 | AC10: -0.31889379 | AD10: 0.15635091 | AE10: -0.025151355 | AF10: 0.24301448 | AG10: 0.3028046 | AH10: -0.083124416 | AI10: -0.032596294 | AJ10: 0.22057237 | AK10: 0.17105849 | AL10: -0.0076633017 | AM10: 0.2368945 | AN10: 0.053892791 | AO10: 0.0032407366 | AP10: 0.0028362627 | AQ10: -0.14360797 | AR10: -0.063933171 | AS10: 0.0007681645 | AT10: -0.10954049 | AU10: 0.021052116 | AV10: 0.024155354 | AW10: 0.015402912
A11: sensitivityscore_After_features.5.block.2.fc2_0.5 | B11: -0.0041591383 | C11: 0.11523823 | D11: 0.16326706 | E11: 0.20245505 | F11: -0.037184904 | G11: -0.046615484 | H11: 0.09482575 | I11: 0.26067735 | J11: -0.04955584 | K11: 1 | L11: 0.5278662 | M11: 0.43983495 | N11: -0.20391349 | O11: 0.23477546 | P11: 0.16625945 | Q11: 0.37300602 | R11: 0.00080244989 | S11: -0.17265106 | T11: -0.066485077 | U11: -0.12501795 | V11: 0.28450823 | W11: 0.043931051 | X11: -0.041563231 | Y11: 0.2449982 | Z11: -0.05405226 | AA11: 0.16707115 | AB11: 0.068483767 | AC11: 0.16568223 | AD11: 0.17378876 | AE11: -0.056268107 | AF11: -0.25123483 | AG11: -0.032223206 | AH11: 0.17346979 | AI11: -0.21452548 | AJ11: -0.16448677 | AK11: -0.24327131 | AL11: 0.091023481 | AM11: 0.10929496 | AN11: 0.26525045 | AO11: 0.41029633 | AP11: -0.13562003 | AQ11: -0.15389653 | AR11: -0.061268416 | AS11: -0.06458707 | AT11: 0.064612208 | AU11: 0.1823237 | AV11: -0.072439753 | AW11: -0.21335862
A12: sensitivityscore_After_features.5.block.2.fc2_0.6 | B12: 0.03249871 | C12: -0.032260178 | D12: -0.04469552 | E12: -0.032133057 | F12: -0.13521505 | G12: -0.015642878 | H12: -0.094162291 | I12: 0.084686165 | J12: -0.11571729 | K12: 0.5278662 | L12: 1 | M12: 0.78019032 | N12: -0.14493238 | O12: -0.00049322272 | P12: 0.16395218 | Q12: 0.16211175 | R12: -0.079281403 | S12: -0.12560854 | T12: -0.084967465 | U12: -0.19503188 | V12: 0.1809302 | W12: -0.071194874 | X12: 0.16381676 | Y12: -0.10979657 | Z12: 0.043948761 | AA12: 0.25105807 | AB12: 0.37092517 | AC12: 0.26707336 | AD12: -0.014836062 | AE12: -0.18895958 | AF12: -0.14322631 | AG12: 0.084657458 | AH12: -0.11005983 | AI12: 0.10074859 | AJ12: 0.13732523 | AK12: 0.097249607 | AL12: 0.00019755285 | AM12: -0.18461795 | AN12: -0.080512324 | AO12: 0.10516075 | AP12: 0.042184756 | AQ12: -0.028840183 | AR12: -0.034945484 | AS12: -0.051589268 | AT12: -0.17113882 | AU12: 0.031266229 | AV12: -0.036791727 | AW12: -0.21471524
A13: sensitivityscore_After_features.5.block.2.fc2_0.7 | B13: 0.032220378 | C13: 0.068899795 | D13: -0.1787369 | E13: -0.093934514 | F13: -0.08881381 | G13: -0.07326719 | H13: -0.076241472 | I13: 0.015375964 | J13: 0.010912338 | K13: 0.43983495 | L13: 0.78019032 | M13: 1 | N13: -0.15191829 | O13: -0.070482157 | P13: -0.013696854 | Q13: 0.13391179 | R13: -0.21050031 | S13: -0.068603987 | T13: -0.087116627 | U13: -0.090425745 | V13: 0.11795952 | W13: -0.12453994 | X13: 0.00349 | Y13: -0.13353933 | Z13: -0.04140508 | AA13: 0.14928092 | AB13: 0.22143947 | AC13: 0.12660624 | AD13: 0.031411556 | AE13: -0.13702531 | AF13: -0.055339708 | AG13: 0.19884808 | AH13: -0.1201155 | AI13: 0.038716155 | AJ13: 0.0038025755 | AK13: -0.085923788 | AL13: 0.062262097 | AM13: -0.15958165 | AN13: 0.026349056 | AO13: 0.12251714 | AP13: 0.019015059 | AQ13: -0.010449256 | AR13: -0.039647189 | AS13: -0.19460349 | AT13: -0.12291778 | AU13: -0.023765167 | AV13: -0.13463676 | AW13: -0.24831349
... A49: sensitivityscore_After_features.7.block.3.0_0.7 | B49: 0.073092053 | C49: 0.0073313764 | D49: 0.21647044 | E49: 0.13495408 | F49: 0.17283101 | G49: -0.20585343 | H49: -0.26228604 | I49: -0.041960112 | J49: 0.015402912 | K49: -0.21335862 | L49: -0.21471524 | M49: -0.24831349 | N49: 0.047044041 | O49: -0.027354584 | P49: -0.033753054 | Q49: -0.10093287 | R49: -0.10412065 | S49: -0.04161518 | T49: 0.036523177 | U49: 0.27973284 | V49: 0.085762254 | W49: 0.03920806 | X49: 0.14693737 | Y49: 0.25261377 | Z49: 0.050746292 | AA49: -0.098704157 | AB49: -0.038288955 | AC49: 0.081722638 | AD49: 0.080391874 | AE49: 0.24037337 | AF49: 0.17798235 | AG49: 0.088565362 | AH49: 0.2043331 | AI49: 0.28911991 | AJ49: 0.46928338 | AK49: 0.24319235 | AL49: 0.096237731 | AM49: 0.056505193 | AN49: -0.07414076 | AO49: -0.12133512 | AP49: 0.13167173 | AQ49: -0.028047789 | AR49: -0.0063276821 | AS49: 0.057913917 | AT49: 0.055755235 | AU49: -0.16179852 | AV49: 0.22429858 | AW49: 1

Sheet Class_2
B1: features.5.block.0.0 | C1: sensitivityscore_After_features.5.block.0.0_0.5 | D1: sensitivityscore_After_features.5.block.0.0_0.6 | E1: sensitivityscore_After_features.5.block.0.0_0.7 | F1: features.5.block.1.0 | G1: sensitivityscore_After_features.5.block.1.0_0.5 | H1: sensitivityscore_After_features.5.block.1.0_0.6 | I1: sensitivityscore_After_features.5.block.1.0_0.7 | J1: features.5.block.2.fc2 | K1: sensitivityscore_After_features.5.block.2.fc2_0.5 | L1: sensitivityscore_After_features.5.block.2.fc2_0.6 | M1: sensitivityscore_After_features.5.block.2.fc2_0.7 | N1: features.5.block.3.0 | O1: sensitivityscore_After_features.5.block.3.0_0.5 | P1: sensitivityscore_After_features.5.block.3.0_0.6 | Q1: sensitivityscore_After_features.5.block.3.0_0.7 | R1: features.6.block.0.0 | S1: sensitivityscore_After_features.6.block.0.0_0.5 | T1: sensitivityscore_After_features.6.block.0.0_0.6 | U1: sensitivityscore_After_features.6.block.0.0_0.7 | V1: features.6.block.1.0 | W1: sensitivityscore_After_features.6.block.1.0_0.5 | X1: sensitivityscore_After_features.6.block.1.0_0.6 | Y1: sensitivityscore_After_features.6.block.1.0_0.7 | Z1: features.6.block.2.fc2 | AA1: sensitivityscore_After_features.6.block.2.fc2_0.5 | AB1: sensitivityscore_After_features.6.block.2.fc2_0.6 | AC1: sensitivityscore_After_features.6.block.2.fc2_0.7 | AD1: features.6.block.3.0 | AE1: sensitivityscore_After_features.6.block.3.0_0.5 | AF1: sensitivityscore_After_features.6.block.3.0_0.6 | AG1: sensitivityscore_After_features.6.block.3.0_0.7 | AH1: features.7.block.0.0 | AI1: sensitivityscore_After_features.7.block.0.0_0.5 | AJ1: sensitivityscore_After_features.7.block.0.0_0.6 | AK1: sensitivityscore_After_features.7.block.0.0_0.7 | AL1: features.7.block.1.0 | AM1: sensitivityscore_After_features.7.block.1.0_0.5 | AN1: sensitivityscore_After_features.7.block.1.0_0.6 | AO1: sensitivityscore_After_features.7.block.1.0_0.7 | AP1: features.7.block.2.fc2 | AQ1: sensitivityscore_After_features.7.block.2.fc2_0.5 | AR1: sensitivityscore_After_features.7.block.2.fc2_0.6 | AS1: sensitivityscore_After_features.7.block.2.fc2_0.7 | AT1: features.7.block.3.0 | AU1: sensitivityscore_After_features.7.block.3.0_0.5 | AV1: sensitivityscore_After_features.7.block.3.0_0.6 | AW1: sensitivityscore_After_features.7.block.3.0_0.7
A2: features.5.block.0.0 | B2: 1 | C2: 0.27108774 | D2: 0.01982386 | E2: -0.019356318 | F2: 0.60977576 | G2: -0.22247979 | H2: -0.15008797 | I2: -0.067637627 | J2: 0.15070261 | K2: -0.032918991 | L2: -0.010009452 | M2: -0.024120054 | N2: 0.44151378 | O2: 0.36130324 | P2: 0.15548183 | Q2: 0.27129691 | R2: 0.28738702 | S2: -0.033981441 | T2: 0.17590122 | U2: 0.078484149 | V2: 0.3284837 | W2: -0.13933315 | X2: 0.04070156 | Y2: -0.085340954 | Z2: 0.4980918 | AA2: -0.10533205 | AB2: -0.19464544 | AC2: -0.038164883 | AD2: 0.035383436 | AE2: -0.072923174 | AF2: 0.031783413 | AG2: 0.057040233 | AH2: 0.036985339 | AI2: 0.059656578 | AJ2: 0.079514144 | AK2: -0.064244845 | AL2: -0.094711408 | AM2: 0.054791844 | AN2: -0.13898648 | AO2: -0.047242183 | AP2: -0.1032079 | AQ2: -0.08642658 | AR2: -0.011751417 | AS2: 0.010595206 | AT2: -0.18377025 | AU2: 0.02332188 | AV2: 0.0041765157 | AW2: -0.18352871
A3: sensitivityscore_After_features.5.block.0.0_0.5 | B3: 0.27108774 | C3: 1 | D3: 0.55412238 | E3: 0.44029093 | F3: 0.18875884 | G3: -0.33250934 | H3: -0.19302004 | I3: -0.24338006 | J3: -0.010155827 | K3: -0.059237056 | L3: -0.067263833 | M3: 0.026240656 | N3: -0.071587701 | O3: 0.0023562347 | P3: -0.052573062 | Q3: 0.13987845 | R3: -0.26074098 | S3: 0.093209995 | T3: 0.12420674 | U3: 0.070712701 | V3: 0.11790756 | W3: -0.34785507 | X3: -0.14197437 | Y3: -0.15848074 | Z3: 0.22640138 | AA3: 0.092305478 | AB3: 0.041980348 | AC3: -0.036012855 | AD3: -0.11361129 | AE3: -0.041963072 | AF3: 0.22179373 | AG3: 0.11628697 | AH3: -0.14974582 | AI3: -0.15522817 | AJ3: 0.13065396 | AK3: -0.028048471 | AL3: 0.057022214 | AM3: 0.039721939 | AN3: -0.082965179 | AO3: 0.081657335 | AP3: 0.18307701 | AQ3: -0.058090733 | AR3: 0.13920991 | AS3: 0.19771545 | AT3: -0.091374176 | AU3: -0.39195107 | AV3: -0.09159071 | AW3: 0.095875212
A4: sensitivityscore_After_features.5.block.0.0_0.6 | B4: 0.01982386 | C4: 0.55412238 | D4: 1 | E4: 0.73269555 | F4: 0.096111857 | G4: -0.032400469 | H4: -0.11028274 | I4: -0.26891981 | J4: 0.016410107 | K4: 0.0093109611 | L4: -0.083642385 | M4: 0.025227699 | N4: -0.18812386 | O4: 0.099177736 | P4: -0.041764822 | Q4: 0.28516496 | R4: -0.41873804 | S4: 0.2026591 | T4: 0.14173893 | U4: 0.2098821 | V4: -0.16497737 | W4: -0.087746522 | X4: 0.16656478 | Y4: 0.093953241 | Z4: -0.0059633082 | AA4: -0.20109727 | AB4: -0.076817093 | AC4: -0.28446901 | AD4: -0.04461909 | AE4: 0.14365531 | AF4: 0.31916209 | AG4: 0.32733815 | AH4: -0.14704691 | AI4: -0.12961812 | AJ4: 0.06107422 | AK4: 0.0067570429 | AL4: -0.069328629 | AM4: -0.046510962 | AN4: 0.0097167518 | AO4: -0.048340739 | AP4: 0.25336438 | AQ4: -0.16112711 | AR4: -0.018874393 | AS4: -0.051931683 | AT4: -0.02268409 | AU4: -0.099356652 | AV4: -0.24402525 | AW4: 0.41248567
A5: sensitivityscore_After_features.5.block.0.0_0.7 | B5: -0.019356318 | C5: 0.44029093 | D5: 0.73269555 | E5: 1 | F5: -0.0067484494 | G5: 0.11477275 | H5: 0.099955662 | I5: -0.12065636 | J5: -0.055439759 | K5: 0.065728343 | L5: 0.0033995329 | M5: 0.010088481 | N5: -0.22358972 | O5: 0.11247017 | P5: 0.049023945 | Q5: 0.13989837 | R5: -0.27218496 | S5: 0.35806242 | T5: 0.26027003 | U5: 0.20947325 | V5: 0.023302094 | W5: -0.057565904 | X5: -0.0016163481 | Y5: -0.052612529 | Z5: -0.02776377 | AA5: -0.096493567 | AB5: 0.06550694 | AC5: -0.044881403 | AD5: 0.10044777 | AE5: 0.12863042 | AF5: 0.2155206 | AG5: 0.25505334 | AH5: -0.10020667 | AI5: -0.099259356 | AJ5: -0.075106581 | AK5: -0.10622127 | AL5: -0.052322967 | AM5: 0.049437715 | AN5: 0.23701327 | AO5: 0.056008694 | AP5: 0.37025816 | AQ5: -0.22753609 | AR5: -0.18749165 | AS5: -0.22202944 | AT5: -0.051626926 | AU5: -0.1431032 | AV5: -0.13745864 | AW5: 0.3600069
A6: features.5.block.1.0 | B6: 0.60977576 | C6: 0.18875884 | D6: 0.096111857 | E6: -0.0067484494 | F6: 1 | G6: -0.094609107 | H6: -0.27677501 | I6: -0.082349097 | J6: -0.0012494638 | K6: 0.041801774 | L6: -0.1431326 | M6: -0.098999252 | N6: 0.062889825 | O6: 0.033252662 | P6: 0.0023251039 | Q6: 0.20659813 | R6: -0.07765661 | S6: 0.036971045 | T6: 0.25814127 | U6: 0.36283688 | V6: 0.013384757 | W6: 0.041412869 | X6: 0.12184691 | Y6: 0.10251428 | Z6: 0.12710075 | AA6: -0.00071183762 | AB6: 0.13231498 | AC6: -0.11353565 | AD6: -0.15061795 | AE6: 0.089830366 | AF6: 0.15886852 | AG6: 0.078248744 | AH6: -0.13712317 | AI6: 0.029970912 | AJ6: -0.023291333 | AK6: 0.043173905 | AL6: -0.051382377 | AM6: 0.0040501673 | AN6: -0.066130211 | AO6: -0.15746132 | AP6: -0.093322402 | AQ6: -0.12517565 | AR6: -0.14700128 | AS6: -0.088252175 | AT6: -0.29090002 | AU6: 0.11242835 | AV6: 0.051125009 | AW6: -0.12432641
A7: sensitivityscore_After_features.5.block.1.0_0.5 | B7: -0.22247979 | C7: -0.33250934 | D7: -0.032400469 | E7: 0.11477275 | F7: -0.094609107 | G7: 1 | H7: 0.39572129 | I7: 0.35633605 | J7: -0.077334209 | K7: 0.13653616 | L7: 0.062144903 | M7: 0.075690098 | N7: -0.10441559 | O7: -0.00081861116 | P7: 0.098749947 | Q7: 0.10383028 | R7: -0.12532167 | S7: -0.19681883 | T7: -0.013629601 | U7: 0.0028698466 | V7: -0.068947691 | W7: 0.064558875 | X7: 0.058575554 | Y7: 0.11826539 | Z7: -0.12167532 | AA7: 0.020933447 | AB7: 0.070437508 | AC7: 0.058907413 | AD7: 0.11265093 | AE7: 0.098070971 | AF7: 0.001484746 | AG7: -0.078584202 | AH7: 0.040146207 | AI7: 0.2766827 | AJ7: 0.059530003 | AK7: -0.030047614 | AL7: 0.032731416 | AM7: 0.099096267 | AN7: 0.20975801 | AO7: -0.20818693 | AP7: 0.069754089 | AQ7: 0.089870779 | AR7: -0.088360205 | AS7: -0.11044244 | AT7: 0.2540524 | AU7: 0.097182726 | AV7: 0.2496037 | AW7: 0.12461054
A8: sensitivityscore_After_features.5.block.1.0_0.6 | B8: -0.15008797 | C8: -0.19302004 | D8: -0.11028274 | E8: 0.099955662 | F8: -0.27677501 | G8: 0.39572129 | H8: 1 | I8: 0.66473164 | J8: 0.14283492 | K8: -0.13628477 | L8: 0.15269108 | M8: 0.1266691 | N8: -0.087416138 | O8: 0.017218403 | P8: -0.0069889544 | Q8: -0.07530969 | R8: 0.069095576 | S8: -0.029752543 | T8: -0.098860908 | U8: -0.093088968 | V8: -0.046810359 | W8: 0.10280771 | X8: 0.053802022 | Y8: 0.059972597 | Z8: -0.01558979 | AA8: 0.017604084 | AB8: 0.15554924 | AC8: 0.21515615 | AD8: 0.0067991042 | AE8: 0.021506007 | AF8: -0.016271784 | AG8: -0.17578015 | AH8: 0.061534079 | AI8: 0.26688769 | AJ8: 0.055578556 | AK8: 0.034682113 | AL8: 0.066212376 | AM8: 0.19933813 | AN8: 0.28308672 | AO8: 0.0062784334 | AP8: 0.13940599 | AQ8: -0.18286765 | AR8: -0.34798827 | AS8: -0.15037051 | AT8: 0.29104431 | AU8: 0.22977839 | AV8: -0.082295629 | AW8: -0.037362327
A9: sensitivityscore_After_features.5.block.1.0_0.7 | B9: -0.067637627 | C9: -0.24338006 | D9: -0.26891981 | E9: -0.12065636 | F9: -0.082349097 | G9: 0.35633605 | H9: 0.66473164 | I9: 1 | J9: 0.1158529 | K9: -0.16887579 | L9: 0.2172002 | M9: 0.11656846 | N9: 0.076182755 | O9: -0.17086083 | P9: 0.0083956811 | Q9: 0.17345224 | R9: 0.056816886 | S9: -0.11676168 | T9: -0.0033775803 | U9: -0.13889221 | V9: -0.089572578 | W9: 0.092524047 | X9: -0.020032527 | Y9: 0.16948369 | Z9: 0.072072665 | AA9: 0.063925272 | AB9: 0.16114509 | AC9: 0.17567089 | AD9: -0.06240679 | AE9: -0.21598045 | AF9: -0.16541125 | AG9: -0.11900032 | AH9: 0.039781928 | AI9: 0.23761134 | AJ9: 0.0067999167 | AK9: -0.095901906 | AL9: 0.074512977 | AM9: 0.22334441 | AN9: 0.33060081 | AO9: 0.20652818 | AP9: 0.022776108 | AQ9: -0.08352006 | AR9: -0.30477799 | AS9: -0.024021109 | AT9: 0.16059553 | AU9: 0.20485974 | AV9: 0.076988044 | AW9: -0.034621253
A10: features.5.block.2.fc2 | B10: 0.15070261 | C10: -0.010155827 | D10: 0.016410107 | E10: -0.055439759 | F10: -0.0012494638 | G10: -0.077334209 | H10: 0.14283492 | I10: 0.1158529 | J10: 1 | K10: -0.12284846 | L10: 0.046232243 | M10: -0.036541908 | N10: 0.091981462 | O10: 0.079173086 | P10: -0.050089566 | Q10: -0.23297633 | R10: 0.20810657 | S10: -0.28529658 | T10: -0.15780865 | U10: 0.016077448 | V10: -0.094352436 | W10: -0.018309363 | X10: 0.030737555 | Y10: -0.049859952 | Z10: 0.33070787 | AA10: -0.01835477 | AB10: -0.059567737 | AC10: -0.046832018 | AD10: -0.12323554 | AE10: 0.029809191 | AF10: 0.059441001 | AG10: 0.051905456 | AH10: -0.44204177 | AI10: 0.46263773 | AJ10: 0.30430676 | AK10: 0.095711048 | AL10: -0.34256012 | AM10: 0.038123346 | AN10: 0.17560185 | AO10: 0.15097028 | AP10: -0.070249987 | AQ10: -0.1195838 | AR10: 0.019617299 | AS10: 0.05524125 | AT10: -0.23483518 | AU10: -0.048738195 | AV10: -0.15905243 | AW10: -0.25746268
A11: sensitivityscore_After_features.5.block.2.fc2_0.5 | B11: -0.032918991 | C11: -0.059237056 | D11: 0.0093109611 | E11: 0.065728343 | F11: 0.041801774 | G11: 0.13653616 | H11: -0.13628477 | I11: -0.16887579 | J11: -0.12284846 | K11: 1 | L11: 0.63539588 | M11: 0.55099238 | N11: -0.20744073 | O11: 0.06852043 | P11: 0.089522474 | Q11: 0.038979693 | R11: -0.24414092 | S11: 0.017138237 | T11: 0.25172957 | U11: 0.15359267 | V11: 0.077804157 | W11: 0.093640277 | X11: 0.086963298 | Y11: 0.042397542 | Z11: -0.060245355 | AA11: 0.11328767 | AB11: -0.044689753 | AC11: -0.038322704 | AD11: 0.335137 | AE11: 0.13435899 | AF11: 0.017757818 | AG11: -0.036550133 | AH11: 0.117606 | AI11: -0.29626626 | AJ11: -0.33472123 | AK11: -0.023726617 | AL11: -0.20795648 | AM11: 0.20366985 | AN11: 0.045062695 | AO11: -0.16757112 | AP11: -0.20001241 | AQ11: 0.10494006 | AR11: 0.041534028 | AS11: -0.067610427 | AT11: 0.081275389 | AU11: -0.19286408 | AV11: 0.10045612 | AW11: -0.035851202
A12: sensitivityscore_After_features.5.block.2.fc2_0.6 | B12: -0.010009452 | C12: -0.067263833 | D12: -0.083642385 | E12: 0.0033995329 | F12: -0.1431326 | G12: 0.062144903 | H12: 0.15269108 | I12: 0.2172002 | J12: 0.046232243 | K12: 0.63539588 | L12: 1 | M12: 0.78890083 | N12: -0.10452826 | O12: 0.059204473 | P12: 0.093292199 | Q12: 0.10242043 | R12: 0.030187038 | S12: -0.083456532 | T12: 0.20276793 | U12: 0.096843795 | V12: -0.019848196 | W12: 0.1673919 | X12: 0.058861665 | Y12: -0.01554897 | Z12: 0.036943803 | AA12: 0.13622802 | AB12: -0.038973742 | AC12: 0.10900454 | AD12: 0.19521353 | AE12: -0.0159244 | AF12: 0.058574429 | AG12: 0.068492042 | AH12: -0.028264486 | AI12: -0.11064557 | AJ12: -0.1298655 | AK12: 0.24829811 | AL12: -0.27692084 | AM12: 0.23755565 | AN12: 0.19040873 | AO12: -0.13211761 | AP12: -0.25412207 | AQ12: -0.13550189 | AR12: -0.19494214 | AS12: -0.18611051 | AT12: 0.13688156 | AU12: -0.20448594 | AV12: -0.018427882 | AW12: -0.013791398
A13: sensitivityscore_After_features.5.block.2.fc2_0.7 | B13: -0.024120054 | C13: 0.026240656 | D13: 0.025227699 | E13: 0.010088481 | F13: -0.098999252 | G13: 0.075690098 | H13: 0.1266691 | I13: 0.11656846 | J13: -0.036541908 | K13: 0.55099238 | L13: 0.78890083 | M13: 1 | N13: -0.24600126 | O13: 0.10450618 | P13: 0.1788468 | Q13: 0.16191381 | R13: -0.08269424 | S13: -0.12039415 | T13: 0.24972018 | U13: 0.14866031 | V13: -0.027437805 | W13: 0.088128524 | X13: 0.095167531 | Y13: 0.041882637 | Z13: -0.081940165 | AA13: 0.13831466 | AB13: -0.064230318 | AC13: 0.16091267 | AD13: 0.28919277 | AE13: 0.071072202 | AF13: 0.092308066 | AG13: 0.014233992 | AH13: -0.048595208 | AI13: -0.20843442 | AJ13: -0.03958462 | AK13: 0.29893219 | AL13: -0.35295191 | AM13: 0.16991545 | AN13: 0.282402 | AO13: -0.083610811 | AP13: 0.011146188 | AQ13: -0.084682774 | AR13: -0.11874313 | AS13: -0.11299709 | AT13: 0.086965342 | AU13: -0.095612394 | AV13: -0.035676689 | AW13: 0.017080817
... A49: sensitivityscore_After_features.7.block.3.0_0.7 | B49: -0.18352871 | C49: 0.095875212 | D49: 0.41248567 | E49: 0.3600069 | F49: -0.12432641 | G49: 0.12461054 | H49: -0.037362327 | I49: -0.034621253 | J49: -0.25746268 | K49: -0.035851202 | L49: -0.013791398 | M49: 0.017080817 | N49: -0.092572594 | O49: -0.11384471 | P49: -0.18950175 | Q49: 0.19898 | R49: -0.0412124 | S49: 0.30516596 | T49: 0.18717763 | U49: -0.015101262 | V49: -0.12239342 | W49: 0.036677388 | X49: 0.0598986 | Y49: 0.13138946 | Z49: 0.034829305 | AA49: -0.16197686 | AB49: 0.077662169 | AC49: 0.016231699 | AD49: -0.072687282 | AE49: 0.062430578 | AF49: 0.1028414 | AG49: 0.18109583 | AH49: -0.081044099 | AI49: -0.15361122 | AJ49: -0.047754975 | AK49: -0.17293121 | AL49: -0.018242213 | AM49: -0.1446058 | AN49: 0.019148321 | AO49: -0.022613576 | AP49: 0.33090296 | AQ49: -0.042454298 | AR49: -0.2023954 | AS49: -0.18471306 | AT49: -0.032938911 | AU49: 0.20458118 | AV49: -0.19049569 | AW49: 1

Sheet Class_3
B1: features.5.block.0.0 | C1: sensitivityscore_After_features.5.block.0.0_0.5 | D1: sensitivityscore_After_features.5.block.0.0_0.6 | E1: sensitivityscore_After_features.5.block.0.0_0.7 | F1: features.5.block.1.0 | G1: sensitivityscore_After_features.5.block.1.0_0.5 | H1: sensitivityscore_After_features.5.block.1.0_0.6 | I1: sensitivityscore_After_features.5.block.1.0_0.7 | J1: features.5.block.2.fc2 | K1: sensitivityscore_After_features.5.block.2.fc2_0.5 | L1: sensitivityscore_After_features.5.block.2.fc2_0.6 | M1: sensitivityscore_After_features.5.block.2.fc2_0.7 | N1: features.5.block.3.0 | O1: sensitivityscore_After_features.5.block.3.0_0.5 | P1: sensitivityscore_After_features.5.block.3.0_0.6 | Q1: sensitivityscore_After_features.5.block.3.0_0.7 | R1: features.6.block.0.0 | S1: sensitivityscore_After_features.6.block.0.0_0.5 | T1: sensitivityscore_After_features.6.block.0.0_0.6 | U1: sensitivityscore_After_features.6.block.0.0_0.7 | V1: features.6.block.1.0 | W1: sensitivityscore_After_features.6.block.1.0_0.5 | X1: sensitivityscore_After_features.6.block.1.0_0.6 | Y1: sensitivityscore_After_features.6.block.1.0_0.7 | Z1: features.6.block.2.fc2 | AA1: sensitivityscore_After_features.6.block.2.fc2_0.5 | AB1: sensitivityscore_After_features.6.block.2.fc2_0.6 | AC1: sensitivityscore_After_features.6.block.2.fc2_0.7 | AD1: features.6.block.3.0 | AE1: sensitivityscore_After_features.6.block.3.0_0.5 | AF1: sensitivityscore_After_features.6.block.3.0_0.6 | AG1: sensitivityscore_After_features.6.block.3.0_0.7 | AH1: features.7.block.0.0 | AI1: sensitivityscore_After_features.7.block.0.0_0.5 | AJ1: sensitivityscore_After_features.7.block.0.0_0.6 | AK1: sensitivityscore_After_features.7.block.0.0_0.7 | AL1: features.7.block.1.0 | AM1: sensitivityscore_After_features.7.block.1.0_0.5 | AN1: sensitivityscore_After_features.7.block.1.0_0.6 | AO1: sensitivityscore_After_features.7.block.1.0_0.7 | AP1: features.7.block.2.fc2 | AQ1: sensitivityscore_After_features.7.block.2.fc2_0.5 | AR1: sensitivityscore_After_features.7.block.2.fc2_0.6 | AS1: sensitivityscore_After_features.7.block.2.fc2_0.7 | AT1: features.7.block.3.0 | AU1: sensitivityscore_After_features.7.block.3.0_0.5 | AV1: sensitivityscore_After_features.7.block.3.0_0.6 | AW1: sensitivityscore_After_features.7.block.3.0_0.7
A2: features.5.block.0.0 | B2: 1 | C2: 0.066080648 | D2: -0.0097822594 | E2: -0.09238304 | F2: 0.5339117 | G2: -0.029434918 | H2: -0.067973677 | I2: -0.10378439 | J2: 0.23880588 | K2: -0.10489941 | L2: -0.12824104 | M2: -0.074290167 | N2: 0.48381661 | O2: -0.021205504 | P2: -0.182382 | Q2: 0.054440607 | R2: 0.15091388 | S2: -0.06536808 | T2: 0.1617047 | U2: 0.019470119 | V2: 0.37388392 | W2: -0.071291878 | X2: -0.072313771 | Y2: -0.051040033 | Z2: -0.1909612 | AA2: -0.038818398 | AB2: -0.057269304 | AC2: -0.016876739 | AD2: -0.13051729 | AE2: 0.13072524 | AF2: -0.00039009967 | AG2: 0.086969327 | AH2: 0.083236396 | AI2: -0.036712083 | AJ2: 0.16785248 | AK2: 0.22144106 | AL2: 0.15247535 | AM2: 0.067330897 | AN2: 0.36910784 | AO2: -0.10849707 | AP2: 0.18215968 | AQ2: -0.27908992 | AR2: -0.24356714 | AS2: -0.31032863 | AT2: 0.042944989 | AU2: -0.0087003307 | AV2: 0.12640732 | AW2: 0.029479851
A3: sensitivityscore_After_features.5.block.0.0_0.5 | B3: 0.066080648 | C3: 1 | D3: 0.58579296 | E3: 0.4767026 | F3: 0.075367767 | G3: -0.10265025 | H3: -0.20837385 | I3: 0.04415697 | J3: -0.2092806 | K3: -0.038006112 | L3: -0.061379494 | M3: -0.032789649 | N3: -0.070308252 | O3: 0.1070344 | P3: -0.057879768 | Q3: 0.061501577 | R3: -0.14839207 | S3: -0.13043521 | T3: 0.035580401 | U3: 0.038112883 | V3: -0.1353738 | W3: 0.053938531 | X3: 0.04749738 | Y3: -0.1543599 | Z3: 0.023768411 | AA3: -0.15758598 | AB3: -0.12893251 | AC3: 0.036792265 | AD3: 0.13673982 | AE3: 0.087574041 | AF3: 0.2053309 | AG3: 0.16497874 | AH3: 0.15257282 | AI3: -0.021716461 | AJ3: 0.013721858 | AK3: 0.22256133 | AL3: 0.18711592 | AM3: -0.013913259 | AN3: -0.0078632552 | AO3: -0.17355255 | AP3: -0.065829051 | AQ3: -0.082256061 | AR3: -0.023936536 | AS3: -0.13369176 | AT3: 0.078711899 | AU3: 0.13889431 | AV3: -0.18964935 | AW3: 0.24529023
A4: sensitivityscore_After_features.5.block.0.0_0.6 | B4: -0.0097822594 | C4: 0.58579296 | D4: 1 | E4: 0.69815748 | F4: 0.13970304 | G4: -0.075408276 | H4: -0.32238979 | I4: -0.029651388 | J4: -0.17013609 | K4: -0.01393524 | L4: -0.15001151 | M4: -0.14886189 | N4: 0.015010995 | O4: 0.043446766 | P4: -0.055937561 | Q4: 0.0056475859 | R4: 0.056446446 | S4: -0.036128274 | T4: 0.14078893 | U4: 0.1490295 | V4: -0.065384663 | W4: 0.041043916 | X4: -0.059359128 | Y4: -0.13578383 | Z4: -0.041091977 | AA4: -0.18147013 | AB4: -0.14244617 | AC4: 0.058750567 | AD4: 0.15269205 | AE4: -0.066203004 | AF4: 0.025912586 | AG4: 0.11564006 | AH4: -0.0080257711 | AI4: 0.23716709 | AJ4: 0.30364187 | AK4: 0.36377549 | AL4: 0.0019321058 | AM4: 0.053138556 | AN4: 0.11100645 | AO4: -0.1395077 | AP4: 0.061960676 | AQ4: 0.11964474 | AR4: 0.030518869 | AS4: -0.13163142 | AT4: -0.086989691 | AU4: -0.064680426 | AV4: 0.039071459 | AW4: 0.089861901
A5: sensitivityscore_After_features.5.block.0.0_0.7 | B5: -0.09238304 | C5: 0.4767026 | D5: 0.69815748 | E5: 1 | F5: 0.10673388 | G5: 0.043695636 | H5: -0.18399187 | I5: -0.0050080564 | J5: -0.041515973 | K5: 0.028225889 | L5: -0.19081016 | M5: -0.20089309 | N5: -0.025983936 | O5: -0.10502812 | P5: -0.20666357 | Q5: -0.13639691 | R5: -0.10924514 | S5: 0.0058610082 | T5: -0.01419281 | U5: 0.20489464 | V5: -0.11291791 | W5: -0.030279961 | X5: 0.0077820435 | Y5: -0.18166466 | Z5: -0.020505174 | AA5: -0.20871997 | AB5: -0.22324929 | AC5: -0.086822671 | AD5: 0.11047032 | AE5: -0.15440381 | AF5: -0.093058027 | AG5: -0.10170975 | AH5: -0.019927022 | AI5: 0.2054278 | AJ5: 0.20570199 | AK5: 0.20201484 | AL5: 0.057220514 | AM5: -0.098617289 | AN5: -0.032383718 | AO5: -0.065934442 | AP5: 0.039520844 | AQ5: 0.062842638 | AR5: 0.08955616 | AS5: 0.034877525 | AT5: -0.025580519 | AU5: -0.037512947 | AV5: -0.012260292 | AW5: 0.066138201
A6: features.5.block.1.0 | B6: 0.5339117 | C6: 0.075367767 | D6: 0.13970304 | E6: 0.10673388 | F6: 1 | G6: -0.064904239 | H6: -0.15938074 | I6: -0.038080884 | J6: 0.32533497 | K6: -0.10611729 | L6: -0.16836761 | M6: -0.14391362 | N6: 0.64128442 | O6: -0.19727005 | P6: -0.076964279 | Q6: -0.11858457 | R6: -0.012139858 | S6: -0.1186157 | T6: 0.16892717 | U6: 0.017226248 | V6: 0.45182845 | W6: -0.12846336 | X6: -0.2506656 | Y6: -0.14235689 | Z6: -0.0035091332 | AA6: -0.013102818 | AB6: -0.18528983 | AC6: -0.1333297 | AD6: 0.00029688359 | AE6: -0.09589639 | AF6: -0.068989214 | AG6: 0.058033981 | AH6: 0.15586997 | AI6: 0.22420701 | AJ6: 0.22093105 | AK6: 0.076887074 | AL6: 0.19115945 | AM6: 0.010838235 | AN6: 0.36280311 | AO6: -0.23292577 | AP6: -0.036823013 | AQ6: -0.20652634 | AR6: -0.18934624 | AS6: -0.16671878 | AT6: 0.11201233 | AU6: -0.049433348 | AV6: 0.019548266 | AW6: 0.028299661
A7: sensitivityscore_After_features.5.block.1.0_0.5 | B7: -0.029434918 | C7: -0.10265025 | D7: -0.075408276 | E7: 0.043695636 | F7: -0.064904239 | G7: 1 | H7: 0.63633788 | I7: 0.5617194 | J7: -0.095647696 | K7: 0.090595277 | L7: 0.25964724 | M7: 0.20200424 | N7: 0.18206 | O7: -0.022275933 | P7: -0.060865886 | Q7: -0.081754717 | R7: -0.065364028 | S7: 0.038994233 | T7: -0.1038868 | U7: 0.038094019 | V7: 0.076538273 | W7: -0.13891314 | X7: -0.12342653 | Y7: -0.16145861 | Z7: -0.29554725 | AA7: -0.12003507 | AB7: -0.066166015 | AC7: -0.21177868 | AD7: 0.045244413 | AE7: 0.046279178 | AF7: -0.20340134 | AG7: -0.23352821 | AH7: -0.068980103 | AI7: 0.11308085 | AJ7: 0.065411491 | AK7: -0.023136337 | AL7: -0.11065269 | AM7: -0.0020485637 | AN7: 0.022138084 | AO7: 0.10715457 | AP7: 0.085358735 | AQ7: -0.078353267 | AR7: -0.011145711 | AS7: 0.10974831 | AT7: -0.084829718 | AU7: -0.27317639 | AV7: 0.24199223 | AW7: 0.070023588
A8: sensitivityscore_After_features.5.block.1.0_0.6 | B8: -0.067973677 | C8: -0.20837385 | D8: -0.32238979 | E8: -0.18399187 | F8: -0.15938074 | G8: 0.63633788 | H8: 1 | I8: 0.55629904 | J8: -0.17508741 | K8: 0.085106432 | L8: 0.31983484 | M8: 0.19255324 | N8: 0.0019962613 | O8: 0.018084687 | P8: 0.13662912 | Q8: -0.015364731 | R8: 0.061095381 | S8: 0.11225942 | T8: -0.089716572 | U8: -0.079409453 | V8: 0.18497775 | W8: 0.06738454 | X8: 0.065094383 | Y8: 0.13730255 | Z8: -0.40531171 | AA8: 0.11890272 | AB8: 0.16112865 | AC8: -0.056882618 | AD8: -0.011072629 | AE8: 0.084159135 | AF8: -0.39435762 | AG8: -0.39777634 | AH8: 0.10825444 | AI8: 0.022345587 | AJ8: 0.027726253 | AK8: 0.046959745 | AL8: 0.052824892 | AM8: 0.045404967 | AN8: -0.049347821 | AO8: 0.29415196 | AP8: 0.100809 | AQ8: -0.080847042 | AR8: 0.11898154 | AS8: 0.23798864 | AT8: 0.069303337 | AU8: -0.23593404 | AV8: 0.028967642 | AW8: 0.00096168237
A9: sensitivityscore_After_features.5.block.1.0_0.7 | B9: -0.10378439 | C9: 0.04415697 | D9: -0.029651388 | E9: -0.0050080564 | F9: -0.038080884 | G9: 0.5617194 | H9: 0.55629904 | I9: 1 | J9: -0.15526412 | K9: -0.0046485334 | L9: 0.11189502 | M9: 0.080366769 | N9: 0.0056274921 | O9: 0.010929645 | P9: 0.1545438 | Q9: -0.21267019 | R9: 0.033510009 | S9: 0.13010971 | T9: -0.023678718 | U9: 0.011881601 | V9: 0.1508066 | W9: -0.14830394 | X9: 0.078911297 | Y9: 0.06315444 | Z9: -0.10549673 | AA9: -0.010257259 | AB9: 0.03032543 | AC9: -0.19632883 | AD9: 0.26172876 | AE9: 0.12581496 | AF9: -0.14955225 | AG9: -0.13768057 | AH9: 0.012921932 | AI9: -0.15286019 | AJ9: -0.067030739 | AK9: 0.062458234 | AL9: 0.014635522 | AM9: 0.065581356 | AN9: 0.048934006 | AO9: 0.12334247 | AP9: 0.1630799 | AQ9: -0.090966979 | AR9: 0.068938657 | AS9: 0.062769852 | AT9: 0.021234825 | AU9: -0.18673177 | AV9: 0.13730012 | AW9: -0.083279404
A10: features.5.block.2.fc2 | B10: 0.23880588 | C10: -0.2092806 | D10: -0.17013609 | E10: -0.041515973 | F10: 0.32533497 | G10: -0.095647696 | H10: -0.17508741 | I10: -0.15526412 | J10: 1 | K10: -0.23521747 | L10: -0.33370616 | M10: -0.39169053 | N10: 0.21731059 | O10: -0.16840657 | P10: -0.071521484 | Q10: -0.0079170565 | R10: -0.060511879 | S10: 0.057800256 | T10: 0.13876622 | U10: 0.14698422 | V10: 0.15324242 | W10: -0.04548226 | X10: 0.049432575 | Y10: 0.039673995 | Z10: 0.08902199 | AA10: 0.14609686 | AB10: 0.13972579 | AC10: -0.038635922 | AD10: -0.37489004 | AE10: -0.218767 | AF10: -0.084397946 | AG10: 0.012885927 | AH10: -0.4020955 | AI10: -0.023235269 | AJ10: -0.19752647 | AK10: -0.15733358 | AL10: -0.31549271 | AM10: 0.019194561 | AN10: -0.037734218 | AO10: -0.1240066 | AP10: 0.053269205 | AQ10: -0.20814233 | AR10: -0.099908124 | AS10: 0.026525174 | AT10: -0.1919476 | AU10: 0.064193485 | AV10: 0.11428918 | AW10: -0.10745004
A11: sensitivityscore_After_features.5.block.2.fc2_0.5 | B11: -0.10489941 | C11: -0.038006112 | D11: -0.01393524 | E11: 0.028225889 | F11: -0.10611729 | G11: 0.090595277 | H11: 0.085106432 | I11: -0.0046485334 | J11: -0.23521747 | K11: 1 | L11: 0.76813379 | M11: 0.69785552 | N11: -0.053657957 | O11: 0.050724874 | P11: -0.10962185 | Q11: -0.24168999 | R11: -0.10750367 | S11: 0.21105201 | T11: -0.042956367 | U11: -0.052638467 | V11: 0.026117016 | W11: 0.028358484 | X11: 0.094830727 | Y11: 0.17574017 | Z11: -0.00011867707 | AA11: 0.38826229 | AB11: 0.23828247 | AC11: 0.16232769 | AD11: 0.026420043 | AE11: 0.35510157 | AF11: 0.17055188 | AG11: -0.042573157 | AH11: 0.26647293 | AI11: -0.01902166 | AJ11: 0.14156355 | AK11: 0.027040382 | AL11: 0.26911776 | AM11: -0.10413292 | AN11: 0.13561988 | AO11: 0.13774875 | AP11: -0.14488652 | AQ11: 0.28464433 | AR11: 0.20158789 | AS11: 0.075595511 | AT11: 0.13241741 | AU11: -0.043178406 | AV11: -0.13102484 | AW11: 0.011254911
A12: sensitivityscore_After_features.5.block.2.fc2_0.6 | B12: -0.12824104 | C12: -0.061379494 | D12: -0.15001151 | E12: -0.19081016 | F12: -0.16836761 | G12: 0.25964724 | H12: 0.31983484 | I12: 0.11189502 | J12: -0.33370616 | K12: 0.76813379 | L12: 1 | M12: 0.79929589 | N12: -0.025945971 | O12: 0.11317147 | P12: -0.088651558 | Q12: -0.22835569 | R12: 0.0066844624 | S12: 0.1766388 | T12: -0.085963505 | U12: -0.016127447 | V12: 0.14056962 | W12: -0.027411826 | X12: 0.064423761 | Y12: 0.08652035 | Z12: -0.12124595 | AA12: 0.39689839 | AB12: 0.32289964 | AC12: 0.19026291 | AD12: 0.118113 | AE12: 0.33505148 | AF12: 0.17804498 | AG12: -0.090342416 | AH12: 0.23808739 | AI12: -0.038496076 | AJ12: -0.0041446376 | AK12: -0.05276739 | AL12: 0.21425147 | AM12: -0.094827875 | AN12: 0.15994403 | AO12: 0.18334413 | AP12: -0.10100458 | AQ12: 0.38770053 | AR12: 0.31385954 | AS12: 0.23129796 | AT12: 0.039244265 | AU12: -0.22777039 | AV12: 0.0086634905 | AW12: 0.10801457
