Workbook

Sheet Sheet1
A1: Class | B1: =Class_0!B1 -> layer1.0.conv1 | C1: =Class_0!C1 -> sensitivityscore_After_layer1.0.conv1_0.5 | D1: =Class_0!D1 -> sensitivityscore_After_layer1.0.conv1_0.6 | E1: =Class_0!E1 -> sensitivityscore_After_layer1.0.conv1_0.7 | F1: =Class_0!F1 -> layer1.0.conv2 | G1: =Class_0!G1 -> sensitivityscore_After_layer1.0.conv2_0.5 | H1: =Class_0!H1 -> sensitivityscore_After_layer1.0.conv2_0.6 | I1: =Class_0!I1 -> sensitivityscore_After_layer1.0.conv2_0.7 | ... AX1: =Class_0!AX1 -> 0
A2: 0 | B2: =Class_0!B49 -> -0.37060628 | C2: =Class_0!C49 -> 0.25038762 | D2: =Class_0!D49 -> 0.0036613148 | E2: =Class_0!E49 -> 0.020554543 | F2: =Class_0!F49 -> -0.21323227 | G2: =Class_0!G49 -> -0.19736653 | H2: =Class_0!H49 -> -0.19215025 | I2: =Class_0!I49 -> -0.19213642 | ... AW2: =Class_0!AW49 -> 1
A3: =A2+1 -> 1 | B3: =Class_1!B49 -> -0.26562001 | C3: =Class_1!C49 -> 0.061661235 | D3: =Class_1!D49 -> -0.063965514 | E3: =Class_1!E49 -> 0.046567631 | F3: =Class_1!F49 -> -0.17085014 | G3: =Class_1!G49 -> -0.2772861 | H3: =Class_1!H49 -> -0.30600266 | I3: =Class_1!I49 -> -0.25837036 | ... AW3: =Class_1!AW49 -> 1
A4: =A3+1 -> 2 | B4: =Class_2!B49 -> 0.097405589 | C4: =Class_2!C49 -> 0.090759066 | D4: =Class_2!D49 -> 0.030087583 | E4: =Class_2!E49 -> -0.091949973 | F4: =Class_2!F49 -> 0.43587877 | G4: =Class_2!G49 -> 0.19761321 | H4: =Class_2!H49 -> 0.19116136 | I4: =Class_2!I49 -> 0.13505957 | ... AW4: =Class_2!AW49 -> 1
A5: =A4+1 -> 3 | B5: =Class_3!B49 -> 0.059535305 | C5: =Class_3!C49 -> 0.12637934 | D5: =Class_3!D49 -> -0.14309194 | E5: =Class_3!E49 -> 0.072933194 | F5: =Class_3!F49 -> 0.11204288 | G5: =Class_3!G49 -> 0.071287065 | H5: =Class_3!H49 -> -0.02573459 | I5: =Class_3!I49 -> 0.13152914 | ... AW5: =Class_3!AW49 -> 1
A6: =A5+1 -> 4 | B6: =Class_4!B49 -> 0.17203088 | C6: =Class_4!C49 -> -0.19033898 | D6: =Class_4!D49 -> -0.12569105 | E6: =Class_4!E49 -> -0.051612073 | F6: =Class_4!F49 -> -0.23097044 | G6: =Class_4!G49 -> 0.36559153 | H6: =Class_4!H49 -> 0.35336019 | I6: =Class_4!I49 -> 0.24725091 | ... AW6: =Class_4!AW49 -> 1
A7: =A6+1 -> 5 | B7: =Class_5!B49 -> -0.014617674 | C7: =Class_5!C49 -> 0.065096868 | D7: =Class_5!D49 -> -0.02181998 | E7: =Class_5!E49 -> 0.019855917 | F7: =Class_5!F49 -> 0.26369004 | G7: =Class_5!G49 -> 0.34258948 | H7: =Class_5!H49 -> 0.24797619 | I7: =Class_5!I49 -> 0.14742789 | ... AW7: =Class_5!AW49 -> 1
A8: =A7+1 -> 6 | B8: =Class_6!B49 -> 0.19074217 | C8: =Class_6!C49 -> -0.11446647 | D8: =Class_6!D49 -> -0.22614017 | E8: =Class_6!E49 -> -0.014274709 | F8: =Class_6!F49 -> 0.093309029 | G8: =Class_6!G49 -> 0.072705985 | H8: =Class_6!H49 -> 0.075762542 | I8: =Class_6!I49 -> 0.098050266 | ... AW8: =Class_6!AW49 -> 1
A9: =A8+1 -> 7 | B9: =Class_7!B49 -> -0.032481752 | C9: =Class_7!C49 -> -0.21051196 | D9: =Class_7!D49 -> -0.098922689 | E9: =Class_7!E49 -> -0.15631859 | F9: =Class_7!F49 -> -0.1567276 | G9: =Class_7!G49 -> 0.27260528 | H9: =Class_7!H49 -> 0.18331432 | I9: =Class_7!I49 -> 0.19256401 | ... AW9: =Class_7!AW49 -> 1
A10: =A9+1 -> 8 | B10: =Class_8!B49 -> -0.33671558 | C10: =Class_8!C49 -> 0.13460928 | D10: =Class_8!D49 -> -0.051282161 | E10: =Class_8!E49 -> 0.069760203 | F10: =Class_8!F49 -> 0.30783276 | G10: =Class_8!G49 -> 0.11750713 | H10: =Class_8!H49 -> 0.19692993 | I10: =Class_8!I49 -> 0.24754001 | ... AW10: =Class_8!AW49 -> 1
A11: =A10+1 -> 9 | B11: =Class_9!B49 -> -0.07436028 | C11: =Class_9!C49 -> -0.2482954 | D11: =Class_9!D49 -> -0.06295841 | E11: =Class_9!E49 -> -0.18718305 | F11: =Class_9!F49 -> -0.20487556 | G11: =Class_9!G49 -> -0.17330251 | H11: =Class_9!H49 -> -0.19365601 | I11: =Class_9!I49 -> -0.17332231 | ... AW11: =Class_9!AW49 -> 1

Sheet Class_0
B1: layer1.0.conv1 | C1: sensitivityscore_After_layer1.0.conv1_0.5 | D1: sensitivityscore_After_layer1.0.conv1_0.6 | E1: sensitivityscore_After_layer1.0.conv1_0.7 | F1: layer1.0.conv2 | G1: sensitivityscore_After_layer1.0.conv2_0.5 | H1: sensitivityscore_After_layer1.0.conv2_0.6 | I1: sensitivityscore_After_layer1.0.conv2_0.7 | J1: layer1.0.conv3 | K1: sensitivityscore_After_layer1.0.conv3_0.5 | L1: sensitivityscore_After_layer1.0.conv3_0.6 | M1: sensitivityscore_After_layer1.0.conv3_0.7 | N1: layer4.0.conv1 | O1: sensitivityscore_After_layer4.0.conv1_0.5 | P1: sensitivityscore_After_layer4.0.conv1_0.6 | Q1: sensitivityscore_After_layer4.0.conv1_0.7 | R1: layer4.0.conv2 | S1: sensitivityscore_After_layer4.0.conv2_0.5 | T1: sensitivityscore_After_layer4.0.conv2_0.6 | U1: sensitivityscore_After_layer4.0.conv2_0.7 | V1: layer4.0.conv3 | W1: sensitivityscore_After_layer4.0.conv3_0.5 | X1: sensitivityscore_After_layer4.0.conv3_0.6 | Y1: sensitivityscore_After_layer4.0.conv3_0.7 | Z1: layer4.1.conv1 | AA1: sensitivityscore_After_layer4.1.conv1_0.5 | AB1: sensitivityscore_After_layer4.1.conv1_0.6 | AC1: sensitivityscore_After_layer4.1.conv1_0.7 | AD1: layer4.1.conv2 | AE1: sensitivityscore_After_layer4.1.conv2_0.5 | AF1: sensitivityscore_After_layer4.1.conv2_0.6 | AG1: sensitivityscore_After_layer4.1.conv2_0.7 | AH1: layer4.1.conv3 | AI1: sensitivityscore_After_layer4.1.conv3_0.5 | AJ1: sensitivityscore_After_layer4.1.conv3_0.6 | AK1: sensitivityscore_After_layer4.1.conv3_0.7 | AL1: layer4.2.conv1 | AM1: sensitivityscore_After_layer4.2.conv1_0.5 | AN1: sensitivityscore_After_layer4.2.conv1_0.6 | AO1: sensitivityscore_After_layer4.2.conv1_0.7 | AP1: layer4.2.conv2 | AQ1: sensitivityscore_After_layer4.2.conv2_0.5 | AR1: sensitivityscore_After_layer4.2.conv2_0.6 | AS1: sensitivityscore_After_layer4.2.conv2_0.7 | AT1: layer4.2.conv3 | AU1: sensitivityscore_After_layer4.2.conv3_0.5 | AV1: sensitivityscore_After_layer4.2.conv3_0.6 | AW1: sensitivityscore_After_layer4.2.conv3_0.7
A2: layer1.0.conv1 | B2: 1 | C2: -0.040638072 | D2: 0.062966591 | E2: 0.071519705 | F2: 0.3818846 | G2: 0.32595443 | H2: 0.21632636 | I2: 0.22431245 | J2: 0.37877908 | K2: -0.013907182 | L2: 0.041257122 | M2: -0.049499585 | N2: -0.17712761 | O2: 0.0056731606 | P2: 0.084236276 | Q2: -0.2691076 | R2: -0.1383436 | S2: -0.1103751 | T2: 0.10361242 | U2: 0.17545803 | V2: 0.099960918 | W2: -0.11809406 | X2: -0.083207471 | Y2: -0.060801471 | Z2: -0.042335139 | AA2: -0.011434605 | AB2: 0.0040761115 | AC2: -0.063762364 | AD2: 0.0013500819 | AE2: -0.10532307 | AF2: 0.16744708 | AG2: 0.063370181 | AH2: 0.10157061 | AI2: -0.25404043 | AJ2: -0.1728424 | AK2: -0.21409698 | AL2: 0.06588835 | AM2: -0.13949312 | AN2: -0.040681314 | AO2: 0.033158668 | AP2: 0.23276991 | AQ2: -0.01048583 | AR2: 0.060025634 | AS2: -0.033565702 | AT2: -0.086797923 | AU2: -0.25969708 | AV2: -0.27499477 | AW2: -0.37060628
A3: sensitivityscore_After_layer1.0.conv1_0.5 | B3: -0.040638072 | C3: 1 | D3: 0.57065614 | E3: 0.19882788 | F3: 0.22623622 | G3: -0.088147401 | H3: 0.036986784 | I3: 0.039311315 | J3: 0.19218901 | K3: -0.00044454438 | L3: -0.17801432 | M3: 0.049078907 | N3: 0.23584965 | O3: 0.28842455 | P3: 0.20676179 | Q3: -0.034950023 | R3: 0.27751729 | S3: -0.086656765 | T3: -0.28194446 | U3: 0.13516818 | V3: 0.28972225 | W3: 0.098593443 | X3: 0.076314803 | Y3: -0.093323014 | Z3: 0.34223875 | AA3: -0.11818317 | AB3: -0.1932484 | AC3: -0.16775563 | AD3: 0.25415268 | AE3: -0.14447468 | AF3: -0.34432026 | AG3: -0.14200993 | AH3: 0.28241555 | AI3: 0.10357745 | AJ3: 0.14791097 | AK3: 0.14278423 | AL3: 0.17532167 | AM3: -0.063046503 | AN3: 0.067671785 | AO3: 0.054848017 | AP3: -0.2007248 | AQ3: -0.059451387 | AR3: -0.09466466 | AS3: -0.098325454 | AT3: 0.35986513 | AU3: 0.37130998 | AV3: 0.30568134 | AW3: 0.25038762
A4: sensitivityscore_After_layer1.0.conv1_0.6 | B4: 0.062966591 | C4: 0.57065614 | D4: 1 | E4: 0.58982199 | F4: 0.33290845 | G4: -0.027526538 | H4: 0.021753693 | I4: 0.15417832 | J4: 0.33848633 | K4: -0.020350137 | L4: -0.05560591 | M4: 0.13093449 | N4: 0.2729851 | O4: 0.15019165 | P4: 0.15420908 | Q4: -0.17857724 | R4: 0.067730795 | S4: -0.029976102 | T4: -0.1526477 | U4: 0.12895104 | V4: 0.21489681 | W4: -0.14704073 | X4: 0.046941328 | Y4: -0.043178786 | Z4: 0.11102261 | AA4: -0.076734684 | AB4: -0.038841571 | AC4: -0.13066041 | AD4: 0.13456555 | AE4: -0.12144994 | AF4: -0.16639455 | AG4: -0.14200339 | AH4: 0.11964266 | AI4: -0.096561619 | AJ4: -0.15080985 | AK4: -0.18023013 | AL4: 0.031684097 | AM4: -0.063362894 | AN4: 0.036259837 | AO4: 0.073391222 | AP4: -0.2018624 | AQ4: -0.09095535 | AR4: -0.16991136 | AS4: -0.20191894 | AT4: 0.36106232 | AU4: 0.10138024 | AV4: 0.11139509 | AW4: 0.0036613148
A5: sensitivityscore_After_layer1.0.conv1_0.7 | B5: 0.071519705 | C5: 0.19882788 | D5: 0.58982199 | E5: 1 | F5: 0.1509428 | G5: -0.13790728 | H5: 0.024456611 | I5: 0.20164833 | J5: 0.04855825 | K5: 0.20107807 | L5: 0.12770643 | M5: 0.10687771 | N5: 0.37569846 | O5: 0.13548138 | P5: 0.15398166 | Q5: -0.028579461 | R5: 0.13674004 | S5: 0.06275633 | T5: 0.2024901 | U5: 0.26874899 | V5: 0.10353438 | W5: 0.030926091 | X5: 0.10149606 | Y5: 0.11445876 | Z5: 0.111307 | AA5: 0.092420384 | AB5: 0.19625342 | AC5: 0.18046275 | AD5: 0.082789566 | AE5: -0.25569977 | AF5: -0.23903319 | AG5: -0.23736914 | AH5: 0.24242994 | AI5: -0.18530576 | AJ5: -0.15329037 | AK5: -0.24053501 | AL5: 0.010661551 | AM5: 0.05257097 | AN5: 0.15249428 | AO5: 0.1228515 | AP5: -0.1122942 | AQ5: -0.21325732 | AR5: -0.22538818 | AS5: -0.40242609 | AT5: 0.053702465 | AU5: 0.12231074 | AV5: 0.065776058 | AW5: 0.020554543
A6: layer1.0.conv2 | B6: 0.3818846 | C6: 0.22623622 | D6: 0.33290845 | E6: 0.1509428 | F6: 1 | G6: -0.069965789 | H6: -0.063664873 | I6: -0.040919879 | J6: 0.58277998 | K6: -0.10502763 | L6: -0.013191054 | M6: -0.043731231 | N6: 0.053930557 | O6: 0.15626691 | P6: 0.13013818 | Q6: -0.074778955 | R6: 0.033219276 | S6: 0.1793391 | T6: 0.15434475 | U6: 0.33373579 | V6: 0.056332021 | W6: 0.020543223 | X6: 0.070488013 | Y6: 0.022237286 | Z6: -0.11606632 | AA6: -0.030468685 | AB6: -0.076411982 | AC6: -0.054285384 | AD6: -0.12934554 | AE6: -0.1456265 | AF6: -0.16644517 | AG6: -0.014638395 | AH6: 0.22362299 | AI6: -0.22954722 | AJ6: -0.24394663 | AK6: -0.18036582 | AL6: 0.2674402 | AM6: 0.036809488 | AN6: -0.032223087 | AO6: 0.15511178 | AP6: 0.12943014 | AQ6: -0.13798063 | AR6: -0.08526994 | AS6: -0.20572652 | AT6: 0.19490253 | AU6: -0.084732652 | AV6: -0.27255272 | AW6: -0.21323227
A7: sensitivityscore_After_layer1.0.conv2_0.5 | B7: 0.32595443 | C7: -0.088147401 | D7: -0.027526538 | E7: -0.13790728 | F7: -0.069965789 | G7: 1 | H7: 0.70278807 | I7: 0.54361601 | J7: 0.099938336 | K7: 0.029091587 | L7: 0.042301156 | M7: 0.042474087 | N7: -0.4027523 | O7: -0.19083537 | P7: -0.18104504 | Q7: -0.09898701 | R7: -0.18260883 | S7: -0.10994246 | T7: -0.083177785 | U7: -0.12673573 | V7: 0.019829032 | W7: -0.12349423 | X7: -0.029142166 | Y7: -0.016235522 | Z7: 0.077929113 | AA7: 0.16277261 | AB7: 0.2857868 | AC7: 0.27269789 | AD7: 0.046505476 | AE7: 0.16807461 | AF7: 0.18113362 | AG7: -0.17666811 | AH7: -0.16926422 | AI7: -0.11041695 | AJ7: -0.10915409 | AK7: -0.136945 | AL7: -0.11297907 | AM7: -0.14371286 | AN7: -0.14968049 | AO7: -0.36915486 | AP7: 0.16323171 | AQ7: 0.10117967 | AR7: 0.20168059 | AS7: 0.16242432 | AT7: -0.20840594 | AU7: -0.35533555 | AV7: -0.14030824 | AW7: -0.19736653
A8: sensitivityscore_After_layer1.0.conv2_0.6 | B8: 0.21632636 | C8: 0.036986784 | D8: 0.021753693 | E8: 0.024456611 | F8: -0.063664873 | G8: 0.70278807 | H8: 1 | I8: 0.76647388 | J8: 0.026381761 | K8: 0.097987018 | L8: 0.032305455 | M8: 0.078245334 | N8: -0.23823977 | O8: 0.083853933 | P8: 0.071773412 | Q8: -0.14148595 | R8: -0.075164725 | S8: -0.12487148 | T8: -0.051130045 | U8: -0.17910595 | V8: -0.0051808179 | W8: -0.01121476 | X8: -0.082075349 | Y8: -0.024609173 | Z8: 0.11045441 | AA8: 0.12693985 | AB8: 0.055961784 | AC8: 0.030367786 | AD8: 0.11362701 | AE8: 0.08372452 | AF8: 0.14104894 | AG8: -0.1768884 | AH8: -0.08799118 | AI8: -0.059515919 | AJ8: 0.020794983 | AK8: -0.025923523 | AL8: 0.021541487 | AM8: -0.19199959 | AN8: -0.10998294 | AO8: -0.27085694 | AP8: 0.2051426 | AQ8: 0.23914996 | AR8: 0.27086731 | AS8: 0.13541481 | AT8: 0.033704862 | AU8: -0.16466232 | AV8: 0.041567864 | AW8: -0.19215025
A9: sensitivityscore_After_layer1.0.conv2_0.7 | B9: 0.22431245 | C9: 0.039311315 | D9: 0.15417832 | E9: 0.20164833 | F9: -0.040919879 | G9: 0.54361601 | H9: 0.76647388 | I9: 1 | J9: 0.042012184 | K9: 0.11621529 | L9: 0.095492078 | M9: 0.13275417 | N9: -0.29470387 | O9: 0.013306861 | P9: 0.075602086 | Q9: -0.094444256 | R9: -0.12731931 | S9: -0.16920244 | T9: -0.019365919 | U9: -0.15562706 | V9: -0.0086384888 | W9: -0.22026412 | X9: -0.23310214 | Y9: -0.077449411 | Z9: 0.047134292 | AA9: 0.20480229 | AB9: 0.073517283 | AC9: 0.066769913 | AD9: -0.014811795 | AE9: 0.025026384 | AF9: 0.098889394 | AG9: -0.14529857 | AH9: -0.13591489 | AI9: -0.20549949 | AJ9: -0.11264149 | AK9: -0.14890988 | AL9: -0.21907257 | AM9: -0.020389057 | AN9: 0.077691449 | AO9: -0.092201398 | AP9: 0.034698666 | AQ9: 0.20054139 | AR9: 0.15634761 | AS9: 0.028249256 | AT9: -0.089755195 | AU9: -0.13269659 | AV9: 0.077125502 | AW9: -0.19213642
A10: layer1.0.conv3 | B10: 0.37877908 | C10: 0.19218901 | D10: 0.33848633 | E10: 0.04855825 | F10: 0.58277998 | G10: 0.099938336 | H10: 0.026381761 | I10: 0.042012184 | J10: 1 | K10: 0.060350846 | L10: 0.13150162 | M10: -0.031982798 | N10: -0.0064015073 | O10: 0.15593524 | P10: 0.10649734 | Q10: -0.026589498 | R10: 0.0050613747 | S10: 0.13404 | T10: 0.23727113 | U10: 0.075533699 | V10: 0.011600207 | W10: -0.28334499 | X10: -0.1610551 | Y10: -0.22905931 | Z10: -0.15360371 | AA10: -0.026115639 | AB10: -0.10165743 | AC10: -0.073444735 | AD10: -0.17821465 | AE10: -0.088160049 | AF10: -0.12495261 | AG10: -0.070007057 | AH10: -0.11493951 | AI10: -0.22634134 | AJ10: -0.26452084 | AK10: -0.26122113 | AL10: 0.1422942 | AM10: 0.18756204 | AN10: 0.11896988 | AO10: 0.27942595 | AP10: 0.043938763 | AQ10: -0.18981699 | AR10: -0.12866857 | AS10: -0.1003828 | AT10: 0.068980117 | AU10: -0.25033262 | AV10: -0.2831102 | AW10: -0.39206924
A11: sensitivityscore_After_layer1.0.conv3_0.5 | B11: -0.013907182 | C11: -0.00044454438 | D11: -0.020350137 | E11: 0.20107807 | F11: -0.10502763 | G11: 0.029091587 | H11: 0.097987018 | I11: 0.11621529 | J11: 0.060350846 | K11: 1 | L11: 0.7871267 | M11: 0.700607 | N11: 0.084747742 | O11: -0.015905557 | P11: -0.047290663 | Q11: 0.15821702 | R11: 0.13870511 | S11: -0.13843204 | T11: -0.027812419 | U11: -0.21591611 | V11: -0.18510987 | W11: -0.20325069 | X11: -0.3643129 | Y11: -0.23960203 | Z11: -0.1300462 | AA11: 0.054876947 | AB11: -0.18137213 | AC11: 0.041558611 | AD11: -0.28114814 | AE11: -0.042137714 | AF11: 0.19642491 | AG11: 0.21202981 | AH11: -0.02664582 | AI11: 0.11168901 | AJ11: 0.0076922091 | AK11: 0.050571151 | AL11: -0.072143273 | AM11: 0.29990637 | AN11: 0.10511779 | AO11: 0.21523077 | AP11: 0.087921682 | AQ11: -0.0060420471 | AR11: -0.089201886 | AS11: -0.21509988 | AT11: -0.27384554 | AU11: 0.074801537 | AV11: 0.031227447 | AW11: -0.016422708
A12: sensitivityscore_After_layer1.0.conv3_0.6 | B12: 0.041257122 | C12: -0.17801432 | D12: -0.05560591 | E12: 0.12770643 | F12: -0.013191054 | G12: 0.042301156 | H12: 0.032305455 | I12: 0.095492078 | J12: 0.13150162 | K12: 0.7871267 | L12: 1 | M12: 0.77920361 | N12: 0.0035330119 | O12: -0.18202748 | P12: -0.060951595 | Q12: 0.05132561 | R12: 0.012019914 | S12: 0.025913955 | T12: 0.10980652 | U12: -0.14792448 | V12: -0.24363482 | W12: -0.27432921 | X12: -0.29050107 | Y12: -0.22601172 | Z12: -0.34911696 | AA12: -0.033393554 | AB12: -0.2516719 | AC12: -0.11869355 | AD12: -0.40859954 | AE12: -0.055944245 | AF12: 0.25871292 | AG12: 0.11514861 | AH12: -0.11454601 | AI12: -0.096349948 | AJ12: -0.17263594 | AK12: -0.094517379 | AL12: -0.10695348 | AM12: 0.25128875 | AN12: 0.017263961 | AO12: 0.012349711 | AP12: -0.0032380808 | AQ12: -0.068171156 | AR12: -0.11820463 | AS12: -0.21024934 | AT12: -0.1919904 | AU12: -0.11853149 | AV12: -0.16015309 | AW12: -0.054398402
A13: sensitivityscore_After_layer1.0.conv3_0.7 | B13: -0.049499585 | C13: 0.049078907 | D13: 0.13093449 | E13: 0.10687771 | F13: -0.043731231 | G13: 0.042474087 | H13: 0.078245334 | I13: 0.13275417 | J13: -0.031982798 | K13: 0.700607 | L13: 0.77920361 | M13: 1 | N13: -0.095903602 | O13: -0.29392042 | P13: -0.17500779 | Q13: -0.086660896 | R13: -0.15131633 | S13: -0.096307212 | T13: -0.11047868 | U13: -0.13026917 | V13: -0.31108338 | W13: -0.35624852 | X13: -0.39580538 | Y13: -0.33557603 | Z13: -0.30711057 | AA13: -0.066836694 | AB13: -0.28183963 | AC13: -0.15946776 | AD13: -0.38729761 | AE13: -0.051174737 | AF13: 0.17558163 | AG13: 0.10257368 | AH13: -0.097200684 | AI13: -0.094126585 | AJ13: -0.14013002 | AK13: -0.02894175 | AL13: -0.18763815 | AM13: 0.1268679 | AN13: -0.099551821 | AO13: 0.015298211 | AP13: -0.11373274 | AQ13: -0.078090171 | AR13: -0.19756793 | AS13: -0.23611611 | AT13: -0.11300591 | AU13: -0.13236575 | AV13: -0.062278555 | AW13: -0.010623535
... A49: sensitivityscore_After_layer4.2.conv3_0.7 | B49: -0.37060628 | C49: 0.25038762 | D49: 0.0036613148 | E49: 0.020554543 | F49: -0.21323227 | G49: -0.19736653 | H49: -0.19215025 | I49: -0.19213642 | J49: -0.39206924 | K49: -0.016422708 | L49: -0.054398402 | M49: -0.010623535 | N49: -0.0066650811 | O49: -0.09874836 | P49: -0.22509598 | Q49: -0.15372502 | R49: -0.057373933 | S49: -0.13023531 | T49: -0.34331132 | U49: -0.0010336717 | V49: -0.20057956 | W49: 0.16815904 | X49: 0.23638667 | Y49: 0.23635247 | Z49: -0.088804432 | AA49: -0.31157085 | AB49: -0.1702422 | AC49: -0.18597687 | AD49: -0.036205561 | AE49: 0.10554434 | AF49: -0.017113355 | AG49: -0.063779396 | AH49: 0.23825222 | AI49: 0.13592327 | AJ49: 0.10629545 | AK49: 0.057157996 | AL49: -0.041595651 | AM49: -0.13574307 | AN49: -0.17482362 | AO49: -0.20894581 | AP49: -0.19890371 | AQ49: 0.031407966 | AR49: -0.02015147 | AS49: 0.056561421 | AT49: 0.26712933 | AU49: 0.5850357 | AV49: 0.44236382 | AW49: 1

Sheet Class_1
B1: layer1.0.conv1 | C1: sensitivityscore_After_layer1.0.conv1_0.5 | D1: sensitivityscore_After_layer1.0.conv1_0.6 | E1: sensitivityscore_After_layer1.0.conv1_0.7 | F1: layer1.0.conv2 | G1: sensitivityscore_After_layer1.0.conv2_0.5 | H1: sensitivityscore_After_layer1.0.conv2_0.6 | I1: sensitivityscore_After_layer1.0.conv2_0.7 | J1: layer1.0.conv3 | K1: sensitivityscore_After_layer1.0.conv3_0.5 | L1: sensitivityscore_After_layer1.0.conv3_0.6 | M1: sensitivityscore_After_layer1.0.conv3_0.7 | N1: layer4.0.conv1 | O1: sensitivityscore_After_layer4.0.conv1_0.5 | P1: sensitivityscore_After_layer4.0.conv1_0.6 | Q1: sensitivityscore_After_layer4.0.conv1_0.7 | R1: layer4.0.conv2 | S1: sensitivityscore_After_layer4.0.conv2_0.5 | T1: sensitivityscore_After_layer4.0.conv2_0.6 | U1: sensitivityscore_After_layer4.0.conv2_0.7 | V1: layer4.0.conv3 | W1: sensitivityscore_After_layer4.0.conv3_0.5 | X1: sensitivityscore_After_layer4.0.conv3_0.6 | Y1: sensitivityscore_After_layer4.0.conv3_0.7 | Z1: layer4.1.conv1 | AA1: sensitivityscore_After_layer4.1.conv1_0.5 | AB1: sensitivityscore_After_layer4.1.conv1_0.6 | AC1: sensitivityscore_After_layer4.1.conv1_0.7 | AD1: layer4.1.conv2 | AE1: sensitivityscore_After_layer4.1.conv2_0.5 | AF1: sensitivityscore_After_layer4.1.conv2_0.6 | AG1: sensitivityscore_After_layer4.1.conv2_0.7 | AH1: layer4.1.conv3 | AI1: sensitivityscore_After_layer4.1.conv3_0.5 | AJ1: sensitivityscore_After_layer4.1.conv3_0.6 | AK1: sensitivityscore_After_layer4.1.conv3_0.7 | AL1: layer4.2.conv1 | AM1: sensitivityscore_After_layer4.2.conv1_0.5 | AN1: sensitivityscore_After_layer4.2.conv1_0.6 | AO1: sensitivityscore_After_layer4.2.conv1_0.7 | AP1: layer4.2.conv2 | AQ1: sensitivityscore_After_layer4.2.conv2_0.5 | AR1: sensitivityscore_After_layer4.2.conv2_0.6 | AS1: sensitivityscore_After_layer4.2.conv2_0.7 | AT1: layer4.2.conv3 | AU1: sensitivityscore_After_layer4.2.conv3_0.5 | AV1: sensitivityscore_After_layer4.2.conv3_0.6 | AW1: sensitivityscore_After_layer4.2.conv3_0.7
A2: layer1.0.conv1 | B2: 1 | C2: -0.0030305802 | D2: 0.10873134 | E2: -0.055558976 | F2: 0.62595353 | G2: 0.21137102 | H2: 0.35472314 | I2: 0.26220418 | J2: 0.62678636 | K2: 0.15625405 | L2: 0.26595823 | M2: -0.0014512559 | N2: 0.13843952 | O2: -0.077495998 | P2: -0.089839535 | Q2: -0.16338297 | R2: -0.079605415 | S2: 0.049285354 | T2: -0.00018350506 | U2: -0.095862688 | V2: -0.073233113 | W2: -0.24294536 | X2: -0.40963605 | Y2: -0.28510134 | Z2: -0.03363474 | AA2: -0.10716781 | AB2: -0.091095879 | AC2: -0.13959919 | AD2: -0.14066422 | AE2: -0.17858046 | AF2: -0.11210055 | AG2: -0.019848705 | AH2: 0.017943931 | AI2: 0.05881078 | AJ2: -0.084919624 | AK2: -0.091813039 | AL2: 0.016225398 | AM2: -0.034158113 | AN2: -0.10723868 | AO2: -0.086570859 | AP2: 0.013605392 | AQ2: -0.16319327 | AR2: -0.16683552 | AS2: -0.17479823 | AT2: 0.11789524 | AU2: -0.28795836 | AV2: -0.32301486 | AW2: -0.26562001
A3: sensitivityscore_After_layer1.0.conv1_0.5 | B3: -0.0030305802 | C3: 1 | D3: 0.18211428 | E3: 0.091452681 | F3: -0.17244298 | G3: -0.039792393 | H3: 0.032850335 | I3: 0.17550432 | J3: -0.21871101 | K3: 0.2291854 | L3: 0.16479727 | M3: 0.32390135 | N3: -0.21028488 | O3: -0.16245846 | P3: -0.20547936 | Q3: 0.019522994 | R3: -0.14575938 | S3: 0.20185599 | T3: 0.16245365 | U3: -0.013845209 | V3: -0.3584541 | W3: -0.20559645 | X3: 0.0098089295 | Y3: -0.20034073 | Z3: -0.22711891 | AA3: -0.033017404 | AB3: 0.088628632 | AC3: 0.22669008 | AD3: -0.33061403 | AE3: -0.070138967 | AF3: 0.10683944 | AG3: 0.19743409 | AH3: -0.33491995 | AI3: -0.051214818 | AJ3: -0.082766855 | AK3: -0.05118698 | AL3: -0.2401239 | AM3: -0.31495408 | AN3: -0.30268237 | AO3: -0.33306037 | AP3: -0.095197199 | AQ3: 0.001991647 | AR3: -0.23177052 | AS3: -0.089383177 | AT3: -0.06018728 | AU3: -0.068617997 | AV3: -0.079612841 | AW3: 0.061661235
A4: sensitivityscore_After_layer1.0.conv1_0.6 | B4: 0.10873134 | C4: 0.18211428 | D4: 1 | E4: 0.56324459 | F4: 0.022887701 | G4: -0.065326435 | H4: 0.065040015 | I4: 0.083668468 | J4: 0.016386322 | K4: -0.037976676 | L4: 0.098482774 | M4: 0.1118354 | N4: -0.066910938 | O4: -0.31799489 | P4: -0.22125776 | Q4: -0.18066927 | R4: -0.1491309 | S4: -0.20294262 | T4: -0.12065059 | U4: -0.26799562 | V4: -0.041199252 | W4: -0.11476759 | X4: -0.072562899 | Y4: -0.046721944 | Z4: -0.060954406 | AA4: -0.29010425 | AB4: -0.23971294 | AC4: -0.2065484 | AD4: -0.055605918 | AE4: -0.034977369 | AF4: -0.09775926 | AG4: -0.059072103 | AH4: -0.046512908 | AI4: -0.1341497 | AJ4: -0.1680947 | AK4: -0.20501091 | AL4: 0.04247244 | AM4: -0.054674082 | AN4: -0.095016958 | AO4: -0.064569112 | AP4: 0.025478186 | AQ4: -0.14174235 | AR4: -0.035712533 | AS4: -0.11808531 | AT4: -0.066228166 | AU4: -0.019037755 | AV4: -0.028138911 | AW4: -0.063965514
A5: sensitivityscore_After_layer1.0.conv1_0.7 | B5: -0.055558976 | C5: 0.091452681 | D5: 0.56324459 | E5: 1 | F5: -0.18095189 | G5: -0.010934566 | H5: -0.143446 | I5: -0.10603199 | J5: -0.13193895 | K5: 0.026147274 | L5: 0.099055562 | M5: 0.11509934 | N5: -0.1548956 | O5: -0.18325857 | P5: -0.084879245 | Q5: -0.14115214 | R5: -0.040539582 | S5: -0.19134469 | T5: -0.030980917 | U5: -0.10112326 | V5: 0.1321408 | W5: -0.025753801 | X5: 0.074314454 | Y5: -0.10118873 | Z5: 0.015869678 | AA5: -0.1502332 | AB5: -0.079891629 | AC5: -0.10804805 | AD5: 0.024223175 | AE5: -0.3885713 | AF5: -0.41490591 | AG5: -0.42606038 | AH5: -0.035849581 | AI5: -0.075804154 | AJ5: -0.084827054 | AK5: -0.15760735 | AL5: 0.016672084 | AM5: -0.065169355 | AN5: -0.23065979 | AO5: -0.16392016 | AP5: 0.12654919 | AQ5: -0.0015981836 | AR5: 0.10119737 | AS5: 0.02242677 | AT5: 0.17371665 | AU5: 0.063059986 | AV5: 0.14352442 | AW5: 0.046567631
A6: layer1.0.conv2 | B6: 0.62595353 | C6: -0.17244298 | D6: 0.022887701 | E6: -0.18095189 | F6: 1 | G6: 0.14656518 | H6: 0.22896409 | I6: 0.0350623 | J6: 0.80724195 | K6: -0.019997957 | L6: -0.01395248 | M6: -0.23489721 | N6: -0.033756764 | O6: -0.076066789 | P6: -0.053461268 | Q6: -0.15947689 | R6: -0.13007652 | S6: 0.12510185 | T6: 0.095427311 | U6: -0.065076191 | V6: 0.0081907124 | W6: -0.12285466 | X6: -0.24608807 | Y6: -0.1165921 | Z6: 0.043215743 | AA6: 0.080277245 | AB6: -0.11123716 | AC6: 0.065353592 | AD6: -0.037819876 | AE6: -0.099795838 | AF6: 0.069322178 | AG6: 0.023937671 | AH6: 0.20298825 | AI6: 0.00034825103 | AJ6: -0.025130182 | AK6: -0.092026864 | AL6: 0.010034713 | AM6: -0.14530373 | AN6: -0.18162615 | AO6: -0.038229367 | AP6: -0.012652725 | AQ6: -0.21087272 | AR6: -0.21411468 | AS6: -0.26762478 | AT6: -0.028858714 | AU6: -0.16907446 | AV6: -0.23570919 | AW6: -0.17085014
A7: sensitivityscore_After_layer1.0.conv2_0.5 | B7: 0.21137102 | C7: -0.039792393 | D7: -0.065326435 | E7: -0.010934566 | F7: 0.14656518 | G7: 1 | H7: 0.70501019 | I7: 0.46306627 | J7: 0.31650789 | K7: 0.084411514 | L7: 0.37921648 | M7: 0.10359761 | N7: -0.0050930665 | O7: -0.18375346 | P7: -0.26519707 | Q7: -0.3149752 | R7: -0.10717887 | S7: 0.33953902 | T7: 0.36151486 | U7: 0.12784917 | V7: -0.12655437 | W7: -0.058050811 | X7: -0.27993942 | Y7: -0.017620792 | Z7: 0.088092543 | AA7: -0.088378085 | AB7: 0.022945002 | AC7: -0.047536752 | AD7: -0.1441233 | AE7: -0.26251846 | AF7: -0.31179502 | AG7: -0.11206105 | AH7: -0.15010237 | AI7: 0.083826985 | AJ7: -0.083954037 | AK7: -0.034142296 | AL7: -0.022563503 | AM7: 0.085336883 | AN7: 0.11037262 | AO7: 0.18187342 | AP7: 0.10627998 | AQ7: -0.049046219 | AR7: 0.18633916 | AS7: 0.19083886 | AT7: 0.27636701 | AU7: -0.40306925 | AV7: -0.29075675 | AW7: -0.2772861
A8: sensitivityscore_After_layer1.0.conv2_0.6 | B8: 0.35472314 | C8: 0.032850335 | D8: 0.065040015 | E8: -0.143446 | F8: 0.22896409 | G8: 0.70501019 | H8: 1 | I8: 0.66331241 | J8: 0.29051557 | K8: 0.18603607 | L8: 0.35833708 | M8: 0.10452044 | N8: 0.080887367 | O8: -0.043778152 | P8: -0.18529488 | Q8: -0.14835302 | R8: 0.061792447 | S8: 0.18778373 | T8: 0.38012483 | U8: 0.01703595 | V8: -0.09557951 | W8: 0.00035710866 | X8: -0.13813206 | Y8: 0.11867417 | Z8: 0.10473321 | AA8: 0.0028689102 | AB8: 0.045799285 | AC8: 0.010914442 | AD8: -0.1267951 | AE8: -0.062246926 | AF8: -0.058983941 | AG8: -0.007705458 | AH8: -0.02323743 | AI8: 0.27214835 | AJ8: 0.16598264 | AK8: 0.17045171 | AL8: -0.050713092 | AM8: 0.033470914 | AN8: 0.075774437 | AO8: 0.12539209 | AP8: 0.025431699 | AQ8: -0.087101523 | AR8: 0.098603775 | AS8: 0.15718997 | AT8: 0.2650492 | AU8: -0.37074684 | AV8: -0.26335109 | AW8: -0.30600266
A9: sensitivityscore_After_layer1.0.conv2_0.7 | B9: 0.26220418 | C9: 0.17550432 | D9: 0.083668468 | E9: -0.10603199 | F9: 0.0350623 | G9: 0.46306627 | H9: 0.66331241 | I9: 1 | J9: 0.1589323 | K9: 0.29530174 | L9: 0.32157101 | M9: 0.22466091 | N9: 0.010515349 | O9: -0.25597022 | P9: -0.15786294 | Q9: -0.27825869 | R9: 0.09716307 | S9: 0.18307244 | T9: 0.33880509 | U9: -0.015426034 | V9: -0.1497102 | W9: 0.042208432 | X9: -0.0088709938 | Y9: 0.10598086 | Z9: -0.11413289 | AA9: 0.02913935 | AB9: 0.20793996 | AC9: -0.091555021 | AD9: -0.17865276 | AE9: 0.14961422 | AF9: 0.015257537 | AG9: 0.11358999 | AH9: -0.16874266 | AI9: 0.071992479 | AJ9: 0.022655956 | AK9: 0.015269522 | AL9: -0.10074164 | AM9: 0.015950795 | AN9: 0.045935349 | AO9: 0.077079536 | AP9: -0.022459174 | AQ9: -0.0021088959 | AR9: 0.099586003 | AS9: -0.0073635848 | AT9: 0.17416552 | AU9: -0.31215427 | AV9: -0.16688991 | AW9: -0.25837036
A10: layer1.0.conv3 | B10: 0.62678636 | C10: -0.21871101 | D10: 0.016386322 | E10: -0.13193895 | F10: 0.80724195 | G10: 0.31650789 | H10: 0.29051557 | I10: 0.1589323 | J10: 1 | K10: 0.059532177 | L10: 0.096308115 | M10: -0.18545838 | N10: -0.021789691 | O10: -0.21042981 | P10: -0.20447656 | Q10: -0.29960306 | R10: -0.13951368 | S10: 0.28520472 | T10: 0.26830875 | U10: 0.016018163 | V10: 0.098577957 | W10: -0.23878906 | X10: -0.44291819 | Y10: -0.2532439 | Z10: 0.11572821 | AA10: 0.12944046 | AB10: -0.091810345 | AC10: 0.086157434 | AD10: 0.017885262 | AE10: -0.14782613 | AF10: -0.088174819 | AG10: -0.090518742 | AH10: 0.19489957 | AI10: -0.072705024 | AJ10: -0.1331736 | AK10: -0.19940055 | AL10: 0.17289655 | AM10: -0.088602901 | AN10: -0.12051942 | AO10: -0.00046652351 | AP10: 0.17111694 | AQ10: -0.09391872 | AR10: -0.075150054 | AS10: -0.12511163 | AT10: 0.093335685 | AU10: -0.27945316 | AV10: -0.26340099 | AW10: -0.23367826
A11: sensitivityscore_After_layer1.0.conv3_0.5 | B11: 0.15625405 | C11: 0.2291854 | D11: -0.037976676 | E11: 0.026147274 | F11: -0.019997957 | G11: 0.084411514 | H11: 0.18603607 | I11: 0.29530174 | J11: 0.059532177 | K11: 1 | L11: 0.69072502 | M11: 0.55558452 | N11: -0.35918116 | O11: -0.3176712 | P11: -0.46897204 | Q11: -0.15687842 | R11: -0.41086896 | S11: -0.1209497 | T11: -0.034827862 | U11: -0.17097772 | V11: -0.29774061 | W11: -0.19450158 | X11: -0.17992219 | Y11: -0.10202566 | Z11: -0.29847234 | AA11: 0.12740755 | AB11: 0.075843689 | AC11: 0.044444824 | AD11: -0.32308476 | AE11: -0.17840996 | AF11: -0.26085247 | AG11: -0.17335937 | AH11: 0.019044482 | AI11: 0.012671338 | AJ11: -0.069849837 | AK11: -0.052028136 | AL11: -0.041086615 | AM11: -0.076888754 | AN11: -0.12526718 | AO11: -0.17951418 | AP11: 0.075977619 | AQ11: 0.14192906 | AR11: 0.11395503 | AS11: 0.066616835 | AT11: -0.0092350356 | AU11: -0.33529161 | AV11: -0.23334978 | AW11: -0.18177394
A12: sensitivityscore_After_layer1.0.conv3_0.6 | B12: 0.26595823 | C12: 0.16479727 | D12: 0.098482774 | E12: 0.099055562 | F12: -0.01395248 | G12: 0.37921648 | H12: 0.35833708 | I12: 0.32157101 | J12: 0.096308115 | K12: 0.69072502 | L12: 1 | M12: 0.62312296 | N12: -0.23557216 | O12: -0.40159108 | P12: -0.54497475 | Q12: -0.3592462 | R12: -0.35145964 | S12: 0.028724457 | T12: -0.049652297 | U12: -0.15106029 | V12: -0.40600735 | W12: -0.24332897 | X12: -0.24625317 | Y12: -0.093662156 | Z12: -0.21733293 | AA12: -0.13756759 | AB12: -0.092085993 | AC12: -0.10128869 | AD12: -0.4301494 | AE12: -0.35341424 | AF12: -0.49359101 | AG12: -0.32536591 | AH12: -0.15652072 | AI12: -0.1416634 | AJ12: -0.30676189 | AK12: -0.25018665 | AL12: -0.057258515 | AM12: 0.042879352 | AN12: -0.050874136 | AO12: -0.030610663 | AP12: 0.058857083 | AQ12: 0.013408574 | AR12: 0.14471322 | AS12: 0.10368222 | AT12: 0.15606343 | AU12: -0.34622477 | AV12: -0.3113646 | AW12: -0.26700021
A13: sensitivityscore_After_layer1.0.conv3_0.7 | B13: -0.0014512559 | C13: 0.32390135 | D13: 0.1118354 | E13: 0.11509934 | F13: -0.23489721 | G13: 0.10359761 | H13: 0.10452044 | I13: 0.22466091 | J13: -0.18545838 | K13: 0.55558452 | L13: 0.62312296 | M13: 1 | N13: -0.3294966 | O13: -0.3545819 | P13: -0.54551566 | Q13: -0.35997893 | R13: -0.24617064 | S13: -0.10655481 | T13: -0.079185741 | U13: -0.13269238 | V13: -0.24409111 | W13: -0.28673608 | X13: -0.19438129 | Y13: -0.087382789 | Z13: -0.23497592 | AA13: -0.1208049 | AB13: -0.035788174 | AC13: -0.16414482 | AD13: -0.23617462 | AE13: -0.12981065 | AF13: -0.26505064 | AG13: -0.074488296 | AH13: -0.18596269 | AI13: -0.23779243 | AJ13: -0.26079759 | AK13: -0.26268563 | AL13: -0.15108512 | AM13: -0.083289447 | AN13: -0.14568653 | AO13: -0.17312115 | AP13: -0.11212614 | AQ13: 0.022167204 | AR13: 0.14602023 | AS13: 0.08033462 | AT13: -0.0089376799 | AU13: -0.27431196 | AV13: -0.14804191 | AW13: -0.27620125
... A49: sensitivityscore_After_layer4.2.conv3_0.7 | B49: -0.26562001 | C49: 0.061661235 | D49: -0.063965514 | E49: 0.046567631 | F49: -0.17085014 | G49: -0.2772861 | H49: -0.30600266 | I49: -0.25837036 | J49: -0.23367826 | K49: -0.18177394 | L49: -0.26700021 | M49: -0.27620125 | N49: 0.22521033 | O49: 0.072272385 | P49: 0.34982487 | Q49: 0.3036432 | R49: 0.2199112 | S49: 0.091688379 | T49: -0.071335005 | U49: 0.096903437 | V49: 0.1992647 | W49: -0.0024395652 | X49: 0.17867715 | Y49: -0.11763058 | Z49: 0.21949408 | AA49: 0.41497463 | AB49: 0.23074529 | AC49: 0.38401144 | AD49: 0.31213268 | AE49: 0.10388261 | AF49: 0.23795413 | AG49: 0.044796402 | AH49: -0.067146562 | AI49: 0.13481535 | AJ49: 0.08580953 | AK49: 0.055174242 | AL49: -0.070915728 | AM49: -0.096753548 | AN49: 0.027589327 | AO49: -0.096054556 | AP49: -0.034820319 | AQ49: 0.13589942 | AR49: -0.13191935 | AS49: -0.077821595 | AT49: -0.065069345 | AU49: 0.73893938 | AV49: 0.70020303 | AW49: 1

Sheet Class_2
B1: layer1.0.conv1 | C1: sensitivityscore_After_layer1.0.conv1_0.5 | D1: sensitivityscore_After_layer1.0.conv1_0.6 | E1: sensitivityscore_After_layer1.0.conv1_0.7 | F1: layer1.0.conv2 | G1: sensitivityscore_After_layer1.0.conv2_0.5 | H1: sensitivityscore_After_layer1.0.conv2_0.6 | I1: sensitivityscore_After_layer1.0.conv2_0.7 | J1: layer1.0.conv3 | K1: sensitivityscore_After_layer1.0.conv3_0.5 | L1: sensitivityscore_After_layer1.0.conv3_0.6 | M1: sensitivityscore_After_layer1.0.conv3_0.7 | N1: layer4.0.conv1 | O1: sensitivityscore_After_layer4.0.conv1_0.5 | P1: sensitivityscore_After_layer4.0.conv1_0.6 | Q1: sensitivityscore_After_layer4.0.conv1_0.7 | R1: layer4.0.conv2 | S1: sensitivityscore_After_layer4.0.conv2_0.5 | T1: sensitivityscore_After_layer4.0.conv2_0.6 | U1: sensitivityscore_After_layer4.0.conv2_0.7 | V1: layer4.0.conv3 | W1: sensitivityscore_After_layer4.0.conv3_0.5 | X1: sensitivityscore_After_layer4.0.conv3_0.6 | Y1: sensitivityscore_After_layer4.0.conv3_0.7 | Z1: layer4.1.conv1 | AA1: sensitivityscore_After_layer4.1.conv1_0.5 | AB1: sensitivityscore_After_layer4.1.conv1_0.6 | AC1: sensitivityscore_After_layer4.1.conv1_0.7 | AD1: layer4.1.conv2 | AE1: sensitivityscore_After_layer4.1.conv2_0.5 | AF1: sensitivityscore_After_layer4.1.conv2_0.6 | AG1: sensitivityscore_After_layer4.1.conv2_0.7 | AH1: layer4.1.conv3 | AI1: sensitivityscore_After_layer4.1.conv3_0.5 | AJ1: sensitivityscore_After_layer4.1.conv3_0.6 | AK1: sensitivityscore_After_layer4.1.conv3_0.7 | AL1: layer4.2.conv1 | AM1: sensitivityscore_After_layer4.2.conv1_0.5 | AN1: sensitivityscore_After_layer4.2.conv1_0.6 | AO1: sensitivityscore_After_layer4.2.conv1_0.7 | AP1: layer4.2.conv2 | AQ1: sensitivityscore_After_layer4.2.conv2_0.5 | AR1: sensitivityscore_After_layer4.2.conv2_0.6 | AS1: sensitivityscore_After_layer4.2.conv2_0.7 | AT1: layer4.2.conv3 | AU1: sensitivityscore_After_layer4.2.conv3_0.5 | AV1: sensitivityscore_After_layer4.2.conv3_0.6 | AW1: sensitivityscore_After_layer4.2.conv3_0.7
A2: layer1.0.conv1 | B2: 1 | C2: 0.39366671 | D2: -0.21155252 | E2: -0.080859245 | F2: 0.59379695 | G2: -0.057700712 | H2: -0.17733801 | I2: -0.065822777 | J2: 0.44645718 | K2: -0.26255315 | L2: -0.11951162 | M2: 0.031312827 | N2: 0.15278325 | O2: -0.051060905 | P2: -0.033883587 | Q2: -0.15270962 | R2: -0.016537455 | S2: 0.011908516 | T2: 0.022693194 | U2: 0.1469718 | V2: 0.16470714 | W2: 0.28465509 | X2: 0.2561067 | Y2: 0.27480862 | Z2: 0.14943104 | AA2: 0.018732972 | AB2: -0.01989313 | AC2: -0.017859778 | AD2: 0.084389284 | AE2: 0.053966426 | AF2: 0.0090985306 | AG2: 0.038167869 | AH2: 0.19878991 | AI2: 0.061358012 | AJ2: 0.053716596 | AK2: 0.11748131 | AL2: 0.055961814 | AM2: -0.017541936 | AN2: -0.033716604 | AO2: -0.11953184 | AP2: 0.19728743 | AQ2: 0.1359433 | AR2: 0.2025668 | AS2: 0.10361031 | AT2: 0.048169968 | AU2: 0.10990253 | AV2: 0.058196488 | AW2: 0.097405589
A3: sensitivityscore_After_layer1.0.conv1_0.5 | B3: 0.39366671 | C3: 1 | D3: -0.050432408 | E3: -0.063570176 | F3: 0.18961401 | G3: -0.19795513 | H3: -0.22654682 | I3: -0.077638758 | J3: 0.13748274 | K3: 0.0023056377 | L3: 0.10059945 | M3: 0.13540086 | N3: 0.14626938 | O3: -0.046999251 | P3: 0.0029508941 | Q3: -0.1303018 | R3: 0.06854709 | S3: 0.15230227 | T3: -0.041183971 | U3: 0.092099805 | V3: 0.026222514 | W3: 0.17733028 | X3: 0.20772723 | Y3: 0.1847428 | Z3: 0.0078909589 | AA3: 0.023560644 | AB3: 0.063305161 | AC3: -0.017292236 | AD3: 0.020492324 | AE3: 0.092569755 | AF3: 0.11693735 | AG3: -0.030427378 | AH3: 0.098648016 | AI3: -0.049915013 | AJ3: -0.2258869 | AK3: -0.13350198 | AL3: -0.043217301 | AM3: -0.019082644 | AN3: -0.024472073 | AO3: 0.017531993 | AP3: -0.031433636 | AQ3: 0.0015505701 | AR3: 0.050827913 | AS3: 0.039380197 | AT3: 0.1219089 | AU3: 0.023894651 | AV3: 0.0015470393 | AW3: 0.090759066
A4: sensitivityscore_After_layer1.0.conv1_0.6 | B4: -0.21155252 | C4: -0.050432408 | D4: 1 | E4: 0.42694187 | F4: -0.16649629 | G4: 0.2628912 | H4: 0.25575846 | I4: 0.14121427 | J4: 0.064461112 | K4: 0.18830985 | L4: 0.073585565 | M4: -0.093126673 | N4: -0.032847717 | O4: 0.15984985 | P4: 0.041055779 | Q4: -0.027177096 | R4: 0.21735256 | S4: 0.0029947818 | T4: -0.26455533 | U4: -0.0051587029 | V4: 0.066594283 | W4: -0.10683631 | X4: -0.048998489 | Y4: -0.013166511 | Z4: 0.067903875 | AA4: -0.12725507 | AB4: -0.049608805 | AC4: -0.011859607 | AD4: -0.033230543 | AE4: -0.11484412 | AF4: -0.085727187 | AG4: -0.27253247 | AH4: 0.025027794 | AI4: -0.022246271 | AJ4: -0.022334218 | AK4: 0.14782344 | AL4: -0.19606926 | AM4: 0.010469158 | AN4: -0.02138765 | AO4: -0.05023409 | AP4: 0.087239875 | AQ4: 0.10552676 | AR4: 0.022289032 | AS4: 0.08447533 | AT4: -0.024449389 | AU4: 0.075382025 | AV4: 0.013180271 | AW4: 0.030087583
A5: sensitivityscore_After_layer1.0.conv1_0.7 | B5: -0.080859245 | C5: -0.063570176 | D5: 0.42694187 | E5: 1 | F5: -0.093254854 | G5: -0.17079814 | H5: -0.22310891 | I5: -0.15800444 | J5: 0.18267737 | K5: -0.14907615 | L5: -0.16165068 | M5: -0.12709216 | N5: 0.06657265 | O5: -0.057780758 | P5: 0.038514799 | Q5: 0.0037679618 | R5: -0.17024498 | S5: 0.016487118 | T5: -0.14545964 | U5: -0.16856247 | V5: 0.076520198 | W5: 0.039756175 | X5: -0.0096166566 | Y5: -0.053532798 | Z5: 0.23169884 | AA5: -0.12407104 | AB5: -0.10259951 | AC5: 0.00011801898 | AD5: 0.24768735 | AE5: -0.27710083 | AF5: -0.30852137 | AG5: -0.16287564 | AH5: 0.1357588 | AI5: -0.20713798 | AJ5: -0.25194912 | AK5: -0.072861507 | AL5: -0.25835711 | AM5: -0.098761034 | AN5: -0.18461531 | AO5: -0.24998958 | AP5: -0.01721986 | AQ5: -0.083436935 | AR5: -0.074638982 | AS5: -0.068259837 | AT5: -0.15138436 | AU5: 0.052108687 | AV5: -0.12568679 | AW5: -0.091949973
A6: layer1.0.conv2 | B6: 0.59379695 | C6: 0.18961401 | D6: -0.16649629 | E6: -0.093254854 | F6: 1 | G6: 0.035479366 | H6: -0.00040545172 | I6: -0.0060014775 | J6: 0.44719518 | K6: -0.12496664 | L6: -0.015189735 | M6: 0.13595615 | N6: 0.31588337 | O6: -0.019819368 | P6: 0.055547065 | Q6: -0.055379503 | R6: 0.202083 | S6: -0.054606273 | T6: -0.0093047281 | U6: -0.13716571 | V6: 0.28703656 | W6: 0.30409786 | X6: 0.36405327 | Y6: 0.36029967 | Z6: 0.14458171 | AA6: -0.02242076 | AB6: 0.0067762814 | AC6: 0.022347794 | AD6: 0.26371982 | AE6: -0.017060569 | AF6: -0.017072506 | AG6: -0.076194475 | AH6: 0.34363923 | AI6: 0.36001096 | AJ6: 0.36106042 | AK6: 0.35781103 | AL6: 0.30292275 | AM6: -0.0033832527 | AN6: 0.075848447 | AO6: -0.060591113 | AP6: 0.44490024 | AQ6: -0.096013103 | AR6: 0.051460139 | AS6: -0.056006633 | AT6: 0.41864626 | AU6: 0.29440991 | AV6: 0.36213719 | AW6: 0.43587877
A7: sensitivityscore_After_layer1.0.conv2_0.5 | B7: -0.057700712 | C7: -0.19795513 | D7: 0.2628912 | E7: -0.17079814 | F7: 0.035479366 | G7: 1 | H7: 0.69569961 | I7: 0.64623115 | J7: 0.043544147 | K7: 0.14132187 | L7: 0.20614096 | M7: 0.19811889 | N7: 0.14822302 | O7: 0.11755572 | P7: 0.072192548 | Q7: -0.18734588 | R7: 0.18246193 | S7: -0.4047394 | T7: -0.26165256 | U7: -0.25211097 | V7: 0.33013811 | W7: -0.017567861 | X7: 0.013650661 | Y7: 0.011262191 | Z7: 0.075647731 | AA7: 0.11841072 | AB7: 0.18001287 | AC7: 0.094311697 | AD7: 0.10787412 | AE7: 0.21406204 | AF7: 0.18770606 | AG7: -0.03904671 | AH7: 0.2915336 | AI7: 0.3280942 | AJ7: 0.30944118 | AK7: 0.28407182 | AL7: 0.013305034 | AM7: -0.0054581697 | AN7: 0.11256125 | AO7: 0.1349473 | AP7: 0.1313943 | AQ7: 0.043835597 | AR7: 0.0048070716 | AS7: 0.098468362 | AT7: 0.10560366 | AU7: 0.22155408 | AV7: 0.29489865 | AW7: 0.19761321
A8: sensitivityscore_After_layer1.0.conv2_0.6 | B8: -0.17733801 | C8: -0.22654682 | D8: 0.25575846 | E8: -0.22310891 | F8: -0.00040545172 | G8: 0.69569961 | H8: 1 | I8: 0.74641972 | J8: -0.18486311 | K8: 0.28273461 | L8: 0.15786978 | M8: 0.2014103 | N8: 0.18959147 | O8: 0.091192175 | P8: 0.044746091 | Q8: 0.010642671 | R8: 0.18114317 | S8: -0.22329685 | T8: -0.059882158 | U8: -0.16961838 | V8: 0.2203526 | W8: 0.018245436 | X8: 0.11139264 | Y8: 0.079102799 | Z8: 0.059051681 | AA8: 0.0047720773 | AB8: 0.046574627 | AC8: -0.068809754 | AD8: -0.085071038 | AE8: -0.080099189 | AF8: -0.1357563 | AG8: -0.27341028 | AH8: 0.16476555 | AI8: 0.22259468 | AJ8: 0.27233656 | AK8: 0.19184496 | AL8: -0.031046603 | AM8: -0.054646493 | AN8: 0.0974558 | AO8: 0.063842258 | AP8: 0.13993022 | AQ8: 0.11553011 | AR8: 0.094732915 | AS8: 0.17580171 | AT8: 0.14593995 | AU8: 0.19748443 | AV8: 0.24413373 | AW8: 0.19116136
A9: sensitivityscore_After_layer1.0.conv2_0.7 | B9: -0.065822777 | C9: -0.077638758 | D9: 0.14121427 | E9: -0.15800444 | F9: -0.0060014775 | G9: 0.64623115 | H9: 0.74641972 | I9: 1 | J9: -0.10959514 | K9: 0.26603584 | L9: 0.3081869 | M9: 0.31703106 | N9: 0.2131628 | O9: -0.070775919 | P9: -0.072580337 | Q9: -0.11142291 | R9: 0.10963407 | S9: -0.20267356 | T9: -0.037839285 | U9: -0.12989769 | V9: 0.20157844 | W9: 0.12742359 | X9: 0.20326444 | Y9: 0.16820133 | Z9: -0.0066439269 | AA9: 0.025483499 | AB9: 0.06518648 | AC9: -0.031251926 | AD9: -0.089598335 | AE9: 0.16629556 | AF9: 0.084006916 | AG9: -0.089567954 | AH9: 0.17052143 | AI9: 0.17761344 | AJ9: 0.22732368 | AK9: 0.019781148 | AL9: -0.11321987 | AM9: -0.10517831 | AN9: 0.041076312 | AO9: 0.12480116 | AP9: 0.031340602 | AQ9: 0.059362768 | AR9: -0.052752631 | AS9: 0.12545047 | AT9: 0.13987334 | AU9: 0.099509223 | AV9: 0.16216177 | AW9: 0.13505957
A10: layer1.0.conv3 | B10: 0.44645718 | C10: 0.13748274 | D10: 0.064461112 | E10: 0.18267737 | F10: 0.44719518 | G10: 0.043544147 | H10: -0.18486311 | I10: -0.10959514 | J10: 1 | K10: -0.15995478 | L10: 0.097908656 | M10: 0.085141663 | N10: 0.37301563 | O10: 0.087298081 | P10: 0.1812483 | Q10: 0.06434886 | R10: 0.24275995 | S10: 0.000367224 | T10: -0.13486241 | U10: 0.17043003 | V10: 0.23253014 | W10: 0.18460697 | X10: 0.093942523 | Y10: 0.19429184 | Z10: 0.3304245 | AA10: -0.016135834 | AB10: 0.068796498 | AC10: 0.11560427 | AD10: 0.34512926 | AE10: -0.094482779 | AF10: -0.098780981 | AG10: -0.078397248 | AH10: 0.2055187 | AI10: 0.09431078 | AJ10: 0.093124788 | AK10: 0.10245667 | AL10: 0.11321724 | AM10: 0.12070214 | AN10: 0.034152802 | AO10: 0.04750707 | AP10: 0.15797117 | AQ10: -0.091314844 | AR10: -0.20919416 | AS10: -0.099207557 | AT10: 0.17055723 | AU10: 0.088889722 | AV10: 0.0088986035 | AW10: 0.054600781
A11: sensitivityscore_After_layer1.0.conv3_0.5 | B11: -0.26255315 | C11: 0.0023056377 | D11: 0.18830985 | E11: -0.14907615 | F11: -0.12496664 | G11: 0.14132187 | H11: 0.28273461 | I11: 0.26603584 | J11: -0.15995478 | K11: 1 | L11: 0.50594663 | M11: 0.32722476 | N11: 0.013390812 | O11: 0.15765752 | P11: 0.14610925 | Q11: 0.086977552 | R11: 0.12573534 | S11: 0.048755615 | T11: -0.060434333 | U11: 0.072662189 | V11: 0.030185156 | W11: 0.066234453 | X11: -0.011959736 | Y11: -0.021784071 | Z11: -0.17876266 | AA11: 0.017284622 | AB11: 0.14025999 | AC11: 0.040128871 | AD11: -0.25372768 | AE11: 0.1219115 | AF11: 0.011203374 | AG11: -0.14712348 | AH11: -0.07912785 | AI11: 0.1909149 | AJ11: 0.3849396 | AK11: 0.18935875 | AL11: -0.19636963 | AM11: -0.1495922 | AN11: -0.12714931 | AO11: -0.19306555 | AP11: 0.095823244 | AQ11: -0.11075583 | AR11: -0.1610709 | AS11: -0.19175576 | AT11: -0.069334766 | AU11: -0.13891529 | AV11: -0.084213206 | AW11: -0.15890301
A12: sensitivityscore_After_layer1.0.conv3_0.6 | B12: -0.11951162 | C12: 0.10059945 | D12: 0.073585565 | E12: -0.16165068 | F12: -0.015189735 | G12: 0.20614096 | H12: 0.15786978 | I12: 0.3081869 | J12: 0.097908656 | K12: 0.50594663 | L12: 1 | M12: 0.81246467 | N12: -0.059119539 | O12: -0.11382605 | P12: -0.13652849 | Q12: -0.2742247 | R12: 0.094726949 | S12: -0.25902874 | T12: -0.2019395 | U12: 0.19134593 | V12: -0.098523661 | W12: -0.073831907 | X12: -0.09314013 | Y12: -0.12225854 | Z12: -0.16669294 | AA12: -0.32296409 | AB12: -0.17027844 | AC12: -0.21424123 | AD12: -0.22790561 | AE12: -0.010685636 | AF12: -0.13652512 | AG12: -0.41721265 | AH12: -0.04771553 | AI12: 0.12225978 | AJ12: 0.21212602 | AK12: -0.04850079 | AL12: -0.24519118 | AM12: -0.49989226 | AN12: -0.42767771 | AO12: -0.2277773 | AP12: -0.058577645 | AQ12: 0.044391643 | AR12: -0.081709008 | AS12: 0.039397103 | AT12: -0.15820204 | AU12: -0.020782194 | AV12: 0.098507326 | AW12: -0.1143782
A13: sensitivityscore_After_layer1.0.conv3_0.7 | B13: 0.031312827 | C13: 0.13540086 | D13: -0.093126673 | E13: -0.12709216 | F13: 0.13595615 | G13: 0.19811889 | H13: 0.2014103 | I13: 0.31703106 | J13: 0.085141663 | K13: 0.32722476 | L13: 0.81246467 | M13: 1 | N13: 0.096498918 | O13: -0.35220813 | P13: -0.12908557 | Q13: -0.43231012 | R13: 0.15205027 | S13: -0.20759326 | T13: -0.041497805 | U13: 0.050648493 | V13: -0.00067315499 | W13: -0.10332316 | X13: -0.0085876492 | Y13: -0.13885515 | Z13: 0.0077030184 | AA13: -0.46414844 | AB13: -0.37363417 | AC13: -0.38936765 | AD13: -0.064624106 | AE13: 0.032717372 | AF13: -0.20861878 | AG13: -0.44442072 | AH13: 0.17945765 | AI13: 0.168551 | AJ13: 0.14943223 | AK13: -0.051347969 | AL13: -0.084334549 | AM13: -0.487685 | AN13: -0.46068709 | AO13: -0.23478227 | AP13: 0.10419074 | AQ13: 0.126128 | AR13: 0.085945684 | AS13: 0.2155422 | AT13: -0.13666471 | AU13: -0.016462223 | AV13: 0.14155648 | AW13: -0.033106348
... A49: sensitivityscore_After_layer4.2.conv3_0.7 | B49: 0.097405589 | C49: 0.090759066 | D49: 0.030087583 | E49: -0.091949973 | F49: 0.43587877 | G49: 0.19761321 | H49: 0.19116136 | I49: 0.13505957 | J49: 0.054600781 | K49: -0.15890301 | L49: -0.1143782 | M49: -0.033106348 | N49: 0.10715317 | O49: -0.078244703 | P49: 0.082410552 | Q49: -0.059082253 | R49: 0.16549511 | S49: 0.025473323 | T49: 0.16940261 | U49: -0.20329642 | V49: 0.052891201 | W49: 0.15621348 | X49: 0.24643668 | Y49: 0.18304762 | Z49: -0.14191516 | AA49: 0.10006774 | AB49: 0.075540458 | AC49: 0.071562154 | AD49: 0.1241868 | AE49: 0.059469474 | AF49: 0.17536928 | AG49: 0.12856293 | AH49: 0.22232698 | AI49: 0.38221876 | AJ49: 0.44991141 | AK49: 0.37621897 | AL49: 0.10055422 | AM49: 0.20176299 | AN49: 0.27055387 | AO49: 0.19250659 | AP49: 0.013960541 | AQ49: -0.13851787 | AR49: 0.045834327 | AS49: -0.033158478 | AT49: 0.3613778 | AU49: 0.72061457 | AV49: 0.71035587 | AW49: 1

Sheet Class_3
B1: layer1.0.conv1 | C1: sensitivityscore_After_layer1.0.conv1_0.5 | D1: sensitivityscore_After_layer1.0.conv1_0.6 | E1: sensitivityscore_After_layer1.0.conv1_0.7 | F1: layer1.0.conv2 | G1: sensitivityscore_After_layer1.0.conv2_0.5 | H1: sensitivityscore_After_layer1.0.conv2_0.6 | I1: sensitivityscore_After_layer1.0.conv2_0.7 | J1: layer1.0.conv3 | K1: sensitivityscore_After_layer1.0.conv3_0.5 | L1: sensitivityscore_After_layer1.0.conv3_0.6 | M1: sensitivityscore_After_layer1.0.conv3_0.7 | N1: layer4.0.conv1 | O1: sensitivityscore_After_layer4.0.conv1_0.5 | P1: sensitivityscore_After_layer4.0.conv1_0.6 | Q1: sensitivityscore_After_layer4.0.conv1_0.7 | R1: layer4.0.conv2 | S1: sensitivityscore_After_layer4.0.conv2_0.5 | T1: sensitivityscore_After_layer4.0.conv2_0.6 | U1: sensitivityscore_After_layer4.0.conv2_0.7 | V1: layer4.0.conv3 | W1: sensitivityscore_After_layer4.0.conv3_0.5 | X1: sensitivityscore_After_layer4.0.conv3_0.6 | Y1: sensitivityscore_After_layer4.0.conv3_0.7 | Z1: layer4.1.conv1 | AA1: sensitivityscore_After_layer4.1.conv1_0.5 | AB1: sensitivityscore_After_layer4.1.conv1_0.6 | AC1: sensitivityscore_After_layer4.1.conv1_0.7 | AD1: layer4.1.conv2 | AE1: sensitivityscore_After_layer4.1.conv2_0.5 | AF1: sensitivityscore_After_layer4.1.conv2_0.6 | AG1: sensitivityscore_After_layer4.1.conv2_0.7 | AH1: layer4.1.conv3 | AI1: sensitivityscore_After_layer4.1.conv3_0.5 | AJ1: sensitivityscore_After_layer4.1.conv3_0.6 | AK1: sensitivityscore_After_layer4.1.conv3_0.7 | AL1: layer4.2.conv1 | AM1: sensitivityscore_After_layer4.2.conv1_0.5 | AN1: sensitivityscore_After_layer4.2.conv1_0.6 | AO1: sensitivityscore_After_layer4.2.conv1_0.7 | AP1: layer4.2.conv2 | AQ1: sensitivityscore_After_layer4.2.conv2_0.5 | AR1: sensitivityscore_After_layer4.2.conv2_0.6 | AS1: sensitivityscore_After_layer4.2.conv2_0.7 | AT1: layer4.2.conv3 | AU1: sensitivityscore_After_layer4.2.conv3_0.5 | AV1: sensitivityscore_After_layer4.2.conv3_0.6 | AW1: sensitivityscore_After_layer4.2.conv3_0.7
A2: layer1.0.conv1 | B2: 1 | C2: -0.10159837 | D2: -0.16050257 | E2: 0.082699056 | F2: 0.67552824 | G2: 0.058967764 | H2: 0.021370446 | I2: 0.060200705 | J2: 0.77293646 | K2: 0.13514111 | L2: 0.12213097 | M2: 0.17156222 | N2: 0.23444531 | O2: -0.12019261 | P2: -0.04044528 | Q2: 0.0012512706 | R2: 0.14484913 | S2: 0.16626691 | T2: 0.088846712 | U2: 0.077847542 | V2: 0.20705921 | W2: 0.21253304 | X2: 0.06948647 | Y2: 0.19471958 | Z2: 0.02223076 | AA2: -0.053547125 | AB2: -0.14738775 | AC2: 0.1228882 | AD2: 0.28252892 | AE2: -0.065766332 | AF2: -0.046718873 | AG2: -0.074496332 | AH2: 0.18787626 | AI2: -0.074238732 | AJ2: 0.0022607984 | AK2: 0.013507267 | AL2: 0.30735805 | AM2: -0.056483877 | AN2: 0.08697945 | AO2: 0.19748074 | AP2: 0.018398038 | AQ2: -0.082336869 | AR2: -0.12963022 | AS2: -0.13733362 | AT2: 0.021597674 | AU2: 0.28198105 | AV2: 0.22427859 | AW2: 0.059535305
A3: sensitivityscore_After_layer1.0.conv1_0.5 | B3: -0.10159837 | C3: 1 | D3: 0.073036208 | E3: -0.22554757 | F3: 0.054241928 | G3: -0.02367915 | H3: -0.02064118 | I3: 0.030379775 | J3: -0.0092625918 | K3: -0.12347434 | L3: 0.0099936222 | M3: -0.12931965 | N3: -0.20845045 | O3: 0.17635225 | P3: 0.12946194 | Q3: 0.022903404 | R3: -0.30479886 | S3: -0.097173151 | T3: -0.090476447 | U3: 0.017774481 | V3: -0.22555169 | W3: -0.21252052 | X3: -0.092906936 | Y3: 0.02832343 | Z3: 0.0053009287 | AA3: -0.025705783 | AB3: -0.033204975 | AC3: -0.06159635 | AD3: -0.0013554309 | AE3: -0.16880068 | AF3: -0.18112156 | AG3: -0.23983647 | AH3: 0.0086248938 | AI3: 9.0696344e-05 | AJ3: 0.10475616 | AK3: 0.078028808 | AL3: -0.061919607 | AM3: -0.047834588 | AN3: -0.0071100456 | AO3: -0.16164063 | AP3: 0.04028449 | AQ3: 0.23280974 | AR3: 0.22234725 | AS3: 0.2315646 | AT3: -0.047373741 | AU3: -0.10120728 | AV3: -0.010861784 | AW3: 0.12637934
A4: sensitivityscore_After_layer1.0.conv1_0.6 | B4: -0.16050257 | C4: 0.073036208 | D4: 1 | E4: 0.48986122 | F4: -0.12935453 | G4: -0.021704837 | H4: 0.1059703 | I4: 0.0042883247 | J4: -0.06623041 | K4: 0.083159111 | L4: 0.087695398 | M4: -0.00071322395 | N4: 0.06391068 | O4: 0.030055993 | P4: -0.014433268 | Q4: -0.048691395 | R4: 0.10425025 | S4: 0.080233529 | T4: -0.086507058 | U4: 0.038168967 | V4: 0.080232539 | W4: -0.13845843 | X4: -0.29354865 | Y4: -0.1119274 | Z4: 0.097172703 | AA4: -0.15727361 | AB4: -0.096719766 | AC4: -0.21943844 | AD4: -0.056833976 | AE4: 0.070692296 | AF4: 0.10929403 | AG4: -0.035030145 | AH4: 0.058347238 | AI4: 0.20227702 | AJ4: 0.30953057 | AK4: 0.31307398 | AL4: -0.13812425 | AM4: 0.28105359 | AN4: 0.17421706 | AO4: 0.18158649 | AP4: -0.039650477 | AQ4: 0.019187453 | AR4: -0.22911493 | AS4: -0.25280014 | AT4: 0.28782417 | AU4: 0.024983131 | AV4: -0.094290374 | AW4: -0.14309194
A5: sensitivityscore_After_layer1.0.conv1_0.7 | B5: 0.082699056 | C5: -0.22554757 | D5: 0.48986122 | E5: 1 | F5: -0.075411057 | G5: -0.41397519 | H5: -0.22782555 | I5: -0.19794658 | J5: -0.022806438 | K5: 0.010564811 | L5: 0.15941458 | M5: 0.27286576 | N5: 0.090188828 | O5: -0.13485182 | P5: -0.13048523 | Q5: 0.056099715 | R5: 0.21853872 | S5: 0.09987786 | T5: -0.13456005 | U5: -0.0057292563 | V5: 0.12270759 | W5: -0.010293516 | X5: -0.2403699 | Y5: -0.049582069 | Z5: 0.02046038 | AA5: -0.25109788 | AB5: -0.01544958 | AC5: -0.033650446 | AD5: -0.10363638 | AE5: 0.15600652 | AF5: 0.19254358 | AG5: 0.091470888 | AH5: -0.098215381 | AI5: 0.11993476 | AJ5: 0.1000044 | AK5: 0.10888549 | AL5: -0.16482002 | AM5: 0.1483605 | AN5: 0.068130751 | AO5: 0.2146659 | AP5: -0.12639456 | AQ5: -0.032603658 | AR5: -0.25207887 | AS5: -0.050119197 | AT5: 0.24438636 | AU5: 0.15061536 | AV5: 0.12181502 | AW5: 0.072933194
A6: layer1.0.conv2 | B6: 0.67552824 | C6: 0.054241928 | D6: -0.12935453 | E6: -0.075411057 | F6: 1 | G6: 0.12063385 | H6: 0.019430239 | I6: 0.029150112 | J6: 0.6742962 | K6: 0.15266603 | L6: 0.07309129 | M6: 0.051584803 | N6: 0.26763611 | O6: -0.15115482 | P6: -0.031729107 | Q6: 0.012278612 | R6: 0.13894943 | S6: 0.095565407 | T6: 0.14259092 | U6: 0.13108025 | V6: 0.10793752 | W6: 0.15187395 | X6: 0.038636899 | Y6: 0.10072003 | Z6: 0.13756454 | AA6: 0.10670484 | AB6: 0.00030172214 | AC6: 0.17529306 | AD6: 0.29414409 | AE6: -0.31404049 | AF6: -0.29983069 | AG6: -0.15895423 | AH6: 0.28930913 | AI6: -0.10630064 | AJ6: -0.019437913 | AK6: -0.074018838 | AL6: 0.33325894 | AM6: -0.081922621 | AN6: 0.23965046 | AO6: 0.13977686 | AP6: 0.022273474 | AQ6: -0.067049114 | AR6: -0.098313751 | AS6: -0.12627917 | AT6: -0.12128126 | AU6: 0.23627177 | AV6: 0.2262765 | AW6: 0.11204288
A7: sensitivityscore_After_layer1.0.conv2_0.5 | B7: 0.058967764 | C7: -0.02367915 | D7: -0.021704837 | E7: -0.41397519 | F7: 0.12063385 | G7: 1 | H7: 0.62490722 | I7: 0.52639548 | J7: 0.13556057 | K7: 0.33855192 | L7: 0.010284951 | M7: 0.018089552 | N7: 0.014449867 | O7: -0.052584877 | P7: 0.082138281 | Q7: -0.12955411 | R7: -0.032694008 | S7: 0.10530769 | T7: 0.23971455 | U7: 0.016733748 | V7: -0.082972484 | W7: -0.14944623 | X7: 0.0074993433 | Y7: -0.064779453 | Z7: 0.10137463 | AA7: 0.23887601 | AB7: -0.1690529 | AC7: -0.0013551226 | AD7: 0.05852748 | AE7: -0.18041309 | AF7: -0.12351907 | AG7: -0.074294226 | AH7: 0.13006394 | AI7: -0.18550026 | AJ7: -0.30442738 | AK7: -0.1716446 | AL7: 0.086267592 | AM7: 0.047185136 | AN7: -0.027750992 | AO7: -0.063865867 | AP7: 0.13563858 | AQ7: -0.060530137 | AR7: -0.13763246 | AS7: -0.049938366 | AT7: -0.24854385 | AU7: 0.1633008 | AV7: 0.091972026 | AW7: 0.071287065
A8: sensitivityscore_After_layer1.0.conv2_0.6 | B8: 0.021370446 | C8: -0.02064118 | D8: 0.1059703 | E8: -0.22782555 | F8: 0.019430239 | G8: 0.62490722 | H8: 1 | I8: 0.60652376 | J8: 0.082907669 | K8: 0.081836668 | L8: -0.17809502 | M8: -0.11401136 | N8: 0.090035384 | O8: -0.058845685 | P8: -0.17912347 | Q8: -0.1215737 | R8: -0.096916024 | S8: 0.042845151 | T8: 0.13362213 | U8: -0.10468645 | V8: -0.066769016 | W8: -0.23533796 | X8: -0.0012889856 | Y8: -0.22072551 | Z8: 0.0055414877 | AA8: 0.029735297 | AB8: -0.068445665 | AC8: 0.0054642165 | AD8: 0.0054722855 | AE8: -0.058929684 | AF8: 0.091254399 | AG8: 0.13236679 | AH8: 0.028581273 | AI8: 0.16647776 | AJ8: -0.071005571 | AK8: 0.076938001 | AL8: 0.16607104 | AM8: -0.0034536856 | AN8: -0.098681466 | AO8: -0.15638321 | AP8: 0.063848551 | AQ8: 0.050989835 | AR8: -0.003451041 | AS8: -0.083291196 | AT8: -0.090541766 | AU8: 0.24402791 | AV8: 0.025974955 | AW8: -0.02573459
A9: sensitivityscore_After_layer1.0.conv2_0.7 | B9: 0.060200705 | C9: 0.030379775 | D9: 0.0042883247 | E9: -0.19794658 | F9: 0.029150112 | G9: 0.52639548 | H9: 0.60652376 | I9: 1 | J9: -0.0027456592 | K9: 0.14422733 | L9: -0.14521065 | M9: -0.11343206 | N9: -0.10133987 | O9: 0.15464779 | P9: 0.15893129 | Q9: -0.13104451 | R9: -0.19355193 | S9: 0.12334661 | T9: 0.12453564 | U9: -0.12022059 | V9: -0.10955557 | W9: -0.23909608 | X9: -0.15414004 | Y9: -0.30431042 | Z9: -0.043449209 | AA9: -0.15510744 | AB9: -0.26085447 | AC9: -0.11313477 | AD9: 0.0063802097 | AE9: -0.037368188 | AF9: 0.091370579 | AG9: -0.036794655 | AH9: 0.11213155 | AI9: 0.047656537 | AJ9: -0.061702374 | AK9: 0.087055955 | AL9: 0.044150891 | AM9: -0.013472436 | AN9: -0.13257854 | AO9: -0.09571922 | AP9: 0.045097922 | AQ9: 0.21867995 | AR9: 0.12859955 | AS9: 0.031018571 | AT9: -0.14067491 | AU9: 0.21156809 | AV9: 0.1225326 | AW9: 0.13152914
A10: layer1.0.conv3 | B10: 0.77293646 | C10: -0.0092625918 | D10: -0.06623041 | E10: -0.022806438 | F10: 0.6742962 | G10: 0.13556057 | H10: 0.082907669 | I10: -0.0027456592 | J10: 1 | K10: 0.095840619 | L10: 0.25899304 | M10: 0.10945635 | N10: 0.36291242 | O10: -0.18118929 | P10: -0.062107382 | Q10: 0.04028884 | R10: 0.11234278 | S10: 0.069347817 | T10: 0.12575938 | U10: 0.12541869 | V10: 0.095424889 | W10: 0.23099085 | X10: 0.15783131 | Y10: 0.2203978 | Z10: -0.0070231661 | AA10: 0.23348536 | AB10: -0.038308859 | AC10: 0.19009983 | AD10: 0.13688797 | AE10: -0.089847331 | AF10: -0.17643378 | AG10: -0.050188034 | AH10: 0.23807511 | AI10: 0.035633216 | AJ10: 0.038587386 | AK10: 0.064489411 | AL10: 0.26605363 | AM10: -0.1353006 | AN10: 0.1290556 | AO10: 0.1339113 | AP10: 0.066170558 | AQ10: -0.030399717 | AR10: -0.057754007 | AS10: -0.11114163 | AT10: -0.14000105 | AU10: 0.12038188 | AV10: 0.11203908 | AW10: -0.037231642
A11: sensitivityscore_After_layer1.0.conv3_0.5 | B11: 0.13514111 | C11: -0.12347434 | D11: 0.083159111 | E11: 0.010564811 | F11: 0.15266603 | G11: 0.33855192 | H11: 0.081836668 | I11: 0.14422733 | J11: 0.095840619 | K11: 1 | L11: 0.51680596 | M11: 0.37021808 | N11: 0.022448995 | O11: -0.10812641 | P11: 0.0039036094 | Q11: -0.22463093 | R11: -0.082557434 | S11: 0.11278809 | T11: 0.16686658 | U11: 0.093190692 | V11: 0.056012907 | W11: -0.2613635 | X11: -0.35337001 | Y11: -0.14300234 | Z11: -0.15951337 | AA11: -0.0019215513 | AB11: -0.22890425 | AC11: 0.077626889 | AD11: -0.098330221 | AE11: -0.080301465 | AF11: 0.0078161384 | AG11: 0.034042635 | AH11: 0.13353111 | AI11: -0.073943032 | AJ11: -0.050595482 | AK11: 0.042257528 | AL11: -0.17730543 | AM11: 0.047076568 | AN11: 0.12150141 | AO11: 0.24362992 | AP11: 0.10695868 | AQ11: 0.210511 | AR11: 0.056787706 | AS11: 0.022216004 | AT11: 0.081202934 | AU11: -0.032799656 | AV11: 0.10758732 | AW11: 0.036498582
A12: sensitivityscore_After_layer1.0.conv3_0.6 | B12: 0.12213097 | C12: 0.0099936222 | D12: 0.087695398 | E12: 0.15941458 | F12: 0.07309129 | G12: 0.010284951 | H12: -0.17809502 | I12: -0.14521065 | J12: 0.25899304 | K12: 0.51680596 | L12: 1 | M12: 0.58892717 | N12: 0.14202713 | O12: 0.0045363787 | P12: -0.004883514 | Q12: -0.028603075 | R12: 0.020603116 | S12: 0.01503354 | T12: 0.00097236119 | U12: 0.2150077 | V12: -0.007724139 | W12: -0.19558412 | X12: -0.14761681 | Y12: -0.0716892 | Z12: -0.088414164 | AA12: 0.1480364 | AB12: -0.042276447 | AC12: 0.2369059 | AD12: -0.18015888 | AE12: 0.0348139 | AF12: -0.062427774 | AG12: -0.050995001 | AH12: 0.096704729 | AI12: 0.0021738822 | AJ12: 0.098291337 | AK12: 0.10973376 | AL12: -0.23482474 | AM12: 0.12846199 | AN12: 0.16817702 | AO12: 0.39846411 | AP12: 0.079480082 | AQ12: 0.16600585 | AR12: -0.011867899 | AS12: 0.13684797 | AT12: 0.10059456 | AU12: 0.016090619 | AV12: 0.04035436 | AW12: 0.025767114
A13: sensitivityscore_After_layer1.0.conv3_0.7 | B13: 0.17156222 | C13: -0.12931965 | D13: -0.00071322395 | E13: 0.27286576 | F13: 0.051584803 | G13: 0.018089552 | H13: -0.11401136 | I13: -0.11343206 | J13: 0.10945635 | K13: 0.37021808 | L13: 0.58892717 | M13: 1 | N13: -0.017344522 | O13: 0.17440665 | P13: 0.042662575 | Q13: -0.0054227887 | R13: 0.13576083 | S13: 0.20564437 | T13: 0.12602481 | U13: 0.0277764 | V13: 0.17793817 | W13: -0.16356333 | X13: -0.12293017 | Y13: -0.0062948014 | Z13: 0.070529405 | AA13: 0.035401223 | AB13: 0.040748101 | AC13: 0.19782969 | AD13: 0.082742971 | AE13: 0.068738157 | AF13: -0.067943326 | AG13: -0.028179517 | AH13: 0.15528841 | AI13: -0.36849819 | AJ13: -0.29085873 | AK13: -0.24623142 | AL13: 0.024665693 | AM13: 0.11623717 | AN13: 0.04133591 | AO13: 0.26448762 | AP13: 0.21691345 | AQ13: 0.15608969 | AR13: 0.074248909 | AS13: 0.24246097 | AT13: 0.014891506 | AU13: 0.21288175 | AV13: 0.21979233 | AW13: 0.22821043
