Workbook

Sheet Sheet1
A1: Class | B1: =Class_0!B1 -> features.7 | C1: =Class_0!C1 -> sensitivityscore_After_features.7_0.5 | D1: =Class_0!D1 -> sensitivityscore_After_features.7_0.6 | E1: =Class_0!E1 -> sensitivityscore_After_features.7_0.7 | F1: =Class_0!F1 -> features.19 | G1: =Class_0!G1 -> sensitivityscore_After_features.19_0.5 | H1: =Class_0!H1 -> sensitivityscore_After_features.19_0.6 | I1: =Class_0!I1 -> sensitivityscore_After_features.19_0.7 | ... AK1: =Class_0!AK1 -> 0
A2: 0 | B2: =Class_0!B30 -> -0.025991847 | C2: =Class_0!C30 -> -0.20551194 | D2: =Class_0!D30 -> -0.16729819 | E2: =Class_0!E30 -> -0.15446516 | F2: =Class_0!F30 -> 0.060216523 | G2: =Class_0!G30 -> -0.066281902 | H2: =Class_0!H30 -> -0.10219943 | I2: =Class_0!I30 -> -0.18697038 | ... AD2: =Class_0!AD30 -> 1
A3: =A2+1 -> 1 | B3: =Class_1!B30 -> -0.14762589 | C3: =Class_1!C30 -> -0.030722299 | D3: =Class_1!D30 -> 0.12317715 | E3: =Class_1!E30 -> -0.01330538 | F3: =Class_1!F30 -> 0.32138996 | G3: =Class_1!G30 -> -0.051092664 | H3: =Class_1!H30 -> -0.068413176 | I3: =Class_1!I30 -> -0.18100421 | ... AD3: =Class_1!AD30 -> 1
A4: =A3+1 -> 2 | B4: =Class_2!B30 -> 0.13630669 | C4: =Class_2!C30 -> -0.17241419 | D4: =Class_2!D30 -> -0.074293892 | E4: =Class_2!E30 -> 0.032351127 | F4: =Class_2!F30 -> -0.12303475 | G4: =Class_2!G30 -> -0.1154663 | H4: =Class_2!H30 -> -0.30033902 | I4: =Class_2!I30 -> -0.16433818 | ... AD4: =Class_2!AD30 -> 1
A5: =A4+1 -> 3 | B5: =Class_3!B30 -> -0.2830385 | C5: =Class_3!C30 -> 0.029467606 | D5: =Class_3!D30 -> 0.043869373 | E5: =Class_3!E30 -> -0.041804124 | F5: =Class_3!F30 -> -0.016252743 | G5: =Class_3!G30 -> 0.086592693 | H5: =Class_3!H30 -> 0.010621625 | I5: =Class_3!I30 -> -0.020271955 | ... AD5: =Class_3!AD30 -> 1
A6: =A5+1 -> 4 | B6: =Class_4!B30 -> -0.097613406 | C6: =Class_4!C30 -> -0.0051587866 | D6: =Class_4!D30 -> 0.14862682 | E6: =Class_4!E30 -> 0.071932256 | F6: =Class_4!F30 -> 0.0030408196 | G6: =Class_4!G30 -> -0.14651933 | H6: =Class_4!H30 -> -0.1478658 | I6: =Class_4!I30 -> -0.2306805 | ... AD6: =Class_4!AD30 -> 1
A7: =A6+1 -> 5 | B7: =Class_5!B30 -> 0.24815881 | C7: =Class_5!C30 -> 0.039776038 | D7: =Class_5!D30 -> 0.21734413 | E7: =Class_5!E30 -> 0.1705704 | F7: =Class_5!F30 -> -0.018567969 | G7: =Class_5!G30 -> -0.066307262 | H7: =Class_5!H30 -> 0.16439974 | I7: =Class_5!I30 -> 0.34192668 | ... AD7: =Class_5!AD30 -> 1
A8: =A7+1 -> 6 | B8: =Class_6!B30 -> 0.18992281 | C8: =Class_6!C30 -> -0.24105196 | D8: =Class_6!D30 -> -0.20957756 | E8: =Class_6!E30 -> -0.33853199 | F8: =Class_6!F30 -> 0.30782253 | G8: =Class_6!G30 -> 0.0021939075 | H8: =Class_6!H30 -> -0.37839996 | I8: =Class_6!I30 -> 0.0081954342 | ... AD8: =Class_6!AD30 -> 1
A9: =A8+1 -> 7 | B9: =Class_7!B30 -> 0.12069297 | C9: =Class_7!C30 -> 0.10147129 | D9: =Class_7!D30 -> 0.21769095 | E9: =Class_7!E30 -> 0.14606502 | F9: =Class_7!F30 -> 0.33269327 | G9: =Class_7!G30 -> 0.029007059 | H9: =Class_7!H30 -> -0.10086688 | I9: =Class_7!I30 -> -0.1049235 | ... AD9: =Class_7!AD30 -> 1
A10: =A9+1 -> 8 | B10: =Class_8!B30 -> -0.21948736 | C10: =Class_8!C30 -> -0.22558552 | D10: =Class_8!D30 -> 0.12453775 | E10: =Class_8!E30 -> -0.21111938 | F10: =Class_8!F30 -> 0.0097059095 | G10: =Class_8!G30 -> -0.0057218859 | H10: =Class_8!H30 -> 0.044561158 | I10: =Class_8!I30 -> 0.038347806 | ... AD10: =Class_8!AD30 -> 1
A11: =A10+1 -> 9 | B11: =Class_9!B30 -> -0.073922387 | C11: =Class_9!C30 -> -0.29038031 | D11: =Class_9!D30 -> 0.026302659 | E11: =Class_9!E30 -> -0.13743878 | F11: =Class_9!F30 -> -0.16605281 | G11: =Class_9!G30 -> 0.13017981 | H11: =Class_9!H30 -> 0.078366804 | I11: =Class_9!I30 -> -0.050652053 | ... AD11: =Class_9!AD30 -> 1

Sheet Class_0
B1: features.7 | C1: sensitivityscore_After_features.7_0.5 | D1: sensitivityscore_After_features.7_0.6 | E1: sensitivityscore_After_features.7_0.7 | F1: features.19 | G1: sensitivityscore_After_features.19_0.5 | H1: sensitivityscore_After_features.19_0.6 | I1: sensitivityscore_After_features.19_0.7 | J1: features.20 | K1: features.21 | L1: sensitivityscore_After_features.21_0.5 | M1: sensitivityscore_After_features.21_0.6 | N1: sensitivityscore_After_features.21_0.7 | O1: features.22 | P1: features.23 | Q1: features.24 | R1: sensitivityscore_After_features.24_0.5 | S1: sensitivityscore_After_features.24_0.6 | T1: sensitivityscore_After_features.24_0.7 | U1: features.25 | V1: features.26 | W1: sensitivityscore_After_features.26_0.5 | X1: sensitivityscore_After_features.26_0.6 | Y1: sensitivityscore_After_features.26_0.7 | Z1: features.27 | AA1: features.28 | AB1: sensitivityscore_After_features.28_0.5 | AC1: sensitivityscore_After_features.28_0.6 | AD1: sensitivityscore_After_features.28_0.7
A2: features.7 | B2: 1 | C2: 0.28536524 | D2: 0.17781715 | E2: 0.07549374 | F2: 0.27434287 | G2: 0.059765979 | H2: 0.066862038 | I2: -0.023393536 | J2: 0.13109078 | K2: 0.13667796 | L2: 0.0085555863 | M2: -0.058438692 | N2: -0.14973464 | O2: 0.095574524 | P2: 0.079532575 | Q2: 0.23218102 | R2: 0.032524104 | S2: 0.13897428 | T2: -0.072885916 | U2: 0.27720536 | V2: 0.054427193 | W2: 0.040167917 | X2: 0.063624263 | Y2: -0.10820356 | Z2: 0.043225156 | AA2: 0.16941943 | AB2: -0.0342458 | AC2: -0.024993249 | AD2: -0.025991847
A3: sensitivityscore_After_features.7_0.5 | B3: 0.28536524 | C3: 1 | D3: 0.57161771 | E3: 0.50084531 | F3: 0.43686867 | G3: -0.21717907 | H3: 0.13067156 | I3: 0.013041131 | J3: 0.26139192 | K3: 0.22192552 | L3: 0.10981124 | M3: 0.11469246 | N3: -0.0056184178 | O3: 0.04470637 | P3: 0.061195453 | Q3: 0.20858557 | R3: -0.10486664 | S3: -0.0005419091 | T3: -0.12475478 | U3: 0.10768629 | V3: -0.013856733 | W3: -0.05759434 | X3: 0.053091116 | Y3: -0.17043837 | Z3: 0.023597503 | AA3: 0.021078442 | AB3: -0.22791634 | AC3: -0.21713763 | AD3: -0.20551194
A4: sensitivityscore_After_features.7_0.6 | B4: 0.17781715 | C4: 0.57161771 | D4: 1 | E4: 0.57701482 | F4: 0.18029693 | G4: -0.084703388 | H4: 0.21049687 | I4: 0.14804691 | J4: 0.0062673542 | K4: 0.0008808459 | L4: 0.16932922 | M4: 0.017778707 | N4: 0.020045995 | O4: -0.020248658 | P4: -0.041026038 | Q4: 0.0060806379 | R4: 0.069611849 | S4: 0.17286692 | T4: -0.050063447 | U4: 0.090039113 | V4: -0.088476216 | W4: -0.084067257 | X4: 0.053774478 | Y4: -0.076554037 | Z4: 0.05496553 | AA4: 0.0832738 | AB4: 0.0026116488 | AC4: -0.023467662 | AD4: -0.16729819
A5: sensitivityscore_After_features.7_0.7 | B5: 0.07549374 | C5: 0.50084531 | D5: 0.57701482 | E5: 1 | F5: 0.066520805 | G5: -0.00073972081 | H5: 0.14671654 | I5: 0.047670341 | J5: -0.030330875 | K5: -0.11127289 | L5: 0.14673324 | M5: -0.15388208 | N5: -0.15954027 | O5: -0.3478228 | P5: -0.26271684 | Q5: -0.08067277 | R5: -0.04764475 | S5: 0.05010973 | T5: 0.037452262 | U5: -0.02033878 | V5: -0.25872915 | W5: -0.088929365 | X5: 0.07895005 | Y5: 0.010001853 | Z5: -0.21142302 | AA5: -0.099557757 | AB5: -0.057378567 | AC5: 0.039458784 | AD5: -0.15446516
A6: features.19 | B6: 0.27434287 | C6: 0.43686867 | D6: 0.18029693 | E6: 0.066520805 | F6: 1 | G6: -0.029697305 | H6: 0.25319452 | I6: 0.12596471 | J6: 0.70830748 | K6: 0.44239325 | L6: 0.13208804 | M6: 0.2275928 | N6: 0.12001445 | O6: 0.58749407 | P6: 0.35995173 | Q6: 0.70546528 | R6: 0.2013213 | S6: 0.18093271 | T6: 0.15835199 | U6: 0.53190709 | V6: 0.42258102 | W6: -0.099722093 | X6: 0.10290653 | Y6: -0.064111919 | Z6: 0.1967133 | AA6: 0.63318411 | AB6: -0.030965227 | AC6: 0.047860474 | AD6: 0.060216523
A7: sensitivityscore_After_features.19_0.5 | B7: 0.059765979 | C7: -0.21717907 | D7: -0.084703388 | E7: -0.00073972081 | F7: -0.029697305 | G7: 1 | H7: 0.51574472 | I7: 0.54724784 | J7: -0.038804757 | K7: 0.087197848 | L7: -0.20048456 | M7: -0.1799389 | N7: -0.15817013 | O7: 0.052838403 | P7: 0.12664171 | Q7: 0.075747343 | R7: 0.3376748 | S7: 0.21491867 | T7: 0.38712307 | U7: 0.085300984 | V7: -0.023417953 | W7: 0.25273659 | X7: 0.35490176 | Y7: 0.23413793 | Z7: 0.016452807 | AA7: 0.054698984 | AB7: -0.096861487 | AC7: -0.03324442 | AD7: -0.066281902
A8: sensitivityscore_After_features.19_0.6 | B8: 0.066862038 | C8: 0.13067156 | D8: 0.21049687 | E8: 0.14671654 | F8: 0.25319452 | G8: 0.51574472 | H8: 1 | I8: 0.76457385 | J8: 0.23642296 | K8: 0.20999287 | L8: 0.00038436614 | M8: 0.11024238 | N8: 0.14394367 | O8: 0.061352985 | P8: 0.26047472 | Q8: 0.17603444 | R8: 0.33391274 | S8: 0.32257043 | T8: 0.17722781 | U8: 0.27466789 | V8: 0.28996891 | W8: -0.033027895 | X8: 0.031917809 | Y8: 0.10946871 | Z8: 0.31603447 | AA8: 0.31449226 | AB8: 0.054746046 | AC8: 0.13817305 | AD8: -0.10219943
A9: sensitivityscore_After_features.19_0.7 | B9: -0.023393536 | C9: 0.013041131 | D9: 0.14804691 | E9: 0.047670341 | F9: 0.12596471 | G9: 0.54724784 | H9: 0.76457385 | I9: 1 | J9: 0.04153513 | K9: 0.16973928 | L9: -0.077630213 | M9: 0.10635773 | N9: 0.13392242 | O9: 0.0778505 | P9: 0.20843571 | Q9: 0.080281188 | R9: 0.36673091 | S9: 0.35814 | T9: 0.085162287 | U9: 0.050381435 | V9: 0.044628758 | W9: 0.10136603 | X9: 0.17796843 | Y9: 0.27381389 | Z9: 0.21560099 | AA9: 0.15527857 | AB9: -0.019253339 | AC9: 0.038283489 | AD9: -0.18697038
A10: features.20 | B10: 0.13109078 | C10: 0.26139192 | D10: 0.0062673542 | E10: -0.030330875 | F10: 0.70830748 | G10: -0.038804757 | H10: 0.23642296 | I10: 0.04153513 | J10: 1 | K10: 0.57787196 | L10: -0.029413691 | M10: 0.031054505 | N10: -0.050480486 | O10: 0.55443695 | P10: 0.50943962 | Q10: 0.61612922 | R10: -0.077895895 | S10: -0.11072492 | T10: -0.0024367233 | U10: 0.68050463 | V10: 0.49321114 | W10: -0.28339466 | X10: -0.093773499 | Y10: -0.25113383 | Z10: 0.31740211 | AA10: 0.64369067 | AB10: -0.15629338 | AC10: -0.090102554 | AD10: -0.12988756
A11: features.21 | B11: 0.13667796 | C11: 0.22192552 | D11: 0.0008808459 | E11: -0.11127289 | F11: 0.44239325 | G11: 0.087197848 | H11: 0.20999287 | I11: 0.16973928 | J11: 0.57787196 | K11: 1 | L11: -0.09987826 | M11: -0.14364387 | N11: -0.10881284 | O11: 0.72672609 | P11: 0.67282558 | Q11: 0.40962045 | R11: 0.076300088 | S11: -0.038724434 | T11: -0.053820445 | U11: 0.34788371 | V11: 0.25671278 | W11: -0.14623108 | X11: -0.11682796 | Y11: -0.24291006 | Z11: 0.29579848 | AA11: 0.29266898 | AB11: -0.23790158 | AC11: -0.14872781 | AD11: -0.2585345
A12: sensitivityscore_After_features.21_0.5 | B12: 0.0085555863 | C12: 0.10981124 | D12: 0.16932922 | E12: 0.14673324 | F12: 0.13208804 | G12: -0.20048456 | H12: 0.00038436614 | I12: -0.077630213 | J12: -0.029413691 | K12: -0.09987826 | L12: 1 | M12: 0.43539838 | N12: 0.60019766 | O12: -0.011807212 | P12: -0.11274604 | Q12: 0.033567923 | R12: -0.0088659466 | S12: 0.028260681 | T12: -0.0045680564 | U12: -0.11721424 | V12: -0.0019804856 | W12: -0.039578408 | X12: -0.12736668 | Y12: -0.024997594 | Z12: 0.11732454 | AA12: 0.072769565 | AB12: -0.019656922 | AC12: 0.096811275 | AD12: 0.086501713
A13: sensitivityscore_After_features.21_0.6 | B13: -0.058438692 | C13: 0.11469246 | D13: 0.017778707 | E13: -0.15388208 | F13: 0.2275928 | G13: -0.1799389 | H13: 0.11024238 | I13: 0.10635773 | J13: 0.031054505 | K13: -0.14364387 | L13: 0.43539838 | M13: 1 | N13: 0.64802985 | O13: 0.083754479 | P13: 0.083870365 | Q13: 0.22619322 | R13: 0.2068549 | S13: 0.31217201 | T13: 0.10451089 | U13: 0.029713376 | V13: 0.34254382 | W13: 0.13860258 | X13: 0.062743012 | Y13: 0.14859437 | Z13: 0.26562365 | AA13: 0.28721121 | AB13: 0.18773897 | AC13: 0.32758431 | AD13: 0.22922954
... A30: sensitivityscore_After_features.28_0.7 | B30: -0.025991847 | C30: -0.20551194 | D30: -0.16729819 | E30: -0.15446516 | F30: 0.060216523 | G30: -0.066281902 | H30: -0.10219943 | I30: -0.18697038 | J30: -0.12988756 | K30: -0.2585345 | L30: 0.086501713 | M30: 0.22922954 | N30: 0.079379044 | O30: -0.059914572 | P30: -0.10392239 | Q30: 0.18428122 | R30: 0.18181536 | S30: 0.22448164 | T30: 0.21061572 | U30: 0.15401955 | V30: 0.26346644 | W30: -0.015198382 | X30: 0.04904078 | Y30: 0.10287855 | Z30: 0.070365777 | AA30: 0.0739241 | AB30: 0.63428581 | AC30: 0.55579452 | AD30: 1

Sheet Class_1
B1: features.7 | C1: sensitivityscore_After_features.7_0.5 | D1: sensitivityscore_After_features.7_0.6 | E1: sensitivityscore_After_features.7_0.7 | F1: features.19 | G1: sensitivityscore_After_features.19_0.5 | H1: sensitivityscore_After_features.19_0.6 | I1: sensitivityscore_After_features.19_0.7 | J1: features.20 | K1: features.21 | L1: sensitivityscore_After_features.21_0.5 | M1: sensitivityscore_After_features.21_0.6 | N1: sensitivityscore_After_features.21_0.7 | O1: features.22 | P1: features.23 | Q1: features.24 | R1: sensitivityscore_After_features.24_0.5 | S1: sensitivityscore_After_features.24_0.6 | T1: sensitivityscore_After_features.24_0.7 | U1: features.25 | V1: features.26 | W1: sensitivityscore_After_features.26_0.5 | X1: sensitivityscore_After_features.26_0.6 | Y1: sensitivityscore_After_features.26_0.7 | Z1: features.27 | AA1: features.28 | AB1: sensitivityscore_After_features.28_0.5 | AC1: sensitivityscore_After_features.28_0.6 | AD1: sensitivityscore_After_features.28_0.7
A2: features.7 | B2: 1 | C2: 0.090575463 | D2: 0.21254827 | E2: 0.12400951 | F2: 0.23075117 | G2: 0.28131684 | H2: 0.15164126 | I2: 0.13878235 | J2: 0.18124283 | K2: 0.29018095 | L2: -0.016861423 | M2: -0.09389238 | N2: 0.04720661 | O2: 0.40717754 | P2: 0.1689669 | Q2: 0.099320975 | R2: -0.12829795 | S2: 0.011325085 | T2: 0.035237389 | U2: 0.15727432 | V2: 0.093329381 | W2: -0.012339705 | X2: 0.066705759 | Y2: 0.13670702 | Z2: 0.15175088 | AA2: 0.27053347 | AB2: 0.00089875365 | AC2: -0.0071379453 | AD2: -0.14762589
A3: sensitivityscore_After_features.7_0.5 | B3: 0.090575463 | C3: 1 | D3: 0.69614385 | E3: 0.51269825 | F3: 0.18576431 | G3: 0.29230423 | H3: 0.17203236 | I3: 0.27351525 | J3: 0.26668909 | K3: 0.37418006 | L3: -0.023395709 | M3: 0.26384649 | N3: 0.066185518 | O3: 0.28865552 | P3: 0.43197336 | Q3: -0.097059133 | R3: 0.21418469 | S3: 0.10777898 | T3: 0.031413752 | U3: -0.1418759 | V3: 0.24544342 | W3: -0.15873743 | X3: -0.16474257 | Y3: -0.025119178 | Z3: 0.1153984 | AA3: 0.21997197 | AB3: 0.12196631 | AC3: -0.09937496 | AD3: -0.030722299
A4: sensitivityscore_After_features.7_0.6 | B4: 0.21254827 | C4: 0.69614385 | D4: 1 | E4: 0.67468617 | F4: 0.23391479 | G4: 0.29505361 | H4: 0.054696249 | I4: 0.1775613 | J4: 0.30058904 | K4: 0.25359419 | L4: 0.10111539 | M4: 0.30447328 | N4: 0.10088533 | O4: 0.21708844 | P4: 0.37169312 | Q4: -0.24722215 | R4: 0.14441081 | S4: 0.064196973 | T4: 0.077004857 | U4: -0.13467613 | V4: 0.20595598 | W4: 0.014855322 | X4: 0.017157788 | Y4: 0.052238481 | Z4: 0.1196938 | AA4: 0.23739954 | AB4: 0.15089514 | AC4: -0.018367244 | AD4: 0.12317715
A5: sensitivityscore_After_features.7_0.7 | B5: 0.12400951 | C5: 0.51269825 | D5: 0.67468617 | E5: 1 | F5: -0.0040268404 | G5: 0.36643608 | H5: 0.21580388 | I5: 0.20588598 | J5: 0.15919944 | K5: 0.065466209 | L5: 0.013770422 | M5: 0.23762367 | N5: 0.12404622 | O5: 0.026133749 | P5: 0.094454937 | Q5: -0.29409187 | R5: -0.10050312 | S5: -0.044268794 | T5: -0.15282404 | U5: -0.28477399 | V5: 0.15500439 | W5: -0.12041461 | X5: -0.12433703 | Y5: -0.11149467 | Z5: -0.15832825 | AA5: 0.071959597 | AB5: -0.033222811 | AC5: -0.0063641037 | AD5: -0.01330538
A6: features.19 | B6: 0.23075117 | C6: 0.18576431 | D6: 0.23391479 | E6: -0.0040268404 | F6: 1 | G6: 0.022893181 | H6: 0.12954747 | I6: 0.11450721 | J6: 0.65992974 | K6: 0.59865174 | L6: 0.1435947 | M6: -0.03629718 | N6: -0.13187511 | O6: 0.61083278 | P6: 0.54061291 | Q6: 0.39304675 | R6: 0.2887167 | S6: 0.20133389 | T6: 0.18559933 | U6: 0.47981459 | V6: 0.15326569 | W6: -0.19967652 | X6: 0.014158811 | Y6: 0.030527339 | Z6: 0.47381778 | AA6: 0.39229917 | AB6: 0.05491341 | AC6: 0.10404079 | AD6: 0.32138996
A7: sensitivityscore_After_features.19_0.5 | B7: 0.28131684 | C7: 0.29230423 | D7: 0.29505361 | E7: 0.36643608 | F7: 0.022893181 | G7: 1 | H7: 0.43311883 | I7: 0.41468895 | J7: 0.06057198 | K7: 0.3039101 | L7: -0.21313927 | M7: -0.15004835 | N7: -0.15905749 | O7: 0.21571755 | P7: 0.31485428 | Q7: 0.072947268 | R7: 0.21601048 | S7: 0.33845672 | T7: 0.13370228 | U7: 0.095368066 | V7: 0.17398378 | W7: 0.17677376 | X7: 0.020802294 | Y7: 0.23660546 | Z7: 0.10362413 | AA7: 0.32229836 | AB7: -0.034403793 | AC7: -0.048995918 | AD7: -0.051092664
A8: sensitivityscore_After_features.19_0.6 | B8: 0.15164126 | C8: 0.17203236 | D8: 0.054696249 | E8: 0.21580388 | F8: 0.12954747 | G8: 0.43311883 | H8: 1 | I8: 0.52753554 | J8: 0.20147844 | K8: 0.30024641 | L8: 0.025833505 | M8: -0.225278 | N8: -0.1101968 | O8: 0.17670578 | P8: 0.25069263 | Q8: 0.22377044 | R8: 0.26394898 | S8: 0.45552291 | T8: 0.15678794 | U8: 0.24126218 | V8: 0.13262385 | W8: -0.2704012 | X8: -0.22557673 | Y8: -0.29027872 | Z8: 0.026975864 | AA8: 0.024330876 | AB8: -0.19528183 | AC8: -0.14107311 | AD8: -0.068413176
A9: sensitivityscore_After_features.19_0.7 | B9: 0.13878235 | C9: 0.27351525 | D9: 0.1775613 | E9: 0.20588598 | F9: 0.11450721 | G9: 0.41468895 | H9: 0.52753554 | I9: 1 | J9: 0.13187811 | K9: 0.41470651 | L9: 0.03838827 | M9: -0.034502721 | N9: -0.15752093 | O9: 0.34525345 | P9: 0.33663712 | Q9: 0.29542488 | R9: 0.28446938 | S9: 0.29698139 | T9: 0.34948381 | U9: 0.29629412 | V9: 0.088250771 | W9: -0.067768895 | X9: -0.020388416 | Y9: 0.015745942 | Z9: 0.1086281 | AA9: 0.1566284 | AB9: -0.097523769 | AC9: -0.13350144 | AD9: -0.18100421
A10: features.20 | B10: 0.18124283 | C10: 0.26668909 | D10: 0.30058904 | E10: 0.15919944 | F10: 0.65992974 | G10: 0.06057198 | H10: 0.20147844 | I10: 0.13187811 | J10: 1 | K10: 0.45912663 | L10: 0.12822547 | M10: -0.18006769 | N10: -0.098874497 | O10: 0.43749707 | P10: 0.42540487 | Q10: 0.30901458 | R10: 0.19024935 | S10: 0.11273241 | T10: 0.17569929 | U10: 0.33668393 | V10: 0.32088555 | W10: -0.038594439 | X10: -0.0047364998 | Y10: -0.17604941 | Z10: 0.26062005 | AA10: 0.18371769 | AB10: 0.094145765 | AC10: 0.032163873 | AD10: 0.30269535
A11: features.21 | B11: 0.29018095 | C11: 0.37418006 | D11: 0.25359419 | E11: 0.065466209 | F11: 0.59865174 | G11: 0.3039101 | H11: 0.30024641 | I11: 0.41470651 | J11: 0.45912663 | K11: 1 | L11: 0.035203151 | M11: -0.068964744 | N11: -0.19453222 | O11: 0.81322119 | P11: 0.84474668 | Q11: 0.41628741 | R11: 0.32765731 | S11: 0.3190673 | T11: 0.3506147 | U11: 0.42678513 | V11: 0.49661689 | W11: -0.045406469 | X11: 0.0054901146 | Y11: 0.22969099 | Z11: 0.59002014 | AA11: 0.40196449 | AB11: 0.14110831 | AC11: 0.055788046 | AD11: 0.19115665
A12: sensitivityscore_After_features.21_0.5 | B12: -0.016861423 | C12: -0.023395709 | D12: 0.10111539 | E12: 0.013770422 | F12: 0.1435947 | G12: -0.21313927 | H12: 0.025833505 | I12: 0.03838827 | J12: 0.12822547 | K12: 0.035203151 | L12: 1 | M12: 0.53850654 | N12: 0.5754431 | O12: -0.023081418 | P12: 0.21264903 | Q12: -0.11866751 | R12: 0.082713689 | S12: 0.2267294 | T12: 0.28876812 | U12: 0.12269903 | V12: 0.20575471 | W12: -0.17120043 | X12: 0.15216521 | Y12: 0.039456719 | Z12: 0.12235232 | AA12: -0.033786122 | AB12: -0.11207327 | AC12: -0.047305708 | AD12: 0.046486243
A13: sensitivityscore_After_features.21_0.6 | B13: -0.09389238 | C13: 0.26384649 | D13: 0.30447328 | E13: 0.23762367 | F13: -0.03629718 | G13: -0.15004835 | H13: -0.225278 | I13: -0.034502721 | J13: -0.18006769 | K13: -0.068964744 | L13: 0.53850654 | M13: 1 | N13: 0.57230325 | O13: -0.10892319 | P13: 0.12431474 | Q13: -0.220533 | R13: -0.21685507 | S13: -0.15843315 | T13: -0.12574595 | U13: -0.15787461 | V13: 0.08790189 | W13: -0.052697088 | X13: 0.15575858 | Y13: 0.089887938 | Z13: 0.018038414 | AA13: 0.1390561 | AB13: -0.073510857 | AC13: -0.029666161 | AD13: -0.01435231
... A30: sensitivityscore_After_features.28_0.7 | B30: -0.14762589 | C30: -0.030722299 | D30: 0.12317715 | E30: -0.01330538 | F30: 0.32138996 | G30: -0.051092664 | H30: -0.068413176 | I30: -0.18100421 | J30: 0.30269535 | K30: 0.19115665 | L30: 0.046486243 | M30: -0.01435231 | N30: -0.23816905 | O30: 0.22644237 | P30: 0.42220073 | Q30: 0.1796706 | R30: 0.028875629 | S30: -0.0017971462 | T30: -0.063149579 | U30: 0.11962283 | V30: 0.42966004 | W30: -0.034358236 | X30: -0.016199855 | Y30: -0.029624949 | Z30: 0.46527548 | AA30: 0.31341289 | AB30: 0.58341232 | AC30: 0.62626754 | AD30: 1

Sheet Class_2
B1: features.7 | C1: sensitivityscore_After_features.7_0.5 | D1: sensitivityscore_After_features.7_0.6 | E1: sensitivityscore_After_features.7_0.7 | F1: features.19 | G1: sensitivityscore_After_features.19_0.5 | H1: sensitivityscore_After_features.19_0.6 | I1: sensitivityscore_After_features.19_0.7 | J1: features.20 | K1: features.21 | L1: sensitivityscore_After_features.21_0.5 | M1: sensitivityscore_After_features.21_0.6 | N1: sensitivityscore_After_features.21_0.7 | O1: features.22 | P1: features.23 | Q1: features.24 | R1: sensitivityscore_After_features.24_0.5 | S1: sensitivityscore_After_features.24_0.6 | T1: sensitivityscore_After_features.24_0.7 | U1: features.25 | V1: features.26 | W1: sensitivityscore_After_features.26_0.5 | X1: sensitivityscore_After_features.26_0.6 | Y1: sensitivityscore_After_features.26_0.7 | Z1: features.27 | AA1: features.28 | AB1: sensitivityscore_After_features.28_0.5 | AC1: sensitivityscore_After_features.28_0.6 | AD1: sensitivityscore_After_features.28_0.7
A2: features.7 | B2: 1 | C2: 0.023400101 | D2: -0.029600833 | E2: 0.093974576 | F2: 0.35387479 | G2: 0.17955002 | H2: -0.014653529 | I2: -0.16767579 | J2: 0.15127851 | K2: 0.28076193 | L2: -0.080774255 | M2: 0.082294269 | N2: 0.25376754 | O2: 0.17751363 | P2: 0.25920168 | Q2: 0.24473944 | R2: 0.062081318 | S2: 0.1120116 | T2: 0.10141625 | U2: 0.47882236 | V2: 0.30289795 | W2: 0.10909403 | X2: 0.00012737102 | Y2: 0.15911721 | Z2: 0.10665017 | AA2: 0.39725733 | AB2: 0.040825704 | AC2: 0.3473061 | AD2: 0.13630669
A3: sensitivityscore_After_features.7_0.5 | B3: 0.023400101 | C3: 1 | D3: 0.65699895 | E3: 0.40741166 | F3: 0.18129053 | G3: -0.027545986 | H3: 0.026270121 | I3: -0.083312948 | J3: 0.16663847 | K3: 0.16803391 | L3: 0.012061216 | M3: -0.070459685 | N3: -0.045052931 | O3: 0.21890562 | P3: 0.14892383 | Q3: -0.10680698 | R3: -0.087135438 | S3: -0.043208433 | T3: -0.021694646 | U3: 0.16505935 | V3: 0.069703125 | W3: -0.19986555 | X3: -0.17897458 | Y3: -0.33367734 | Z3: -0.042580247 | AA3: 0.044126278 | AB3: -0.27348711 | AC3: -0.17981288 | AD3: -0.17241419
A4: sensitivityscore_After_features.7_0.6 | B4: -0.029600833 | C4: 0.65699895 | D4: 1 | E4: 0.59340686 | F4: 0.095205913 | G4: -0.18599294 | H4: -0.22128603 | I4: -0.23243991 | J4: 0.24515248 | K4: 0.25124213 | L4: -0.047699148 | M4: -0.14042154 | N4: -0.10013993 | O4: 0.15946196 | P4: 0.31560495 | Q4: -0.1195121 | R4: -0.00029649349 | S4: -0.015455937 | T4: -0.16417639 | U4: 0.087537917 | V4: 0.078597922 | W4: -0.30723232 | X4: -0.38192599 | Y4: -0.48480389 | Z4: -0.057196247 | AA4: 0.12140929 | AB4: -0.21523752 | AC4: -0.058264788 | AD4: -0.074293892
A5: sensitivityscore_After_features.7_0.7 | B5: 0.093974576 | C5: 0.40741166 | D5: 0.59340686 | E5: 1 | F5: 0.12812168 | G5: -0.11259563 | H5: -0.068846182 | I5: 0.088857269 | J5: 0.18330473 | K5: 0.2488269 | L5: 0.11310569 | M5: -0.10279375 | N5: -0.02903853 | O5: 0.093165045 | P5: 0.31899686 | Q5: -0.10435254 | R5: -0.03319703 | S5: 0.0094230235 | T5: -0.11526748 | U5: 0.099511263 | V5: 0.058708786 | W5: -0.17753212 | X5: -0.2389648 | Y5: -0.24481402 | Z5: -0.057037353 | AA5: 0.04318328 | AB5: -0.072158921 | AC5: 0.031744912 | AD5: 0.032351127
A6: features.19 | B6: 0.35387479 | C6: 0.18129053 | D6: 0.095205913 | E6: 0.12812168 | F6: 1 | G6: -0.037513576 | H6: -0.039041233 | I6: -0.064859096 | J6: 0.74474162 | K6: 0.48238351 | L6: -0.17041897 | M6: -0.2031356 | N6: 0.0072185068 | O6: 0.52087374 | P6: 0.60988288 | Q6: 0.39669004 | R6: 0.1272278 | S6: 0.015955116 | T6: 0.16848433 | U6: 0.52295031 | V6: 0.21620363 | W6: 0.24771507 | X6: 0.052835722 | Y6: 0.123581 | Z6: 0.060965216 | AA6: 0.22724056 | AB6: -0.17835233 | AC6: 0.064695823 | AD6: -0.12303475
A7: sensitivityscore_After_features.19_0.5 | B7: 0.17955002 | C7: -0.027545986 | D7: -0.18599294 | E7: -0.11259563 | F7: -0.037513576 | G7: 1 | H7: 0.6444175 | I7: 0.22155044 | J7: -0.03272265 | K7: 0.13098902 | L7: -0.2582932 | M7: -0.076197581 | N7: -0.18459474 | O7: 0.1232551 | P7: -0.10346314 | Q7: -0.11091739 | R7: 0.16828453 | S7: 0.083653583 | T7: 0.24693325 | U7: -0.10091429 | V7: 0.055379781 | W7: 0.05646565 | X7: 0.063440268 | Y7: 0.099161327 | Z7: 0.090239294 | AA7: -0.091165961 | AB7: 0.0425098 | AC7: -0.080486711 | AD7: -0.1154663
A8: sensitivityscore_After_features.19_0.6 | B8: -0.014653529 | C8: 0.026270121 | D8: -0.22128603 | E8: -0.068846182 | F8: -0.039041233 | G8: 0.6444175 | H8: 1 | I8: 0.65884914 | J8: -0.0134444 | K8: 0.11676369 | L8: -0.1634605 | M8: 0.0079258235 | N8: -0.29984932 | O8: 0.13222896 | P8: -0.13632687 | Q8: -0.19241397 | R8: 0.13006632 | S8: 0.16339272 | T8: 0.3081285 | U8: -0.11203635 | V8: 0.04918309 | W8: 0.19487394 | X8: 0.12985626 | Y8: 0.20431112 | Z8: 0.015571879 | AA8: -0.17473368 | AB8: -0.10032159 | AC8: -0.33489494 | AD8: -0.30033902
A9: sensitivityscore_After_features.19_0.7 | B9: -0.16767579 | C9: -0.083312948 | D9: -0.23243991 | E9: 0.088857269 | F9: -0.064859096 | G9: 0.22155044 | H9: 0.65884914 | I9: 1 | J9: -0.069903685 | K9: -0.0075391728 | L9: -0.023398012 | M9: 0.11896069 | N9: -0.17292647 | O9: 0.12454237 | P9: -0.23583025 | Q9: -0.054964278 | R9: -0.087932808 | S9: 0.0026683901 | T9: 0.20375374 | U9: -0.093312473 | V9: -0.10465137 | W9: 0.15534627 | X9: 0.14815204 | Y9: 0.12261605 | Z9: -0.11990201 | AA9: -0.20067643 | AB9: -0.048335458 | AC9: -0.29205103 | AD9: -0.16433818
A10: features.20 | B10: 0.15127851 | C10: 0.16663847 | D10: 0.24515248 | E10: 0.18330473 | F10: 0.74474162 | G10: -0.03272265 | H10: -0.0134444 | I10: -0.069903685 | J10: 1 | K10: 0.48818592 | L10: -0.17920649 | M10: -0.33811515 | N10: -0.084373271 | O10: 0.38268119 | P10: 0.59192514 | Q10: 0.25091737 | R10: 0.17413338 | S10: 0.066210945 | T10: 0.15672428 | U10: 0.37654498 | V10: 0.16997173 | W10: 0.21746912 | X10: 0.093610993 | Y10: 0.13122283 | Z10: 0.074535916 | AA10: 0.1198609 | AB10: -0.10735682 | AC10: -0.023228844 | AD10: -0.16886791
A11: features.21 | B11: 0.28076193 | C11: 0.16803391 | D11: 0.25124213 | E11: 0.2488269 | F11: 0.48238351 | G11: 0.13098902 | H11: 0.11676369 | I11: -0.0075391728 | J11: 0.48818592 | K11: 1 | L11: -0.14324453 | M11: 0.021836852 | N11: 0.16704045 | O11: 0.62780696 | P11: 0.72057611 | Q11: 0.45769609 | R11: 0.18927247 | S11: 0.18680262 | T11: 0.1733364 | U11: 0.42207373 | V11: 0.43662401 | W11: -0.10807613 | X11: 0.066205104 | Y11: -0.033760469 | Z11: 0.33162112 | AA11: 0.34967194 | AB11: -0.23013059 | AC11: 0.086643475 | AD11: 0.039324019
A12: sensitivityscore_After_features.21_0.5 | B12: -0.080774255 | C12: 0.012061216 | D12: -0.047699148 | E12: 0.11310569 | F12: -0.17041897 | G12: -0.2582932 | H12: -0.1634605 | I12: -0.023398012 | J12: -0.17920649 | K12: -0.14324453 | L12: 1 | M12: 0.44582778 | N12: 0.45694346 | O12: 0.046998031 | P12: -0.10114821 | Q12: -0.32712012 | R12: -0.20135098 | S12: -0.016837265 | T12: -0.016047178 | U12: -0.25619134 | V12: -0.14214039 | W12: -0.14536128 | X12: -0.29930437 | Y12: 0.10657932 | Z12: -0.15286824 | AA12: -0.074410792 | AB12: 0.051250917 | AC12: 0.066063385 | AD12: 0.12342305
A13: sensitivityscore_After_features.21_0.6 | B13: 0.082294269 | C13: -0.070459685 | D13: -0.14042154 | E13: -0.10279375 | F13: -0.2031356 | G13: -0.076197581 | H13: 0.0079258235 | I13: 0.11896069 | J13: -0.33811515 | K13: 0.021836852 | L13: 0.44582778 | M13: 1 | N13: 0.65048874 | O13: 0.070050344 | P13: -0.16354833 | Q13: -0.094091556 | R13: -0.22289684 | S13: 0.016865706 | T13: 0.10079679 | U13: -0.16408398 | V13: 0.12363733 | W13: -0.23776818 | X13: -0.18029208 | Y13: -0.04123652 | Z13: 0.032781375 | AA13: 0.09491453 | AB13: -0.30467173 | AC13: -0.038325172 | AD13: 0.082145801
... A30: sensitivityscore_After_features.28_0.7 | B30: 0.13630669 | C30: -0.17241419 | D30: -0.074293892 | E30: 0.032351127 | F30: -0.12303475 | G30: -0.1154663 | H30: -0.30033902 | I30: -0.16433818 | J30: -0.16886791 | K30: 0.039324019 | L30: 0.12342305 | M30: 0.082145801 | N30: 0.3545519 | O30: -0.086423424 | P30: 0.10508 | Q30: 0.21360232 | R30: 0.11394038 | S30: 0.30071422 | T30: 0.18798585 | U30: 0.095599409 | V30: 0.22906619 | W30: -0.011642873 | X30: 0.076972298 | Y30: 0.13215444 | Z30: 0.27835621 | AA30: 0.24425414 | AB30: 0.57365502 | AC30: 0.77786701 | AD30: 1

Sheet Class_3
B1: features.7 | C1: sensitivityscore_After_features.7_0.5 | D1: sensitivityscore_After_features.7_0.6 | E1: sensitivityscore_After_features.7_0.7 | F1: features.19 | G1: sensitivityscore_After_features.19_0.5 | H1: sensitivityscore_After_features.19_0.6 | I1: sensitivityscore_After_features.19_0.7 | J1: features.20 | K1: features.21 | L1: sensitivityscore_After_features.21_0.5 | M1: sensitivityscore_After_features.21_0.6 | N1: sensitivityscore_After_features.21_0.7 | O1: features.22 | P1: features.23 | Q1: features.24 | R1: sensitivityscore_After_features.24_0.5 | S1: sensitivityscore_After_features.24_0.6 | T1: sensitivityscore_After_features.24_0.7 | U1: features.25 | V1: features.26 | W1: sensitivityscore_After_features.26_0.5 | X1: sensitivityscore_After_features.26_0.6 | Y1: sensitivityscore_After_features.26_0.7 | Z1: features.27 | AA1: features.28 | AB1: sensitivityscore_After_features.28_0.5 | AC1: sensitivityscore_After_features.28_0.6 | AD1: sensitivityscore_After_features.28_0.7
A2: features.7 | B2: 1 | C2: 0.075498794 | D2: -0.0042521897 | E2: 0.038693804 | F2: 0.045479148 | G2: 0.21593937 | H2: 0.076147459 | I2: 0.14848644 | J2: 0.06856378 | K2: 0.12569219 | L2: -0.056646593 | M2: -0.078869074 | N2: -0.10186165 | O2: 0.17094827 | P2: 0.21801936 | Q2: -0.096458583 | R2: -0.35513649 | S2: -0.2617333 | T2: -0.067740287 | U2: -0.25133989 | V2: -0.29925066 | W2: -0.094504068 | X2: -0.067561323 | Y2: 0.10659966 | Z2: -0.34676735 | AA2: -0.34828989 | AB2: -0.3025996 | AC2: -0.23233616 | AD2: -0.2830385
A3: sensitivityscore_After_features.7_0.5 | B3: 0.075498794 | C3: 1 | D3: 0.6597884 | E3: 0.45831934 | F3: 0.17267385 | G3: 0.014461666 | H3: 0.04260778 | I3: 0.03805207 | J3: 0.26238984 | K3: 0.15483459 | L3: 0.22029755 | M3: 0.11767216 | N3: 0.22010687 | O3: 0.11757828 | P3: 0.065829825 | Q3: 0.14653569 | R3: -0.02304968 | S3: -0.20614724 | T3: -0.055284897 | U3: 0.11129526 | V3: 0.014117887 | W3: -0.023124581 | X3: -0.14202209 | Y3: 0.027395825 | Z3: 0.0029583413 | AA3: 0.22273544 | AB3: 0.11426006 | AC3: 0.0091612799 | AD3: 0.029467606
A4: sensitivityscore_After_features.7_0.6 | B4: -0.0042521897 | C4: 0.6597884 | D4: 1 | E4: 0.79793274 | F4: 0.14078323 | G4: -0.056817308 | H4: 0.14946437 | I4: 0.058192858 | J4: 0.21250882 | K4: 0.27894387 | L4: 0.22597006 | M4: 0.13054082 | N4: 0.29325964 | O4: 0.34552897 | P4: 0.10909809 | Q4: 0.14087742 | R4: -0.238476 | S4: -0.21918819 | T4: -0.1171481 | U4: 0.058075344 | V4: -0.074799453 | W4: -0.15573677 | X4: -0.20674467 | Y4: -0.19478786 | Z4: -0.04247153 | AA4: 0.13714745 | AB4: -0.051630991 | AC4: -0.081928971 | AD4: 0.043869373
A5: sensitivityscore_After_features.7_0.7 | B5: 0.038693804 | C5: 0.45831934 | D5: 0.79793274 | E5: 1 | F5: 0.073415584 | G5: 0.10539205 | H5: 0.18359673 | I5: 0.14697347 | J5: 0.28932238 | K5: 0.23550794 | L5: 0.20040821 | M5: 0.15071745 | N5: 0.19161025 | O5: 0.30288333 | P5: 0.10473842 | Q5: 0.13270094 | R5: -0.24241818 | S5: -0.1173422 | T5: -0.10399605 | U5: 0.11078133 | V5: -0.075059993 | W5: -0.14148618 | X5: -0.11517814 | Y5: -0.21273265 | Z5: -0.036651998 | AA5: 0.024542814 | AB5: -0.13579683 | AC5: -0.092963002 | AD5: -0.041804124
A6: features.19 | B6: 0.045479148 | C6: 0.17267385 | D6: 0.14078323 | E6: 0.073415584 | F6: 1 | G6: 0.095284945 | H6: 0.084804415 | I6: 0.13789666 | J6: 0.47561623 | K6: 0.46614626 | L6: -0.038415036 | M6: 0.085903152 | N6: -0.0011084487 | O6: 0.47654579 | P6: 0.4762143 | Q6: 0.3173615 | R6: -0.083752021 | S6: 0.10990384 | T6: 0.10191609 | U6: 0.1333435 | V6: 0.056935861 | W6: 0.19330362 | X6: -0.037886152 | Y6: 0.27036632 | Z6: 0.074162426 | AA6: 0.09725269 | AB6: 0.071757421 | AC6: 0.28840214 | AD6: -0.016252743
A7: sensitivityscore_After_features.19_0.5 | B7: 0.21593937 | C7: 0.014461666 | D7: -0.056817308 | E7: 0.10539205 | F7: 0.095284945 | G7: 1 | H7: 0.69848246 | I7: 0.75140911 | J7: 0.25532256 | K7: 0.1816157 | L7: 0.2220872 | M7: 0.10177422 | N7: 0.20320889 | O7: 0.070100583 | P7: 0.20805033 | Q7: -0.0062767089 | R7: 0.13440113 | S7: 0.044063706 | T7: 0.2468822 | U7: 0.049164793 | V7: 0.18457291 | W7: -0.10298252 | X7: -0.23283142 | Y7: -0.11033073 | Z7: 0.1665219 | AA7: 0.20661917 | AB7: -0.043371732 | AC7: 0.034508152 | AD7: 0.086592693
A8: sensitivityscore_After_features.19_0.6 | B8: 0.076147459 | C8: 0.04260778 | D8: 0.14946437 | E8: 0.18359673 | F8: 0.084804415 | G8: 0.69848246 | H8: 1 | I8: 0.74015424 | J8: 0.20699299 | K8: 0.21531822 | L8: 0.16963681 | M8: 0.013877029 | N8: 0.15062706 | O8: 0.20768548 | P8: 0.29746691 | Q8: -0.026759773 | R8: 0.0039105781 | S8: 0.067568118 | T8: 0.30749801 | U8: -0.026053411 | V8: 0.048978281 | W8: -0.2951751 | X8: -0.46301404 | Y8: -0.1722321 | Z8: 0.08823582 | AA8: 0.10857255 | AB8: -0.16763115 | AC8: -0.057399869 | AD8: 0.010621625
A9: sensitivityscore_After_features.19_0.7 | B9: 0.14848644 | C9: 0.03805207 | D9: 0.058192858 | E9: 0.14697347 | F9: 0.13789666 | G9: 0.75140911 | H9: 0.74015424 | I9: 1 | J9: 0.23697387 | K9: 0.20326019 | L9: 0.13904613 | M9: -0.039292662 | N9: 0.16645696 | O9: 0.16430806 | P9: 0.28932071 | Q9: -0.046445485 | R9: 0.02378021 | S9: 0.14262018 | T9: 0.25885389 | U9: 0.013022499 | V9: 0.033743265 | W9: -0.1841675 | X9: -0.31550756 | Y9: -0.017500976 | Z9: 0.10074548 | AA9: 0.03773043 | AB9: -0.16246308 | AC9: 0.011144728 | AD9: -0.020271955
A10: features.20 | B10: 0.06856378 | C10: 0.26238984 | D10: 0.21250882 | E10: 0.28932238 | F10: 0.47561623 | G10: 0.25532256 | H10: 0.20699299 | I10: 0.23697387 | J10: 1 | K10: 0.65931713 | L10: -0.047189992 | M10: 0.058175171 | N10: 0.011107963 | O10: 0.53001062 | P10: 0.60831012 | Q10: 0.4568852 | R10: 0.014653378 | S10: 0.17620398 | T10: 0.13778518 | U10: 0.18509677 | V10: 0.16795062 | W10: -0.13746394 | X10: -0.20361253 | Y10: 0.024611182 | Z10: 0.11844416 | AA10: 0.1653762 | AB10: -0.022688947 | AC10: 0.057581226 | AD10: -0.035849963
A11: features.21 | B11: 0.12569219 | C11: 0.15483459 | D11: 0.27894387 | E11: 0.23550794 | F11: 0.46614626 | G11: 0.1816157 | H11: 0.21531822 | I11: 0.20326019 | J11: 0.65931713 | K11: 1 | L11: -0.015419861 | M11: 0.24547182 | N11: 0.17042449 | O11: 0.80116092 | P11: 0.75670766 | Q11: 0.54806724 | R11: -0.18892614 | S11: 0.16677284 | T11: 0.14137788 | U11: 0.19117309 | V11: 0.23394745 | W11: -0.045805031 | X11: -0.094259291 | Y11: -0.013144669 | Z11: 0.21581902 | AA11: 0.40133622 | AB11: 0.12726205 | AC11: 0.19195621 | AD11: -0.0028912806
A12: sensitivityscore_After_features.21_0.5 | B12: -0.056646593 | C12: 0.22029755 | D12: 0.22597006 | E12: 0.20040821 | F12: -0.038415036 | G12: 0.2220872 | H12: 0.16963681 | I12: 0.13904613 | J12: -0.047189992 | K12: -0.015419861 | L12: 1 | M12: 0.56217247 | N12: 0.65418248 | O12: -0.18499337 | P12: -0.19024859 | Q12: 0.018855239 | R12: 0.27286374 | S12: 0.041506286 | T12: 0.11061626 | U12: 0.016113488 | V12: 0.19856664 | W12: -0.011755291 | X12: -0.0029828863 | Y12: -0.025316157 | Z12: 0.14071388 | AA12: 0.17637191 | AB12: 0.1512984 | AC12: 0.10637028 | AD12: 0.25872354
A13: sensitivityscore_After_features.21_0.6 | B13: -0.078869074 | C13: 0.11767216 | D13: 0.13054082 | E13: 0.15071745 | F13: 0.085903152 | G13: 0.10177422 | H13: 0.013877029 | I13: -0.039292662 | J13: 0.058175171 | K13: 0.24547182 | L13: 0.56217247 | M13: 1 | N13: 0.74841802 | O13: 0.0077751275 | P13: 0.059021331 | Q13: 0.19131566 | R13: 0.079769371 | S13: -0.047139194 | T13: 0.060419721 | U13: 0.17325439 | V13: 0.17343031 | W13: 0.074199344 | X13: 0.037989183 | Y13: -0.040894498 | Z13: 0.17760313 | AA13: 0.38228368 | AB13: 0.35966836 | AC13: 0.37928868 | AD13: 0.23524697
... A30: sensitivityscore_After_features.28_0.7 | B30: -0.2830385 | C30: 0.029467606 | D30: 0.043869373 | E30: -0.041804124 | F30: -0.016252743 | G30: 0.086592693 | H30: 0.010621625 | I30: -0.020271955 | J30: -0.035849963 | K30: -0.0028912806 | L30: 0.25872354 | M30: 0.23524697 | N30: 0.18688635 | O30: -0.16742991 | P30: -0.14349533 | Q30: 0.14232579 | R30: 0.26274999 | S30: -0.072629524 | T30: -0.18102968 | U30: 0.20392587 | V30: 0.47328665 | W30: 0.01169163 | X30: 0.062321903 | Y30: -0.0023009483 | Z30: 0.40123978 | AA30: 0.23040039 | AB30: 0.57771535 | AC30: 0.66652624 | AD30: 1

Sheet Class_4
B1: features.7 | C1: sensitivityscore_After_features.7_0.5 | D1: sensitivityscore_After_features.7_0.6 | E1: sensitivityscore_After_features.7_0.7 | F1: features.19 | G1: sensitivityscore_After_features.19_0.5 | H1: sensitivityscore_After_features.19_0.6 | I1: sensitivityscore_After_features.19_0.7 | J1: features.20 | K1: features.21 | L1: sensitivityscore_After_features.21_0.5 | M1: sensitivityscore_After_features.21_0.6 | N1: sensitivityscore_After_features.21_0.7 | O1: features.22 | P1: features.23 | Q1: features.24 | R1: sensitivityscore_After_features.24_0.5 | S1: sensitivityscore_After_features.24_0.6 | T1: sensitivityscore_After_features.24_0.7 | U1: features.25 | V1: features.26 | W1: sensitivityscore_After_features.26_0.5 | X1: sensitivityscore_After_features.26_0.6 | Y1: sensitivityscore_After_features.26_0.7 | Z1: features.27 | AA1: features.28 | AB1: sensitivityscore_After_features.28_0.5 | AC1: sensitivityscore_After_features.28_0.6 | AD1: sensitivityscore_After_features.28_0.7
A2: features.7 | B2: 1 | C2: 0.042744057 | D2: 0.007493024 | E2: 0.098900578 | F2: 0.36997099 | G2: 0.11163241 | H2: 0.34924085 | I2: 0.28824666 | J2: 0.21289206 | K2: 0.21117574 | L2: 0.17019704 | M2: 0.31820425 | N2: 0.16165009 | O2: 0.20061552 | P2: 0.11449318 | Q2: 0.13915051 | R2: 0.30717442 | S2: 0.15097099 | T2: 0.28292922 | U2: 0.20196145 | V2: 0.12197413 | W2: 0.27875046 | X2: 0.28001341 | Y2: 0.24161398 | Z2: 0.002999343 | AA2: 0.097923499 | AB2: -0.2020887 | AC2: -0.27145898 | AD2: -0.097613406
A3: sensitivityscore_After_features.7_0.5 | B3: 0.042744057 | C3: 1 | D3: 0.67106371 | E3: 0.54160856 | F3: -0.02765936 | G3: -0.070336079 | H3: -0.13927082 | I3: -0.16005972 | J3: -0.14566583 | K3: 0.10091988 | L3: 0.24064265 | M3: 0.0046312515 | N3: -0.013485138 | O3: 0.1455272 | P3: 0.0691 | Q3: -0.10451683 | R3: -0.10587484 | S3: -0.10092063 | T3: -0.094034633 | U3: -0.12696167 | V3: -0.061095013 | W3: -0.16929962 | X3: -0.13168203 | Y3: 0.13006624 | Z3: -0.063484772 | AA3: -0.11661832 | AB3: -0.046619551 | AC3: -0.075002322 | AD3: -0.0051587866
A4: sensitivityscore_After_features.7_0.6 | B4: 0.007493024 | C4: 0.67106371 | D4: 1 | E4: 0.55461342 | F4: 0.1847608 | G4: -0.24303714 | H4: -0.11529227 | I4: -0.20506499 | J4: 0.16232163 | K4: 0.196861 | L4: 0.13251431 | M4: -0.047972674 | N4: -0.18533677 | O4: 0.11647026 | P4: 0.28309579 | Q4: -0.051074288 | R4: -0.072231786 | S4: -0.025356634 | T4: 0.061606164 | U4: -0.10220166 | V4: -0.088535314 | W4: -0.16097102 | X4: 0.040640718 | Y4: 0.22053068 | Z4: -0.077373304 | AA4: 0.089474663 | AB4: 0.12514112 | AC4: 0.22162811 | AD4: 0.14862682
A5: sensitivityscore_After_features.7_0.7 | B5: 0.098900578 | C5: 0.54160856 | D5: 0.55461342 | E5: 1 | F5: 0.10983598 | G5: -0.057165805 | H5: 0.016103997 | I5: 0.00070642904 | J5: -0.080084565 | K5: 0.30120378 | L5: 0.022833705 | M5: -0.20250018 | N5: -0.072821668 | O5: 0.12220681 | P5: 0.20549884 | Q5: -0.24754734 | R5: 0.099869349 | S5: 0.10362651 | T5: 0.041437192 | U5: -0.16698269 | V5: -0.2584477 | W5: -0.067580562 | X5: 0.043067148 | Y5: 0.026580723 | Z5: -0.23926617 | AA5: -0.32897538 | AB5: 0.080887859 | AC5: 0.079592593 | AD5: 0.071932256
A6: features.19 | B6: 0.36997099 | C6: -0.02765936 | D6: 0.1847608 | E6: 0.10983598 | F6: 1 | G6: 0.30845625 | H6: 0.25197868 | I6: 0.23858438 | J6: 0.61864833 | K6: 0.58601648 | L6: 0.18322433 | M6: 0.018552369 | N6: 0.22307384 | O6: 0.07856511 | P6: 0.58202785 | Q6: 0.36413889 | R6: 0.24383153 | S6: 0.28639897 | T6: 0.23422855 | U6: 0.48840051 | V6: 0.20787542 | W6: 0.07834196 | X6: 0.23904158 | Y6: 0.02157102 | Z6: 0.066315797 | AA6: 0.32703438 | AB6: 0.14485589 | AC6: 0.064686906 | AD6: 0.0030408196
A7: sensitivityscore_After_features.19_0.5 | B7: 0.11163241 | C7: -0.070336079 | D7: -0.24303714 | E7: -0.057165805 | F7: 0.30845625 | G7: 1 | H7: 0.67100065 | I7: 0.76945738 | J7: 0.061367435 | K7: 0.3316039 | L7: 0.51855817 | M7: 0.33021352 | N7: 0.4342885 | O7: -0.075571728 | P7: 0.0049751541 | Q7: 0.30925488 | R7: 0.5940955 | S7: 0.53591066 | T7: 0.3731056 | U7: 0.6112104 | V7: 0.44036667 | W7: 0.25917215 | X7: 0.35951679 | Y7: 0.1054066 | Z7: 0.41343533 | AA7: 0.19525638 | AB7: -0.24484817 | AC7: -0.12370204 | AD7: -0.14651933
A8: sensitivityscore_After_features.19_0.6 | B8: 0.34924085 | C8: -0.13927082 | D8: -0.11529227 | E8: 0.016103997 | F8: 0.25197868 | G8: 0.67100065 | H8: 1 | I8: 0.85063224 | J8: 0.18296544 | K8: 0.23731811 | L8: 0.49748381 | M8: 0.46392497 | N8: 0.38034023 | O8: -0.17150359 | P8: -0.09848177 | Q8: 0.099527428 | R8: 0.69555115 | S8: 0.61598266 | T8: 0.58641944 | U8: 0.40594519 | V8: 0.48001572 | W8: 0.54304 | X8: 0.65253463 | Y8: 0.29896038 | Z8: 0.44771468 | AA8: -0.045858309 | AB8: -0.22023629 | AC8: -0.22008466 | AD8: -0.1478658
A9: sensitivityscore_After_features.19_0.7 | B9: 0.28824666 | C9: -0.16005972 | D9: -0.20506499 | E9: 0.00070642904 | F9: 0.23858438 | G9: 0.76945738 | H9: 0.85063224 | I9: 1 | J9: 0.19246845 | K9: 0.20263564 | L9: 0.53281149 | M9: 0.49255687 | N9: 0.34818389 | O9: -0.12538615 | P9: -0.083964899 | Q9: 0.27059897 | R9: 0.76190281 | S9: 0.70646296 | T9: 0.61711585 | U9: 0.45453906 | V9: 0.46462015 | W9: 0.52593088 | X9: 0.61579389 | Y9: 0.22234035 | Z9: 0.44648146 | AA9: 0.028013699 | AB9: -0.43255536 | AC9: -0.24352195 | AD9: -0.2306805
A10: features.20 | B10: 0.21289206 | C10: -0.14566583 | D10: 0.16232163 | E10: -0.080084565 | F10: 0.61864833 | G10: 0.061367435 | H10: 0.18296544 | I10: 0.19246845 | J10: 1 | K10: 0.5045098 | L10: 0.15015483 | M10: 0.2232715 | N10: 0.091969334 | O10: 0.23188232 | P10: 0.50522543 | Q10: 0.45937043 | R10: 0.26743542 | S10: 0.38013277 | T10: 0.17917156 | U10: 0.41718698 | V10: 0.096532559 | W10: 0.28419279 | X10: 0.4351509 | Y10: 0.14835533 | Z10: -0.052623886 | AA10: 0.12064476 | AB10: 0.043232671 | AC10: 0.061918986 | AD10: -0.10498222
A11: features.21 | B11: 0.21117574 | C11: 0.10091988 | D11: 0.196861 | E11: 0.30120378 | F11: 0.58601648 | G11: 0.3316039 | H11: 0.23731811 | I11: 0.20263564 | J11: 0.5045098 | K11: 1 | L11: 0.14117014 | M11: 0.076296432 | N11: 0.32709464 | O11: 0.55025077 | P11: 0.68842953 | Q11: 0.13260055 | R11: 0.20894175 | S11: 0.1181586 | T11: -0.0074742962 | U11: 0.40338492 | V11: 0.10043915 | W11: 0.098745324 | X11: 0.29810843 | Y11: 0.012273558 | Z11: 0.021153296 | AA11: 0.15598882 | AB11: 0.14054979 | AC11: 0.16041754 | AD11: 0.15254705
A12: sensitivityscore_After_features.21_0.5 | B12: 0.17019704 | C12: 0.24064265 | D12: 0.13251431 | E12: 0.022833705 | F12: 0.18322433 | G12: 0.51855817 | H12: 0.49748381 | I12: 0.53281149 | J12: 0.15015483 | K12: 0.14117014 | L12: 1 | M12: 0.66668353 | N12: 0.67597313 | O12: -0.10878982 | P12: -0.13206248 | Q12: 0.087264391 | R12: 0.38678511 | S12: 0.50859763 | T12: 0.4933307 | U12: 0.19092945 | V12: 0.19899506 | W12: 0.36665581 | X12: 0.4293944 | Y12: 0.26376304 | Z12: 0.25386718 | AA12: -0.069906063 | AB12: 0.0030152722 | AC12: -0.0083212954 | AD12: -0.086691127
A13: sensitivityscore_After_features.21_0.6 | B13: 0.31820425 | C13: 0.0046312515 | D13: -0.047972674 | E13: -0.20250018 | F13: 0.018552369 | G13: 0.33021352 | H13: 0.46392497 | I13: 0.49255687 | J13: 0.2232715 | K13: 0.076296432 | L13: 0.66668353 | M13: 1 | N13: 0.59794649 | O13: 0.31074614 | P13: -0.043116501 | Q13: 0.080367985 | R13: 0.3388832 | S13: 0.3351698 | T13: 0.34960485 | U13: 0.33349385 | V13: 0.36280324 | W13: 0.54981139 | X13: 0.48005797 | Y13: 0.28708102 | Z13: 0.41405475 | AA13: 0.10232002 | AB13: -0.098886425 | AC13: -0.0066113671 | AD13: -0.10659691
... A30: sensitivityscore_After_features.28_0.7 | B30: -0.097613406 | C30: -0.0051587866 | D30: 0.14862682 | E30: 0.071932256 | F30: 0.0030408196 | G30: -0.14651933 | H30: -0.1478658 | I30: -0.2306805 | J30: -0.10498222 | K30: 0.15254705 | L30: -0.086691127 | M30: -0.10659691 | N30: 0.17982372 | O30: 0.012129496 | P30: 0.2081832 | Q30: -0.10964978 | R30: -0.50064122 | S30: -0.30559406 | T30: -0.41530578 | U30: -0.23534215 | V30: -0.3049812 | W30: -0.42889674 | X30: -0.36629798 | Y30: -0.22762681 | Z30: -0.20242449 | AA30: -0.016752134 | AB30: 0.38876152 | AC30: 0.56435889 | AD30: 1

Sheet Class_5
B1: features.7 | C1: sensitivityscore_After_features.7_0.5 | D1: sensitivityscore_After_features.7_0.6 | E1: sensitivityscore_After_features.7_0.7 | F1: features.19 | G1: sensitivityscore_After_features.19_0.5 | H1: sensitivityscore_After_features.19_0.6 | I1: sensitivityscore_After_features.19_0.7 | J1: features.20 | K1: features.21 | L1: sensitivityscore_After_features.21_0.5 | M1: sensitivityscore_After_features.21_0.6 | N1: sensitivityscore_After_features.21_0.7 | O1: features.22 | P1: features.23 | Q1: features.24 | R1: sensitivityscore_After_features.24_0.5 | S1: sensitivityscore_After_features.24_0.6 | T1: sensitivityscore_After_features.24_0.7 | U1: features.25 | V1: features.26 | W1: sensitivityscore_After_features.26_0.5 | X1: sensitivityscore_After_features.26_0.6 | Y1: sensitivityscore_After_features.26_0.7 | Z1: features.27 | AA1: features.28 | AB1: sensitivityscore_After_features.28_0.5 | AC1: sensitivityscore_After_features.28_0.6 | AD1: sensitivityscore_After_features.28_0.7
A2: features.7 | B2: 1 | C2: 0.20318481 | D2: 0.25434899 | E2: -0.034333516 | F2: 0.15081961 | G2: 0.20150385 | H2: 0.27113277 | I2: 0.40158979 | J2: 0.20107392 | K2: 0.28324071 | L2: 0.037964829 | M2: -0.24912533 | N2: -0.08302331 | O2: 0.58237176 | P2: 0.30466172 | Q2: 0.48725048 | R2: 0.045934851 | S2: 0.11161686 | T2: 0.057220656 | U2: 0.26657902 | V2: 0.1706871 | W2: -0.067567211 | X2: 0.050492261 | Y2: 0.20192519 | Z2: 0.30520338 | AA2: 0.14608701 | AB2: -0.13910505 | AC2: 0.1352341 | AD2: 0.24815881
A3: sensitivityscore_After_features.7_0.5 | B3: 0.20318481 | C3: 1 | D3: 0.39319021 | E3: 0.08617638 | F3: 0.17429637 | G3: -0.07172513 | H3: -0.16637701 | I3: -0.070037341 | J3: 0.14570521 | K3: -0.061527879 | L3: -0.10241642 | M3: -0.13243385 | N3: -0.048940685 | O3: 0.13645538 | P3: 0.037215492 | Q3: 0.041999766 | R3: 0.19697743 | S3: 0.031079586 | T3: 0.025667292 | U3: -0.032777815 | V3: -0.11778292 | W3: -0.030110292 | X3: -0.050096229 | Y3: 0.23133416 | Z3: -0.23179799 | AA3: 0.02258883 | AB3: -0.16619435 | AC3: -0.017417351 | AD3: 0.039776038
A4: sensitivityscore_After_features.7_0.6 | B4: 0.25434899 | C4: 0.39319021 | D4: 1 | E4: 0.21439691 | F4: -0.39140815 | G4: 0.1663719 | H4: 0.074783348 | I4: 0.33799267 | J4: -0.1718771 | K4: -0.16271394 | L4: 0.16198178 | M4: -0.032757457 | N4: 0.26759268 | O4: -0.11448407 | P4: -0.29234028 | Q4: -0.12553815 | R4: 0.13130986 | S4: 0.029331994 | T4: 0.21962707 | U4: -0.14964202 | V4: -0.26292726 | W4: 0.0056376037 | X4: 0.10557004 | Y4: 0.055329225 | Z4: -0.27171951 | AA4: -0.21310688 | AB4: 0.15162603 | AC4: 0.1682732 | AD4: 0.21734413
A5: sensitivityscore_After_features.7_0.7 | B5: -0.034333516 | C5: 0.08617638 | D5: 0.21439691 | E5: 1 | F5: -0.2003336 | G5: -0.14486253 | H5: -0.085397132 | I5: -0.046760707 | J5: -0.031670415 | K5: -0.12028236 | L5: -0.1360389 | M5: -0.10719991 | N5: -0.010747249 | O5: -0.049756908 | P5: -0.12265616 | Q5: -0.096943495 | R5: -0.21657302 | S5: -0.064074587 | T5: -0.060491189 | U5: -0.16570626 | V5: 0.11081097 | W5: -0.17575956 | X5: 0.095891945 | Y5: 0.1423824 | Z5: -0.0024043164 | AA5: 0.21650503 | AB5: 0.37170202 | AC5: 0.15267195 | AD5: 0.1705704
A6: features.19 | B6: 0.15081961 | C6: 0.17429637 | D6: -0.39140815 | E6: -0.2003336 | F6: 1 | G6: 0.12803067 | H6: -0.1953765 | I6: -0.21099619 | J6: 0.49341913 | K6: 0.36428949 | L6: 0.004220702 | M6: -0.015200238 | N6: -0.1603261 | O6: 0.46261738 | P6: 0.41242816 | Q6: 0.41745633 | R6: -0.062795428 | S6: -0.0255263 | T6: -0.14855617 | U6: 0.44592793 | V6: 0.43702802 | W6: 0.070395143 | X6: 0.14509112 | Y6: 0.14832073 | Z6: 0.29685933 | AA6: 0.41905044 | AB6: -0.30258251 | AC6: -0.21073091 | AD6: -0.018567969
A7: sensitivityscore_After_features.19_0.5 | B7: 0.20150385 | C7: -0.07172513 | D7: 0.1663719 | E7: -0.14486253 | F7: 0.12803067 | G7: 1 | H7: 0.55700436 | I7: 0.56027492 | J7: 0.085814145 | K7: 0.18688419 | L7: 0.11883708 | M7: 0.11983632 | N7: 0.2142252 | O7: 0.26804706 | P7: 0.040962508 | Q7: 0.2177369 | R7: -0.06155015 | S7: 0.08280581 | T7: 0.013704274 | U7: 0.12870924 | V7: 0.12649062 | W7: 0.23723353 | X7: 0.20138383 | Y7: -0.15324853 | Z7: 0.13999179 | AA7: -0.051226314 | AB7: -0.24902935 | AC7: -0.11899287 | AD7: -0.066307262
A8: sensitivityscore_After_features.19_0.6 | B8: 0.27113277 | C8: -0.16637701 | D8: 0.074783348 | E8: -0.085397132 | F8: -0.1953765 | G8: 0.55700436 | H8: 1 | I8: 0.68078777 | J8: -0.32133993 | K8: 0.10146347 | L8: 0.12349958 | M8: 0.0075663554 | N8: 0.24076193 | O8: 0.13918723 | P8: -0.038529307 | Q8: -0.059904659 | R8: 0.038042497 | S8: -0.0098016889 | T8: 0.0010461363 | U8: -0.26458719 | V8: -0.18052288 | W8: 0.082033017 | X8: -0.021894596 | Y8: -0.073996139 | Z8: -0.010884127 | AA8: -0.21713924 | AB8: 0.023212725 | AC8: 0.20863933 | AD8: 0.16439974
A9: sensitivityscore_After_features.19_0.7 | B9: 0.40158979 | C9: -0.070037341 | D9: 0.33799267 | E9: -0.046760707 | F9: -0.21099619 | G9: 0.56027492 | H9: 0.68078777 | I9: 1 | J9: -0.42392005 | K9: 0.061969561 | L9: 0.06294116 | M9: -0.049432977 | N9: 0.22230852 | O9: 0.09309394 | P9: -0.075167735 | Q9: -0.10940736 | R9: 0.13827243 | S9: 0.10930515 | T9: 0.12924873 | U9: -0.20119981 | V9: -0.19388063 | W9: 0.12471192 | X9: 0.076320345 | Y9: -0.17954584 | Z9: -0.048976739 | AA9: -0.39882937 | AB9: 0.11909503 | AC9: 0.32745499 | AD9: 0.34192668
A10: features.20 | B10: 0.20107392 | C10: 0.14570521 | D10: -0.1718771 | E10: -0.031670415 | F10: 0.49341913 | G10: 0.085814145 | H10: -0.32133993 | I10: -0.42392005 | J10: 1 | K10: 0.41507345 | L10: 0.066622619 | M10: -0.043833502 | N10: -0.14502444 | O10: 0.46599723 | P10: 0.31217891 | Q10: 0.64265078 | R10: -0.1891308 | S10: 0.053803093 | T10: -0.054033797 | U10: 0.43914668 | V10: 0.41001503 | W10: -0.12591446 | X10: 0.054154849 | Y10: 0.18899841 | Z10: 0.32932903 | AA10: 0.48394682 | AB10: -0.44060613 | AC10: -0.34086212 | AD10: -0.32037761
A11: features.21 | B11: 0.28324071 | C11: -0.061527879 | D11: -0.16271394 | E11: -0.12028236 | F11: 0.36428949 | G11: 0.18688419 | H11: 0.10146347 | I11: 0.061969561 | J11: 0.41507345 | K11: 1 | L11: 0.0097443379 | M11: -0.0858314 | N11: 0.14042846 | O11: 0.61720663 | P11: 0.62738289 | Q11: 0.27201499 | R11: 0.23139126 | S11: 0.34654884 | T11: 0.22634373 | U11: 0.24876229 | V11: 0.2149937 | W11: -0.090985341 | X11: -0.11776152 | Y11: -0.11442787 | Z11: 0.23051543 | AA11: -0.046878341 | AB11: -0.30371333 | AC11: -0.055085506 | AD11: 0.031823154
A12: sensitivityscore_After_features.21_0.5 | B12: 0.037964829 | C12: -0.10241642 | D12: 0.16198178 | E12: -0.1360389 | F12: 0.004220702 | G12: 0.11883708 | H12: 0.12349958 | I12: 0.06294116 | J12: 0.066622619 | K12: 0.0097443379 | L12: 1 | M12: 0.37790868 | N12: 0.31082834 | O12: -0.21996586 | P12: -0.16840706 | Q12: -0.13204107 | R12: 0.34114729 | S12: 0.25539552 | T12: 0.32993553 | U12: 0.16985251 | V12: -0.24538748 | W12: 0.12403862 | X12: 0.075720445 | Y12: 0.083716493 | Z12: -0.08320611 | AA12: -0.034791656 | AB12: -0.039235509 | AC12: 0.11668068 | AD12: -0.072906724
A13: sensitivityscore_After_features.21_0.6 | B13: -0.24912533 | C13: -0.13243385 | D13: -0.032757457 | E13: -0.10719991 | F13: -0.015200238 | G13: 0.11983632 | H13: 0.0075663554 | I13: -0.049432977 | J13: -0.043833502 | K13: -0.0858314 | L13: 0.37790868 | M13: 1 | N13: 0.65219741 | O13: -0.27373127 | P13: -0.31978466 | Q13: -0.33080565 | R13: 0.35490763 | S13: 0.20035461 | T13: 0.28984804 | U13: -0.19944138 | V13: 0.076415891 | W13: 0.54562412 | X13: 0.31915189 | Y13: 0.016364363 | Z13: 0.19999728 | AA13: -0.074441838 | AB13: -0.10651292 | AC13: -0.058658836 | AD13: -0.1175608
... A30: sensitivityscore_After_features.28_0.7 | B30: 0.24815881 | C30: 0.039776038 | D30: 0.21734413 | E30: 0.1705704 | F30: -0.018567969 | G30: -0.066307262 | H30: 0.16439974 | I30: 0.34192668 | J30: -0.32037761 | K30: 0.031823154 | L30: -0.072906724 | M30: -0.1175608 | N30: 0.1895681 | O30: 0.095731696 | P30: 0.14017988 | Q30: -0.11567104 | R30: 0.12271602 | S30: -0.022411415 | T30: 0.088853772 | U30: 0.015878459 | V30: -0.045201473 | W30: 0.22817751 | X30: 0.43940878 | Y30: 0.37940821 | Z30: -0.091099039 | AA30: 0.0065338529 | AB30: 0.64000416 | AC30: 0.76153893 | AD30: 1

Sheet Class_6
B1: features.7 | C1: sensitivityscore_After_features.7_0.5 | D1: sensitivityscore_After_features.7_0.6 | E1: sensitivityscore_After_features.7_0.7 | F1: features.19 | G1: sensitivityscore_After_features.19_0.5 | H1: sensitivityscore_After_features.19_0.6 | I1: sensitivityscore_After_features.19_0.7 | J1: features.20 | K1: features.21 | L1: sensitivityscore_After_features.21_0.5 | M1: sensitivityscore_After_features.21_0.6 | N1: sensitivityscore_After_features.21_0.7 | O1: features.22 | P1: features.23 | Q1: features.24 | R1: sensitivityscore_After_features.24_0.5 | S1: sensitivityscore_After_features.24_0.6 | T1: sensitivityscore_After_features.24_0.7 | U1: features.25 | V1: features.26 | W1: sensitivityscore_After_features.26_0.5 | X1: sensitivityscore_After_features.26_0.6 | Y1: sensitivityscore_After_features.26_0.7 | Z1: features.27 | AA1: features.28 | AB1: sensitivityscore_After_features.28_0.5 | AC1: sensitivityscore_After_features.28_0.6 | AD1: sensitivityscore_After_features.28_0.7
A2: features.7 | B2: 1 | C2: 0.15728004 | D2: 0.22548465 | E2: 0.10038763 | F2: 0.15178851 | G2: 0.055587829 | H2: 0.11564959 | I2: 0.095364909 | J2: 0.40498606 | K2: 0.26801269 | L2: -0.0074736309 | M2: -0.050651584 | N2: -0.050119744 | O2: 0.28855409 | P2: 0.31388965 | Q2: 0.20471058 | R2: -0.2849403 | S2: -0.30208115 | T2: 0.10960672 | U2: 0.1014076 | V2: 0.15814886 | W2: -0.020706636 | X2: -0.051169212 | Y2: 0.1564872 | Z2: 0.16061876 | AA2: 0.060090068 | AB2: -0.047638048 | AC2: -0.0134119 | AD2: 0.18992281
A3: sensitivityscore_After_features.7_0.5 | B3: 0.15728004 | C3: 1 | D3: 0.66786719 | E3: 0.57387314 | F3: 0.0088764444 | G3: -0.2439423 | H3: 0.089695868 | I3: -0.121025 | J3: 0.079885345 | K3: -0.062984032 | L3: 0.14671059 | M3: -0.017130428 | N3: 0.075778884 | O3: 0.10856587 | P3: 0.036266349 | Q3: -0.029111244 | R3: 0.092708917 | S3: 0.0012615709 | T3: 0.022169209 | U3: 0.04709205 | V3: -0.12990543 | W3: -0.12898903 | X3: -0.21667219 | Y3: -0.2715016 | Z3: -0.1990449 | AA3: -0.25883766 | AB3: -0.19989192 | AC3: -0.24749425 | AD3: -0.24105196
A4: sensitivityscore_After_features.7_0.6 | B4: 0.22548465 | C4: 0.66786719 | D4: 1 | E4: 0.71984759 | F4: 0.19663307 | G4: -0.26331402 | H4: 0.13721402 | I4: 0.0092239607 | J4: 0.22119529 | K4: 0.034288651 | L4: 0.33460565 | M4: 0.088382913 | N4: 0.25430537 | O4: 0.23381215 | P4: 0.18706582 | Q4: 0.12362903 | R4: 0.18333445 | S4: 0.10190898 | T4: 0.071874271 | U4: 0.12368278 | V4: 0.0073560466 | W4: 0.10668125 | X4: 0.034031403 | Y4: -0.17778164 | Z4: -0.046759573 | AA4: -0.1679032 | AB4: -0.13223788 | AC4: -0.20907341 | AD4: -0.20957756
A5: sensitivityscore_After_features.7_0.7 | B5: 0.10038763 | C5: 0.57387314 | D5: 0.71984759 | E5: 1 | F5: 0.034649675 | G5: -0.36113556 | H5: 0.11803453 | I5: -0.10647103 | J5: 0.026096316 | K5: -0.10596911 | L5: 0.14042135 | M5: 0.00069106706 | N5: 0.037687675 | O5: 0.075421101 | P5: 0.046388114 | Q5: -0.11906385 | R5: -0.13744351 | S5: -0.057321068 | T5: -0.15941853 | U5: -0.045741177 | V5: 0.048281797 | W5: -0.025895515 | X5: -0.051931147 | Y5: -0.23966671 | Z5: 0.013562572 | AA5: -0.21158525 | AB5: -0.24838658 | AC5: -0.28501672 | AD5: -0.33853199
A6: features.19 | B6: 0.15178851 | C6: 0.0088764444 | D6: 0.19663307 | E6: 0.034649675 | F6: 1 | G6: -0.19239592 | H6: -0.22514577 | I6: -0.20153001 | J6: 0.69147241 | K6: 0.72006169 | L6: 0.14516066 | M6: 0.22659324 | N6: 0.32757792 | O6: 0.64425161 | P6: 0.70722641 | Q6: 0.60519513 | R6: 0.10388009 | S6: -0.091348236 | T6: 0.15073513 | U6: 0.53621884 | V6: 0.411318 | W6: 0.41833193 | X6: 0.29510658 | Y6: 0.26727844 | Z6: 0.50041455 | AA6: 0.46209849 | AB6: 0.38441536 | AC6: 0.18665787 | AD6: 0.30782253
A7: sensitivityscore_After_features.19_0.5 | B7: 0.055587829 | C7: -0.2439423 | D7: -0.26331402 | E7: -0.36113556 | F7: -0.19239592 | G7: 1 | H7: 0.36340061 | I7: 0.53894948 | J7: 0.12198557 | K7: 0.13422348 | L7: 0.046497902 | M7: -0.029602794 | N7: -0.20729065 | O7: 0.13482429 | P7: -0.071421277 | Q7: -0.18028909 | R7: -0.093413107 | S7: -0.21677969 | T7: -0.0091204668 | U7: -0.17649198 | V7: -0.30266501 | W7: -0.36898048 | X7: -0.46748317 | Y7: 0.0071757689 | Z7: -0.2706618 | AA7: -0.17015633 | AB7: -0.0088615701 | AC7: -0.16393013 | AD7: 0.0021939075
A8: sensitivityscore_After_features.19_0.6 | B8: 0.11564959 | C8: 0.089695868 | D8: 0.13721402 | E8: 0.11803453 | F8: -0.22514577 | G8: 0.36340061 | H8: 1 | I8: 0.35769072 | J8: -0.11672199 | K8: -0.031444157 | L8: -0.038582188 | M8: -0.1377624 | N8: -0.1792336 | O8: 0.043407779 | P8: -0.13126511 | Q8: -0.064068174 | R8: 0.041411104 | S8: -0.087741151 | T8: -0.090436805 | U8: -0.19333279 | V8: -0.21396684 | W8: -0.27695694 | X8: -0.37816505 | Y8: -0.21549773 | Z8: -0.1419431 | AA8: -0.096462678 | AB8: -0.13275039 | AC8: -0.27546564 | AD8: -0.37839996
A9: sensitivityscore_After_features.19_0.7 | B9: 0.095364909 | C9: -0.121025 | D9: 0.0092239607 | E9: -0.10647103 | F9: -0.20153001 | G9: 0.53894948 | H9: 0.35769072 | I9: 1 | J9: -0.008530447 | K9: 0.049053948 | L9: 0.26214059 | M9: 0.087851823 | N9: 0.060161736 | O9: 0.036396779 | P9: -0.088954785 | Q9: 0.019501736 | R9: 0.068697172 | S9: 0.14220548 | T9: -0.010345897 | U9: -0.04990466 | V9: -0.13313239 | W9: -0.38747636 | X9: -0.45104664 | Y9: -0.31432836 | Z9: -0.14705133 | AA9: -0.15163215 | AB9: -0.11136184 | AC9: -0.10794117 | AD9: 0.0081954342
A10: features.20 | B10: 0.40498606 | C10: 0.079885345 | D10: 0.22119529 | E10: 0.026096316 | F10: 0.69147241 | G10: 0.12198557 | H10: -0.11672199 | I10: -0.008530447 | J10: 1 | K10: 0.62227061 | L10: 0.1788817 | M10: 0.088287717 | N10: 0.20601259 | O10: 0.49662222 | P10: 0.5948169 | Q10: 0.45748891 | R10: -0.066214274 | S10: -0.28264106 | T10: 0.13945505 | U10: 0.47568801 | V10: 0.30172782 | W10: 0.25333714 | X10: 0.11184897 | Y10: 0.23110226 | Z10: 0.31205259 | AA10: 0.32611754 | AB10: 0.21529508 | AC10: 0.12433561 | AD10: 0.30516506
A11: features.21 | B11: 0.26801269 | C11: -0.062984032 | D11: 0.034288651 | E11: -0.10596911 | F11: 0.72006169 | G11: 0.13422348 | H11: -0.031444157 | I11: 0.049053948 | J11: 0.62227061 | K11: 1 | L11: 0.10597741 | M11: 0.20449509 | N11: 0.18620655 | O11: 0.70403259 | P11: 0.83280361 | Q11: 0.55796485 | R11: -0.072236779 | S11: -0.20626404 | T11: -0.092180264 | U11: 0.39054204 | V11: 0.3259039 | W11: 0.1071614 | X11: 0.11735573 | Y11: 0.15653904 | Z11: 0.51067 | AA11: 0.40684536 | AB11: 0.41164948 | AC11: 0.14399465 | AD11: 0.40626611
A12: sensitivityscore_After_features.21_0.5 | B12: -0.0074736309 | C12: 0.14671059 | D12: 0.33460565 | E12: 0.14042135 | F12: 0.14516066 | G12: 0.046497902 | H12: -0.038582188 | I12: 0.26214059 | J12: 0.1788817 | K12: 0.10597741 | L12: 1 | M12: 0.58698585 | N12: 0.71755188 | O12: 0.30204742 | P12: 0.22042372 | Q12: 0.24475419 | R12: 0.197691 | S12: 0.19264495 | T12: 0.019649555 | U12: 0.41995829 | V12: 0.24833381 | W12: -0.060394284 | X12: -0.199349 | Y12: -0.23331606 | Z12: 0.16804494 | AA12: 0.11868304 | AB12: 0.045518835 | AC12: 0.010648605 | AD12: 0.023681929
