Workbook

Sheet Sheet1
A1: Class | B1: =Class_0!B1 -> Conv2d_1a_3x3.conv | C1: =Class_0!C1 -> Conv2d_2a_3x3.conv | D1: =Class_0!D1 -> Conv2d_2b_3x3.conv | E1: =Class_0!E1 -> maxpool1 | F1: =Class_0!F1 -> Conv2d_3b_1x1.conv | G1: =Class_0!G1 -> Conv2d_4a_3x3.conv | H1: =Class_0!H1 -> maxpool2 | I1: =Class_0!I1 -> Mixed_5b.branch1x1.conv | ... CV1: =Class_0!CV1 -> 0
A2: 0 | B2: =Class_0!B93 -> 0.15137683 | C2: =Class_0!C93 -> 0.14751232 | D2: =Class_0!D93 -> 0.28787725 | E2: =Class_0!E93 -> 0.026350328 | F2: =Class_0!F93 -> -0.0036028475 | G2: =Class_0!G93 -> 0.22421211 | H2: =Class_0!H93 -> 0.073077893 | I2: =Class_0!I93 -> 0.20930784 | ... CO2: =Class_0!CO93 -> 1
A3: 1 | B3: =Class_1!B93 -> 0.11830364 | C3: =Class_1!C93 -> 0.055331918 | D3: =Class_1!D93 -> 0.048400365 | E3: =Class_1!E93 -> -0.17842739 | F3: =Class_1!F93 -> -0.23580365 | G3: =Class_1!G93 -> -0.094327594 | H3: =Class_1!H93 -> -0.053944142 | I3: =Class_1!I93 -> -0.19415711 | ... CO3: =Class_1!CO93 -> 1
A4: 2 | B4: =Class_2!B93 -> 0.044069292 | C4: =Class_2!C93 -> 0.061388305 | D4: =Class_2!D93 -> 0.28892868 | E4: =Class_2!E93 -> -0.12431729 | F4: =Class_2!F93 -> -0.12462546 | G4: =Class_2!G93 -> -0.10838178 | H4: =Class_2!H93 -> -0.094133568 | I4: =Class_2!I93 -> -0.075072695 | ... CO4: =Class_2!CO93 -> 1
A6: Overall corelation | B6: =MIN(B2:B4) -> 0.044069292 | C6: =MIN(C2:C4) -> 0.055331918 | D6: =MIN(D2:D4) -> 0.048400365 | E6: =MIN(E2:E4) -> -0.17842739 | F6: =MIN(F2:F4) -> -0.23580365 | G6: =MIN(G2:G4) -> -0.10838178 | H6: =MIN(H2:H4) -> -0.094133568 | I6: =MIN(I2:I4) -> -0.19415711 | ... CO6: =MIN(CO2:CO4) -> 1
B7: =IF(AND(B2>0,B3>0,B4>0),TRUE,FALSE) -> TRUE | C7: =IF(AND(C2>0,C3>0,C4>0),TRUE,FALSE) -> TRUE | D7: =IF(AND(D2>0,D3>0,D4>0),TRUE,FALSE) -> TRUE | E7: =IF(AND(E2>0,E3>0,E4>0),TRUE,FALSE) -> FALSE | F7: =IF(AND(F2>0,F3>0,F4>0),TRUE,FALSE) -> FALSE | G7: =IF(AND(G2>0,G3>0,G4>0),TRUE,FALSE) -> FALSE | H7: =IF(AND(H2>0,H3>0,H4>0),TRUE,FALSE) -> FALSE | I7: =IF(AND(I2>0,I3>0,I4>0),TRUE,FALSE) -> FALSE | ... CO7: =IF(AND(CO2>0,CO3>0,CO4>0),TRUE,FALSE) -> TRUE
A8: Max Corelation layer
A9: Affects 2 classes | B9: =IF(OR(AND(B2>0,B3>0), AND(B2>0,B4>0), AND(B3>0,B4>0)), TRUE, FALSE) -> TRUE | C9: =IF(OR(AND(C2>0,C3>0), AND(C2>0,C4>0), AND(C3>0,C4>0)), TRUE, FALSE) -> TRUE | D9: =IF(OR(AND(D2>0,D3>0), AND(D2>0,D4>0), AND(D3>0,D4>0)), TRUE, FALSE) -> TRUE | E9: =IF(OR(AND(E2>0,E3>0), AND(E2>0,E4>0), AND(E3>0,E4>0)), TRUE, FALSE) -> FALSE | F9: =IF(OR(AND(F2>0,F3>0), AND(F2>0,F4>0), AND(F3>0,F4>0)), TRUE, FALSE) -> FALSE | G9: =IF(OR(AND(G2>0,G3>0), AND(G2>0,G4>0), AND(G3>0,G4>0)), TRUE, FALSE) -> FALSE | H9: =IF(OR(AND(H2>0,H3>0), AND(H2>0,H4>0), AND(H3>0,H4>0)), TRUE, FALSE) -> FALSE | I9: =IF(OR(AND(I2>0,I3>0), AND(I2>0,I4>0), AND(I3>0,I4>0)), TRUE, FALSE) -> FALSE | ... CO9: =IF(OR(AND(CO2>0,CO3>0), AND(CO2>0,CO4>0), AND(CO3>0,CO4>0)), TRUE, FALSE) -> TRUE

Sheet Class_0
B1: Conv2d_1a_3x3.conv | C1: Conv2d_2a_3x3.conv | D1: Conv2d_2b_3x3.conv | E1: maxpool1 | F1: Conv2d_3b_1x1.conv | G1: Conv2d_4a_3x3.conv | H1: maxpool2 | I1: Mixed_5b.branch1x1.conv | J1: Mixed_5b.branch5x5_1.conv | K1: Mixed_5b.branch5x5_2.conv | L1: Mixed_5b.branch3x3dbl_1.conv | M1: Mixed_5b.branch3x3dbl_2.conv | N1: Mixed_5b.branch3x3dbl_3.conv | O1: Mixed_5b.branch_pool.conv | P1: Mixed_5c.branch1x1.conv | Q1: Mixed_5c.branch5x5_1.conv | R1: Mixed_5c.branch5x5_2.conv | S1: Mixed_5c.branch3x3dbl_1.conv | T1: Mixed_5c.branch3x3dbl_2.conv | U1: Mixed_5c.branch3x3dbl_3.conv | V1: Mixed_5c.branch_pool.conv | W1: Mixed_5d.branch1x1.conv | X1: Mixed_5d.branch5x5_1.conv | Y1: Mixed_5d.branch5x5_2.conv | Z1: Mixed_5d.branch3x3dbl_1.conv | AA1: Mixed_5d.branch3x3dbl_2.conv | AB1: Mixed_5d.branch3x3dbl_3.conv | AC1: Mixed_5d.branch_pool.conv | AD1: Mixed_6a.branch3x3.conv | AE1: Mixed_6a.branch3x3dbl_1.conv | AF1: Mixed_6a.branch3x3dbl_2.conv | AG1: Mixed_6a.branch3x3dbl_3.conv | AH1: Mixed_6b.branch1x1.conv | AI1: Mixed_6b.branch7x7_1.conv | AJ1: Mixed_6b.branch7x7_2.conv | AK1: Mixed_6b.branch7x7_3.conv | AL1: Mixed_6b.branch7x7dbl_1.conv | AM1: Mixed_6b.branch7x7dbl_2.conv | AN1: Mixed_6b.branch7x7dbl_3.conv | AO1: Mixed_6b.branch7x7dbl_4.conv | AP1: Mixed_6b.branch7x7dbl_5.conv | AQ1: Mixed_6b.branch_pool.conv | AR1: Mixed_6c.branch1x1.conv | AS1: Mixed_6c.branch7x7_1.conv | AT1: Mixed_6c.branch7x7_2.conv | AU1: Mixed_6c.branch7x7_3.conv | AV1: Mixed_6c.branch7x7dbl_1.conv | AW1: Mixed_6c.branch7x7dbl_2.conv | AX1: Mixed_6c.branch7x7dbl_3.conv | AY1: Mixed_6c.branch7x7dbl_4.conv | AZ1: Mixed_6c.branch7x7dbl_5.conv | BA1: Mixed_6c.branch_pool.conv | BB1: Mixed_6d.branch1x1.conv | BC1: Mixed_6d.branch7x7_1.conv | BD1: Mixed_6d.branch7x7_2.conv | BE1: Mixed_6d.branch7x7_3.conv | BF1: Mixed_6d.branch7x7dbl_1.conv | BG1: Mixed_6d.branch7x7dbl_2.conv | BH1: Mixed_6d.branch7x7dbl_3.conv | BI1: Mixed_6d.branch7x7dbl_4.conv | BJ1: Mixed_6d.branch7x7dbl_5.conv | BK1: Mixed_6d.branch_pool.conv | BL1: Mixed_6e.branch1x1.conv | BM1: sensitivityscore_After_Mixed_6e.branch1x1.conv_0.5 | BN1: sensitivityscore_After_Mixed_6e.branch1x1.conv_0.6 | BO1: sensitivityscore_After_Mixed_6e.branch1x1.conv_0.7 | BP1: sensitivityscore_After_Mixed_6e.branch1x1.conv_0.8 | BQ1: Mixed_6e.branch7x7_1.conv | BR1: sensitivityscore_After_Mixed_6e.branch7x7_1.conv_0.5 | BS1: sensitivityscore_After_Mixed_6e.branch7x7_1.conv_0.6 | BT1: sensitivityscore_After_Mixed_6e.branch7x7_1.conv_0.7 | BU1: sensitivityscore_After_Mixed_6e.branch7x7_1.conv_0.8 | BV1: Mixed_6e.branch7x7_2.conv | BW1: sensitivityscore_After_Mixed_6e.branch7x7_2.conv_0.5 | BX1: sensitivityscore_After_Mixed_6e.branch7x7_2.conv_0.6 | BY1: sensitivityscore_After_Mixed_6e.branch7x7_2.conv_0.7 | BZ1: sensitivityscore_After_Mixed_6e.branch7x7_2.conv_0.8 | CA1: Mixed_6e.branch7x7_3.conv | CB1: sensitivityscore_After_Mixed_6e.branch7x7_3.conv_0.5 | CC1: sensitivityscore_After_Mixed_6e.branch7x7_3.conv_0.6 | CD1: sensitivityscore_After_Mixed_6e.branch7x7_3.conv_0.7 | CE1: sensitivityscore_After_Mixed_6e.branch7x7_3.conv_0.8 | CF1: Mixed_6e.branch7x7dbl_1.conv | CG1: sensitivityscore_After_Mixed_6e.branch7x7dbl_1.conv_0.5 | CH1: sensitivityscore_After_Mixed_6e.branch7x7dbl_1.conv_0.6 | CI1: sensitivityscore_After_Mixed_6e.branch7x7dbl_1.conv_0.7 | CJ1: sensitivityscore_After_Mixed_6e.branch7x7dbl_1.conv_0.8 | CK1: Mixed_6e.branch7x7dbl_2.conv | CL1: Mixed_6e.branch7x7dbl_3.conv | CM1: Mixed_6e.branch7x7dbl_4.conv | CN1: Mixed_6e.branch7x7dbl_5.conv | CO1: Mixed_6e.branch_pool.conv
A2: Conv2d_1a_3x3.conv | B2: 1 | C2: 0.42033927 | D2: 0.16308896 | E2: -0.22346306 | F2: -0.13371775 | G2: -0.01977939 | H2: 0.19365614 | I2: 0.20027697 | J2: 0.18135277 | K2: 0.033373107 | L2: 0.0942484 | M2: -0.1199373 | N2: 0.01259574 | O2: 0.2298213 | P2: 0.18120818 | Q2: -0.0091254667 | R2: -0.18017505 | S2: -0.29593922 | T2: -0.39366598 | U2: -0.11072309 | V2: -0.0067135604 | W2: 0.055765743 | X2: 0.28068686 | Y2: -0.029631978 | Z2: 0.084969472 | AA2: 0.31122531 | AB2: -0.053532518 | AC2: -0.081436702 | AD2: 0.14748508 | AE2: -0.03167835 | AF2: -0.11572385 | AG2: 0.097642516 | AH2: 0.023497604 | AI2: 0.13388337 | AJ2: -0.1118239 | AK2: -0.20133153 | AL2: 0.092772591 | AM2: -0.079938998 | AN2: -0.19048845 | AO2: -0.25782104 | AP2: -0.088044772 | AQ2: -0.23449021 | AR2: 0.023033212 | AS2: -0.087939009 | AT2: -0.23399951 | AU2: -0.16660622 | AV2: -0.24154524 | AW2: -0.1251452 | AX2: -0.22471427 | AY2: -0.3210715 | AZ2: -0.20112533 | BA2: -0.17763698 | BB2: -0.066129251 | BC2: -0.033010643 | BD2: 0.035330493 | BE2: -0.19378008 | BF2: -0.028318776 | BG2: -0.01722834 | BH2: -0.051151073 | BI2: 0.085355353 | BJ2: 0.12397997 | BK2: -0.15729751 | BL2: -0.10920149 | BM2: 0.02260005 | BN2: 0.20269461 | BO2: 0.067711946 | BP2: 0.41241951 | BQ2: -0.080597339 | BR2: -0.016132202 | BS2: 0.06761905 | BT2: 0.058672834 | BU2: -0.021243923 | BV2: -0.18016939 | BW2: 0.15254395 | BX2: -0.084240412 | BY2: 0.14221485 | BZ2: 0.22445685 | CA2: -0.078757127 | CB2: 0.088581273 | CC2: -0.0035027759 | CD2: -0.037559962 | CE2: -0.35761144 | CF2: -0.085460847 | CG2: -0.16726356 | CH2: 0.20216988 | CI2: 0.052095983 | CJ2: 0.010804357 | CK2: -0.064241241 | CL2: -0.020589613 | CM2: 0.14792013 | CN2: -0.097737516 | CO2: 0.15137683
A3: Conv2d_2a_3x3.conv | B3: 0.42033927 | C3: 1 | D3: 0.35615836 | E3: 0.048190013 | F3: 0.149951 | G3: 0.12121542 | H3: 0.062974418 | I3: 0.020822666 | J3: 0.070636932 | K3: -0.0035578374 | L3: 0.03538957 | M3: -0.047695462 | N3: -0.10734362 | O3: 0.050133655 | P3: 0.038900923 | Q3: 0.12950993 | R3: 0.13913862 | S3: -0.18124649 | T3: -0.14653745 | U3: -0.040125992 | V3: -0.094889927 | W3: 0.097846355 | X3: 0.091310392 | Y3: 0.11007349 | Z3: 0.18751266 | AA3: 0.24883884 | AB3: 0.18322656 | AC3: -0.089850282 | AD3: 0.12912417 | AE3: -0.22944855 | AF3: -0.22288334 | AG3: 0.075083994 | AH3: -0.0024955225 | AI3: 0.32049 | AJ3: -0.16574294 | AK3: -0.06650909 | AL3: -0.14417116 | AM3: -0.10993095 | AN3: -0.24394872 | AO3: -0.19350079 | AP3: -0.20238435 | AQ3: 0.065799999 | AR3: 0.027165465 | AS3: -0.14109891 | AT3: -0.21344957 | AU3: -0.052393354 | AV3: 0.058872465 | AW3: -0.013809633 | AX3: -0.18082041 | AY3: -0.13097501 | AZ3: -0.073993208 | BA3: -0.043352621 | BB3: -0.14840592 | BC3: 0.011587127 | BD3: 0.14173074 | BE3: -0.026063696 | BF3: -0.35065111 | BG3: -0.27743938 | BH3: -0.21700478 | BI3: -0.0079513972 | BJ3: -0.052030256 | BK3: -0.049465793 | BL3: -0.14650661 | BM3: 0.14425785 | BN3: 0.195014 | BO3: 0.10146971 | BP3: 0.07897496 | BQ3: 0.15476593 | BR3: -0.069873603 | BS3: 0.1020875 | BT3: 0.00066290766 | BU3: 0.012234969 | BV3: 0.10218496 | BW3: -0.1884069 | BX3: -0.27100943 | BY3: -0.080659142 | BZ3: 0.13466824 | CA3: 0.31433565 | CB3: -0.10337703 | CC3: -0.20147314 | CD3: -0.36174127 | CE3: -0.51707552 | CF3: -0.077224078 | CG3: -0.15036412 | CH3: 0.11650863 | CI3: 0.088941302 | CJ3: 0.16303863 | CK3: -0.14665104 | CL3: -0.073174956 | CM3: 0.096982046 | CN3: 0.06183956 | CO3: 0.14751232
A4: Conv2d_2b_3x3.conv | B4: 0.16308896 | C4: 0.35615836 | D4: 1 | E4: 0.2230356 | F4: 0.055069135 | G4: 0.20799662 | H4: 0.2176509 | I4: 0.2764458 | J4: 0.081301553 | K4: -0.017797216 | L4: -0.16218577 | M4: 0.14662081 | N4: 0.14231565 | O4: -0.10660618 | P4: 0.19166266 | Q4: -0.21458056 | R4: -0.17010473 | S4: -0.028537892 | T4: 0.033410165 | U4: -0.0076130384 | V4: 0.17412763 | W4: 0.14497791 | X4: 0.082987336 | Y4: 0.10249061 | Z4: 0.24142842 | AA4: 0.29757583 | AB4: 0.32956662 | AC4: 0.043560259 | AD4: 0.12245037 | AE4: -0.16204048 | AF4: -0.21513487 | AG4: -0.083926966 | AH4: 0.38278312 | AI4: 0.10135379 | AJ4: -0.20554064 | AK4: -0.037806818 | AL4: -0.10387161 | AM4: -0.083178687 | AN4: -0.037734406 | AO4: 0.0016366156 | AP4: 0.16133263 | AQ4: 0.21107857 | AR4: 0.23130057 | AS4: 0.099379033 | AT4: 0.1713498 | AU4: 0.24614475 | AV4: 0.024979293 | AW4: 0.11703479 | AX4: -0.12072687 | AY4: -0.050319534 | AZ4: -0.17916899 | BA4: 0.18993252 | BB4: 0.039937153 | BC4: 0.3537348 | BD4: 0.46255742 | BE4: 0.1924705 | BF4: -0.079092851 | BG4: -0.084557193 | BH4: 0.045591638 | BI4: 0.064111939 | BJ4: 0.16990626 | BK4: 0.24160916 | BL4: -0.0064372216 | BM4: 0.14819709 | BN4: -0.035039186 | BO4: 0.0019059306 | BP4: -0.0072104587 | BQ4: 0.15943791 | BR4: -0.021871527 | BS4: 0.048085209 | BT4: 0.095745676 | BU4: -0.0047133559 | BV4: 0.15165559 | BW4: 0.025071983 | BX4: -0.19603192 | BY4: -0.16430711 | BZ4: 0.27857334 | CA4: 0.2048453 | CB4: 0.0060792622 | CC4: -0.045872264 | CD4: -0.073959229 | CE4: -0.20443939 | CF4: 0.0056205986 | CG4: -0.19075387 | CH4: -0.1726621 | CI4: -0.054553791 | CJ4: -0.0040063698 | CK4: 0.19431712 | CL4: 0.20583751 | CM4: 0.25012108 | CN4: 0.20127445 | CO4: 0.28787725
A5: maxpool1 | B5: -0.22346306 | C5: 0.048190013 | D5: 0.2230356 | E5: 1 | F5: 0.78105175 | G5: 0.73699762 | H5: 0.34323412 | I5: 0.36488533 | J5: 0.17566564 | K5: 0.10485277 | L5: 0.23181314 | M5: 0.17026732 | N5: 0.1081579 | O5: 0.089690021 | P5: 0.24912601 | Q5: 0.099465246 | R5: 0.080057146 | S5: 0.048963289 | T5: 0.16945662 | U5: 0.15378302 | V5: 0.31423265 | W5: 0.17110619 | X5: -0.13230573 | Y5: 0.13721571 | Z5: 0.10662111 | AA5: -0.018180213 | AB5: 0.20725612 | AC5: 0.45500423 | AD5: -0.05759819 | AE5: -0.16977456 | AF5: 0.169025 | AG5: 0.094359624 | AH5: 0.39207943 | AI5: -0.092318039 | AJ5: -0.020525342 | AK5: -0.033112066 | AL5: 0.21472124 | AM5: -0.028406569 | AN5: 0.1522534 | AO5: 0.13584995 | AP5: 0.31371296 | AQ5: 0.31910975 | AR5: 0.038434401 | AS5: 0.29697261 | AT5: 0.30083616 | AU5: 0.49521415 | AV5: 0.46045651 | AW5: 0.32753051 | AX5: 0.10138496 | AY5: 0.31330307 | AZ5: -0.037408895 | BA5: 0.28794679 | BB5: 0.24902081 | BC5: 0.2355251 | BD5: 0.17348019 | BE5: 0.15902052 | BF5: -0.12671912 | BG5: -0.11963384 | BH5: -0.092485367 | BI5: -0.11051672 | BJ5: -0.29346051 | BK5: 0.14466189 | BL5: 0.071869208 | BM5: 0.12662809 | BN5: -0.051654376 | BO5: -0.026967282 | BP5: -0.20406826 | BQ5: 0.36991643 | BR5: -0.17380077 | BS5: -0.20786226 | BT5: 0.056410619 | BU5: 0.011291682 | BV5: 0.1913073 | BW5: -0.18762341 | BX5: -0.15858685 | BY5: -0.25599757 | BZ5: -0.084881345 | CA5: 0.148572 | CB5: 0.031177663 | CC5: -0.077195055 | CD5: -0.11922666 | CE5: 0.035775259 | CF5: -0.048889461 | CG5: 0.08386461 | CH5: -0.3004117 | CI5: 0.042525209 | CJ5: 0.016389549 | CK5: 0.029926016 | CL5: 0.079963172 | CM5: -0.13514017 | CN5: -0.11583223 | CO5: 0.026350328
A6: Conv2d_3b_1x1.conv | B6: -0.13371775 | C6: 0.149951 | D6: 0.055069135 | E6: 0.78105175 | F6: 1 | G6: 0.65780061 | H6: 0.36608296 | I6: 0.17546246 | J6: 0.16048371 | K6: 0.14936352 | L6: 0.20501108 | M6: -0.030872554 | N6: -0.039338699 | O6: 0.13321096 | P6: 0.12638433 | Q6: 0.084311907 | R6: 0.15713176 | S6: 0.035241053 | T6: 0.10093547 | U6: 0.14097092 | V6: 0.11744821 | W6: 0.12133668 | X6: -0.047256899 | Y6: 0.20446066 | Z6: 0.043808264 | AA6: -0.087879246 | AB6: 0.076395337 | AC6: 0.34499487 | AD6: 0.023687494 | AE6: -0.10776144 | AF6: 0.1164015 | AG6: -0.019592246 | AH6: 0.17929068 | AI6: -0.031303563 | AJ6: -0.14104413 | AK6: -0.015660571 | AL6: 0.15002391 | AM6: -0.24620188 | AN6: -0.081919148 | AO6: -0.046543917 | AP6: 0.077342252 | AQ6: 0.17647564 | AR6: -0.14851236 | AS6: 0.26731592 | AT6: 0.10827711 | AU6: 0.29555508 | AV6: 0.31536781 | AW6: 0.18631772 | AX6: -0.059153073 | AY6: 0.15207805 | AZ6: -0.10782188 | BA6: 0.048074191 | BB6: 0.0033644338 | BC6: 0.071576186 | BD6: -0.055121136 | BE6: -0.03993453 | BF6: -0.27909813 | BG6: -0.29566411 | BH6: -0.25147412 | BI6: -0.2056655 | BJ6: -0.25761445 | BK6: 0.068389083 | BL6: -0.093389913 | BM6: 0.20905797 | BN6: 0.049802249 | BO6: 0.008032313 | BP6: -0.30631646 | BQ6: 0.24011951 | BR6: -0.077418206 | BS6: -0.11552447 | BT6: 0.24407889 | BU6: 0.043719405 | BV6: 0.071256183 | BW6: -0.28314777 | BX6: -0.20177033 | BY6: -0.27845617 | BZ6: -0.042818012 | CA6: 0.070824098 | CB6: -0.20299131 | CC6: -0.18229788 | CD6: -0.30139893 | CE6: -0.096837553 | CF6: -0.16180296 | CG6: -0.0093385005 | CH6: -0.15458704 | CI6: 0.00018502473 | CJ6: 0.013577862 | CK6: -0.16110181 | CL6: 0.083519112 | CM6: -0.10606444 | CN6: -0.13847905 | CO6: -0.0036028475
A7: Conv2d_4a_3x3.conv | B7: -0.01977939 | C7: 0.12121542 | D7: 0.20799662 | E7: 0.73699762 | F7: 0.65780061 | G7: 1 | H7: 0.46773993 | I7: 0.35615554 | J7: 0.10462505 | K7: 0.063111282 | L7: 0.17815725 | M7: 0.23460044 | N7: 0.11438472 | O7: 0.18835502 | P7: 0.28156545 | Q7: 0.05407534 | R7: 0.099328065 | S7: 0.14432176 | T7: 0.071385182 | U7: 0.27752526 | V7: 0.32574065 | W7: 0.22758084 | X7: 0.19830604 | Y7: 0.36042229 | Z7: 0.1857076 | AA7: 0.17624205 | AB7: 0.19662803 | AC7: 0.40085055 | AD7: 0.10610768 | AE7: -0.0072085344 | AF7: 0.37190086 | AG7: 0.25107439 | AH7: 0.21783181 | AI7: 0.05867577 | AJ7: 0.073610008 | AK7: 0.0098762712 | AL7: 0.27014591 | AM7: 0.018570362 | AN7: 0.1136113 | AO7: 0.28368187 | AP7: 0.34427035 | AQ7: 0.32978412 | AR7: 0.10365303 | AS7: 0.24697867 | AT7: 0.33968278 | AU7: 0.40558392 | AV7: 0.3687272 | AW7: 0.22633835 | AX7: 0.1180857 | AY7: 0.26254477 | AZ7: 0.10226041 | BA7: 0.31561751 | BB7: 0.38290021 | BC7: 0.19205314 | BD7: 0.12432159 | BE7: 0.23282493 | BF7: 0.00043752032 | BG7: 0.015580401 | BH7: 0.13634859 | BI7: 0.1801122 | BJ7: -0.013356711 | BK7: 0.17225824 | BL7: 0.21009497 | BM7: 0.21692147 | BN7: 0.049197933 | BO7: -0.063550186 | BP7: 0.01659848 | BQ7: 0.4732587 | BR7: -0.13749478 | BS7: -0.095410579 | BT7: 0.15012888 | BU7: -0.012351977 | BV7: 0.2757461 | BW7: -0.11519814 | BX7: 0.02096399 | BY7: -0.27473041 | BZ7: 0.02979455 | CA7: 0.28028948 | CB7: 0.0048460402 | CC7: -0.28277105 | CD7: -0.34709888 | CE7: -0.063055695 | CF7: 0.10227981 | CG7: -0.0039291581 | CH7: -0.24724403 | CI7: 0.012809077 | CJ7: 0.11309782 | CK7: 0.11734268 | CL7: 0.25736306 | CM7: -0.097521015 | CN7: 0.032752486 | CO7: 0.22421211
A8: maxpool2 | B8: 0.19365614 | C8: 0.062974418 | D8: 0.2176509 | E8: 0.34323412 | F8: 0.36608296 | G8: 0.46773993 | H8: 1 | I8: 0.77545377 | J8: 0.048400902 | K8: 0.30814346 | L8: 0.43780865 | M8: 0.37581861 | N8: 0.31342792 | O8: 0.17937891 | P8: 0.65435966 | Q8: 0.29858087 | R8: -0.019361768 | S8: 0.30415769 | T8: 0.34917782 | U8: 0.08546914 | V8: 0.42311626 | W8: 0.41696437 | X8: 0.32353499 | Y8: 0.10020388 | Z8: 0.27249553 | AA8: 0.26210017 | AB8: 0.32540606 | AC8: 0.50333072 | AD8: 0.28834308 | AE8: -0.053121001 | AF8: -0.022019908 | AG8: -0.06706667 | AH8: 0.4455812 | AI8: 0.13075249 | AJ8: 0.089759979 | AK8: 0.11026481 | AL8: 0.42704592 | AM8: 0.21086639 | AN8: 0.006470491 | AO8: 0.054913268 | AP8: 0.29241116 | AQ8: 0.12324694 | AR8: 0.21080394 | AS8: 0.35392418 | AT8: 0.28311881 | AU8: 0.096348923 | AV8: 0.23306228 | AW8: 0.047339634 | AX8: -0.015228015 | AY8: 0.11206318 | AZ8: 0.028363095 | BA8: 0.33886421 | BB8: 0.10847482 | BC8: 0.31527068 | BD8: -0.0045099932 | BE8: 0.023714375 | BF8: 0.20022302 | BG8: 0.0402228 | BH8: 0.10164249 | BI8: 0.12454067 | BJ8: -0.049121709 | BK8: -0.010717099 | BL8: -0.093606487 | BM8: 0.047237743 | BN8: 0.044426499 | BO8: -0.16086852 | BP8: 0.035364815 | BQ8: 0.16725969 | BR8: -0.22361799 | BS8: -0.23841671 | BT8: 0.13551273 | BU8: -0.041255172 | BV8: -0.0032476369 | BW8: 0.070319997 | BX8: -0.0051612711 | BY8: -0.19533779 | BZ8: 0.12208428 | CA8: 0.064834351 | CB8: 0.034609446 | CC8: -0.1621072 | CD8: -0.26307701 | CE8: 0.032855923 | CF8: 0.054436731 | CG8: -0.057065888 | CH8: -0.06567387 | CI8: -0.10367921 | CJ8: -0.016597349 | CK8: 0.070989316 | CL8: 0.066790808 | CM8: 0.034424742 | CN8: -0.20193688 | CO8: 0.073077893
A9: Mixed_5b.branch1x1.conv | B9: 0.20027697 | C9: 0.020822666 | D9: 0.2764458 | E9: 0.36488533 | F9: 0.17546246 | G9: 0.35615554 | H9: 0.77545377 | I9: 1 | J9: 0.03206192 | K9: 0.16012716 | L9: 0.23912069 | M9: 0.29517306 | N9: 0.32206017 | O9: -0.0055461401 | P9: 0.5710383 | Q9: 0.27034675 | R9: -0.095914234 | S9: 0.30314409 | T9: 0.28704292 | U9: -0.057330178 | V9: 0.53495036 | W9: 0.3656222 | X9: 0.16111333 | Y9: -0.059913219 | Z9: 0.419235 | AA9: 0.37357044 | AB9: 0.25170295 | AC9: 0.48751589 | AD9: 0.21702948 | AE9: -0.14888565 | AF9: -0.01165249 | AG9: 0.079957364 | AH9: 0.47144718 | AI9: 0.075843744 | AJ9: -0.00050132064 | AK9: -0.04229948 | AL9: 0.38074959 | AM9: 0.23473583 | AN9: 0.13776575 | AO9: 0.13180573 | AP9: 0.33268958 | AQ9: 0.23212444 | AR9: 0.30120556 | AS9: 0.22741172 | AT9: 0.27628138 | AU9: 0.15207138 | AV9: 0.21779503 | AW9: 0.087467075 | AX9: 0.13715069 | AY9: 0.041269109 | AZ9: 0.030959033 | BA9: 0.40926116 | BB9: 0.29689904 | BC9: 0.31089168 | BD9: 0.12412969 | BE9: 0.020235806 | BF9: 0.20544384 | BG9: 0.15000007 | BH9: 0.22286036 | BI9: 0.21626072 | BJ9: -0.03777937 | BK9: -0.0019883549 | BL9: 0.0082133674 | BM9: 0.053697908 | BN9: 0.052823143 | BO9: -0.099228945 | BP9: 0.019759719 | BQ9: 0.18127015 | BR9: -0.27754021 | BS9: -0.29564265 | BT9: -0.050171169 | BU9: -0.060461784 | BV9: 0.07267363 | BW9: 0.10968095 | BX9: 0.080119004 | BY9: -0.035111735 | BZ9: 0.19468544 | CA9: 0.092952654 | CB9: 0.18897319 | CC9: -0.039395272 | CD9: -0.085276954 | CE9: 0.12454493 | CF9: 0.022731402 | CG9: -0.10786013 | CH9: -0.079519377 | CI9: -0.17148056 | CJ9: -0.026240746 | CK9: 0.10439825 | CL9: -0.036538138 | CM9: 0.11717448 | CN9: -0.17358948 | CO9: 0.20930784
A10: Mixed_5b.branch5x5_1.conv | B10: 0.18135277 | C10: 0.070636932 | D10: 0.081301553 | E10: 0.17566564 | F10: 0.16048371 | G10: 0.10462505 | H10: 0.048400902 | I10: 0.03206192 | J10: 1 | K10: 0.64355865 | L10: -0.0304566 | M10: -0.065423448 | N10: 0.14573291 | O10: 0.25907907 | P10: -0.065098989 | Q10: 0.13512485 | R10: -0.041676672 | S10: -0.17752742 | T10: -0.15092986 | U10: 0.025793272 | V10: -0.053864714 | W10: -0.19235133 | X10: -0.15830428 | Y10: -0.086195983 | Z10: 0.015365682 | AA10: 0.031923501 | AB10: -0.066119615 | AC10: 0.050639804 | AD10: -0.171213 | AE10: -0.11644 | AF10: -0.039166631 | AG10: -0.25618268 | AH10: 0.019706784 | AI10: -0.15311427 | AJ10: -0.22583208 | AK10: -0.096027553 | AL10: -0.26792445 | AM10: -0.14677575 | AN10: -0.067481377 | AO10: -0.090569653 | AP10: 0.029938907 | AQ10: 0.084747252 | AR10: -0.03429746 | AS10: 0.061000434 | AT10: 0.044757951 | AU10: 0.13972085 | AV10: -0.14107512 | AW10: 0.12755853 | AX10: -0.28890591 | AY10: -0.22559738 | AZ10: -0.18813075 | BA10: -0.20982777 | BB10: -0.099876022 | BC10: 0.020827097 | BD10: -0.077617617 | BE10: -0.022279802 | BF10: -0.19563121 | BG10: -0.24088527 | BH10: -0.12221853 | BI10: -0.036615029 | BJ10: -0.073072835 | BK10: -0.043625689 | BL10: -0.013913399 | BM10: 0.1204712 | BN10: 0.11144846 | BO10: -0.14131084 | BP10: -0.04387133 | BQ10: 0.090429301 | BR10: 0.15881148 | BS10: 0.14667711 | BT10: 0.14441047 | BU10: -0.012930057 | BV10: -0.15189711 | BW10: -0.081703661 | BX10: 0.1124936 | BY10: -0.0078149212 | BZ10: 0.027665038 | CA10: -0.14732347 | CB10: -0.079908023 | CC10: -0.0045720669 | CD10: -0.066328606 | CE10: -0.16224459 | CF10: -0.085702555 | CG10: -0.23671359 | CH10: -0.047136105 | CI10: 0.14000261 | CJ10: -0.072842357 | CK10: -0.31823262 | CL10: 0.054792297 | CM10: 0.21761166 | CN10: -0.060615595 | CO10: 0.0032924345
A11: Mixed_5b.branch5x5_2.conv | B11: 0.033373107 | C11: -0.0035578374 | D11: -0.017797216 | E11: 0.10485277 | F11: 0.14936352 | G11: 0.063111282 | H11: 0.30814346 | I11: 0.16012716 | J11: 0.64355865 | K11: 1 | L11: 0.13850056 | M11: 0.12201454 | N11: 0.34952484 | O11: 0.23484188 | P11: 0.22594639 | Q11: 0.32740468 | R11: 0.1139457 | S11: 0.058616152 | T11: 0.1769406 | U11: 0.079069709 | V11: 0.047215954 | W11: -0.012016811 | X11: 0.0084708716 | Y11: -0.076362233 | Z11: 0.090717456 | AA11: 0.031496748 | AB11: 0.15672566 | AC11: 0.26438295 | AD11: -0.05697799 | AE11: -0.14508978 | AF11: -0.0065889403 | AG11: -0.37982031 | AH11: 0.0032704265 | AI11: -0.15464963 | AJ11: -0.17629953 | AK11: 0.037076296 | AL11: -0.055999998 | AM11: 0.10445744 | AN11: -0.021244126 | AO11: -0.10203667 | AP11: 0.041012356 | AQ11: -0.020280915 | AR11: -0.14660475 | AS11: 0.28895016 | AT11: 0.057748744 | AU11: 0.028322336 | AV11: -0.08098729 | AW11: 0.08893211 | AX11: -0.24978075 | AY11: -0.081579911 | AZ11: -0.16197494 | BA11: -0.11463953 | BB11: -0.10575073 | BC11: 0.048735666 | BD11: -0.22372128 | BE11: -0.090749528 | BF11: -0.010821529 | BG11: -0.18298115 | BH11: -0.08897889 | BI11: -0.13115702 | BJ11: -0.1947193 | BK11: -0.24379215 | BL11: -0.16826222 | BM11: 0.24055744 | BN11: 0.1614705 | BO11: 0.013886418 | BP11: -0.080437118 | BQ11: -0.02495301 | BR11: 0.11602872 | BS11: -0.22067326 | BT11: 0.13046627 | BU11: 0.11642283 | BV11: -0.32733064 | BW11: -0.055505712 | BX11: 0.19327448 | BY11: -0.14382048 | BZ11: 0.17637537 | CA11: -0.16994666 | CB11: 0.076517306 | CC11: 0.061642181 | CD11: -0.083974784 | CE11: 0.037633736 | CF11: -0.21306137 | CG11: -0.094058507 | CH11: -0.011601787 | CI11: 0.19150984 | CJ11: -0.13479253 | CK11: -0.36024565 | CL11: -0.15237247 | CM11: -0.0035522585 | CN11: -0.3252349 | CO11: -0.31172996
A12: Mixed_5b.branch3x3dbl_1.conv | B12: 0.0942484 | C12: 0.03538957 | D12: -0.16218577 | E12: 0.23181314 | F12: 0.20501108 | G12: 0.17815725 | H12: 0.43780865 | I12: 0.23912069 | J12: -0.0304566 | K12: 0.13850056 | L12: 1 | M12: 0.27337005 | N12: 0.12821015 | O12: 0.20279604 | P12: 0.31777986 | Q12: 0.15227254 | R12: -0.019795103 | S12: -0.028243492 | T12: 0.25746353 | U12: 0.118659 | V12: 0.0020359848 | W12: 0.093868324 | X12: 0.11438806 | Y12: 0.070845617 | Z12: -0.058610933 | AA12: 0.044462188 | AB12: 0.11590669 | AC12: 0.21470883 | AD12: -0.0059892644 | AE12: -0.27526624 | AF12: 0.074472667 | AG12: 0.15951264 | AH12: 0.13371479 | AI12: -0.029357767 | AJ12: 0.050893417 | AK12: 0.14199341 | AL12: 0.26644545 | AM12: 0.062730511 | AN12: -0.031707585 | AO12: -0.13153478 | AP12: 0.0017129958 | AQ12: 0.14774983 | AR12: 0.036350502 | AS12: 0.13188726 | AT12: 0.10448991 | AU12: -0.050338445 | AV12: 0.30315162 | AW12: 0.12969473 | AX12: 0.15722753 | AY12: 0.32036655 | AZ12: 0.10150002 | BA12: 0.13803801 | BB12: 0.038436053 | BC12: -0.15832931 | BD12: -0.18455238 | BE12: -0.079910879 | BF12: 0.084948129 | BG12: -0.081552442 | BH12: -0.12483294 | BI12: -0.11629042 | BJ12: -0.31001292 | BK12: -0.0074592848 | BL12: -0.027594843 | BM12: 0.16558077 | BN12: 0.019832252 | BO12: -0.046122607 | BP12: -0.10678725 | BQ12: 0.1110353 | BR12: -0.17682806 | BS12: -0.27600522 | BT12: -0.0062287876 | BU12: 0.16927031 | BV12: -0.04066527 | BW12: 0.005236135 | BX12: -0.056914371 | BY12: -0.11146003 | BZ12: -0.072528501 | CA12: -0.015553193 | CB12: 0.041806138 | CC12: -0.053163044 | CD12: -0.23792232 | CE12: -0.011568313 | CF12: -0.14997176 | CG12: 0.066320633 | CH12: -0.11573396 | CI12: 0.036156373 | CJ12: 0.20982457 | CK12: -0.28014867 | CL12: 0.0036206456 | CM12: 0.038338835 | CN12: -0.15452794 | CO12: -0.24995944
A13: Mixed_5b.branch3x3dbl_2.conv | B13: -0.1199373 | C13: -0.047695462 | D13: 0.14662081 | E13: 0.17026732 | F13: -0.030872554 | G13: 0.23460044 | H13: 0.37581861 | I13: 0.29517306 | J13: -0.065423448 | K13: 0.12201454 | L13: 0.27337005 | M13: 1 | N13: 0.431109 | O13: 0.10406087 | P13: 0.18563798 | Q13: 0.17310707 | R13: 0.037575158 | S13: 0.31280406 | T13: 0.20260342 | U13: 0.31896887 | V13: 0.34845494 | W13: 0.13345068 | X13: 0.22285457 | Y13: 0.054980154 | Z13: 0.25873757 | AA13: 0.28420665 | AB13: 0.53919207 | AC13: 0.17616962 | AD13: 0.21671839 | AE13: -0.11677848 | AF13: -0.024264971 | AG13: 0.099628381 | AH13: 0.011210331 | AI13: 0.055878703 | AJ13: 0.24506654 | AK13: 0.086580345 | AL13: 0.17475178 | AM13: 0.20571657 | AN13: 0.15836228 | AO13: 0.096372647 | AP13: 0.17320811 | AQ13: 0.30002608 | AR13: 0.17463711 | AS13: 0.30287885 | AT13: 0.27108486 | AU13: 0.21353412 | AV13: 0.26702198 | AW13: 0.23658281 | AX13: 0.26334276 | AY13: 0.21637377 | AZ13: 0.2761505 | BA13: 0.43393559 | BB13: 0.11002978 | BC13: 0.10567853 | BD13: 0.017883352 | BE13: 0.2713709 | BF13: 0.30377908 | BG13: 0.071173569 | BH13: 0.19452167 | BI13: 0.025393779 | BJ13: -0.086896141 | BK13: 0.032046829 | BL13: 0.28387339 | BM13: 0.17462458 | BN13: 0.085157462 | BO13: -0.041491798 | BP13: 0.024583029 | BQ13: 0.14104472 | BR13: 0.11370862 | BS13: -0.014895433 | BT13: -0.042355321 | BU13: -0.16290382 | BV13: 0.099042255 | BW13: 0.23456296 | BX13: 0.23206209 | BY13: -0.10601391 | BZ13: 0.17075009 | CA13: 0.10697333 | CB13: 0.23310905 | CC13: -0.079062009 | CD13: -0.012514942 | CE13: 0.13532901 | CF13: -0.053114847 | CG13: 0.11398531 | CH13: -0.099938324 | CI13: 0.12653387 | CJ13: 0.090255914 | CK13: -0.075845357 | CL13: -0.027665397 | CM13: -0.11830896 | CN13: 0.058705113 | CO13: -0.057750876
... A93: Mixed_6e.branch_pool.conv | B93: 0.15137683 | C93: 0.14751232 | D93: 0.28787725 | E93: 0.026350328 | F93: -0.0036028475 | G93: 0.22421211 | H93: 0.073077893 | I93: 0.20930784 | J93: 0.0032924345 | K93: -0.31172996 | L93: -0.24995944 | M93: -0.057750876 | N93: 0.058519756 | O93: 0.12823789 | P93: 0.060420019 | Q93: 0.021840052 | R93: -0.030652064 | S93: -0.074071085 | T93: -0.30209287 | U93: -0.12775628 | V93: 0.04935029 | W93: 0.17381706 | X93: 0.0033007067 | Y93: 0.076280445 | Z93: 0.205568 | AA93: 0.26412106 | AB93: -0.078940816 | AC93: -0.010894045 | AD93: 0.12325083 | AE93: 0.057269198 | AF93: 0.091906764 | AG93: 0.32523263 | AH93: 0.16009723 | AI93: 0.12101627 | AJ93: -0.04755044 | AK93: -0.1818794 | AL93: 0.033590091 | AM93: 0.01457973 | AN93: 0.084887977 | AO93: 0.26856478 | AP93: 0.12586472 | AQ93: 0.2187845 | AR93: 0.36333299 | AS93: -0.13531145 | AT93: 0.093981687 | AU93: 0.24337502 | AV93: -0.11625449 | AW93: -0.064962404 | AX93: 0.014532709 | AY93: -0.15387316 | AZ93: 0.009367803 | BA93: 0.10231128 | BB93: 0.19781164 | BC93: 0.16201559 | BD93: 0.37441116 | BE93: 0.25171782 | BF93: 0.054242648 | BG93: 0.23972223 | BH93: 0.38025573 | BI93: 0.41070175 | BJ93: 0.40471964 | BK93: 0.32672223 | BL93: 0.11060335 | BM93: -0.059011616 | BN93: -0.021491028 | BO93: -0.26110141 | BP93: 0.20243104 | BQ93: 0.23806699 | BR93: -0.22793633 | BS93: 0.1479244 | BT93: -0.081920311 | BU93: -0.29327459 | BV93: 0.32591067 | BW93: 0.34948349 | BX93: 0.10511723 | BY93: 0.13575087 | BZ93: 0.071518611 | CA93: 0.3883366 | CB93: -0.085023649 | CC93: -0.30457469 | CD93: -0.17789325 | CE93: -0.27948986 | CF93: 0.40889461 | CG93: 0.068487533 | CH93: 0.14219158 | CI93: -0.16060956 | CJ93: 0.017287239 | CK93: 0.38303588 | CL93: 0.4207498 | CM93: 0.43262336 | CN93: 0.36878845 | CO93: 1

Sheet Class_1
B1: Conv2d_1a_3x3.conv | C1: Conv2d_2a_3x3.conv | D1: Conv2d_2b_3x3.conv | E1: maxpool1 | F1: Conv2d_3b_1x1.conv | G1: Conv2d_4a_3x3.conv | H1: maxpool2 | I1: Mixed_5b.branch1x1.conv | J1: Mixed_5b.branch5x5_1.conv | K1: Mixed_5b.branch5x5_2.conv | L1: Mixed_5b.branch3x3dbl_1.conv | M1: Mixed_5b.branch3x3dbl_2.conv | N1: Mixed_5b.branch3x3dbl_3.conv | O1: Mixed_5b.branch_pool.conv | P1: Mixed_5c.branch1x1.conv | Q1: Mixed_5c.branch5x5_1.conv | R1: Mixed_5c.branch5x5_2.conv | S1: Mixed_5c.branch3x3dbl_1.conv | T1: Mixed_5c.branch3x3dbl_2.conv | U1: Mixed_5c.branch3x3dbl_3.conv | V1: Mixed_5c.branch_pool.conv | W1: Mixed_5d.branch1x1.conv | X1: Mixed_5d.branch5x5_1.conv | Y1: Mixed_5d.branch5x5_2.conv | Z1: Mixed_5d.branch3x3dbl_1.conv | AA1: Mixed_5d.branch3x3dbl_2.conv | AB1: Mixed_5d.branch3x3dbl_3.conv | AC1: Mixed_5d.branch_pool.conv | AD1: Mixed_6a.branch3x3.conv | AE1: Mixed_6a.branch3x3dbl_1.conv | AF1: Mixed_6a.branch3x3dbl_2.conv | AG1: Mixed_6a.branch3x3dbl_3.conv | AH1: Mixed_6b.branch1x1.conv | AI1: Mixed_6b.branch7x7_1.conv | AJ1: Mixed_6b.branch7x7_2.conv | AK1: Mixed_6b.branch7x7_3.conv | AL1: Mixed_6b.branch7x7dbl_1.conv | AM1: Mixed_6b.branch7x7dbl_2.conv | AN1: Mixed_6b.branch7x7dbl_3.conv | AO1: Mixed_6b.branch7x7dbl_4.conv | AP1: Mixed_6b.branch7x7dbl_5.conv | AQ1: Mixed_6b.branch_pool.conv | AR1: Mixed_6c.branch1x1.conv | AS1: Mixed_6c.branch7x7_1.conv | AT1: Mixed_6c.branch7x7_2.conv | AU1: Mixed_6c.branch7x7_3.conv | AV1: Mixed_6c.branch7x7dbl_1.conv | AW1: Mixed_6c.branch7x7dbl_2.conv | AX1: Mixed_6c.branch7x7dbl_3.conv | AY1: Mixed_6c.branch7x7dbl_4.conv | AZ1: Mixed_6c.branch7x7dbl_5.conv | BA1: Mixed_6c.branch_pool.conv | BB1: Mixed_6d.branch1x1.conv | BC1: Mixed_6d.branch7x7_1.conv | BD1: Mixed_6d.branch7x7_2.conv | BE1: Mixed_6d.branch7x7_3.conv | BF1: Mixed_6d.branch7x7dbl_1.conv | BG1: Mixed_6d.branch7x7dbl_2.conv | BH1: Mixed_6d.branch7x7dbl_3.conv | BI1: Mixed_6d.branch7x7dbl_4.conv | BJ1: Mixed_6d.branch7x7dbl_5.conv | BK1: Mixed_6d.branch_pool.conv | BL1: Mixed_6e.branch1x1.conv | BM1: sensitivityscore_After_Mixed_6e.branch1x1.conv_0.5 | BN1: sensitivityscore_After_Mixed_6e.branch1x1.conv_0.6 | BO1: sensitivityscore_After_Mixed_6e.branch1x1.conv_0.7 | BP1: sensitivityscore_After_Mixed_6e.branch1x1.conv_0.8 | BQ1: Mixed_6e.branch7x7_1.conv | BR1: sensitivityscore_After_Mixed_6e.branch7x7_1.conv_0.5 | BS1: sensitivityscore_After_Mixed_6e.branch7x7_1.conv_0.6 | BT1: sensitivityscore_After_Mixed_6e.branch7x7_1.conv_0.7 | BU1: sensitivityscore_After_Mixed_6e.branch7x7_1.conv_0.8 | BV1: Mixed_6e.branch7x7_2.conv | BW1: sensitivityscore_After_Mixed_6e.branch7x7_2.conv_0.5 | BX1: sensitivityscore_After_Mixed_6e.branch7x7_2.conv_0.6 | BY1: sensitivityscore_After_Mixed_6e.branch7x7_2.conv_0.7 | BZ1: sensitivityscore_After_Mixed_6e.branch7x7_2.conv_0.8 | CA1: Mixed_6e.branch7x7_3.conv | CB1: sensitivityscore_After_Mixed_6e.branch7x7_3.conv_0.5 | CC1: sensitivityscore_After_Mixed_6e.branch7x7_3.conv_0.6 | CD1: sensitivityscore_After_Mixed_6e.branch7x7_3.conv_0.7 | CE1: sensitivityscore_After_Mixed_6e.branch7x7_3.conv_0.8 | CF1: Mixed_6e.branch7x7dbl_1.conv | CG1: sensitivityscore_After_Mixed_6e.branch7x7dbl_1.conv_0.5 | CH1: sensitivityscore_After_Mixed_6e.branch7x7dbl_1.conv_0.6 | CI1: sensitivityscore_After_Mixed_6e.branch7x7dbl_1.conv_0.7 | CJ1: sensitivityscore_After_Mixed_6e.branch7x7dbl_1.conv_0.8 | CK1: Mixed_6e.branch7x7dbl_2.conv | CL1: Mixed_6e.branch7x7dbl_3.conv | CM1: Mixed_6e.branch7x7dbl_4.conv | CN1: Mixed_6e.branch7x7dbl_5.conv | CO1: Mixed_6e.branch_pool.conv
A2: Conv2d_1a_3x3.conv | B2: 1 | C2: 0.50990435 | D2: 0.38825815 | E2: 0.12094327 | F2: -0.023167587 | G2: -0.062516388 | H2: -0.062897954 | I2: -0.056614065 | J2: 0.088452186 | K2: 0.02874558 | L2: 0.084729295 | M2: 0.021444441 | N2: 0.060215497 | O2: 0.14229346 | P2: -0.16195746 | Q2: 0.11889574 | R2: -0.053418255 | S2: 0.043188233 | T2: 0.0061966569 | U2: 0.19732359 | V2: 0.018260529 | W2: 0.16257348 | X2: 0.12915891 | Y2: 0.12622942 | Z2: -0.31669587 | AA2: -0.20959765 | AB2: 0.17742499 | AC2: 0.17522905 | AD2: 0.1735301 | AE2: 0.01767128 | AF2: 0.076319863 | AG2: -0.065045252 | AH2: 0.23549517 | AI2: -0.071519468 | AJ2: 0.023362007 | AK2: 0.16310573 | AL2: -0.16875593 | AM2: -0.050585543 | AN2: -0.15900052 | AO2: 0.037856661 | AP2: 0.089597791 | AQ2: 0.019163162 | AR2: 0.052470201 | AS2: 0.18266324 | AT2: 0.29671521 | AU2: 0.17732352 | AV2: -0.060724791 | AW2: -0.074033457 | AX2: 0.069424232 | AY2: 0.081110143 | AZ2: -0.11275192 | BA2: 0.025188996 | BB2: 0.10626779 | BC2: -0.14487144 | BD2: -0.080873087 | BE2: -0.084931132 | BF2: 0.065852863 | BG2: 0.028462734 | BH2: 0.037180799 | BI2: 0.12631806 | BJ2: 0.13818713 | BK2: 0.17347707 | BL2: 0.06115052 | BM2: 0.15867055 | BN2: 0.083262251 | BO2: 0.1860025 | BP2: 0.20217071 | BQ2: 0.12392128 | BR2: -0.28841302 | BS2: -0.16008331 | BT2: 0.11690846 | BU2: -0.13503416 | BV2: 0.21310962 | BW2: -0.031297689 | BX2: -0.045585274 | BY2: -0.2213864 | BZ2: 0.011777763 | CA2: 0.21231228 | CB2: -0.073644952 | CC2: 0.15798654 | CD2: -0.018359999 | CE2: -0.0813446 | CF2: 0.21009889 | CG2: 0.4070708 | CH2: -0.06646 | CI2: -0.068346093 | CJ2: -0.00072474589 | CK2: 0.37257059 | CL2: 0.23985321 | CM2: 0.35454862 | CN2: 0.31285398 | CO2: 0.11830364
A3: Conv2d_2a_3x3.conv | B3: 0.50990435 | C3: 1 | D3: 0.52682262 | E3: 0.047399888 | F3: 0.004071305 | G3: 0.072196343 | H3: 0.12037689 | I3: 0.10833905 | J3: 0.1228172 | K3: 0.36872327 | L3: -0.065372758 | M3: -0.21604465 | N3: -0.059410536 | O3: 0.087932967 | P3: -0.10432789 | Q3: -0.10420128 | R3: -0.24205416 | S3: 0.18721297 | T3: 0.23655584 | U3: 0.25497109 | V3: 0.042044083 | W3: 0.016438714 | X3: 0.1477895 | Y3: 0.11199233 | Z3: -0.0060520638 | AA3: 0.001634047 | AB3: 0.097676956 | AC3: 0.1560961 | AD3: 0.24428866 | AE3: -0.14252303 | AF3: 0.18248567 | AG3: 0.042552106 | AH3: 0.27759991 | AI3: -0.10696061 | AJ3: 0.050049781 | AK3: 0.088136328 | AL3: -0.26261863 | AM3: -0.22491355 | AN3: -0.159335 | AO3: -0.031063563 | AP3: -0.099944525 | AQ3: 0.094107401 | AR3: 0.014887979 | AS3: 0.28341576 | AT3: 0.24785178 | AU3: 0.13514283 | AV3: -0.024241223 | AW3: -0.056345476 | AX3: 0.024175169 | AY3: 0.05815388 | AZ3: -0.12436991 | BA3: -0.026782765 | BB3: 0.21486173 | BC3: 0.0089598729 | BD3: 0.10131388 | BE3: 0.17707676 | BF3: 0.032934382 | BG3: -0.0016573108 | BH3: 0.013141821 | BI3: 0.21110501 | BJ3: 0.11662681 | BK3: 0.069381252 | BL3: 0.14000846 | BM3: 0.040500464 | BN3: -0.016544769 | BO3: 0.074238141 | BP3: 0.083034132 | BQ3: 0.12375437 | BR3: 0.030365907 | BS3: 0.029886425 | BT3: 0.051264358 | BU3: -0.052662507 | BV3: 0.15348296 | BW3: 0.15907591 | BX3: 0.229396 | BY3: -0.064013013 | BZ3: -0.012887475 | CA3: 0.050978883 | CB3: -0.046380931 | CC3: 0.15734056 | CD3: 0.19089819 | CE3: 0.10918583 | CF3: 0.0032445071 | CG3: 0.054250875 | CH3: -0.24609025 | CI3: -0.14726345 | CJ3: -0.033873161 | CK3: 0.20642396 | CL3: 0.010880064 | CM3: 0.049193823 | CN3: 0.076595127 | CO3: 0.055331918
A4: Conv2d_2b_3x3.conv | B4: 0.38825815 | C4: 0.52682262 | D4: 1 | E4: 0.035060746 | F4: 0.09745793 | G4: 0.07483037 | H4: 0.10637282 | I4: 0.15005757 | J4: 0.39473794 | K4: 0.24559572 | L4: -0.1590536 | M4: -0.14777454 | N4: -0.23302153 | O4: -0.022783166 | P4: 0.038300508 | Q4: -0.072759999 | R4: -0.26415536 | S4: -0.022150743 | T4: 0.0093921071 | U4: -0.018308702 | V4: 0.062116973 | W4: 0.14932974 | X4: 0.16558131 | Y4: 0.047221277 | Z4: 0.068711686 | AA4: 0.18157515 | AB4: 0.11585401 | AC4: -0.038947863 | AD4: 0.12091249 | AE4: -0.23115199 | AF4: 0.17253815 | AG4: -0.1319764 | AH4: 0.22111768 | AI4: -0.073992651 | AJ4: -0.049855876 | AK4: -0.011642652 | AL4: -0.2780733 | AM4: -0.079486722 | AN4: 0.0080576876 | AO4: -0.061667644 | AP4: -0.068357858 | AQ4: -0.024282469 | AR4: 0.093543126 | AS4: -0.029383455 | AT4: 0.28354862 | AU4: 0.19661017 | AV4: -0.17224571 | AW4: -0.032015412 | AX4: -0.085938076 | AY4: 0.034529005 | AZ4: 0.021249984 | BA4: 0.15477046 | BB4: 0.21772818 | BC4: -0.11204625 | BD4: -0.09032989 | BE4: -0.053058417 | BF4: -0.13556667 | BG4: -0.20961467 | BH4: -0.17077705 | BI4: -0.14554109 | BJ4: -0.1972896 | BK4: 0.15394695 | BL4: 0.070157461 | BM4: 0.16679522 | BN4: 0.049719526 | BO4: 0.069162834 | BP4: 0.099846013 | BQ4: 0.070059986 | BR4: -0.30517766 | BS4: 0.016382148 | BT4: 0.20608808 | BU4: -0.02507056 | BV4: 0.025356268 | BW4: -0.065586195 | BX4: 0.10902977 | BY4: -0.2170085 | BZ4: -0.17747633 | CA4: 0.10522917 | CB4: -0.035633133 | CC4: 0.067561182 | CD4: 0.12493383 | CE4: 0.095993806 | CF4: -0.032121337 | CG4: 0.23651187 | CH4: 0.070033461 | CI4: -0.032426917 | CJ4: 0.056649388 | CK4: 0.13074188 | CL4: 0.14145592 | CM4: 0.0029033253 | CN4: 0.11246049 | CO4: 0.048400365
A5: maxpool1 | B5: 0.12094327 | C5: 0.047399888 | D5: 0.035060746 | E5: 1 | F5: 0.87948484 | G5: 0.6443488 | H5: 0.49368825 | I5: 0.34515076 | J5: 0.14377431 | K5: 0.065475667 | L5: 0.30940402 | M5: 0.075139576 | N5: 0.15459703 | O5: 0.47893549 | P5: 0.26988289 | Q5: 0.16888186 | R5: 0.2689246 | S5: -0.067163154 | T5: 0.068026752 | U5: 0.058430044 | V5: 0.27355819 | W5: 0.032713089 | X5: 0.25008168 | Y5: 0.21329364 | Z5: -0.21745795 | AA5: -0.083602132 | AB5: 0.24430901 | AC5: 0.34552349 | AD5: 0.097565028 | AE5: 0.029080838 | AF5: 0.00035928272 | AG5: 0.19749218 | AH5: 0.1268163 | AI5: 0.22424605 | AJ5: 0.137004 | AK5: 0.025750943 | AL5: -0.2910386 | AM5: -0.011712842 | AN5: -0.14117844 | AO5: 0.15228974 | AP5: 0.1787649 | AQ5: -0.0076107457 | AR5: 0.011462963 | AS5: 0.10202666 | AT5: -0.013195197 | AU5: 0.03490503 | AV5: -0.16742252 | AW5: -0.36334663 | AX5: -0.13647652 | AY5: 0.0616447 | AZ5: -0.021511615 | BA5: 0.12711556 | BB5: 0.13529031 | BC5: -0.17603057 | BD5: -0.24249473 | BE5: -0.032710295 | BF5: -0.093450033 | BG5: -0.18592697 | BH5: 0.0097156942 | BI5: -0.038409664 | BJ5: -0.084926948 | BK5: 0.0062325433 | BL5: 0.048848509 | BM5: 0.15890115 | BN5: 0.19489643 | BO5: 0.37161283 | BP5: 0.30511398 | BQ5: -0.077644017 | BR5: -0.024193533 | BS5: -0.12462906 | BT5: 0.0020557372 | BU5: -0.048246124 | BV5: -0.038617572 | BW5: 0.060818698 | BX5: 0.14689259 | BY5: -0.017710281 | BZ5: -0.11244918 | CA5: 0.07698524 | CB5: 0.051874356 | CC5: 0.082192925 | CD5: -0.039455378 | CE5: -0.249064 | CF5: 0.15205271 | CG5: 0.24980235 | CH5: -0.19309937 | CI5: -0.29364192 | CJ5: -0.26044686 | CK5: 0.3334986 | CL5: 0.17916545 | CM5: 0.052976114 | CN5: 0.088780468 | CO5: -0.17842739
A6: Conv2d_3b_1x1.conv | B6: -0.023167587 | C6: 0.004071305 | D6: 0.09745793 | E6: 0.87948484 | F6: 1 | G6: 0.64042316 | H6: 0.42410494 | I6: 0.26315263 | J6: 0.14017956 | K6: 0.18192785 | L6: 0.16101528 | M6: 0.023543103 | N6: 0.073111556 | O6: 0.44118772 | P6: 0.19058416 | Q6: 0.078169741 | R6: 0.17749029 | S6: -0.026753163 | T6: 0.034255608 | U6: 0.0028957648 | V6: 0.25603056 | W6: -0.026400082 | X6: 0.10945794 | Y6: 0.073028397 | Z6: -0.13824202 | AA6: 0.013907448 | AB6: 0.1460082 | AC6: 0.26564301 | AD6: 0.010282155 | AE6: -0.010643295 | AF6: -0.10494424 | AG6: 0.067187406 | AH6: 0.050772917 | AI6: 0.25174975 | AJ6: 0.16430178 | AK6: 0.094838112 | AL6: -0.2862195 | AM6: 0.018177238 | AN6: -0.09464447 | AO6: 0.13455675 | AP6: 0.1497099 | AQ6: -0.052517907 | AR6: -0.026347924 | AS6: 0.015981507 | AT6: -0.10740902 | AU6: 0.049826537 | AV6: -0.26659648 | AW6: -0.35155837 | AX6: -0.15764877 | AY6: 0.053725464 | AZ6: -0.045588335 | BA6: 0.12550579 | BB6: 0.14240284 | BC6: -0.2341961 | BD6: -0.24664344 | BE6: 0.026763464 | BF6: -0.1187386 | BG6: -0.23974874 | BH6: -0.11072303 | BI6: -0.1531922 | BJ6: -0.23438644 | BK6: 0.080831076 | BL6: 0.0039166972 | BM6: 0.15964518 | BN6: 0.12510982 | BO6: 0.35635503 | BP6: 0.2518913 | BQ6: -0.059036529 | BR6: 0.012991488 | BS6: -0.13613536 | BT6: 0.096265407 | BU6: 0.12223471 | BV6: -0.016547769 | BW6: -0.008905449 | BX6: 0.095663649 | BY6: -0.019647119 | BZ6: -0.22378277 | CA6: 0.093586716 | CB6: 0.080270264 | CC6: 0.031721481 | CD6: 0.0037196246 | CE6: -0.080827292 | CF6: 0.096432153 | CG6: 0.17778615 | CH6: -0.10231376 | CI6: -0.29916493 | CJ6: -0.13231886 | CK6: 0.20756583 | CL6: 0.066318079 | CM6: -0.070197387 | CN6: -0.05439819 | CO6: -0.23580365
A7: Conv2d_4a_3x3.conv | B7: -0.062516388 | C7: 0.072196343 | D7: 0.07483037 | E7: 0.6443488 | F7: 0.64042316 | G7: 1 | H7: 0.54896933 | I7: 0.31043639 | J7: 0.27915116 | K7: 0.31617377 | L7: 0.30523648 | M7: 0.27771294 | N7: 0.26602242 | O7: 0.42202236 | P7: 0.26602078 | Q7: 0.22093031 | R7: 0.33419273 | S7: -0.054927952 | T7: 0.17373816 | U7: 0.027101824 | V7: 0.3122207 | W7: 0.22172497 | X7: 0.30371205 | Y7: 0.21380783 | Z7: 0.017867774 | AA7: 0.076371328 | AB7: 0.19569853 | AC7: 0.30735583 | AD7: 0.31450403 | AE7: 0.030324742 | AF7: 0.072156899 | AG7: 0.3037182 | AH7: 0.15801538 | AI7: 0.12924481 | AJ7: 0.11185522 | AK7: 0.081866434 | AL7: 0.0056459069 | AM7: 0.19927858 | AN7: 0.13093656 | AO7: 0.32436902 | AP7: 0.16542893 | AQ7: 0.0017728784 | AR7: 0.26862621 | AS7: 0.11523526 | AT7: 0.24309032 | AU7: 0.16693814 | AV7: -0.18069043 | AW7: 0.021748955 | AX7: 0.13630356 | AY7: 0.17358062 | AZ7: 0.019883629 | BA7: 0.16964795 | BB7: 0.22851452 | BC7: 0.18120487 | BD7: 0.10299596 | BE7: 0.18540206 | BF7: -0.10154759 | BG7: -0.1044564 | BH7: 0.13530129 | BI7: 0.025349957 | BJ7: 0.09905895 | BK7: 0.14412315 | BL7: 0.24124349 | BM7: 0.059714363 | BN7: 0.0032934667 | BO7: 0.095645481 | BP7: 0.11368375 | BQ7: 0.066826995 | BR7: 0.12353464 | BS7: -0.11571607 | BT7: 0.047111117 | BU7: 0.057573687 | BV7: 0.12876982 | BW7: -0.032365826 | BX7: 0.23404477 | BY7: 0.015610775 | BZ7: -0.11480571 | CA7: 0.18887131 | CB7: -0.057171795 | CC7: -0.033545439 | CD7: 0.028680438 | CE7: -0.19606585 | CF7: 0.12842543 | CG7: 0.057273482 | CH7: -0.028423982 | CI7: -0.38752386 | CJ7: -0.012104917 | CK7: 0.15800534 | CL7: 0.087496501 | CM7: 0.013363848 | CN7: 0.030417724 | CO7: -0.094327594
A8: maxpool2 | B8: -0.062897954 | C8: 0.12037689 | D8: 0.10637282 | E8: 0.49368825 | F8: 0.42410494 | G8: 0.54896933 | H8: 1 | I8: 0.72233255 | J8: 0.26195208 | K8: 0.3106237 | L8: 0.39980193 | M8: 0.25158115 | N8: 0.26793541 | O8: 0.31532354 | P8: 0.44030472 | Q8: 0.24397547 | R8: 0.31713667 | S8: -0.046095702 | T8: 0.23014949 | U8: 0.095157719 | V8: 0.44322835 | W8: 0.26952872 | X8: 0.20833128 | Y8: 0.30960442 | Z8: 0.085072496 | AA8: 0.3042674 | AB8: 0.29551469 | AC8: 0.6135083 | AD8: 0.44169913 | AE8: 0.04662558 | AF8: 0.015658918 | AG8: 0.37354495 | AH8: 0.44692718 | AI8: 0.15196793 | AJ8: 0.16537164 | AK8: 0.025999665 | AL8: 0.037634211 | AM8: 0.20752348 | AN8: 0.13439886 | AO8: 0.33038416 | AP8: 0.17282042 | AQ8: 0.032641579 | AR8: 0.29318621 | AS8: 0.03490911 | AT8: -0.028077352 | AU8: -0.032713818 | AV8: -0.13959305 | AW8: -0.20454733 | AX8: -0.10302334 | AY8: 0.15372484 | AZ8: 0.10785238 | BA8: 0.20579593 | BB8: 0.35938995 | BC8: 0.18974055 | BD8: -0.009492696 | BE8: 0.13025533 | BF8: 0.20988352 | BG8: 0.04916748 | BH8: 0.24486568 | BI8: 0.053817518 | BJ8: -0.018952638 | BK8: 0.0075420654 | BL8: 0.33014072 | BM8: 0.25453804 | BN8: 0.19501393 | BO8: 0.33511921 | BP8: 0.25104858 | BQ8: -0.069340801 | BR8: -0.0923938 | BS8: -0.13332702 | BT8: 0.31654557 | BU8: 0.11284968 | BV8: -0.025180154 | BW8: 0.036792991 | BX8: 0.081143559 | BY8: 0.15171621 | BZ8: 0.17037569 | CA8: -0.023702419 | CB8: 0.035518035 | CC8: -0.12551843 | CD8: 0.061546629 | CE8: -0.22121315 | CF8: 0.09937909 | CG8: 0.16369415 | CH8: -0.41353762 | CI8: 0.01402797 | CJ8: -0.11711971 | CK8: 0.17863591 | CL8: 0.16957665 | CM8: 0.17665946 | CN8: 0.15521979 | CO8: -0.053944142
A9: Mixed_5b.branch1x1.conv | B9: -0.056614065 | C9: 0.10833905 | D9: 0.15005757 | E9: 0.34515076 | F9: 0.26315263 | G9: 0.31043639 | H9: 0.72233255 | I9: 1 | J9: 0.049031747 | K9: 0.19388818 | L9: 0.30920853 | M9: 0.10133045 | N9: 0.27182531 | O9: 0.23044368 | P9: 0.5505282 | Q9: 0.23771097 | R9: 0.25126909 | S9: -0.091372759 | T9: 0.24596298 | U9: 0.093967944 | V9: 0.4259743 | W9: 0.31866728 | X9: 0.31044228 | Y9: 0.27174045 | Z9: 0.068579157 | AA9: 0.16170724 | AB9: 0.1677507 | AC9: 0.56557876 | AD9: 0.31986481 | AE9: 0.075512271 | AF9: 0.039387409 | AG9: 0.15136541 | AH9: 0.44374571 | AI9: 0.077722961 | AJ9: 0.028778055 | AK9: 0.027341517 | AL9: 0.010463864 | AM9: 0.18536946 | AN9: 0.0965509 | AO9: 0.25941917 | AP9: 0.22556815 | AQ9: 0.053579213 | AR9: 0.2048613 | AS9: -0.22276726 | AT9: -0.14172192 | AU9: -0.15611164 | AV9: -0.11644245 | AW9: -0.20435927 | AX9: -0.19833167 | AY9: -0.046886228 | AZ9: -0.013356669 | BA9: 0.29170706 | BB9: 0.36089689 | BC9: 0.067009728 | BD9: -0.1572309 | BE9: -0.091112652 | BF9: 0.0040934141 | BG9: -0.033119604 | BH9: 0.099165858 | BI9: -0.027822991 | BJ9: -0.085554408 | BK9: -0.0365912 | BL9: 0.3771408 | BM9: 0.20944816 | BN9: 0.34872691 | BO9: 0.40351778 | BP9: 0.39556331 | BQ9: -0.20561772 | BR9: -0.13945285 | BS9: -0.11680884 | BT9: 0.36219491 | BU9: 0.073190993 | BV9: -0.26949247 | BW9: -0.06853938 | BX9: -0.099184546 | BY9: 0.052442943 | BZ9: 0.082489124 | CA9: -0.30100769 | CB9: 0.0064935838 | CC9: -0.34111445 | CD9: -0.14739065 | CE9: -0.30155608 | CF9: 0.11704769 | CG9: 0.14605978 | CH9: -0.17269329 | CI9: 0.097850779 | CJ9: -0.032745092 | CK9: 0.10884421 | CL9: 0.20277866 | CM9: 0.11711763 | CN9: 0.029177475 | CO9: -0.19415711
A10: Mixed_5b.branch5x5_1.conv | B10: 0.088452186 | C10: 0.1228172 | D10: 0.39473794 | E10: 0.14377431 | F10: 0.14017956 | G10: 0.27915116 | H10: 0.26195208 | I10: 0.049031747 | J10: 1 | K10: 0.40194763 | L10: -0.00626831 | M10: 0.11740633 | N10: -0.1131777 | O10: 0.17216439 | P10: 0.077789768 | Q10: 0.36778537 | R10: 0.17256535 | S10: -0.18550618 | T10: -0.21957228 | U10: -0.20130284 | V10: 0.057469144 | W10: -0.088026568 | X10: 0.14446466 | Y10: -0.039618782 | Z10: -0.065581046 | AA10: 0.078666911 | AB10: 0.21422953 | AC10: 0.12622844 | AD10: 0.1729159 | AE10: 0.0047327633 | AF10: 0.34085843 | AG10: 0.058122046 | AH10: 0.002635239 | AI10: 0.14693931 | AJ10: 0.25231278 | AK10: 0.029663165 | AL10: -0.21497871 | AM10: -0.055845767 | AN10: -0.098024643 | AO10: -0.12757246 | AP10: -0.16195946 | AQ10: -0.29466228 | AR10: 0.058999444 | AS10: -0.089305309 | AT10: -0.054865317 | AU10: 0.23165 | AV10: -0.21409415 | AW10: -0.024550472 | AX10: -0.12181916 | AY10: 0.13383219 | AZ10: 0.055783094 | BA10: -0.26611425 | BB10: -0.020308093 | BC10: 0.11279256 | BD10: -0.023771946 | BE10: -0.13025901 | BF10: -0.061837237 | BG10: -0.12875531 | BH10: 0.021349263 | BI10: -0.026077115 | BJ10: 0.0049269995 | BK10: -0.0020294915 | BL10: 0.0027591686 | BM10: 0.084939751 | BN10: 0.1397549 | BO10: 0.14123508 | BP10: -0.079129527 | BQ10: -0.053710071 | BR10: -0.10583899 | BS10: -0.041291195 | BT10: 0.13992225 | BU10: -0.050433257 | BV10: 0.0058126721 | BW10: 0.13957054 | BX10: 0.13838862 | BY10: 0.047728885 | BZ10: 0.12445168 | CA10: 0.10710243 | CB10: -0.080144849 | CC10: 0.0048375953 | CD10: 0.13249145 | CE10: 0.13741611 | CF10: 0.060018346 | CG10: 0.066060944 | CH10: -0.068200955 | CI10: -0.28824372 | CJ10: -0.1217488 | CK10: -0.00040719394 | CL10: 0.1779173 | CM10: 0.2041084 | CN10: 0.24932222 | CO10: 0.0068804762
A11: Mixed_5b.branch5x5_2.conv | B11: 0.02874558 | C11: 0.36872327 | D11: 0.24559572 | E11: 0.065475667 | F11: 0.18192785 | G11: 0.31617377 | H11: 0.3106237 | I11: 0.19388818 | J11: 0.40194763 | K11: 1 | L11: -0.089900139 | M11: 0.0011973428 | N11: -0.020648604 | O11: 0.14823811 | P11: -0.095519179 | Q11: 0.066743713 | R11: 0.025872787 | S11: 0.058954082 | T11: 0.13350999 | U11: -0.092853877 | V11: -0.12529587 | W11: -0.055767644 | X11: 0.15012874 | Y11: -0.1133261 | Z11: 0.040962468 | AA11: 0.05455829 | AB11: 0.22987311 | AC11: 0.17945414 | AD11: 0.3294219 | AE11: 0.062920448 | AF11: 0.082554731 | AG11: 0.047787853 | AH11: 0.22978279 | AI11: 0.14578486 | AJ11: 0.22552461 | AK11: -0.010024429 | AL11: -0.15750117 | AM11: -0.071660465 | AN11: 0.095417027 | AO11: 0.07420984 | AP11: -0.10266158 | AQ11: -0.24107884 | AR11: 0.22961441 | AS11: 0.02898634 | AT11: 0.11113953 | AU11: 0.20773849 | AV11: -0.1224109 | AW11: -0.01467634 | AX11: -0.029683058 | AY11: 0.19403119 | AZ11: 0.035285653 | BA11: -0.049222152 | BB11: 0.12486852 | BC11: 0.28819145 | BD11: 0.14864244 | BE11: 0.094905975 | BF11: 0.021606969 | BG11: -0.24069659 | BH11: -0.30987229 | BI11: -0.30410429 | BJ11: -0.29791617 | BK11: 0.10492601 | BL11: 0.15523621 | BM11: 0.11943211 | BN11: 0.16193631 | BO11: 0.15566737 | BP11: -0.043728773 | BQ11: -0.10683688 | BR11: -0.02514416 | BS11: -0.11172202 | BT11: 0.1628934 | BU11: 0.055442814 | BV11: -0.0080002189 | BW11: -0.014182511 | BX11: 0.09865964 | BY11: 0.056274028 | BZ11: -0.032553307 | CA11: -0.030221461 | CB11: 0.0084891763 | CC11: -0.092039905 | CD11: 0.050799251 | CE11: -0.00081043026 | CF11: 0.10525509 | CG11: -0.023182173 | CH11: -0.14395933 | CI11: -0.18663248 | CJ11: 0.17612837 | CK11: -0.033172864 | CL11: -0.065978075 | CM11: -0.0090405604 | CN11: -0.072726227 | CO11: -0.016829
A12: Mixed_5b.branch3x3dbl_1.conv | B12: 0.084729295 | C12: -0.065372758 | D12: -0.1590536 | E12: 0.30940402 | F12: 0.16101528 | G12: 0.30523648 | H12: 0.39980193 | I12: 0.30920853 | J12: -0.00626831 | K12: -0.089900139 | L12: 1 | M12: 0.55637214 | N12: 0.2621458 | O12: 0.076604418 | P12: 0.30614201 | Q12: 0.27610466 | R12: 0.25070856 | S12: 0.014792686 | T12: 0.10051082 | U12: 0.19430352 | V12: 0.1749537 | W12: 0.11516982 | X12: 0.18497755 | Y12: 0.30323808 | Z12: -0.10139115 | AA12: -0.074131513 | AB12: 0.26697669 | AC12: 0.36289704 | AD12: 0.332401 | AE12: 0.080975742 | AF12: -0.12981413 | AG12: 0.261899 | AH12: 0.14809786 | AI12: 0.25186874 | AJ12: 0.23966668 | AK12: 0.25043141 | AL12: 0.11374596 | AM12: 0.062829208 | AN12: -0.066043827 | AO12: 0.21023894 | AP12: 0.096108633 | AQ12: 0.084848221 | AR12: 0.18414592 | AS12: 0.22520429 | AT12: 0.11476976 | AU12: 0.077683722 | AV12: 0.084374497 | AW12: 0.089515063 | AX12: 0.13846183 | AY12: 0.10876177 | AZ12: 0.16134252 | BA12: -0.0058366729 | BB12: 0.20246648 | BC12: 0.016792619 | BD12: -0.23067204 | BE12: -0.18732321 | BF12: 0.49523869 | BG12: 0.50198978 | BH12: 0.42821074 | BI12: 0.30372144 | BJ12: 0.35435878 | BK12: -0.042848101 | BL12: 0.053697077 | BM12: 0.33826332 | BN12: 0.13323576 | BO12: 0.16489833 | BP12: 0.16697202 | BQ12: -0.10571585 | BR12: 0.013705529 | BS12: -0.208234 | BT12: 0.14492073 | BU12: 0.14349992 | BV12: -0.14130941 | BW12: 0.0027268248 | BX12: -0.039630015 | BY12: -0.091706151 | BZ12: 0.058850435 | CA12: -0.083488545 | CB12: -0.2688723 | CC12: -0.060961745 | CD12: 0.050031212 | CE12: -0.26053119 | CF12: 0.16040467 | CG12: 0.15749548 | CH12: -0.23087173 | CI12: -0.055899287 | CJ12: -0.022873743 | CK12: 0.2104688 | CL12: 0.13700583 | CM12: 0.16808693 | CN12: 0.046142691 | CO12: -0.11010013
A13: Mixed_5b.branch3x3dbl_2.conv | B13: 0.021444441 | C13: -0.21604465 | D13: -0.14777454 | E13: 0.075139576 | F13: 0.023543103 | G13: 0.27771294 | H13: 0.25158115 | I13: 0.10133045 | J13: 0.11740633 | K13: 0.0011973428 | L13: 0.55637214 | M13: 1 | N13: 0.58091746 | O13: 0.047182415 | P13: 0.37971179 | Q13: 0.45024431 | R13: 0.42983378 | S13: -0.22130249 | T13: -0.098964428 | U13: -0.10015737 | V13: 0.23164113 | W13: 0.18107858 | X13: 0.0021929202 | Y13: 0.2962099 | Z13: -0.040597783 | AA13: -0.038467967 | AB13: 0.09830873 | AC13: 0.43720546 | AD13: 0.357291 | AE13: 0.0076915977 | AF13: -0.11427005 | AG13: 0.078157397 | AH13: 0.094367636 | AI13: 0.063719006 | AJ13: 0.042216104 | AK13: 0.0091982763 | AL13: 0.31581982 | AM13: 0.3711482 | AN13: 0.29992106 | AO13: 0.41092902 | AP13: 0.26772227 | AQ13: -0.016327636 | AR13: 0.20637939 | AS13: 0.083289333 | AT13: 0.26645348 | AU13: 0.017623848 | AV13: 0.024093886 | AW13: 0.17671945 | AX13: 0.12601226 | AY13: -0.052392561 | AZ13: 0.11346693 | BA13: 0.02025242 | BB13: 0.010252361 | BC13: 0.22608347 | BD13: -0.062038284 | BE13: -0.098123052 | BF13: 0.28047456 | BG13: 0.18956262 | BH13: 0.26120586 | BI13: 0.040730834 | BJ13: 0.2697222 | BK13: 0.073913974 | BL13: -0.025516794 | BM13: 0.18471305 | BN13: 0.12882135 | BO13: 0.14669506 | BP13: 0.068969291 | BQ13: -0.064302392 | BR13: -0.06355314 | BS13: -0.3811162 | BT13: -0.051551238 | BU13: 0.16438441 | BV13: 0.0036676375 | BW13: 0.032498446 | BX13: 0.10188733 | BY13: 0.014861464 | BZ13: 0.079232257 | CA13: 0.062328813 | CB13: -0.31396379 | CC13: -0.026374004 | CD13: -0.17354085 | CE13: -0.23643396 | CF13: 0.12489642 | CG13: -0.0070856576 | CH13: -0.11370029 | CI13: -0.056982228 | CJ13: 0.078570836 | CK13: 0.048031514 | CL13: 0.1467979 | CM13: 0.078702067 | CN13: -0.041357143 | CO13: -0.044565824
... A93: Mixed_6e.branch_pool.conv | B93: 0.11830364 | C93: 0.055331918 | D93: 0.048400365 | E93: -0.17842739 | F93: -0.23580365 | G93: -0.094327594 | H93: -0.053944142 | I93: -0.19415711 | J93: 0.0068804762 | K93: -0.016829 | L93: -0.11010013 | M93: -0.044565824 | N93: 0.081352728 | O93: -0.12944289 | P93: 0.010559295 | Q93: -0.070876429 | R93: -0.01716686 | S93: 0.028939022 | T93: -0.0054882461 | U93: -0.0079255414 | V93: -0.18728769 | W93: 0.11361923 | X93: -0.042653857 | Y93: -0.16090972 | Z93: -0.069418586 | AA93: 0.11335738 | AB93: 0.15555003 | AC93: -0.23739502 | AD93: 0.17934988 | AE93: -0.039206417 | AF93: -0.05823079 | AG93: -0.040743552 | AH93: 0.31671938 | AI93: -0.0093205197 | AJ93: -0.053436779 | AK93: -0.029434989 | AL93: 0.066048318 | AM93: 0.057885542 | AN93: 0.11228538 | AO93: 0.15974608 | AP93: 0.077104384 | AQ93: -0.058415327 | AR93: 0.28741966 | AS93: 0.27328705 | AT93: 0.19712463 | AU93: 0.006860057 | AV93: 0.010004365 | AW93: 0.18197923 | AX93: 0.24566592 | AY93: 0.063274192 | AZ93: -0.013196707 | BA93: 0.1644658 | BB93: 0.10388808 | BC93: 0.31191694 | BD93: 0.37675993 | BE93: 0.41099365 | BF93: 0.1211844 | BG93: 0.057403759 | BH93: 0.0014445339 | BI93: 0.11972209 | BJ93: -0.01383246 | BK93: 0.26288173 | BL93: -0.0045803568 | BM93: -0.16165039 | BN93: -0.14320352 | BO93: -0.25188612 | BP93: -0.21060948 | BQ93: 0.1651896 | BR93: -0.0614738 | BS93: -0.15193233 | BT93: -0.091478176 | BU93: -0.33270889 | BV93: 0.13818185 | BW93: 0.10308594 | BX93: 0.13580138 | BY93: -0.026867082 | BZ93: 0.12595892 | CA93: 0.13950561 | CB93: -0.081831392 | CC93: -0.0094420458 | CD93: -0.061824357 | CE93: 0.20145516 | CF93: 0.011614098 | CG93: -0.095604567 | CH93: 0.070833693 | CI93: -0.16589102 | CJ93: -0.24340872 | CK93: 0.10305211 | CL93: 0.11520307 | CM93: 0.12998207 | CN93: 0.18265523 | CO93: 1

Sheet Class_2
B1: Conv2d_1a_3x3.conv | C1: Conv2d_2a_3x3.conv | D1: Conv2d_2b_3x3.conv | E1: maxpool1 | F1: Conv2d_3b_1x1.conv | G1: Conv2d_4a_3x3.conv | H1: maxpool2 | I1: Mixed_5b.branch1x1.conv | J1: Mixed_5b.branch5x5_1.conv | K1: Mixed_5b.branch5x5_2.conv | L1: Mixed_5b.branch3x3dbl_1.conv | M1: Mixed_5b.branch3x3dbl_2.conv | N1: Mixed_5b.branch3x3dbl_3.conv | O1: Mixed_5b.branch_pool.conv | P1: Mixed_5c.branch1x1.conv | Q1: Mixed_5c.branch5x5_1.conv | R1: Mixed_5c.branch5x5_2.conv | S1: Mixed_5c.branch3x3dbl_1.conv | T1: Mixed_5c.branch3x3dbl_2.conv | U1: Mixed_5c.branch3x3dbl_3.conv | V1: Mixed_5c.branch_pool.conv | W1: Mixed_5d.branch1x1.conv | X1: Mixed_5d.branch5x5_1.conv | Y1: Mixed_5d.branch5x5_2.conv | Z1: Mixed_5d.branch3x3dbl_1.conv | AA1: Mixed_5d.branch3x3dbl_2.conv | AB1: Mixed_5d.branch3x3dbl_3.conv | AC1: Mixed_5d.branch_pool.conv | AD1: Mixed_6a.branch3x3.conv | AE1: Mixed_6a.branch3x3dbl_1.conv | AF1: Mixed_6a.branch3x3dbl_2.conv | AG1: Mixed_6a.branch3x3dbl_3.conv | AH1: Mixed_6b.branch1x1.conv | AI1: Mixed_6b.branch7x7_1.conv | AJ1: Mixed_6b.branch7x7_2.conv | AK1: Mixed_6b.branch7x7_3.conv | AL1: Mixed_6b.branch7x7dbl_1.conv | AM1: Mixed_6b.branch7x7dbl_2.conv | AN1: Mixed_6b.branch7x7dbl_3.conv | AO1: Mixed_6b.branch7x7dbl_4.conv | AP1: Mixed_6b.branch7x7dbl_5.conv | AQ1: Mixed_6b.branch_pool.conv | AR1: Mixed_6c.branch1x1.conv | AS1: Mixed_6c.branch7x7_1.conv | AT1: Mixed_6c.branch7x7_2.conv | AU1: Mixed_6c.branch7x7_3.conv | AV1: Mixed_6c.branch7x7dbl_1.conv | AW1: Mixed_6c.branch7x7dbl_2.conv | AX1: Mixed_6c.branch7x7dbl_3.conv | AY1: Mixed_6c.branch7x7dbl_4.conv | AZ1: Mixed_6c.branch7x7dbl_5.conv | BA1: Mixed_6c.branch_pool.conv | BB1: Mixed_6d.branch1x1.conv | BC1: Mixed_6d.branch7x7_1.conv | BD1: Mixed_6d.branch7x7_2.conv | BE1: Mixed_6d.branch7x7_3.conv | BF1: Mixed_6d.branch7x7dbl_1.conv | BG1: Mixed_6d.branch7x7dbl_2.conv | BH1: Mixed_6d.branch7x7dbl_3.conv | BI1: Mixed_6d.branch7x7dbl_4.conv | BJ1: Mixed_6d.branch7x7dbl_5.conv | BK1: Mixed_6d.branch_pool.conv | BL1: Mixed_6e.branch1x1.conv | BM1: sensitivityscore_After_Mixed_6e.branch1x1.conv_0.5 | BN1: sensitivityscore_After_Mixed_6e.branch1x1.conv_0.6 | BO1: sensitivityscore_After_Mixed_6e.branch1x1.conv_0.7 | BP1: sensitivityscore_After_Mixed_6e.branch1x1.conv_0.8 | BQ1: Mixed_6e.branch7x7_1.conv | BR1: sensitivityscore_After_Mixed_6e.branch7x7_1.conv_0.5 | BS1: sensitivityscore_After_Mixed_6e.branch7x7_1.conv_0.6 | BT1: sensitivityscore_After_Mixed_6e.branch7x7_1.conv_0.7 | BU1: sensitivityscore_After_Mixed_6e.branch7x7_1.conv_0.8 | BV1: Mixed_6e.branch7x7_2.conv | BW1: sensitivityscore_After_Mixed_6e.branch7x7_2.conv_0.5 | BX1: sensitivityscore_After_Mixed_6e.branch7x7_2.conv_0.6 | BY1: sensitivityscore_After_Mixed_6e.branch7x7_2.conv_0.7 | BZ1: sensitivityscore_After_Mixed_6e.branch7x7_2.conv_0.8 | CA1: Mixed_6e.branch7x7_3.conv | CB1: sensitivityscore_After_Mixed_6e.branch7x7_3.conv_0.5 | CC1: sensitivityscore_After_Mixed_6e.branch7x7_3.conv_0.6 | CD1: sensitivityscore_After_Mixed_6e.branch7x7_3.conv_0.7 | CE1: sensitivityscore_After_Mixed_6e.branch7x7_3.conv_0.8 | CF1: Mixed_6e.branch7x7dbl_1.conv | CG1: sensitivityscore_After_Mixed_6e.branch7x7dbl_1.conv_0.5 | CH1: sensitivityscore_After_Mixed_6e.branch7x7dbl_1.conv_0.6 | CI1: sensitivityscore_After_Mixed_6e.branch7x7dbl_1.conv_0.7 | CJ1: sensitivityscore_After_Mixed_6e.branch7x7dbl_1.conv_0.8 | CK1: Mixed_6e.branch7x7dbl_2.conv | CL1: Mixed_6e.branch7x7dbl_3.conv | CM1: Mixed_6e.branch7x7dbl_4.conv | CN1: Mixed_6e.branch7x7dbl_5.conv | CO1: Mixed_6e.branch_pool.conv
